Workbook

Sheet ALL
A1: Customer | B1: Property-Owner Name | C1: JOROBE, DELICIA | D1: BOYD | E1: +
B2: Property address: street | C2: 4085 E 153RD ST | D2: 24990 WOODLINE | E2: 16319 S, LOTUS
B3: Property city, state, zip | C3: CLEVELAND, OH 44128 | D3: Bedford Heights, OH 44146 | E3: Cleveland, OH 44128
B4: Customer Email | C4: EMI | D4: Customer Email | E4: livingessencestudio13@gmail.com
B5: Cst-owner Phone# | C5: (216) 466-1853 | D5: Cst-owner Phone# | E5: (216) 990-5643
B6: Co-Owner.cst#2 | C6: NA | D6: Co-Owner.cst#2 | E6: NA
B7: cst ph # 2 | C7: na | D7: 0 | E7: na
B8: Cst address # 2 | C8: 3224 E OVERLOOK RD | D8: 0 | E8: na
B9: city, state-cst#2 | C9: CLEVELAND HEIGHTS, OH 44118 | D9: 0 | E9: na
B10: email-cst #2 | C10: na | D10: 0 | E10: na
A11: Loss Info | B11: Cause of Loss | C11: WEATHER RELATED | D11: Wind = Roof | E11: WIND
B12: date of loss | C12: 44254 | D12: date of loss | E12: 44665
B13: rebuild type 1 | C13: interior repairs | D13: rebuild type 1 | E13: exterior repairs
B14: rebuild type 2 | C14: exterior repairs | D14: rebuild type 2 | E14: interior repairs
B15: rebuild type 3 | C15: NA | D15: rebuild type 3 | E15: 0
B16: DEMO | C16: Y | D16: DEMO | E16: y
B17: Mitigation | C17: N | D17: Mitigation | E17: TBD
B18: Other Structures | C18: N | D18: Other Structures | E18: na
A19: CPS | B19: Replacement | C19: Y | D19: Y | E19: y
B20: CPS / CLN / CON/ CGN | C20: Y | D20: Y | E20: NA
B21: Year Built | C21: PRE 1980 | D21: AFTER 1980 | E21: pre 1980
B22: Contract Date | C22: 44723 | D22: Contract Date | E22: 44673
B23: Loss of use/ ALE | C23: TBD | D23: Loss of use/ ALE | E23: y
B24: Breathing issue | C24: NA | D24: TBD | E24: TBD
B25: HMR | C25: NA | D25: TBD | E25: tbd
B26: Insurance Co. Name | C26: TRAVCO INSURANCE | D26: STATE FARM | E26: WESTFIELD INS
A27: Insurance Co. | B27: Claim # | C27: IKW2742001H | D27: 35 | E27: CLM #0002332090
B28: policy # | C28: 0M7310604029830653 1 | D28: policy # | E28: PL
B29: Email INS. co. | C29: www.travelers.com/claimuploadcenter. | D29: Email INS. co. | E29: 0
B30: DESK Adjuster DA | C30: Kenneth Pride | D30: DESK Adjuster DA | E30: COPE, BRITTANY
B31: DA Phone | C31: (216) 618-4382 | D31: DA Phone | E31: 330.887.0386
B32: DA Ph. Ext. # | C32: (216) 618-4382 | D32: DA Ph. Ext. # | E32: 330.887.0386
B33: DA Email | C33: KPRIDE@travelers.com | D33: DA Email | E33: BRITTANYCOPE@WESTFIELDGRP.COM
B34: Field Adjuster Name | C34: 0 | D34: Field Adjuster Name | E34: FA
B35: Phone # field adj | C35: 0 | D35: Phone # field adj | E35: PH
B36: Field adj email | C36: 0 | D36: Field adj email | E36: EMI
B37: adj contents | C37: CA | D37: adj contents | E37: CA
B38: adj CPS phone # | C38: PH | D38: adj CPS phone # | E38: PH
B39: adj CPS email | C39: CPS | D39: adj CPS email | E39: CPS
B40: TMP adj | C40: TMP | D40: EMS adj | E40: TMP
...

Sheet Sheet1
A1: S500 Page 43 9.2.8 Emergencies
A2: In many Circumstances, water damage restoration projects begin on an emergency basis. Emergency situations might impede communications about the project or limit the opportunity to document the project as described in this section. However, once an emergency situation is resolved, to the extent possible, restorers should complete the appropriate documentation and correct communication deficiencies caused by the emergency
A3: S500 Page 58 12.2.1
A4: Mitigation Procedures should begin as soon as safely possible following the initial moisture intrusion. If building materials and structural assemblies are exposed to water vapor for extended periods, moisture penetrates into them more Deeply. The more water they absorb, the more Time, Effort, and Expensive required to dry them.
A5: With extended exposure to moisture, some materials undergo permanent damage that could have been partially or completely prevented with a more rapid response, in addition, in most environments the extended presence of water or excessive humidity can lead to microbial growth ( E.G., Bacteria and Mold) amplification that can cause a general deterioration of environmental conditions over time, potentially leading to significant health and safety hazards for workers and occupations.
A8: negative air calcs, you probably need about 100-200cfm negative air
A10: Achieve negative air pressure with that window
A15: Bi-product of incomplete combustion is smoke and soot. If synthetic materials burned, ie polyester from couches and mattresses and other similar items it omits very dangerous particles such as hydrogen cyanide and so one. This the NFPA requires firefighters to do overhaul (fire is out) in full PPE and SCBA. Therefore, everything in that home where soot and smoke damage may be is a hazardous environment. Call it CAT 3 or regulated hazard it is still hazardous.
A21: **Absent a direct contract with an insurer, restoration contractors are under no legal obligation to an insurer, its adjuster, or a third party. Restorers may, in their professional discretion and judgment, accept or reject the opinions and requests from insurers and their consultants. Unless and until such opinions are mutually agreed upon by the restorer and the customer, and formally incorporated into the restoration contract or scope of required work, third party opinions have no effect on the restorer’s duties. The insurer’s consultant’s opinions are not binding on the restorer. See attached industry peer reviewed white paper, “RIA – TPC Price Positioning Statement.”

Sheet CPS RPT
B1: DATE | C1: CO. | D1: NAME | E1: STREET | F1: CITY | G1: ZIP | H1: JOB | I1: 1. GENERAL AUTH | J1: 2. customer agreement | K1: 3. W9 | L1: 4. JOBSITE VERIFY & SOL | M1: 5,PKT 5.CPS BOX COUNT REPORT | N1: 6 PKT XACTIMATE CPS INVOICE | O1: EMAIL # 1 | P1: 7 JOB Overview pics | Q1: 8. CPS Overview Photos | R1: 9 CPS BOX COUNT PHOTO REPORT | S1: 10. EMAIL COVER SHEET | T1: PRIORITY | U1: ACTIVE
C2: APC | D2: Ali, Tony | F2: WESTLAKE | H2: WTR | L2: Y | M2: Y | P2: Y | R2: Y | T2: 1 | U2: ACTIVE
C3: APC | D3: Battle, Larry Jr | F3: Parma | H3: WTR | I3: y | J3: y | L3: y | M3: y | P3: y | Q3: y | R3: y | T3: 1 | U3: ACTIVE
C4: OH23P | D4: BOYD | E4: WOODLINE | G4: 44146 | H4: RFG | L4: y | M4: y | P4: y | T4: 9 | U4: ACTIVE
B5: 45193 | C5: OH22P | D5: Eaton, Marilyn | E5: 4514 East Blvd | F5: Garfield Hts., OH | G5: 44105 | H5: RFG | L5: y | M5: y | P5: y | R5: y | T5: 9 | U5: ACTIVE
C6: OH | D6: EDWINS LEADERSHIP | L6: y | P6: y | T6: 2 | U6: ACTIVE
D7: Four Symbolic Lodge | E7: 14402 KINSMAN | G7: OH | H7: W/H | L7: y | T7: 3 | U7: ACTIVE
A8: ACT | C8: APC | D8: Franklin, Annette | E8: E 256 | H8: RFG | I8: y | J8: y | L8: y | M8: y | P8: y | Q8: y | R8: y | T8: 1 | U8: ACTIVE
C9: APC | D9: GOVEA, JESUS | F9: Jonesboro | H9: WTR | I9: y | J9: y | L9: y | M9: y | P9: y | R9: y | T9: 1 | U9: ACTIVE
D10: GREENWALT MIKE | E10: 11601 GOVERNOR | G10: OH | H10: W/H | M10: y | R10: y | T10: 6 | U10: ACTIVE
D11: GRIFFUS TINA | E11: 1954 SPRINGSIDE | G11: OH | H11: WTR | L11: y | T11: 9 | U11: ACTIVE
A12: WFI | B12: 44665 | C12: APC | D12: Harmon, Lisa | E12: 16319 S. Lotus | F12: Cleveland, | G12: 44128 | H12: RFG | I12: Y | J12: Y | L12: y | M12: y | P12: y | Q12: y | R12: y | T12: 1 | U12: ACTIVE
C13: OH23P | D13: HARVEY, CORA | E13: GREENHURST | H13: WTR | L13: y | M13: y | Q13: y | R13: y | T13: 1 | U13: ACTIVE
C14: OH23P | D14: Hobbs, Donetta & Nemon | E14: GLENSIDE | H14: WTR | I14: y | J14: y | L14: y | T14: 1 | U14: ACTIVE
A15: XXX | B15: 44627 | C15: APC | D15: Jackson,Sandra | E15: 310 Landing Dr. | F15: Fayetteville | G15: GA | H15: RFG | J15: y | L15: y | M15: y | P15: y | Q15: y | T15: 2 | U15: ACTIVE
A16: ACT | C16: APC | D16: Jones, Margaret | E16: 23209 Vera Street | F16: Warrensville HGTS | G16: OH | H16: RFG | T16: 1 | U16: ACTIVE
A17: ACT | C17: APC | D17: Jones, Margaret | E17: 23209 Vera Street | F17: Warrensville HGTS | G17: OH | H17: RFG | T17: 1 | U17: ACTIVE
A18: TRV | B18: 44596 | C18: APC | D18: Kimble, Audrey | E18: 2756 Northwood Ct. | F18: Marietta, | G18: GA | H18: RFG | I18: Y | J18: Y | L18: Y | M18: Y | P18: Y | Q18: Y | T18: 2 | U18: ACTIVE
D19: KOSWATTA ERIKA | T19: 2 | U19: ACTIVE
C20: APC | D20: LAWRENCE, GENEATHA | E20: STRANDHILL | H20: RFG | I20: y | J20: y | L20: y | T20: 1 | U20: ACTIVE
C21: APC | D21: Lawson, Ms. LORI | E21: TULLAMORE | H21: RFG | I21: x | J21: x | L21: x | M21: x | T21: 1 | U21: ACTIVE
C22: OH23P | D22: Leeth, Ronald | E22: MIAMI | H22: WTR | I22: y | J22: y | K22: y | L22: y | M22: y | P22: y | Q22: y | R22: y | T22: 1 | U22: ACTIVE
D23: LISA THOMAS | E23: 5149 MILLER AVE | G23: OH | H23: W/H | L23: y | T23: 1 | U23: ACTIVE
C24: APC | D24: LOCKHART | E24: E238 | F24: EUCLID | G24: 44134 | H24: WTR | I24: y | J24: Y | L24: Y | M24: Y | P24: Y | Q24: Y | T24: 1 | U24: ACTIVE
C25: APC | D25: LOZANO, Marcus | F25: AUSTELL | H25: WTR | I25: y | J25: y | L25: y | M25: y | P25: y | Q25: y | R25: y | T25: 1 | U25: ACTIVE
C26: APC | D26: Matlock, Paggie | E26: OAKWOOD | H26: RFG | L26: y | M26: y | P26: y | R26: y | T26: 2 | U26: ACTIVE
B27: GA23A | C27: APC | D27: Moiye 3, Ras | E27: DIXLEEON | H27: WTR | I27: y | J27: y | L27: y | P27: y | Q27: y | R27: y | T27: 1 | U27: ACTIVE
A28: SFI | B28: 44908 | C28: APC | D28: Moiye, Ras 1 | E28: 395 Dix Lee-On Ct | F28: Fayetteville | G28: GA | H28: WTR | T28: 1 | U28: ACTIVE
D29: MURRAY MONICA | E29: USA | H29: WTR | T29: 1 | U29: ACTIVE
B30: 44640 | C30: APC | D30: NDU, Belinda | E30: 255 Astaire Manor | F30: Fayetteville | G30: GA | H30: WTR | I30: y | J30: y | L30: y | M30: y | T30: 2 | U30: ACTIVE
B31: 45241 | C31: OH22P | D31: Paige, Tom | E31: 4492 St. Germain Blvd | F31: Cleveland, OH | G31: 44128 | H31: TREE | L31: Y | M31: Y | T31: 2 | U31: ACTIVE
C32: OHA | D32: PATEL | E32: OH23T-PATEL@MOTEL | H32: WTR | T32: 9 | U32: ACTIVE
C33: OH23P | D33: Price, TRACIE | E33: W. ROCKLAND | H33: RFG | I33: y | J33: y | L33: y | P33: y | T33: 2 | U33: ACTIVE
A34: USA | B34: 44921 | C34: APC | D34: Reid, Andrew | E34: 2528 East Alberson Dr. | F34: Albany | G34: GA | H34: RFG | I34: Y | J34: Y | L34: Y | M34: Y | T34: 1 | U34: ACTIVE
B35: 44856 | C35: APC | D35: Ringo, Craig | E35: 5697 Daniel Dr. | F35: Bedford Hts | G35: 44146 | H35: WTR | K35: Y | L35: Y | M35: Y | P35: Y | Q35: Y | R35: Y | T35: 1 | U35: ACTIVE
C36: APC | D36: MEADOWS, ROB | E36: 160 FAIRFAX | F36: CLE | G36: 44128 | H36: THEFT | I36: y | J36: y | T36: 1 | U36: ACTIVE
D37: ROBINSON NIKKOLE | E37: 357 E 270 EUCLID | F37: OH | H37: WTR | I37: y | J37: y | L37: y | Q37: y | T37: 1 | U37: ACTIVE
B38: 44914 | C38: APC | D38: Salem, Zahara | E38: 841 Horseshoe Way | F38: Avon Lake | G38: 44111 | H38: WTR | L38: y | M38: y | P38: y | T38: 2 | U38: ACTIVE
C39: OH22P | D39: SARKAR | E39: DAVIDSON | F39: Richmond Hts., OH | G39: 44143 | H39: WTR | L39: y | M39: y | T39: 1 | U39: ACTIVE
C40: APC | D40: Stroud, Brittany | E40: 5106 East 113th Street, | F40: Garfield | H40: FIRE | I40: Y | J40: Y | L40: Y | T40: 1 | U40: ACTIVE
...

Sheet ALL 2
B1: DATE | C1: CO. | D1: NAME | E1: STREET | F1: CITY | G1: ZIP | H1: JOB | I1: 1. GENERAL AUTH | J1: 2.customer agreement | K1: Email (#1) | L1: 3.W9 | M1: 4. JOBSITE VERIFY & SOL | N1: 5,PKT CPS BOX COUNT REPORT | O1: 6 PKT XACTIMATE CPS INVOICE | P1: 7 JOB Overview pics | Q1: 8. CPS Overview Photos | R1: 9 CPS BOX COUNT PHOTO REPORT | S1: 10. EMAIL COVER SHEET | U1: ACTIVE
C2: APC | D2: AGNEW | F2: Cleveland | G2: 44087 | H2: WTR | I2: N | J2: N | K2: N | L2: N | M2: Y | N2: Y | P2: Y | Q2: Y | R2: Y | U2: ACTIVE
C3: APC | D3: Ali, Tony | F3: WESTLAKE | H3: WTR | I3: N | J3: N | K3: N | L3: N | M3: Y | N3: Y | O3: Y | P3: Y | Q3: Y | R3: Y | U3: ACTIVE
B4: 44920 | C4: APC | D4: Anderson, Vanessa | E4: 771 Edgewood Rd. | F4: Richmond Hts. | G4: 44134 | H4: WTR | I4: PAID | J4: =TRIM(Q4) -> PAID | K4: PAID | L4: PAID | M4: PAID | N4: PAID | O4: PAID | P4: PAID | Q4: PAID | R4: PAID | S4: PAID | U4: ACTIVE
D5: Ayo Akalla | E5: 3685 E 153 | H5: FIRE | I5: N | J5: N | K5: N | L5: N | M5: N | N5: N | O5: N | P5: N | Q5: N | R5: N | U5: ACTIVE
C6: APC | D6: Battle, Larry Jr | E6: Parma | H6: WTR | I6: Y | J6: Y | K6: Y | L6: N | M6: Y | N6: Y | O6: Y | Q6: Y | U6: ACTIVE
C7: OH23P | D7: BOYD | E7: WOODLINE | G7: 44146 | H7: RFG | I7: N | J7: N | K7: N | L7: N | M7: Y | N7: Y | Q7: TBD | R7: Y | S7: Y | U7: ACTIVE
B8: 45284 | C8: OH22P | D8: BROADHEAD | E8: CEDAR | G8: 44106 | H8: WTR | I8: N | J8: N | M8: Y | N8: Y | P8: Y | Q8: Y | R8: Y | U8: ACTIVE
D9: BROWN ANETTA | U9: ACTIVE
C10: APC | D10: BrowN,Terell | E10: MANOR | H10: WTR | I10: Y | J10: Y | M10: Y | N10: N | P10: Y | Q10: NA | R10: N | U10: ACTIVE
C11: OH | D11: Charles Brown | E11: 36875 Pepper Dr | F11: OH | H11: W/H | I11: N | J11: N | K11: N | L11: N | M11: N | N11: N | O11: N | P11: N | Q11: N | R11: N | S11: N | T11: N | U11: ACTIVE
B12: 45207 | C12: OH22P | D12: DRAKE | E12: 3626 East 78th Str. | F12: CLEVE | G12: 44105 | H12: RFG | I12: N | J12: N | K12: N | L12: N | M12: N | N12: N | O12: N | P12: N | Q12: N | R12: N | S12: NAR | U12: ACTIVE
C13: OH23P | D13: Dumas,TyronE | G13: 44146 | H13: WTR | I13: N | J13: N | K13: N | L13: N | M13: Y | N13: Y | Q13: TBD | R13: N | S13: Y | U13: ACTIVE
B14: 45193 | C14: OH22P | D14: Eaton, Marilyn | E14: 4514 East Blvd | F14: Garfield Hts., OH | G14: 44105 | H14: RFG | I14: N | J14: N | M14: N | N14: Y | P14: Y | Q14: Y | R14: Y | U14: ACTIVE
C15: OH22P | D15: EDWARDS | E15: TUPELO | G15: 44146 | H15: RFG | I15: Y | J15: Y | M15: Y | P15: Y | Q15: TBD | U15: ACTIVE
C16: OH | D16: EDWINS LEADERSHIP | U16: ACTIVE
C17: OH23P | D17: FERGUSON, ROBERT | E17: HILLCROFT | H17: RFG | I17: Y | J17: Y | M17: Y | N17: N | Q17: N | R17: N | S17: N | U17: ACTIVE
D18: Four Symbolic Lodge | E18: 14402 KINSMAN | F18: OH | H18: W/H | I18: N | J18: N | K18: N | L18: N | M18: Y | N18: N | O18: N | P18: N | Q18: N | R18: N | S18: N | T18: N | U18: ACTIVE
A19: ACT | C19: APC | D19: Franklin, Annette | E19: E 256 | H19: RFG | I19: Y | J19: Y | K19: N | L19: N | M19: Y | N19: Y | Q19: Y | R19: N | S19: N | U19: ACTIVE
B20: 44636 | C20: APC | D20: Gollate, Nicole | E20: 13700 Cormere Ave. | F20: Cleveland, | G20: 44120 | H20: WTR | I20: Y | J20: Y | K20: Y | L20: Y | M20: Y | N20: Y | O20: N | Q20: Y | R20: N | S20: Y | U20: ACTIVE
C21: APC | D21: GOVEA, JESUS | F21: Jonesboro | H21: WTR | I21: Y | J21: Y | K21: Y | L21: N | M21: Y | N21: Y | O21: N | Q21: Y | R21: Y | S21: Y | U21: ACTIVE
D22: GREENWALT MIKE | E22: 11601 GOVERNOR | F22: OH | H22: W/H | I22: N | J22: N | N22: Y | Q22: Y | S22: Y | U22: ACTIVE
D23: GRIFFUS TINA | E23: 1954 SPRINGSIDE | F23: OH | H23: WTR | I23: N | J23: N | K23: N | L23: N | M23: N | N23: N | O23: N | P23: N | Q23: N | R23: N | S23: N | T23: N | U23: ACTIVE
C24: OH22P | D24: GRILLS | G24: 44146 | H24: WTR | I24: N | J24: N | M24: N | N24: N | P24: N | Q24: TBD | R24: N | U24: ACTIVE
A25: WFI | B25: 44665 | C25: APC | D25: Harmon, Lisa | E25: 16319 S. Lotus | F25: Cleveland, | G25: 44128 | H25: RFG | I25: Y | J25: Y | K25: Y | L25: N | M25: Y | N25: Y | Q25: Y | R25: N | S25: Y | U25: ACTIVE
C26: OH23P | D26: HARVEY, CORA | E26: GREENHURST | H26: WTR | K26: Y | M26: Y | N26: Y | R26: Y | S26: Y | U26: ACTIVE
C27: OH23P | D27: Hobbs, Donetta & Nemon | E27: GLENSIDE | H27: WTR | I27: Y | J27: Y | K27: Y | M27: Y | N27: N | Q27: N | R27: N | U27: ACTIVE
A28: XXX | B28: 44627 | C28: APC | D28: Jackson,Sandra | E28: 310 Landing Dr. | F28: Fayetteville | G28: GA | H28: RFG | I28: Y | J28: Y | K28: Y | L28: N | M28: Y | N28: Y | Q28: Y | R28: Y | S28: Y | U28: ACTIVE
A29: XXX | B29: 44629 | C29: APC | D29: Jackson2, Sandra | E29: 215 Sunset Ave. | F29: Atlanta | G29: GA | H29: RFG | I29: Y | J29: Y | L29: N | M29: Y | N29: N | Q29: Y | R29: Y | S29: N | U29: ACTIVE
C30: APC | D30: Jenkins. Martha | E30: DIXLEEON | H30: WTR | I30: Y | J30: Y | K30: Y | L30: Y | M30: Y | N30: Y | O30: Y | P30: Y | Q30: Y | R30: Y | S30: Y | U30: ACTIVE
A31: ACT | C31: APC | D31: Jones, Margaret | E31: 23209 Vera Street | F31: Warrensville HGTS | G31: OH | H31: RFG | I31: N | J31: N | K31: N | L31: N | M31: N | N31: N | Q31: Y | R31: N | S31: N | U31: ACTIVE
A32: TRV | B32: 44596 | C32: APC | D32: Kimble, Audrey | E32: 2756 Northwood Ct. | F32: Marietta, | G32: GA | H32: RFG | I32: Y | J32: Y | K32: Y | L32: N | M32: Y | N32: Y | Q32: Y | R32: N | S32: Y | U32: ACTIVE
D33: KOSWATTA ERIKA | U33: ACTIVE
C34: APC | D34: LAWRENCE, GENEATHA | E34: STRANDHILL | H34: RFG | I34: Y | J34: Y | K34: N | L34: N | M34: Y | N34: N | Q34: Y | R34: N | S34: N | U34: ACTIVE
C35: APC | D35: Lawson, Ms. LORI | E35: TULLAMORE | H35: RFG | I35: Y | J35: Y | K35: N | L35: N | M35: Y | N35: N | Q35: Y | R35: N | S35: N | U35: ACTIVE
C36: OH23P | D36: Leeth, Ronald | E36: MIAMI | H36: WTR | I36: Y | J36: Y | K36: N | L36: N | M36: Y | N36: Y | Q36: Y | R36: Y | S36: N | T36: N | U36: ACTIVE
D37: LISA THOMAS | E37: 5149 MILLER AVE | F37: OH | H37: W/H | I37: N | J37: N | K37: N | L37: N | M37: N | N37: N | O37: N | P37: N | Q37: N | R37: N | S37: N | U37: ACTIVE
C38: APC | D38: LOCKHART | E38: E238 | F38: EUCLID | G38: 44134 | H38: WTR | I38: Y | J38: Y | K38: Y | L38: N | M38: Y | N38: Y | O38: N | P38: N | Q38: 5555 | R38: Y | S38: N | U38: ACTIVE
C39: APC | D39: LOZANO, Marcus | F39: AUSTELL | H39: WTR | I39: Y | J39: Y | K39: Y | L39: N | M39: Y | N39: Y | O39: N | Q39: Y | R39: N | S39: Y | U39: ACTIVE
C40: APC | D40: Matlock, Paggie | E40: OAKWOOD | H40: RFG | I40: N | J40: N | K40: N | L40: N | M40: Y | N40: Y | Q40: Y | R40: N | S40: Y | U40: ACTIVE
...

Sheet REPCPSLIST
A1: C
A2: Create Email (#1) per the numbered attachments list following below.
A3: (Note: Pictures & further documentation to follow under separate Email #2)
A4: ALL REPORTS TO INCLUDE the following prefix :
A5: “REPORT #, State Code, YEAR, COMPANY# (A/T/P/Q/M),CUSTOMER Name, @STREET.”
A6: COMPANY CODES; A= APC ... P=PROVISO/JAMAL ….. T=TONY/WAYSIDE …. Q=QUINTON/PLATINUM … M=MISC
A7: EX. = ( 3. W9 FORM OH23A SMITH @ Main St.).
A8: CONTRACT PACKAGE
A9: 1.GENERAL AUTHORIZATION
A10: 2.CUSTOMER AGREEMENT
A11: 3. W9 form.
A12: ENCIRLE REPORTS: Retrieve/DOWNLOAD REPORTS; (Create as needed)
... A21: Submit ADDITIONAL Justification/Rebuttals as needed per Invoice.

Sheet ALPHA A-Z
A1: # | B1: DATE | C1: CO. | D1: NAME | E1: STREET | F1: CITY | G1: ZIP | H1: JOB | I1: RFG | J1: INT | K1: MIT | L1: CPS | M1: RPL | N1: RCV | O1: SPLM | P1: ALE | Q1: M2 | R1: RF2 | S1: SD2 | T1: IN2 | U1: CP2 | V1: AL2 | W1: REL | X1: Column1 | Y1: STREET | AA1: STREET | AB1: EXT | AC1: SDG
C2: APC | D2: Ayo Akala | E2: E 153 | H2: FIRE | I2: =IF(H2="RFG","OPEN","N/A") -> N/A | K2: PAID | M2: N/A | AA2: OH23A Akalla @E153 Fire
C3: APC | D3: Franklin, Annette | E3: E 256 | H3: RFG | I3: =IF(H3="RFG","OPEN","N/A") -> OPEN | M3: N/A | X3: =1+DONE!Y58 -> 4 | AA3: OH23 FRANKLIN @256street
A4: WFI | B4: 44665 | C4: APC | D4: Harmon, Lisa | E4: 16319 S. Lotus | F4: Cleveland, | G4: 44128 | H4: RFG | I4: =IF(H4="RFG","OPEN","N/A") -> OPEN | J4: PAID | K4: 8888 | L4: 6666 | M4: TBD | P4: TBD | R4: RF2 | S4: N | U4: =IF(#REF!=1,"N/A","OPEN") -> #REF! | V4: =IF(#REF!="N","N/A","OPEN") -> #REF! | Z4: Lotus | AA4: 16319 S. Lotus | AB4: =IF(#REF!="RFG","OPEN","N/A") -> #REF! | AC4: N
A5: LMI | B5: 44627 | C5: APC | D5: Jackson,Sandra | E5: 310 Landing Dr. | F5: Fayetteville | G5: GA | H5: RFG | I5: =IF(H5="RFG","OPEN","N/A") -> OPEN | J5: 6666 | K5: 5555 | L5: 4444 | M5: N/A | P5: N | R5: RF2 | S5: N | U5: =IF(#REF!=1,"N/A","OPEN") -> #REF! | V5: =IF(#REF!="N","N/A","OPEN") -> #REF! | X5: =1+X4 -> 1 | Y5: 310 | Z5: Landing | AA5: 310 Landing Dr. | AB5: =IF(#REF!="RFG","OPEN","N/A") -> #REF! | AC5: N
B6: 44629 | C6: APC | D6: Jackson2, Sandra | E6: 215 Sunset Ave. | F6: Atlanta | G6: GA | H6: RFG | I6: =IF(H6="RFG","OPEN","N/A") -> OPEN | J6: 6666 | K6: 3333 | L6: 1 | M6: N/A | P6: N | R6: RF2 | S6: N | U6: =IF(#REF!=1,"N/A","OPEN") -> #REF! | V6: =IF(#REF!="N","N/A","OPEN") -> #REF! | X6: =1+X5 -> 2 | Y6: 215 | Z6: Sunset | AA6: 215 Sunset Ave. | AB6: =IF(#REF!="RFG","OPEN","N/A") -> #REF! | AC6: N
C7: APC | D7: Jones, Margaret | E7: 23209 Vera Street | F7: Warrensville HGTS | G7: OH | H7: RFG | I7: =IF(H7="RFG","OPEN","N/A") -> OPEN | M7: TBD | AA7: 23209 Vera Street
A8: TRV | B8: 44596 | C8: APC | D8: Kimble, Audrey | E8: 2756 Northwood Ct. | F8: Marietta, | G8: GA | H8: RFG | I8: =IF(H8="RFG","OPEN","N/A") -> OPEN | J8: 3333 | K8: 5555 | L8: 3333 | M8: TBD | P8: N | R8: RF2 | S8: N | U8: =IF(#REF!=1,"N/A","OPEN") -> #REF! | V8: =IF(#REF!="N","N/A","OPEN") -> #REF! | X8: =1+X7 -> 1 | Y8: 2756 | Z8: Northwood | AA8: 2756 Northwood Ct. | AB8: =IF(#REF!="RFG","OPEN","N/A") -> #REF! | AC8: N
C9: APC | D9: LAWRENCE, GENEATHA | E9: STRANDHILL | H9: RFG | I9: =IF(H9="RFG","OPEN","N/A") -> OPEN | M9: TBD | AA9: STRANDHILL
C10: APC | D10: Lawson, Ms. LORI | E10: TULLAMORE | H10: RFG | I10: =IF(H10="RFG","OPEN","N/A") -> OPEN | L10: TBD | M10: TBD | R10: =#REF! -> #REF! | S10: =#REF! -> #REF! | U10: =IF(L10=1,"N/A","OPEN") -> OPEN | V10: TBD | W10: TBD | X10: =1+#REF! -> #REF! | AA10: TULLAMORE | AB10: =IF(H10="RFG","OPEN","N/A") -> OPEN | AC10: =#REF! -> #REF!
C11: APC | D11: Matlock, Paggie | E11: OAKWOOD | H11: RFG | I11: =IF(H11="RFG","OPEN","N/A") -> OPEN | M11: TBD | AA11: OAKWOOD
B12: 44526 | C12: APC | D12: Moore, Joyce | E12: 3789 Mayfield Rd. | F12: Cleveland Hts. | G12: 44121 | H12: RFG | I12: =IF(H12="RFG","OPEN","N/A") -> OPEN | J12: 1 | K12: 1 | L12: 0 | M12: TBD | P12: N | R12: =IF(#REF!="RFG","OPEN","N/A") -> #REF! | S12: N | U12: =IF(#REF!=1,"N/A","OPEN") -> #REF! | V12: =IF(#REF!="N","N/A","OPEN") -> #REF! | X12: =1+X11 -> 1 | Y12: 3789 | Z12: Mayfield | AA12: 3789 Mayfield Rd. | AB12: =IF(#REF!="RFG","OPEN","N/A") -> #REF! | AC12: N
A13: USA | B13: 44921 | C13: APC | D13: Reid, Andrew | E13: 2528 East Alberson Dr. | F13: Albany | G13: GA | H13: RFG | I13: =IF(H13="RFG","OPEN","N/A") -> OPEN | J13: ESTD | K13: 6666 | L13: 5555 | M13: TBD | P13: N | R13: =IF(#REF!="RFG","OPEN","N/A") -> #REF! | S13: N | U13: =IF(#REF!=1,"N/A","OPEN") -> #REF! | V13: =IF(#REF!="N","N/A","OPEN") -> #REF! | X13: =1+#REF! -> #REF! | Y13: 2528 | Z13: East | AA13: 2528 East Alberson Dr. | AB13: =IF(#REF!="RFG","OPEN","N/A") -> #REF! | AC13: N
C14: APC | D14: STEELE | F14: GA | G14: 33333 | H14: RFG | I14: =IF(H14="RFG","OPEN","N/A") -> OPEN | J14: PAID | K14: 6666 | L14: 7777 | M14: N/A | P14: TBD | Q14: NA | R14: NA | S14: NA | T14: NA | U14: NA | V14: NA | W14: NA | X14: =1+DONE!Y56 -> 2 | AB14: PAID | AC14: NA
B15: 44312 | C15: APC | D15: Tamplin, Adalene | E15: 287 Roberts Rd. | F15: Barnesville | G15: GA | H15: RFG | I15: =IF(H15="RFG","OPEN","N/A") -> OPEN | J15: 3333 | K15: 5555 | L15: 4444 | M15: TBD | P15: N | R15: =IF(#REF!="RFG","OPEN","N/A") -> #REF! | S15: N | U15: =IF(#REF!=1,"N/A","OPEN") -> #REF! | V15: =IF(#REF!="N","N/A","OPEN") -> #REF! | X15: =1+X14 -> 3 | Y15: 287 | Z15: Roberts | AA15: 287 Roberts Rd. | AB15: =IF(#REF!="RFG","OPEN","N/A") -> #REF! | AC15: N
A16: TRV | B16: 44598 | C16: APC | D16: Torres,Angel | E16: 1201 Springwood Dr. | F16: Conyers | G16: GA | H16: RFG | I16: =IF(H16="RFG","OPEN","N/A") -> OPEN | J16: 15000 | K16: 5555 | L16: 6666 | M16: TBD | P16: N | R16: =IF(#REF!="RFG","OPEN","N/A") -> #REF! | S16: N | U16: =IF(#REF!=1,"N/A","OPEN") -> #REF! | V16: =IF(#REF!="N","N/A","OPEN") -> #REF! | X16: =1+X15 -> 4 | Y16: 1201 | Z16: Springwood | AA16: 1201 Springwood Dr. | AB16: =IF(#REF!="RFG","OPEN","N/A") -> #REF! | AC16: N
C17: APC | D17: ROB | E17: 160 FAIRFAX | F17: CLE | G17: 44128 | H17: THEFT | I17: =IF(H17="RFG","OPEN","N/A") -> N/A | J17: 1 | K17: PAID | L17: 7777 | M17: TBD | P17: N | R17: =IF(#REF!="RFG","OPEN","N/A") -> #REF! | S17: N | U17: =IF(#REF!=1,"N/A","OPEN") -> #REF! | V17: =IF(#REF!="N","N/A","OPEN") -> #REF! | X17: =1+X16 -> 5 | Y17: 160 | Z17: FAIRFAX | AA17: 160 FAIRFAX | AB17: =IF(#REF!="RFG","OPEN","N/A") -> #REF! | AC17: N
C18: APC | D18: Webb, Terika | E18: 17814 Dillewood Rd, | F18: Cleveland | H18: VDM | I18: =IF(H18="RFG","OPEN","N/A") -> N/A | M18: TBD | X18: =1+X17 -> 6 | AA18: 17814 Dillewood Rd, Cleveland, OH, USA
C19: APC | D19: AGNEW | F19: Cleveland | G19: 44087 | H19: WTR | I19: =IF(H19="RFG","OPEN","N/A") -> N/A | J19: 4444 | K19: PAID | L19: 5555 | M19: TBD | P19: TBD | R19: =IF(#REF!="RFG","OPEN","N/A") -> #REF! | S19: N | U19: =IF(#REF!=1,"N/A","OPEN") -> #REF! | V19: =IF(#REF!="N","N/A","OPEN") -> #REF! | X19: =+#REF!+1 -> #REF! | AB19: =IF(#REF!="RFG","OPEN","N/A") -> #REF! | AC19: N
C20: APC | D20: Ali, Tony | F20: WESTLAKE | H20: WTR | I20: =IF(H20="RFG","OPEN","N/A") -> N/A | M20: TBD | AA20: OH23A Ali@ Lorain
B21: 44920 | C21: APC | D21: Anderson, Vanessa | E21: 771 Edgewood Rd. | F21: Richmond Hts. | G21: 44134 | H21: WTR | I21: =IF(H21="RFG","OPEN","N/A") -> N/A | J21: PAID | K21: 7777 | L21: PAID | M21: PAID | P21: TBD | R21: =IF(#REF!="RFG","OPEN","N/A") -> #REF! | S21: N | U21: =IF(#REF!=1,"N/A","OPEN") -> #REF! | V21: =IF(#REF!="N","N/A","OPEN") -> #REF! | X21: =1+X20 -> 1 | Y21: 771 | Z21: Edgewood | AA21: 771 Edgewood Rd. | AB21: =IF(#REF!="RFG","OPEN","N/A") -> #REF! | AC21: N
C22: APC | D22: Battle, Larry Jr | E22: Parma | H22: WTR | I22: =IF(H22="RFG","OPEN","N/A") -> N/A | M22: TBD | AA22: Parma
C23: APC | D23: Stroud, Brittany | E23: 5106 East 113th Street, | F23: Garfield | H23: FIRE | I23: =IF(H23="RFG","OPEN","N/A") -> N/A | M23: TBD | AA23: 5106 East 113th Street,
B24: 44636 | C24: APC | D24: Gollate, Nicole | E24: 13700 Cormere Ave. | F24: Cleveland, | G24: 44120 | H24: WTR | I24: =IF(H24="RFG","OPEN","N/A") -> N/A | J24: 4444 | K24: 7777 | L24: 4444 | M24: TBD | P24: TBD | R24: =IF(#REF!="RFG","OPEN","N/A") -> #REF! | S24: N | U24: =IF(#REF!=1,"N/A","OPEN") -> #REF! | V24: =IF(#REF!="N","N/A","OPEN") -> #REF! | X24: =1+X23 -> 1 | Y24: 13700 | Z24: Cormere | AA24: 13700 Cormere Ave. | AB24: =IF(#REF!="RFG","OPEN","N/A") -> #REF! | AC24: N
C25: APC | D25: GOVEA, JESUS | F25: Jonesboro | H25: WTR | I25: =IF(H25="RFG","OPEN","N/A") -> N/A | L25: TBD | M25: TBD | R25: =#REF! -> #REF! | S25: =#REF! -> #REF! | U25: =IF(L25=1,"N/A","OPEN") -> OPEN | V25: TBD | W25: TBD | X25: =1+#REF! -> #REF! | AB25: =IF(H25="RFG","OPEN","N/A") -> N/A | AC25: =#REF! -> #REF!
C26: APC | D26: Jenkins. Martha | E26: DIXLEEON | H26: WTR | I26: =IF(H26="RFG","OPEN","N/A") -> N/A | J26: PAID | M26: PAID | AA26: DIXLEEON
C27: APC | D27: KENNETH | E27: LINCOLN | H27: WTR | I27: =IF(H27="RFG","OPEN","N/A") -> N/A | M27: TBD | AA27: OH23A KENNY @ LINCOLN
C28: APC | D28: LOCKHART | E28: E238 | F28: EUCLID | G28: 44134 | H28: WTR | I28: =IF(H28="RFG","OPEN","N/A") -> N/A | J28: PAID | K28: 6666 | L28: 5555 | M28: TBD | P28: TBD | R28: =IF(#REF!="RFG","OPEN","N/A") -> #REF! | S28: N | U28: =IF(#REF!=1,"N/A","OPEN") -> #REF! | V28: =IF(#REF!="N","N/A","OPEN") -> #REF! | W28: Y | X28: =1+X27 -> 1 | Y28: E238 | Z28: E238 | AA28: E238 | AB28: =IF(#REF!="RFG","OPEN","N/A") -> #REF! | AC28: N
C29: APC | D29: LOZANO, Marcus | F29: AUSTELL | H29: WTR | I29: =IF(H29="RFG","OPEN","N/A") -> N/A | M29: TBD | AA29: GA23A Lozano @ Austell
B30: GA23A | C30: APC | D30: Moiye 3, Ras | E30: DIXLEEON | H30: WTR | I30: =IF(H30="RFG","OPEN","N/A") -> N/A | J30: PAID | M30: PAID | AA30: GA23Moiye @DIX LEE ON 3
A31: SFI | B31: 44908 | C31: APC | D31: Moiye, Ras | E31: 395 Dix Lee-On Ct | F31: Fayetteville | G31: GA | H31: WTR | I31: =IF(H31="RFG","OPEN","N/A") -> N/A | J31: 2222 | K31: 5555 | L31: 5555 | M31: TBD | P31: N | R31: =IF(#REF!="RFG","OPEN","N/A") -> #REF! | S31: N | U31: =IF(#REF!=1,"N/A","OPEN") -> #REF! | V31: =IF(#REF!="N","N/A","OPEN") -> #REF! | X31: =1+X30 -> 1 | Y31: 395 | Z31: Dix | AA31: 395 Dix Lee-On Ct | AB31: =IF(#REF!="RFG","OPEN","N/A") -> #REF! | AC31: N
B32: 44640 | C32: APC | D32: NDU, Belinda | E32: 255 Astaire Manor | F32: Fayetteville | G32: GA | H32: WTR | I32: =IF(H32="RFG","OPEN","N/A") -> N/A | J32: DEPR? | K32: PAID | L32: 11111 | M32: TBD | P32: N | R32: =IF(#REF!="RFG","OPEN","N/A") -> #REF! | S32: N | U32: =IF(#REF!=1,"N/A","OPEN") -> #REF! | V32: =IF(#REF!="N","N/A","OPEN") -> #REF! | X32: =1+X31 -> 2 | Y32: 255 | Z32: Astaire | AA32: 255 Astaire Manor | AB32: =IF(#REF!="RFG","OPEN","N/A") -> #REF! | AC32: N
B33: 44856 | C33: APC | D33: Ringo, Craig | E33: 5697 Daniel Dr. | F33: Bedford Hts | G33: 44146 | H33: WTR | I33: =IF(H33="RFG","OPEN","N/A") -> N/A | J33: PAID | K33: 15000 | L33: 12000 | M33: TBD | P33: Y | R33: =IF(#REF!="RFG","OPEN","N/A") -> #REF! | S33: N | U33: =IF(#REF!=1,"N/A","OPEN") -> #REF! | V33: =IF(#REF!="N","N/A","OPEN") -> #REF! | X33: =1+X32 -> 3 | Y33: 5697 | Z33: Daniel | AA33: 5697 Daniel Dr. | AB33: =IF(#REF!="RFG","OPEN","N/A") -> #REF! | AC33: NA
B34: 44914 | C34: APC | D34: Salem, Zahara | E34: 841 Horseshoe Way | F34: Avon Lake | G34: 44111 | H34: WTR | I34: =IF(H34="RFG","OPEN","N/A") -> N/A | J34: PAID | K34: 7777 | L34: 4499 | M34: TBD | P34: N | R34: =IF(#REF!="RFG","OPEN","N/A") -> #REF! | S34: N | U34: =IF(#REF!=1,"N/A","OPEN") -> #REF! | V34: =IF(#REF!="N","N/A","OPEN") -> #REF! | W34: Y | X34: =1+X33 -> 4 | Y34: 841 | Z34: Horseshoe | AA34: 841 Horseshoe Way | AB34: =IF(#REF!="RFG","OPEN","N/A") -> #REF! | AC34: N
C35: APC | D35: Stroud, Brittany | E35: E113 ST | H35: WTR | I35: =IF(H35="RFG","OPEN","N/A") -> N/A | M35: TBD | X35: =1+X34 -> 5 | AA35: OH23A STROUD@E113TH
C36: APC | D36: Terell BrowN | E36: MANOR | H36: WTR | I36: =IF(H36="RFG","OPEN","N/A") -> N/A | L36: NA | M36: N/A | R36: =#REF! -> #REF! | S36: =#REF! -> #REF! | U36: =IF(L36=1,"N/A","OPEN") -> OPEN | V36: TBD | W36: TBD | X36: =1+X35 -> 6 | AB36: =IF(H36="RFG","OPEN","N/A") -> N/A | AC36: =#REF! -> #REF!
A37: # | B37: DATE | C37: CO. | D37: NAME | E37: STREET | F37: CITY | G37: ZIP | H37: JOB | I37: RFG | J37: INT | K37: MIT | L37: CPS | M37: RPL | N37: RCV | O37: SPLM | P37: ALE | Q37: M2 | R37: RF2 | S37: SD2 | T37: IN2 | U37: CP2 | V37: AL2 | W37: REL | X37: Column1 | Y37: STREET | AA37: STREET | AB37: EXT | AC37: SDG
B38: 45226 | C38: OH21P | H38: a | I38: =IF(H38="RFG","OPEN","N/A") -> N/A
B39: 45226 | C39: OH21P | D39: Solomon | E39: 3581 Ingleside Rd. | F39: Shaker Hts., OH | G39: 44120 | H39: RFG | I39: =IF(H39="RFG","OPEN","N/A") -> OPEN | J39: PAID | K39: Y | L39: Y | M39: N/A | P39: NA | R39: Y | S39: Y | T39: NA | U39: NA | V39: NA | X39: 2201 | Y39: 3581 | Z39: Ingleside | AA39: 3581 Ingleside Rd. | AB39: Y | AC39: NA
B40: 45283 | C40: OH22P | D40: WYNN | E40: 331 Royal Oak Blvd | F40: Richmond Hts., OH | G40: 44143 | H40: FIRE | I40: =IF(H40="RFG","OPEN","N/A") -> N/A | J40: PAID | K40: Y | L40: Y | M40: PAID | P40: Y | R40: NA | S40: NA | U40: Y | V40: Y | X40: =1+X39 -> 2202 | Y40: 331 | Z40: Royal OAK | AA40: 331 Royal Oak Blvd | AB40: NA | AC40: NA
...

Sheet PROVISIO
B1: 22 | R1: MIT SPLM
A2: # | B2: DATE | C2: CO. | D2: NAME | E2: STREET | F2: CITY | G2: ZIP | H2: JOB | I2: EXT | J2: RFG | K2: SDG | L2: INT | M2: MIT | N2: CPS | O2: RPL | P2: RCV | Q2: ALE | R2: MIT | S2: RFG | T2: SDG | U2: INT | V2: CPS | W2: ALE
B3: 44254 | C3: OH22P | D3: Jarboe, Delicia | E3: 4085 East 153 rd Str. | F3: Cleveland, OH | G3: 44128 | H3: WTR | I3: NA | J3: NA | K3: NA | L3: 155 | M3: NA | N3: NA | O3: NA | Q3: NA | R3: NA | S3: NA | T3: NA | U3: 155 | V3: NA | W3: N
B4: 44496 | C4: OH21P | D4: Solomon | E4: 3581 Ingleside Rd. | F4: Shaker Hts., OH | G4: 44120 | H4: RFG | J4: Y | K4: NA | L4: Y | M4: Y | N4: Y | O4: NA | Q4: NA | T4: NA | V4: NA | W4: N
B5: 44842 | C5: OH22P | D5: DRAKE | E5: 3626 East 78th Str. | F5: CLEVE | G5: 44105 | H5: RFG | I5: Y | J5: 25 | K5: 45 | L5: 32 | M5: Y | N5: NA | O5: NA | Q5: NA | V5: NA
B6: 44807 | C6: OH22P | D6: Seawright | E6: 3889 East 140th Str. | F6: Cleveland, OH | G6: 44120 | H6: RFG | I6: 9 | J6: 41 | L6: Y | M6: Y | N6: Y | O6: TBD | Q6: TBD | V6: TBD
B7: 44828 | C7: OH22P | D7: Eaton, Marilyn | E7: 4514 East Blvd | F7: Garfield Hts., OH | G7: 44105 | H7: RFG | J7: Y | K7: NA | L7: Y | M7: Y | N7: Y | O7: TBD | Q7: TBD | V7: TBD
B8: 44828 | C8: OH22P | D8: Thomas, Nicole | E8: 1620 Belwood | F8: Cleveland Hts., OH | G8: 44118 | H8: RFG | J8: Y | K8: Y | L8: 29 | M8: Y | N8: Y | O8: TBD | Q8: TBD | V8: TBD
B9: 44846 | C9: OH22P | D9: Edwards, Clarence | E9: 13706 Glendale Ave. | F9: Cleveland, OH | G9: 44120 | H9: VAN | J9: NA | K9: NA | L9: 181 | M9: Y | N9: NA | O9: TBD | Q9: Y | V9: TBD
B10: 44876 | C10: OH22P | D10: Paige, Tom | E10: 4492 St. Germain Blvd | F10: Cleveland, OH | G10: 44128 | H10: TREE | I10: 16 | J10: Y | K10: Y | L10: Y | M10: Y | N10: 11 | O10: Y | Q10: Y | V10: Y
B11: 44895 | C11: OH22P | D11: Hodges | E11: 7297 Northam Dr. | F11: Bedford, OH | G11: 44146 | H11: TREE | I11: 8 | J11: Y | K11: Y | L11: Y | M11: Y | N11: Y | O11: Y | Q11: TBD | V11: Y
B12: 44899 | C12: OH22P | D12: Thornton, Ericka | E12: 6280 Eldridge Blvd | F12: Bedford, OH | G12: 44146 | H12: RFG | I12: Y | J12: Y | K12: Y | L12: 21 | M12: Y | N12: NA | O12: Y | Q12: NA | V12: Y
B13: 44918 | C13: OH22P | D13: WYNN | E13: 331 Royal Oak Blvd | F13: Richmond Hts., OH | G13: 44143 | H13: FIRE | I13: NA | J13: NA | K13: NA | L13: Y | M13: Y | N13: Y | O13: Y | Q13: Y | V13: Y
B14: 44919 | C14: OH22P | D14: BROADHEAD | E14: CEDAR | G14: 44106 | H14: WTR | I14: NA | J14: NA | K14: NA | L14: 36 | M14: Y | N14: Y | O14: Y | Q14: TBD | V14: Y
C15: OH22P | D15: EDWARDS | E15: TUPELO | G15: 44146 | H15: RFG | I15: TBD | J15: Y | K15: 19 | L15: Y | M15: Y | N15: TBD | O15: TBD | Q15: TBD | V15: TBD
C16: OH22P | D16: GRILLS | G16: 44146 | H16: WTR | I16: NA | J16: NA | K16: Y | L16: Y | M16: Y | N16: TBD | O16: TBD | Q16: NA | V16: TBD
C17: OH22P | D17: SARKAR | E17: DAVIDSON | F17: Richmond Hts., OH | G17: 44143 | H17: WTR | I17: NA | J17: NA | K17: NA | L17: Y | M17: Y | N17: Y | O17: TBD | Q17: TBD | V17: TBD
C18: OH23P | D18: WARD | E18: TARKINGTON | F18: CLE | G18: 44128 | H18: WTR | I18: NA | J18: NA | K18: NA | L18: Y | M18: Y | N18: Y | O18: Y | Q18: TBD | V18: Y
C19: OH23P | D19: Dumas,TyronE | G19: 44146 | H19: WTR | I19: TBD | J19: TBD | K19: NA | L19: Y | M19: Y | N19: Y | O19: Y | Q19: TBD | V19: Y
C20: OH23P | D20: WARD | E20: THROCKLEY | F20: CLE | G20: 44128 | H20: FIRE | I20: TBD | J20: TBD | K20: Y | L20: Y | M20: Y | N20: TBD | O20: TBD | Q20: TBD | V20: TBD
C21: OH23P | D21: BOYD | E21: WOODLINE | G21: 44146 | H21: RFG | I21: TBD | J21: Y | K21: Y | L21: Y | M21: Y | N21: Y | O21: TBD | Q21: TBD | V21: TBD
B27: CLOSED NO FURTHER ACTIVITY | R27: MIT SPLM
A28: # | B28: DATE | C28: CO. | D28: NAME | E28: STREET | F28: CITY | G28: ZIP | H28: JOB | I28: EXT | J28: RFG | K28: SDG | L28: INT | M28: MIT | N28: CPS | O28: RPLC | Q28: ALE | R28: MIT | S28: RFG | T28: SDG | U28: INT | V28: CPS | W28: ALE
A29: TBD | B29: 44665 | C29: OH22P | D29: Andrea | E29: 3711 Blanchie Ave | G29: OH | H29: Ben
A30: TBD | B30: 44794 | C30: OH22P | D30: Apt @ Detroit | E30: 24325 Detroit Rd. | F30: Westlake, | G30: OH | J30: NA | K30: NA | L30: NA | M30: Y | N30: NA
A31: TBD | B31: 44853 | C31: OH22P | D31: CARR | E31: 99 W. St. Clair Ave. | F31: Cleveland, OH | G31: OH
A32: TBD | B32: 44723 | C32: OH22P | D32: Davis | E32: 12500 Parkhill Ave. | F32: Cleveland, OH | G32: OH | H32: Charmine
A33: TBD | B33: 44697 | C33: OH22P | D33: Galloway, LINDA | E33: 15865 Glynn Rd. | F33: Cleveland, OH
A34: TBD | C34: OH22P | D34: GREEN, RODERICK
A35: TBD | C35: OH22P | D35: Halton, Jocelyn | E35: 7609 Maplewood Dr. | F35: APPRAISAL
A36: TBD | B36: 44730 | C36: OH22P | D36: Halton, Jocelyn | E36: 7609 Maplewood Dr. | F36: Solon, | G36: OH | H36: Julia | N36: Y
A37: TBD | C37: OH22P | D37: HOBBS | E37: HOBBS @ GLENSIDE | I37: NA
A38: TBD | C38: OH22P | D38: Hollinger | F38: OAKWOOD | N38: Y
A39: TBD | C39: OH22P | D39: JAMAL | E39: RM | F39: ADDIT RO | L39: 35
A40: TBD | C40: OH22P | D40: KIRKWOOD | E40: STOCKBRIGDE | F40: CLEVE | I40: NA | J40: NA | K40: Y | L40: NA | M40: NA | N40: NA
A41: TBD | C41: OH22P | D41: LEETH | E41: FOREST GROVE AVE | I41: NA | J41: Y | K41: 25
A42: TBD | C42: OH22P | D42: MAYES | E42: DAVIS MAYES | J42: 87
A43: TBD | B43: 44533 | C43: OH22P | D43: Painter,Calvin | E43: 4346 Archer Rd. | F43: Cleveland | G43: OH | N43: Y
A44: TBD | C44: OH22P | D44: Patterson, Marilyn | E44: 5181 Theodore Str. | F44: Maple Hts., | G44: OH | N44: Y
A45: TBD | C45: OH22P | D45: ROBINSON | E45: BLANCHE AVE | I45: NA
...

Sheet how2
C1: LEGEND | D1: VERIFY
B2: EMS IN$ | C2: Interior Mitigation/Emergency Services Invoice | D2: Originally sent to INS CO. | E2: Enter amount$.
B3: SPLM$ | C3: Supplemental invoice | D3: Submitted to INS CO. | E3: Enter amount$.
B4: SENT | C4: Date sent to INS CO. | D4: Verify email SENT | E4: ENTER DATE
B5: PAID | C5: Verify payment | D5: ENTER $ | E5: ENTER DATE
B6: EXT EMS$ | C6: Exterior Mitigation/Emergency Services Invoice | D6: =+D2 -> Originally sent to INS CO. | E6: =+E2 -> Enter amount$.
B7: SPLM$ | C7: =+C3 -> Supplemental invoice | D7: =+D3 -> Submitted to INS CO. | E7: =+E3 -> Enter amount$.
B8: SENT | C8: =+C4 -> Date sent to INS CO. | D8: =+D4 -> Verify email SENT | E8: =+E4 -> ENTER DATE
B9: PAID | C9: =+C5 -> Verify payment | D9: =+D5 -> ENTER $ | E9: =+E5 -> ENTER DATE
B10: REBUILD | C10: Rebuilt Invoice | D10: =+D6 -> Originally sent to INS CO. | E10: =+E6 -> Enter amount$.
B11: SPLM$ | C11: =+C7 -> Supplemental invoice | D11: =+D7 -> Submitted to INS CO. | E11: =+E7 -> Enter amount$.
B12: SENT | C12: =+C8 -> Date sent to INS CO. | D12: =+D8 -> Verify email SENT | E12: =+E8 -> ENTER DATE
B13: PAID | C13: =+C9 -> Verify payment | D13: =+D9 -> ENTER $ | E13: =+E9 -> ENTER DATE
B14: CPS$ | C14: Contents Packing & Storage (only) | D14: =+D10 -> Originally sent to INS CO. | E14: =+E10 -> Enter amount$.
B15: SPLM$ | C15: =+C11 -> Supplemental invoice | D15: =+D11 -> Submitted to INS CO. | E15: =+E11 -> Enter amount$.
B16: SENT | C16: =+C12 -> Date sent to INS CO. | D16: =+D12 -> Verify email SENT | E16: =+E12 -> ENTER DATE
B17: PAID | C17: =+C13 -> Verify payment | D17: =+D13 -> ENTER $ | E17: =+E13 -> ENTER DATE
B18: RPL CPS | C18: Replacement contents Invoice sent to ensure. | D18: =+D14 -> Originally sent to INS CO. | E18: =+E14 -> Enter amount$.
B19: SPLM$ | C19: =+C15 -> Supplemental invoice | D19: =+D15 -> Submitted to INS CO. | E19: =+E15 -> Enter amount$.
B20: SENT | C20: =+C16 -> Date sent to INS CO. | D20: =+D16 -> Verify email SENT | E20: =+E16 -> ENTER DATE
B21: PAID | C21: =+C17 -> Verify payment | D21: =+D17 -> ENTER $ | E21: =+E17 -> ENTER DATE
B22: MISC | C22: Miscellaneous Invoice | D22: =+D18 -> Originally sent to INS CO. | E22: =+E18 -> Enter amount$.
B23: SPLM$ | C23: =+C19 -> Supplemental invoice | D23: =+D19 -> Submitted to INS CO. | E23: =+E19 -> Enter amount$.
B24: SENT | C24: =+C20 -> Date sent to INS CO. | D24: =+D20 -> Verify email SENT | E24: =+E20 -> ENTER DATE
B25: PAID | C25: =+C21 -> Verify payment | D25: =+D21 -> ENTER $ | E25: =+E21 -> ENTER DATE
B26: HMR | C26: HAZARDOUS Mitigation Invoice | D26: =+D22 -> Originally sent to INS CO. | E26: =+E22 -> Enter amount$.
B27: SPLM$ | C27: =+C23 -> Supplemental invoice | D27: =+D23 -> Submitted to INS CO. | E27: =+E23 -> Enter amount$.
B28: SENT | C28: =+C24 -> Date sent to INS CO. | D28: =+D24 -> Verify email SENT | E28: =+E24 -> ENTER DATE
B29: PAID | C29: =+C25 -> Verify payment | D29: =+D25 -> ENTER $ | E29: =+E25 -> ENTER DATE
B30: APPRSL | C30: Appraisal (if selected) | D30: =+D26 -> Originally sent to INS CO. | E30: =+E26 -> Enter amount$.
B31: PAID | C31: Verify payment | D31: =+D29 -> ENTER $ | E31: =+E29 -> ENTER DATE
B32: REL | C32: RELEASE (IF ACCEPTED BY OWNER & APC) | D32: =+D30 -> Originally sent to INS CO. | E32: =+E28 -> ENTER DATE
B33: PAID | C33: Verify payment | D33: =+D31 -> ENTER $ | E33: =+E29 -> ENTER DATE

Sheet CST
A1: 1 | B1: =+ALL!$C$1 -> JOROBE, DELICIA | C1: EMS IN$ | D1: SPLM$ | E1: SENT | F1: PAID | G1: EXT EMS$ | H1: =+D1 -> SPLM$ | I1: =+E1 -> SENT | J1: =+F1 -> PAID | K1: REBUILD | L1: =+H1 -> SPLM$ | M1: =+I1 -> SENT | N1: =+J1 -> PAID | O1: CPS$ | P1: =+L1 -> SPLM$ | Q1: =+M1 -> SENT | R1: =+N1 -> PAID | S1: Supplemental Invoices/Reconcile
C2: 2000 | D2: 1200
A3: 12 | B3: =+ALL!$C$12 -> 44254
A4: 27 | B4: =+ALL!$C$27 -> IKW2742001H | C4: RPL CPS | D4: =+P1 -> SPLM$ | E4: =+Q1 -> SENT | F4: =+R1 -> PAID | G4: MISC | H4: =+D4 -> SPLM$ | I4: =+E4 -> SENT | J4: =+F4 -> PAID | K4: HMR | L4: =+H4 -> SPLM$ | M4: =+I4 -> SENT | N4: =+J4 -> PAID | O4: APPRSL | P4: =+N4 -> PAID | Q4: REL | R4: =+N4 -> PAID
A5: 26 | B5: =+ALL!$C$26 -> TRAVCO INSURANCE
A8: =1+A1 -> 2 | B8: =+ALL!$D$1 -> BOYD | C8: =+C1 -> EMS IN$ | D8: =+D1 -> SPLM$ | E8: =+E1 -> SENT | F8: =+F1 -> PAID | G8: =+G1 -> EXT EMS$ | H8: =+H1 -> SPLM$ | I8: =+I1 -> SENT | J8: =+J1 -> PAID | K8: REBUILD | L8: =+H8 -> SPLM$ | M8: =+I8 -> SENT | N8: =+J8 -> PAID | O8: CPS$ | P8: =+L8 -> SPLM$ | Q8: =+M8 -> SENT | R8: =+N8 -> PAID
C9: 2000 | D9: 1200
A10: 12 | B10: =+ALL!$D$12 -> date of loss
A11: 27 | B11: =+ALL!$D$27 -> 35 | C11: RPL CPS | D11: =+P8 -> SPLM$ | E11: =+Q8 -> SENT | F11: =+R8 -> PAID | G11: MISC | H11: =+D11 -> SPLM$ | I11: =+E11 -> SENT | J11: =+F11 -> PAID | K11: HMR | L11: =+H11 -> SPLM$ | M11: =+I11 -> SENT | N11: =+J11 -> PAID | O11: APPRSL | P11: =+N11 -> PAID | Q11: REL | R11: =+N11 -> PAID
A12: 26 | B12: =+ALL!$D$26 -> STATE FARM
A15: =1+A8 -> 3 | B15: =+ALL!$E$1 -> + | C15: =+C8 -> EMS IN$ | D15: =+D8 -> SPLM$ | E15: =+E8 -> SENT | F15: =+F8 -> PAID | G15: =+G8 -> EXT EMS$ | H15: =+H8 -> SPLM$ | I15: =+I8 -> SENT | J15: =+J8 -> PAID | K15: REBUILD | L15: =+H15 -> SPLM$ | M15: =+I15 -> SENT | N15: =+J15 -> PAID | O15: CPS$ | P15: =+L15 -> SPLM$ | Q15: =+M15 -> SENT | R15: =+N15 -> PAID
C16: 2000 | D16: 1200
A17: 12 | B17: =+ALL!$E$12 -> 44665
A18: 27 | B18: =+ALL!E27 -> CLM #0002332090 | C18: RPL CPS | D18: =+P15 -> SPLM$ | E18: =+Q15 -> SENT | F18: =+R15 -> PAID | G18: MISC | H18: =+D18 -> SPLM$ | I18: =+E18 -> SENT | J18: =+F18 -> PAID | K18: HMR | L18: =+H18 -> SPLM$ | M18: =+I18 -> SENT | N18: =+J18 -> PAID | O18: APPRSL | P18: =+N18 -> PAID | Q18: REL | R18: =+N18 -> PAID
A19: 26 | B19: =+ALL!E26 -> WESTFIELD INS
A22: =1+A15 -> 4 | B22: =+ALL!F1 -> 0 | C22: =+C15 -> EMS IN$ | D22: =+D15 -> SPLM$ | E22: =+E15 -> SENT | F22: =+F15 -> PAID | G22: =+G15 -> EXT EMS$ | H22: =+H15 -> SPLM$ | I22: =+I15 -> SENT | J22: =+J15 -> PAID | K22: REBUILD | L22: =+H22 -> SPLM$ | M22: =+I22 -> SENT | N22: =+J22 -> PAID | O22: CPS$ | P22: =+L22 -> SPLM$ | Q22: =+M22 -> SENT | R22: =+N22 -> PAID
C23: 2000 | D23: 1200
A24: 12 | B24: =+ALL!F12 -> 0
A25: 27 | B25: =+ALL!F27 -> 0 | C25: RPL CPS | D25: =+P22 -> SPLM$ | E25: =+Q22 -> SENT | F25: =+R22 -> PAID | G25: MISC | H25: =+D25 -> SPLM$ | I25: =+E25 -> SENT | J25: =+F25 -> PAID | K25: HMR | L25: =+H25 -> SPLM$ | M25: =+I25 -> SENT | N25: =+J25 -> PAID | O25: APPRSL | P25: =+N25 -> PAID | Q25: REL | R25: =+N25 -> PAID
A26: 26 | B26: =+ALL!F26 -> 0
A29: =1+A22 -> 5 | B29: =+ALL!G$1 -> 0 | C29: =+C22 -> EMS IN$ | D29: =+D22 -> SPLM$ | E29: =+E22 -> SENT | F29: =+F22 -> PAID | G29: =+G22 -> EXT EMS$ | H29: =+H22 -> SPLM$ | I29: =+I22 -> SENT | J29: =+J22 -> PAID | K29: REBUILD | L29: =+H29 -> SPLM$ | M29: =+I29 -> SENT | N29: =+J29 -> PAID | O29: CPS$ | P29: =+L29 -> SPLM$ | Q29: =+M29 -> SENT | R29: =+N29 -> PAID
C30: 2000 | D30: 1200
A31: 12 | B31: =+ALL!G12 -> 0
A32: 27 | B32: =+ALL!G27 -> 0 | C32: RPL CPS | D32: =+P29 -> SPLM$ | E32: =+Q29 -> SENT | F32: =+R29 -> PAID | G32: MISC | H32: =+D32 -> SPLM$ | I32: =+E32 -> SENT | J32: =+F32 -> PAID | K32: HMR | L32: =+H32 -> SPLM$ | M32: =+I32 -> SENT | N32: =+J32 -> PAID | O32: APPRSL | P32: =+N32 -> PAID | Q32: REL | R32: =+N32 -> PAID
A33: 26 | B33: =+ALL!G26 -> 0
A36: =1+A29 -> 6 | B36: =+ALL!$H$1 -> 0 | C36: EMS IN$ | D36: SPLM$ | E36: SENT | F36: PAID | G36: EXT EMS$ | H36: =+D36 -> SPLM$ | I36: =+E36 -> SENT | J36: =+F36 -> PAID | K36: REBUILD | L36: =+H36 -> SPLM$ | M36: =+I36 -> SENT | N36: =+J36 -> PAID | O36: CPS$ | P36: =+L36 -> SPLM$ | Q36: =+M36 -> SENT | R36: =+N36 -> PAID
C37: 2000 | D37: 1200
A38: 12 | B38: =+ALL!$H$12 -> 0
A39: 27 | B39: =+ALL!$H$27 -> 0 | C39: RPL CPS | D39: =+P36 -> SPLM$ | E39: =+Q36 -> SENT | F39: =+R36 -> PAID | G39: MISC | H39: =+D39 -> SPLM$ | I39: =+E39 -> SENT | J39: =+F39 -> PAID | K39: HMR | L39: =+H39 -> SPLM$ | M39: =+I39 -> SENT | N39: =+J39 -> PAID | O39: APPRSL | P39: =+N39 -> PAID | Q39: REL | R39: =+N39 -> PAID
A40: 26 | B40: =+ALL!$H$26 -> 0
A43: =1+A36 -> 7 | B43: =+ALL!$I$1 -> 0 | C43: =+C36 -> EMS IN$ | D43: =+D36 -> SPLM$ | E43: =+E36 -> SENT | F43: =+F36 -> PAID | G43: =+G36 -> EXT EMS$ | H43: =+H36 -> SPLM$ | I43: =+I36 -> SENT | J43: =+J36 -> PAID | K43: REBUILD | L43: =+H43 -> SPLM$ | M43: =+I43 -> SENT | N43: =+J43 -> PAID | O43: CPS$ | P43: =+L43 -> SPLM$ | Q43: =+M43 -> SENT | R43: =+N43 -> PAID
C44: 2000 | D44: 1200
A45: 12 | B45: =+ALL!$I$12 -> 0
A46: 27 | B46: =+ALL!$I$27 -> 0 | C46: RPL CPS | D46: =+P43 -> SPLM$ | E46: =+Q43 -> SENT | F46: =+R43 -> PAID | G46: MISC | H46: =+D46 -> SPLM$ | I46: =+E46 -> SENT | J46: =+F46 -> PAID | K46: HMR | L46: =+H46 -> SPLM$ | M46: =+I46 -> SENT | N46: =+J46 -> PAID | O46: APPRSL | P46: =+N46 -> PAID | Q46: REL | R46: =+N46 -> PAID
A47: 26 | B47: =+ALL!$I$26 -> 0
A50: =1+A43 -> 8 | B50: =+ALL!$J$1 -> 0 | C50: =+C43 -> EMS IN$ | D50: =+D43 -> SPLM$ | E50: =+E43 -> SENT | F50: =+F43 -> PAID | G50: =+G43 -> EXT EMS$ | H50: =+H43 -> SPLM$ | I50: =+I43 -> SENT | J50: =+J43 -> PAID | K50: REBUILD | L50: =+H50 -> SPLM$ | M50: =+I50 -> SENT | N50: =+J50 -> PAID | O50: CPS$ | P50: =+L50 -> SPLM$ | Q50: =+M50 -> SENT | R50: =+N50 -> PAID
C51: 2000 | D51: 1200
A52: 12 | B52: =+ALL!$J$12 -> 0
A53: 27 | B53: =+ALL!J27 -> 0 | C53: RPL CPS | D53: =+P50 -> SPLM$ | E53: =+Q50 -> SENT | F53: =+R50 -> PAID | G53: MISC | H53: =+D53 -> SPLM$ | I53: =+E53 -> SENT | J53: =+F53 -> PAID | K53: HMR | L53: =+H53 -> SPLM$ | M53: =+I53 -> SENT | N53: =+J53 -> PAID | O53: APPRSL | P53: =+N53 -> PAID | Q53: REL | R53: =+N53 -> PAID
A54: 26 | B54: =+ALL!J26 -> 0
...

Sheet SPLM
B1: Supplemental Invoices/Reconcile TRACKING
C2: =ALL!C51 -> OH22 JARBOE | D2: =ALL!D51 -> OH23P BOYD @ WOODLINE | E2: =ALL!E51 -> OH22 HARMON | F2: =ALL!F51 -> 0 | G2: =ALL!G51 -> 0 | H2: NY20 JONES, M | I2: NY20 JONES, M
B3: =ALL!B1 -> Property-Owner Name | C3: =ALL!C1 -> JOROBE, DELICIA | D3: =ALL!D1 -> BOYD | E3: =ALL!E1 -> + | F3: =ALL!F1 -> 0 | G3: =ALL!G1 -> 0 | H3: =ALL!H1 -> 0 | I3: =ALL!I1 -> 0
B4: =ALL!B26 -> Insurance Co. Name | C4: =ALL!C26 -> TRAVCO INSURANCE | D4: =ALL!D26 -> STATE FARM | E4: =ALL!E26 -> WESTFIELD INS | F4: =ALL!F26 -> 0 | G4: =ALL!G26 -> 0 | H4: =ALL!H26 -> 0 | I4: =ALL!I26 -> 0
B5: =ALL!B27 -> Claim # | C5: =ALL!C27 -> IKW2742001H | D5: =ALL!D27 -> 35 | E5: =ALL!E27 -> CLM #0002332090 | F5: =ALL!F27 -> 0 | G5: =ALL!G27 -> 0 | H5: =ALL!H27 -> 0 | I5: =ALL!I27 -> 0
B6: FOLLOWING DUE FOR EACH SUBMITTAL
B7: CONTRACTOR W-9 FORM
B8: GENERAL AUTHORIZATION
B9: EMERGENCY SERVICES WORK AUTHORIZATION
B10: Assignment Of Benefits AOB
B11: CONTRACTOR & HOMEOWNER AGREEMENT_____
B12: Notice of Right of Recession
B13: Also see each Invoice type for specific info to be sent into insurer.
B15: Depreciation Hold & or Undisputed Claim Portion Release
B17: Final Closeout
B18: FINAL INVOICE CHECKLIST
B19: Letter of Satisfaction
... B35: INVOICES Paid in Full
A41: 1 | B41: EXTERIOR Mitigation/Emergency Services
B42: CREATE SUPPLEMENTAL XACT ESTIMATE
B43: Submit supplemental invoice.
B44: INVOICES Paid in Full or as agreed
A45: 2 | B45: INTERIOR Mitigation/Emergency Services
B46: =+B42 -> CREATE SUPPLEMENTAL XACT ESTIMATE
B47: =+B43 -> Submit supplemental invoice.
B48: =+B44 -> INVOICES Paid in Full or as agreed
A49: 3 | B49: REBUILD INTERIOR & EXTERIOR
B50: =+B46 -> CREATE SUPPLEMENTAL XACT ESTIMATE
B51: =+B47 -> Submit supplemental invoice.
B52: =+B48 -> INVOICES Paid in Full or as agreed
A53: 4 | B53: Contents / PACKOUT
B54: =+B50 -> CREATE SUPPLEMENTAL XACT ESTIMATE
B55: =+B51 -> Submit supplemental invoice.
B56: =+B52 -> INVOICES Paid in Full or as agreed
A57: 5 | B57: Contents / REPLACEMENT ITEMS
B58: =+B54 -> CREATE SUPPLEMENTAL XACT ESTIMATE
B59: =+B55 -> Submit supplemental invoice.
B60: =+B56 -> INVOICES Paid in Full or as agreed
A61: 6 | B61: Supplements/NEW ITEMS ONLY
B62: =+B58 -> CREATE SUPPLEMENTAL XACT ESTIMATE
...

Sheet Submit
B1: DATE
A2: # | B2: DATE | C2: CO. | D2: NAME | E2: STREET | F2: CITY | G2: ZIP | H2: JOB | I2: EXT | J2: RFG | K2: SDG | L2: INT | M2: MIT | N2: CPS | O2: RPL | P2: RCV | Q2: ALE | R2: M2 | S2: RF2 | T2: SD2 | U2: IN2 | V2: CP2 | W2: AL2 | X2: REL | Y2: Column1 | Z2: STREET

Sheet DONE
A1: STATUS | B1: CODE | C1: NAME | D1: ADDRESS | E1: CITY/STATE
C2: Vanessa Sanchez | D2: 32 Evergreen Ave | E2: Brentwood, GA
A3: c | C3: Latonya Queen | D3: 6134 Hickory Lane Dr. | E3: Union City, GA
A4: c | C4: Wilson | D4: 5909 Grand River Dr. | E4: College Park, GA
A5: c | C5: Parks | D5: 1056 Lawton | E5: Atlanta, | F5: GA
A6: c | C6: Anna Donahoo | D6: 121 Charles St. W | E6: Kitchener, ON, Canada
A7: c | C7: Marcia Spence | D7: 3321 Washington Blvd. | E7: Cleveland Hts., Oh
A8: c | C8: Jacqueline Bair | D8: 789 Woodview Rd | E8: Cleveland Hts., Oh
A9: c | C9: Theresa Wilson | D9: 5909 Grand River Dr. | E9: Atlanta, | F9: GA
A10: c | C10: Carpenter | D10: 5 Hickory Street | E10: Central Islip, NY
A11: c | C11: Marcos Lozano | D11: 5992 Hidden Holm Ln | E11: Austell, GA
A12: c | C12: Karl & Joyce Allen
A13: c | C13: Tisha Brooks | D13: 295 Huntington Str. | E13: Covington, GA
A14: c | C14: Robbie S. Ware | D14: 1369 Almont Dr. | E14: Atlanta | F14: GA
A15: c | C15: Seedia Ceesay | D15: 184 Aaron Ct
A16: c | C16: Valencia Lavender | D16: 2755 Flat Shoals Rd. | E16: College Park, GA
A17: c | C17: Sherrod Brown | D17: 4435 Cascade Rd. | E17: Atlanta | F17: GA
A18: c | C18: Bernice Wallace | D18: 16416 Glendale Ave | E18: Cleveland, | F18: OH
A19: c | C19: Dennis Dexter | D19: 4571 Scarborough Rd | E19: Atlanta | F19: GA
A20: c | C20: John Preer | D20: 3557 Valeland Ave. | E20: Atlanta | F20: GA
A21: c | C21: John Murphy | D21: 2504 Rex Ave. | E21: Atlanta | F21: GA
A22: c | C22: Sandi Lewis | D22: 2738 Elkmont Ridge | E22: Atlanta | F22: GA
A23: c | C23: Anthony Barnhill | D23: 614 Bowling Green Circle | E23: Elyria, | F23: OH
A24: c | C24: Kurt IDT | D24: 1333 E. 188th Str. | E24: Cleveland, | F24: OH | G24: Daycare
A25: c | C25: Idt | D25: 14008 Shaw Ave. | E25: East Cleveland, OH
A26: c | C26: Jamison Gorin | D26: 2313 Grandview | E26: Cleveland Hts., OH
A27: c | C27: Narsina Jones | D27: Mercantile | E27: Beachwwod, OH
A28: c | C28: Yolanda River | D28: 2888 East 117th Str. | E28: Cleveland | F28: OH | G28: Jacqueline
A29: c | C29: Abdul Adil Imran | D29: 15212 Mzple Park Dr. | E29: Maple Hts., OH
A30: c | C30: Dennis Z. McGrew | D30: 9801 South Harvard Ave. | E30: Chicago, | F30: IL
A31: c | C31: Tericka Webb | D31: 2649 East 110th Str. | E31: Cleveland, | F31: OH
A32: c | C32: Linda Donaldson | D32: 300 Landing Dr. | E32: Fayetteville, | F32: GA
A33: c | C33: Shardae Seals
A34: c | C34: Mya West | D34: 3582 Ingleside Rd. | E34: Shaaker Hts., OH
A35: c | C35: Chuck Sherman | D35: 1139 East 76th Str. | E35: Cleveland, | F35: OH
A36: c | C36: Moe | D36: 3817 East 71st Str. | E36: Cleveland, | F36: OH
A37: c | C37: William Edwards | D37: 2033 Case Str. | E37: Twinsburg, OH
A38: c | C38: Edith Johnson | D38: 1791 Wrenford Rd. | E38: South Euclid, OH
A39: c | C39: TERIKA ART LLC | D39: 3611 Chatham Ave. | E39: Cleveland, OH
A40: c | C40: Robert Dubose | D40: 12202 Farringdon Ave. | E40: Cleveland, OH
...

Sheet DROPDN
A1: Cause of Loss | B1: WATER
B2: Wind = Roof
B3: Water Damage=WTR
B4: Fire Smoke
B5: Wind=Tree
B6: Hurricane =HURR
B7: TBD
A9: date of loss | B9: 44051
A11: rebuild type 1 | B11: INTERIOR REPAIRS
B12: roofing shingles replacement
B13: fencing
B14: shed
B15: porch patio
B16: interior repairs
B17: exterior repairs
B18: TBD
B19: N/A
A20: rebuild type 2 | B20: INTERIOR REPAIRS
B21: roofing shingles replacement
B22: fencing
B23: shed
B24: porch patio
B25: interior repairs
B26: exterior repairs
B27: TBD
B28: N/A
B29: SIDING
A32: rebuild type 3 | B32: INTERIOR REPAIRS
B33: roofing shingles replacement
B34: fencing
B35: shed
B36: porch patio
B37: interior repairs
B38: exterior repairs
B39: TBD
B40: N/A
A42: DEMO | B42: Y
B43: N
B44: TBD
B45: =+B40 -> N/A
...
