Workbook
Name _ftn1: demand!$B$946
Name _ftnref1: demand!$B$957
Name ALL: ALL!#REF!
Name COMPANY_HEADER: REBLD!$A$4:$D$12
Name FINAL_INVOICES_STATEMENT: ALL!$D$171
Name newclaimspacerow1: ALL!$AJ$1
Name RE___DEMAND_FOR_APPRAISAL: demand!$D$283
Name SORT_A__Z: #REF!
Name SPLM_START_INFO: ALL!#REF!

Sheet ALL
B1: A-Z | C1: NAME | D1: Property-Owner Name | E1: Sheet Map | F1: Bradley, Curtis L | G1: KOSWATTA, ERIKA | H1: Williams, Bridgett | I1: Battle, Larry Jr | J1: ANDERSON, PETE | K1: WYNN, NICK | L1: FERGUSON, ROBERT & MRS | M1: RUSH, TIFFANY LOAN # 0579206154 | N1: RUSH, TIFFANY WTR | O1: TORRES, ANGEL | P1: Harvey, CORA | Q1: ROBINSON, NiKKole | R1: LEETH, RONNIE | S1: LANEY, Anthony | T1: LAWRENCE, GENEATHA | U1: SMITH, JANET | V1: Wimbish, Tawana | W1: HICKS, JASON | X1: Akala, Ayo SMOKE FIRE | Y1: Akala, Ayo VND | Z1: Akala, Ayo TREE | AA1: Cousette, JOHN Vandalism | AB1: Cousette, JOHN ROOF | AC1: JONES, BREANNA | AD1: Collins, Darlene | AE1: NEWMAN, NICOLE | AF1: Peggy Henderson | AG1: Romero Beverly | AH1: TAYLOR DAVIDSON, WARREN | AI1: Goshen, Aaron & Shania | AJ1: Brownlee. LAVERNE | AK1: Craig Ringo | AL1: SMITH, JANET | AM1: Brown, Cassandra | AN1: Hurt, Chaunte | AO1: Dejarnette Mattie | AP1: Burns2, RUBY | AQ1: CARTER, KAREN | AR1: CHERRY, LAUREN LB8997 | AS1: Johnson, Paul & Tamra | AT1: LACEY, EUNICE | AU1: BROOKS, DANIEL;JANAE POA | AV1: Smith, Brian | AW1: THOMAS, ANITA | AX1: Hatten, Nedra | AY1: HOWARD, MATTHEW | AZ1: MONTGOMERY, JAVIONNA | BB1: BROWNLEE, KEN | BC1: HUTCHINSON | BL1: new claim | BN1: A-Z | BO1: BROWN,Courtney | BP1: JOHNSON,MIKE WTR | BQ1: JOHNSON,MIKE RFG | BR1: Burns, ERIC | BS1: Tamplin, Adalene | BT1: George Greenawalt | BU1: Brown, Charles | BV1: Lozano, Marcos | BW1: Johnson, Margaret | BX1: Carib Investment ,LLC | BY1: Franklin Annette | BZ1: Lanier, Shari | CA1: Corbin, Wanda | CB1: WILLIS, CATRERA | CC1: Greenawalt, Mike | CD1: THOMAS, LISA | CE1: Ragland | CF1: Webb, Terika | CG1: Red Ink CLE LLC Amir
A2: E1 | B2: =E1 -> Sheet Map | C2: =$F$1 -> Bradley, Curtis L | D2: Property address: street | G2: TBD | H2: CPS ADJUSTER | I2: TBD | J2: 0 | K2: SHEREFINAL 1M0N 11.28.22 | M2: 956 Roanoke Road, | N2: 956 Roanoke Road, | O2: One Tower Square | P2: TBD | Q2: TBD | R2: TBD | T2: 3936 Strandhill Road | U2: 2819-21 Ludlow Road | V2: 300 Lynhurst Drive | W2: 5630 Turney Road | X2: 3685 E153 | Y2: 3685 E153 | Z2: 3685 E153 | AA2: 1133 East 111th St | AB2: 1133 East 111th St | AC2: 6033 Bear Creek Dr #420 | AD2: 1334 Elwood RD | AE2: 4767 E 88 STR | AF2: 12413-15Gruss Ave, | AG2: 592 Clubland Circle Southeast | AH2: 15009 Harvard Ave | AI2: 969 E 348th St | AJ2: 13509 Alvin Ave | AK2: 5697 Daniel Street | AL2: 2821 Ludlow Road | AM2: 6918 Hecker Ave, | AN2: 703 E 241st St | AO2: 16755 Lorain ST. | AP2: 3 Washington Square | AQ2: 7 Washington Square | AR2: 2687 E.128th | AS2: 9402 Shepard Road | AT2: 13601 5th Ave | AU2: 3427 SANDALWOOD LN | AV2: 831 Gertrude Place NW, | AW2: 6600 GERTRUDE | AX2: 628 Quilliams Road | AY2: 3247 East 55th Street | AZ2: 3034 Ashwood Road, | BB2: 3922 E 189 STR | BC2: 17823 Rauland Dr | BL2: HOME | BM2: INACTIVE | BN2: =BO1 -> BROWN,Courtney | BO2: 6479 Veracruse Dr | BP2: 1841 Childress Dr SW | BQ2: 1841 Childress Drive Southwes | BR2: 488 Trebisky RD | BS2: 287 Roberts Rd | BT2: 11604 Governor Ave | BU2: TBD | BV2: Direct: (844) 306-0752 Ext.591641 | BW2: 3619 Rolling Green Ridge | BX2: 4745 East 88th Street, | BY2: One State Farm Plaza | BZ2: 1408 East 124th Street | CA2: 15907 Eldamere Ave | CB2: 969 E 348th St | CC2: 11601 Governor Avenue | CD2: 5149 Miller Avenue | CE2: 42 NORDHAM DR | CF2: 4981 Horizon Drive | CG2: 1790 E 43rd St,
A3: F1 | B3: =$X$1 -> Akala, Ayo SMOKE FIRE | C3: =$G$1 -> KOSWATTA, ERIKA | D3: Property city, state, zip | F3: ='[1]jobinfo(2)'!$C$53 -> GUEST CLOSET | G3: Foyer/Entry Room | H3: GUEST CLOSET | I3: FOYER/ENTRY ROOM | J3: Foyer | K3: Foyer | L3: Kitchen Travel area | M3: Cleveland Heights, OH | N3: Cleveland Heights, OH | O3: FOYER - TRAVEL AREA | P3: Front Room Foyer/entry | Q3: FOYER/ENTRY ROOM | R3: Foyer & HALL | S3: FOYER | T3: Cleveland, OH 44128 | U3: Cleveland, OH 44120 | V3: Atlanta, GA 30311 | W3: Garfield Heights, OH, 44125 | X3: Cleveland OH 44120 | Y3: Cleveland OH 44120 | Z3: Cleveland OH 44120 | AA3: Cleveland, OH | AB3: Cleveland, OH | AC3: Bedford Heights, OH 44146 | AD3: East Cleveland, OH 44108 | AE3: GARFILELD, OH 44125 | AF3: Cleveland, OH 44108 | AG3: Conyers, GA, | AH3: Cleveland, OH 4412 | AI3: Eastlake, Ohio 44095 | AJ3: Garfield Heights 44105 | AK3: Bedford Hgts OH 44146 | AL3: Cleveland, OH 44120 | AM3: Cleveland, OH 44106 | AN3: Euclid, OH 44123 | AO3: Chagrin Falls, Ohio 44023, USA | AP3: Euclid, OH 44143 | AQ3: Euclid, OH 44143 | AR3: CLEVELAND, OH 44120 | AS3: Macedonia, OH, USA | AT3: East Cleveland, OH 44112 | AU3: Austintown, OH 44511 | AV3: Atlanta, GA 30318 | AW3: Cleveland, OH 44105 | AX3: Cleveland Heights, OH 44121 | AY3: Cleveland, OH 44127 | AZ3: Cleveland, OH, USA 44120 | BB3: CLEVELAND, OH 44128 | BC3: WALTON HILLS, OH 44146 | BL3: Atlanta, GA 30318 | BN3: =#REF! -> #REF! | BO3: Morrow, GA 30260 | BP3: Atlanta, GA, 30311 | BQ3: Atlanta, GA, 30311 | BR3: Richmond Heights, OH 44143 | BS3: Barnesville, GA 30204 | BT3: Cleveland, OH 44111 | BU3: TBD | BV3: FOYER / ENTRY | BW3: Atlanta, GA, 30331 | BX3: Garfield Heights, OH | BY3: Living Room Travel Area | BZ3: Cleveland, OH 44106 | CA3: Cleveland, OH 44128 | CB3: Eastlake, Ohio 44095 | CC3: Cleveland, OH, 44111 | CD3: Maple Heights, OH | CE3: Bedford, OH 44146 | CF3: Richmond Heights 44143 | CG3: Cleveland, OH, 44103
A4: G1 | B4: =$Z$1 -> Akala, Ayo TREE | C4: =$H$1 -> Williams, Bridgett | D4: Customer Email | G4: TBD | H4: ANNA LISA | I4: TBD | J4: 0 | K4: Matthew.Mertz@LIBERTYMUTUAL.COM | M4: dr.tiffanyrw@counselingsecure.com | N4: dr.tiffanyrw@counselingsecure.com | O4: Attn: Consumer Affairs | P4: TBD | Q4: 0 | R4: TBD | T4: GANNLAWRENCE@HOTMAIL.COM | U4: smithh1963@gmail.com | V4: tawanawimbish@yahoo.com | W4: LJ53089@YAHOO.COM | X4: kiitan.akala@gmail.com | Y4: kiitan.akala@gmail.com | Z4: kiitan.akala@gmail.com | AA4: john.cousette@yahoo.com | AB4: john.cousette@yahoo.com | AC4: BREANNAJ9950@GMAI.COM | AD4: OH24ACOLLINS@ELWOOD RD | AE4: NICC524@GMAIL.COM | AF4: pthornton8@roadrunner.com | AG4: Djembepaid@gmail.com | AH4: GOLDENHAWK38@GMAIL.COM | AI4: AaronShaniaGoshen@gmail.com | AJ4: lavernbrownlee107@gmail.com | AK4: CraigRINGO@GMAIL.COM | AL4: smithh1963@gmail.com | AM4: browncass.mzsan73@gmail.com | AN4: Clhurt87@gmail.com | AO4: MIKEWILEY21@YAHOO.COM | AP4: dorothy.webb@sbcglobal.net | AQ4: KAREN.CARTER5214@GMAIL.COM | AR4: lauren@anniewillventures.com | AS4: tringo68@yahoo.com | AT4: Emdlacey@gmail.com | AU4: JANAETAB16@YAHOO.COM | AV4: BRIAN.ASHTON.SMITH.211@GMAIL.COM | AW4: Trenddamnish@yahoo.com | AX4: Msnedra1015@aol.com | AY4: HOWARDSERVICES@YAHOO.COM | AZ4: JAVIONNA@ICLOUD.COM | BB4: KHAIAKEN@SBCGLOBAL.NET | BL4: BW | BN4: =BP1 -> JOHNSON,MIKE WTR | BO4: Courtabrown88@gmail.com | BP4: majohnson3619@gmail.com | BQ4: majohnson3619@gmail.com | BR4: casino2011@gmail.com | BS4: ATLENETAMPLIN220@icloud.com | BT4: zerodark@netzero.net | BU4: www.burnsandwilcox.com | BW4: Klassykliquemj@yahoo.com | BX4: kerryanncampbell88@gmail.com | BZ4: SHARILANIER312@YAHOO. COM | CA4: corbinw27@gmail.com | CB4: CATRERAWILLIS2003@YAHOO.COM | CC4: gmail.com | CD4: LTSLIM7@GMAIL.COM | CE4: HERMANRAGLAND8268@YAHOO.COM | CF4: TERIKA86@ME.COM | CG4: CALDWELL.AMIR@GMAIL.COM
A5: H1 | B5: =$Y$1 -> Akala, Ayo VND | C5: =$I$1 -> Battle, Larry Jr | D5: Cst-owner Phone# | F5: ='[1]jobinfo(2)'!$C$67 -> BR3 CLOSET | G5: Linen CLST | H5: Basement Stairs | I5: TBD | J5: 0 | K5: STAIRS UP | M5: 2163168365 | N5: STAIRS BASEMENT | O5: - | P5: TBD | Q5: Family Room | R5: TBD | S5: RFG HOUSE | T5: (216) 262-4239 | U5: (216) 403-7739 | V5: (404) 226-8335 | W5: 216) 624-9774 | X5: (202) 830-8979 | Y5: (202) 830-8979 | Z5: (202) 830-8979 | AA5: (216) 456-1400 | AB5: (216) 456-1400 | AC5: (702) 525-1551 | AD5: (216) 851-4881 | AE5: 216 640 4975 | AF5: (216) 554-3404 | AG5: (414) 732-8842 | AH5: (216) 925-9362 | AI5: (216) 376-0509 | AJ5: 2162403945 | AK5: 216.294.5133 | AL5: (216) 403-7739 | AM5: (216) 288-5176 | AN5: (216) 334-0599 | AO5: (440) 629-9046 | AP5: (216) 408-4595 | AQ5: 2165267685 | AR5: (216) 548-8897 | AS5: (216) 399-6191 | AT5: (216) 450-4913 | AU5: (330) 951-2652 | AV5: (404) 444-1325 | AW5: (216) 315-2040 | AX5: (216) 240-4123 | AY5: (216) 224-4392 | AZ5: (216) 551-5572 | BB5: 2163241337 | BC5: (216) 8320190 | BL5: (404) 444-1325 | BN5: =BQ1 -> JOHNSON,MIKE RFG | BO5: (470) 230-2860 | BP5: (404) 380-4620 | BQ5: (404) 380-4620 | BR5: (216) 695-1629 | BS5: 478.832.4889 | BT5: (216) 476-9000 | BU5: TBD | BW5: (678) 789-2192 | BX5: (216) 855-4691 | BY5: TBD | BZ5: (216) 255-8944 | CA5: (216) 214-8560 | CB5: 2169708478 | CC5: (216) 251-5022 | CD5: (216) 632-9421 | CE5: 2162000903 | CF5: 216) 235-0005 | CG5: (216) 374-2899
A6: I1 | B6: =$J$1 -> ANDERSON, PETE | C6: =$J$1 -> ANDERSON, PETE | D6: Co-Owner.cst#2 | G6: TBD | H6: 812-235-7239 | I6: TBD | J6: Phone: (800) 326-0950 x1210210 | K6: 216.314.6086 | M6: NA | N6: NA | P6: TBD | Q6: TBD | R6: TBD | T6: TBD | U6: TERRANCE DAVIS | V6: TBD | W6: TBD | AA6: NA | AB6: NA | AC6: TBD | AD6: NA | AE6: NA | AF6: TBD | AG6: tbd | AH6: NA | AI6: Aaron Christopher Goshen | AJ6: TBD | AL6: HILLARY SMITH | AM6: TBD | AO6: TBD | AR6: TBD | AT6: TBD | AU6: TBD | AV6: MRS. | AX6: TBD | AY6: OH25 HOWARD @E55 | BB6: NA | BC6: TBD | BL6: MRS. | BN6: =BR1 -> Burns, ERIC | BP6: TBD | BQ6: TBD | BR6: na | BS6: 0 | BT6: NA | BU6: TBD | BV6: TBD | BW6: Michael Johnson | BY6: TBD | CA6: Corbin, CATHERINE | CB6: NA | CC6: TBD | CD6: TBD | CE6: MRS | CF6: TLW, LLC
A7: J1 | B7: =$I$1 -> Battle, Larry Jr | C7: =$K$1 -> WYNN, NICK | D7: cst ph # 2 | F7: ='[1]jobinfo(2)'!$C$69 -> BR2 CLOSET | G7: Bedroom # 2 | H7: LL Bathroom | I7: TBD | J7: 0 | K7: Bedroom # 1 | M7: NA | N7: Laundry Room | O7: 17 | P7: TBD | Q7: Bath Guest Flr 1 | R7: TBD | T7: TBD | U7: 2163185051 | V7: TBD | W7: 2163185051 | AA7: (216) 304-8664 | AB7: (216) 304-8664 | AC7: TBD | AD7: 216 308 5049 | AF7: TBD | AG7: tbd | AH7: NA | AJ7: TBD | AM7: TBD | AO7: 216 310 4319 | AR7: TBD | AT7: TBD | AU7: TBD | AX7: TBD | BB7: NA | BC7: TBD | BL7: TBD | BN7: =BS1 -> Tamplin, Adalene | BP7: TBD | BQ7: TBD | BR7: na | BS7: 0 | BT7: (216) 251-5022 | BU7: TBD | BW7: (404) 380-4620 | BY7: TBD | CA7: (216) 336-8742 | CB7: NA | CC7: TBD | CD7: TBD | CG7: +1 (216) 218-9027 Amir
A8: K1 | B8: =$F$1 -> Bradley, Curtis L | C8: =$L$1 -> FERGUSON, ROBERT & MRS | D8: Cst address # 2 | F8: ='[1]jobinfo(2)'!$C$56 -> Kitchen | G8: Living Room-FAMILY ROOM | H8: Kitchen | I8: BAR AREA | J8: Kitchen | K8: Dining Room | L8: CLOSET | M8: NA | N8: Nook | O8: BEDROOM1 PROTECT TRAVEL AREA | P8: Kitchen | Q8: Bathroom | R8: REC ROOM #1 /MAIN | S8: STAIRS UP | T8: TBD | U8: TBD | V8: TBD | W8: TBD | AA8: NA | AB8: NA | AC8: TBD | AD8: NA | AF8: TBD | AG8: tbd | AH8: NA | AI8: 1203 Starlight Ave | AJ8: TBD | AL8: TBD | AM8: TBD | AO8: TBD | AR8: TBD | AT8: TBD | AU8: TBD | AX8: TBD | BB8: NA | BC8: TBD | BL8: TBD | BN8: =BT1 -> George Greenawalt | BP8: TBD | BQ8: TBD | BR8: na | BS8: 0 | BT8: NA | BU8: TBD | BV8: Living Room | BW8: 3619 Rolling Green Ridge | BY8: GUEST CLOSET | CB8: NA | CC8: TBD | CD8: TBD
B9: =$AU$1 -> BROOKS, DANIEL;JANAE POA | C9: =$M$1 -> RUSH, TIFFANY LOAN # 0579206154 | D9: city, state-cst#2 | F9: ='[1]jobinfo(2)'!$C$76 -> Utility Room | G9: Master BR Closet2 | H9: TBD | I9: TBD | J9: 0 | K9: PRIMARY BR Closet | M9: NA | N9: TBD | O9: - | P9: TBD | Q9: BONUS ROOM GARAGE | R9: TBD | T9: TBD | U9: TBD | V9: TBD | W9: TBD | AA9: NA | AB9: NA | AC9: TBD | AD9: NA | AF9: TBD | AG9: tbd | AH9: NA | AI9: Aubrey TX 76227-3778 | AJ9: TBD | AL9: TBD | AM9: TBD | AO9: TBD | AR9: TBD | AT9: TBD | AU9: TBD | AX9: TBD | BB9: NA | BC9: TBD | BL9: TBD | BN9: =BU1 -> Brown, Charles | BP9: TBD | BQ9: TBD | BR9: na | BS9: 0 | BT9: NA | BU9: TBD | BW9: Atlanta, GA, 30331 | BY9: TBD | CB9: NA | CC9: TBD | CD9: TBD
B10: =$AM$1 -> Brown, Cassandra | C10: =$N$1 -> RUSH, TIFFANY WTR | D10: email-cst #2 | G10: Grange Insurance Business | H10: David Boltin | I10: TBD | J10: 0 | K10: #REF! | M10: NA | N10: TBD | O10: Attn: Consumer Affairs | P10: TBD | Q10: TBD | R10: TBD | T10: TBD | U10: TBD | V10: TBD | W10: TBD | AA10: smith.tywan@yahoo.com | AB10: smith.tywan@yahoo.com | AC10: TBD | AD10: NA | AF10: TBD | AG10: tbd | AH10: NA | AJ10: TBD | AL10: TBD | AM10: TBD | AO10: TBD | AR10: TBD | AT10: TBD | AU10: TBD | AV10: renaissancemanbs@aol.com | AX10: TBD | BB10: NA | BC10: TBD | BL10: TBD | BN10: =BV1 -> Lozano, Marcos | BP10: TBD | BQ10: TBD | BR10: na | BS10: 0 | BT10: NA | BU10: TBD | BV10: Claims Supervisor: Britt Strong | BW10: majohnson3619@gmail.com | BY10: State Farm Insurance | CB10: NA | CC10: TBD | CD10: TBD
B11: =$BB$1 -> BROWNLEE, KEN | C11: =$O$1 -> TORRES, ANGEL | D11: Cause of Loss | F11: Y | G11: Y | H11: Y | I11: Y | J11: y | K11: y | L11: y | M11: WIND & TREE | N11: Y | O11: y | P11: Y | Q11: TBD | R11: Y | S11: NA | T11: WIND/HAIL | U11: WATER | V11: Wind=Tree/HAIL | W11: WATER | X11: FIRE | Y11: VANDALISM | Z11: TREE WIND | AA11: Vandalism | AB11: TORNADO | AC11: WATER | AD11: FIRE/SMOKE | AE11: WATER | AF11: Fire & Smoke | AG11: Wind / Hail | AH11: Vehicle | AI11: WATER | AJ11: Wind=Tree | AK11: WATER LEAK | AL11: WATER | AM11: Water | AN11: FIRE | AO11: WATER | AP11: WATER | AQ11: WATER | AR11: FIRE | AS11: WATER | AT11: BATHTUB OVERFLOW | AU11: WATER PIPE BROKE | AV11: KITCHEN WATER PIPE BROKE | AW11: Water Damage=WTR | AX11: BATHTUB OVERFLOW | AY11: Wind / Hail | AZ11: WATER BATHTUB OVERFLOW | BB11: WATER | BC11: BROKEN WATER LINE | BL11: KITCHEN WATER PIPE BROKE | BN11: =BW1 -> Johnson, Margaret | BO11: Wind / Hail | BP11: WATER | BQ11: Water | BR11: wind tree | BS11: Wind = Roof | BT11: FIRE GARAGE | BU11: TBD | BV11: TBD | BW11: WIND & TREE | BX11: FIRE | BY11: N | BZ11: WINDSTORM AND HAIL | CA11: Wind / Hail | CB11: WATER | CC11: WIND | CD11: Wind / Hail | CE11: WIND | CF11: Tornado | CG11: WIND
B12: =$AJ$1 -> Brownlee. LAVERNE | C12: =$P$1 -> Harvey, CORA | D12: date of loss | F12: Y | G12: Y | H12: Y | I12: Y | J12: tbd | K12: tbd | L12: y | M12: 45331 | N12: Y | O12: tbd | P12: Y | Q12: TBD | R12: Y | S12: TBD | T12: 45163 | U12: TBD | V12: 45390 | W12: 45483 | X12: 45476 | Y12: 45476 | Z12: 45526 | AA12: 45511 | AB12: 45510 | AC12: 45402 | AD12: 45524 | AE12: 45568 | AF12: 45330 | AG12: 45335 | AH12: 45510 | AI12: 45563 | AJ12: 45618 | AK12: 44858 | AL12: 45628 | AM12: 45686 | AN12: Sunday, March 2, 2025 | AO12: 45735 | AP12: Wednesday, March 19, 2025 | AQ12: 45735 | AR12: Friday, August 16, 2024 | AS12: 45751 | AT12: 45765 | AU12: Sunday, March 2, 2025 | AV12: Tuesday, March 11, 2025 | AW12: Friday, September 12, 2025 | AX12: 45824 | AY12: 45827 | AZ12: Saturday, August 26, 2025 | BB12: 45986 | BC12: 46062 | BL12: Tuesday, March 11, 2025 | BN12: =BX1 -> Carib Investment ,LLC | BO12: 45570 | BP12: 45330 | BQ12: 45330 | BR12: 45618 | BS12: 44312 | BT12: 44638 | BU12: TBD | BV12: TBD | BW12: 45329 | BX12: 45739 | BY12: N | BZ12: 45721 | CA12: 45521 | CB12: 45563 | CC12: 45163 | CD12: 45163 | CE12: 45510 | CF12: 45510 | CG12: 45529
B13: =$AP$1 -> Burns2, RUBY | C13: =$Q$1 -> ROBINSON, NiKKole | D13: rebuild type 1 | F13: Y | G13: Y | H13: Y | I13: Y | J13: y | K13: y | L13: y | M13: ROOF REPAIR | N13: Y | O13: TBD | P13: Y | Q13: TBD | R13: Y | S13: TBD | T13: ROOF | U13: Interior Repairs LEVEL 1 &2 | V13: ROOF Exterior | W13: Interior Repairs LEVEL 1 | Z13: roofing shingles replacement | AA13: Interior Repairs LEVEL 1 | AB13: ROOF SHINGLES | AC13: Interior Repairs | AD13: Interior Repairs LEVEL 1 | AE13: Interior Repairs LEVEL 1 | AF13: interior repairs | AG13: ROOF REPLACE SHINGLES | AH13: VEHICLE HIT EAST SIDE OF THE HOME, OPPOSITE OF THE DRIVEWAY | AI13: interior repairs | AJ13: ROOF REPLACE SHINGLES | AK13: interior repairs | AL13: Interior Repairs LEVEL 1 | AM13: INTERIOR ROOMS IMPACTED | AN13: interior repairs | AO13: INTERIOR ROOMS IMPACTED | AP13: Interior Repairs LEVEL 1 | AQ13: Interior Repairs LEVEL 1 | AR13: DOORS/PORCHES EXT | AS13: Interior Repairs LEVEL 1 | AT13: interior repairs LVL2 | AU13: interior repairs | AV13: interior repairs | AW13: interior repairs LVL1 | AX13: interior repairs LVL2 | AY13: ROOF | AZ13: interior repairs LVL1 | BB13: interior repairs LVL1 | BC13: interior repairs LVL1 | BL13: interior repairs | BN13: =BY1 -> Franklin Annette | BO13: ROOF DAMAGE | BP13: interior repairs | BQ13: roof shingles | BR13: TREE HIT HOUSE FROM WIND STROM | BS13: roofing shingles replacement | BT13: exterior repairs | BU13: TBD | BV13: TBD | BW13: roofing shingles replacement | BX13: interior repairs | BY13: N | BZ13: Interior Repairs LEVEL 2 | CA13: Homesite | CB13: roofing shingles replacement | CC13: ROOF | CD13: roofing shingles replacement | CF13: SHED | CG13: ROOF EXTERIOR
B14: =$AQ$1 -> CARTER, KAREN | C14: =$R$1 -> LEETH, RONNIE | D14: rebuild type 2 | F14: grangeinsurance.com | G14: TBD | H14: claims@claims.allstate.com | I14: TBD | J14: 0 | K14: #REF! | M14: EXT REPAIRS | N14: BETH.OLDFORD@RYSECLAIMS.COM.BETH | P14: TBD | Q14: TBD | R14: TBD | T14: SIDING | V14: interior repairs | W14: Interior Repairs LEVEL 2 | Z14: exterior repairs | AA14: Interior Repairs LEVEL 2 | AB14: Interior Repairs LEVEL 3 | AD14: Interior Repairs LEVEL 2 | AE14: Interior Repairs LEVEL 2 | AF14: interior repairs | AG14: EXTERIOR REPAIRS | AH14: BRICK | AI14: interior repairs | AJ14: Interior Repairs LEVEL 1 | AK14: NA | AL14: Interior Repairs LEVEL 2 | AM14: TBD | AN14: ALL LEVELS | AO14: TBD | AR14: SDG | AS14: Interior Repairs LEVEL 2 | AT14: interior repairs LVL1 | AU14: interior repairs | AV14: interior repairs | AW14: interior repairs LVL2 | AX14: interior repairs LVL1 | AY14: interior repairs LVL2 | AZ14: interior repairs LVL2 | BB14: interior repairs LVL2 | BC14: BASEMENT | BL14: interior repairs | BN14: =BZ1 -> Lanier, Shari | BO14: INTERIOR ROOMS IMPACTED | BP14: interior repairs | BQ14: interior repairs | BR14: ROOF SHINGLES | BS14: interior repairs | BT14: exterior repairs | BU14: TBD | BV14: wgrace@alacritysolutions.com | BW14: interior repairs | BY14: TBD | BZ14: SIDING | CA14: INTERIOR ROOMS IMPACTED | CC14: INTERIOR REPAIRS | CD14: interior repairs | CE14: Interior Repairs LEVEL 2 | CF14: TREE REMOVAL | CG14: AWNING EXT
B15: =$AR$1 -> CHERRY, LAUREN LB8997 | C15: =$S$1 -> LANEY, Anthony | D15: rebuild type 3 | G15: TBD | H15: Drew over at Paul Davis. | I15: TBD | J15: Dunn Sterling | K15: #REF! | L15: CLEMENTS, NATASHA | M15: WTR INT FOYER | N15: OLDFORD, BETH | O15: Ins Adj Trvlr David Walker | P15: TBD | Q15: 0 | R15: Ann.Conway@usaa.com | T15: INTERIOR REPAIRS | V15: TBD | W15: TBD | AA15: Interior Repairs BSMNT | AB15: TBD | AD15: Interior Repairs LEVEL3 | AE15: Interior Repairs BSMNT | AF15: TBD | AG15: Interior Repairs LEVEL 1 &2 | AH15: SIDING | AJ15: Interior Repairs LEVEL 2 &3 | AK15: NA | AL15: Interior Repairs LEVEL 3 | AM15: TBD | AN15: EXTERIOR REPAIRS | AO15: TBD | AR15: Interior Repairs LEVELS = 4 | AT15: BASEMENT | AU15: TBD | AV15: TBD | AX15: BASEMENT | AY15: interior repairs LVL1 | AZ15: interior repairs BSMNT | BL15: TBD | BN15: =CA1 -> Corbin, Wanda | BO15: PBR CLST, BR2, BR1 CLST, LINEN, GARAGE | BP15: TBD | BQ15: TBD | BR15: INTERIOR DAMAGE | BS15: exterior repairs | BT15: exterior repairs | BW15: exterior repairs | BY15: Jason 931-629-2250 | BZ15: ROOF | CA15: KIT/Bath/LINEN/BR1 CLST | CB15: TBD | CC15: INTERIOR REPAIRS | CD15: TBD | CF15: GAZEBO | CG15: Interior Repairs LEVEL 3
B16: =$AD$1 -> Collins, Darlene | C16: =$T$1 -> LAWRENCE, GENEATHA | D16: DEMO | F16: grangeinsurance.com | G16: BenczeR@Grangeinsurance.com | H16: claims@claims.allstate.com | I16: tbd | J16: claims@claims.allstate.com | K16: orlando.reyes@libertymutual.com | L16: statefarmfireclaims@statefarm.com | M16: TBD | N16: TBD | O16: mptaylor@travelers.com | P16: ASIA.BABLES@LIBERTYMUTUAL.COM | Q16: Nicole.Schaumleffel@libertymutual.com | R16: 432v85zlpxmb@claims.usaa.com | S16: benjamin.bybee@allstate.COM | T16: Y | U16: Y | V16: Y | W16: Y | AA16: Y | AB16: Y | AC16: N | AD16: Y | AE16: Y | AF16: Y | AG16: Y | AH16: INTERIOR | AI16: Y | AJ16: Y | AK16: y | AL16: Y | AM16: Y | AN16: Y | AO16: Y | AP16: Y | AQ16: Y | AR16: Y | AS16: Y | AT16: Y | AU16: Y | AV16: Y | AW16: Y | AX16: Y | AY16: Y | AZ16: Y | BB16: Y | BC16: Y | BL16: Y | BN16: =CB1 -> WILLIS, CATRERA | BO16: Y | BP16: Y | BQ16: Y | BR16: y | BS16: Y | BT16: Y | BV16: candacebrown@alacritysolutions.com | BW16: Y | BY16: statefarmfireclaims@statefarm.com | CA16: Y | CB16: Y | CC16: Y | CD16: TBD | CE16: Y | CF16: Y
B17: =$AB$1 -> Cousette, JOHN ROOF | C17: =$U$1 -> SMITH, JANET | D17: Mitigation | G17: TBD | H17: TBD | I17: TBD | J17: 0 | K17: #REF! | M17: TBD | N17: TBD | O17: 0 | P17: TBD | Q17: TBD | R17: TBD | T17: Y | U17: Y | V17: Y | W17: Y | AA17: Y | AB17: Y | AC17: N | AD17: Y | AE17: Y | AF17: Y | AG17: Y | AH17: Y | AI17: Y | AJ17: Y | AK17: y | AL17: Y | AM17: Y | AN17: Y | AO17: Y | AP17: Y | AQ17: Y | AR17: Y | AS17: Y | AT17: Y | AU17: Y | AV17: Y | AW17: Y | AX17: Y | AY17: Y | AZ17: Y | BB17: Y | BC17: Y | BL17: Y | BN17: =CC1 -> Greenawalt, Mike | BO17: Y | BP17: Y | BQ17: Y | BR17: y | BS17: Y | BT17: NA | BU17: TBD | BW17: Y | BY17: TBD | CA17: Y | CB17: Y | CC17: Y | CD17: TBD | CE17: Y | CF17: Y
B18: =$AA$1 -> Cousette, JOHN Vandalism | C18: =$V$1 -> Wimbish, Tawana | D18: Other Structures | F18: C: 216-559-6953 | G18: (614) 593-7718 | H18: 8886568005 | I18: ext | J18: ext (1213490) | K18: 330-437-6722 | M18: NA | N18: TBD | O18: 813.731.6489 | P18: 469 997 2808 | Q18: 1 (757) 854-8187 | R18: 44453 | S18: x1225768 | T18: TBD | U18: NA | V18: NA | W18: NA | AA18: NA | AB18: NA | AC18: N | AD18: NA | AE18: NA | AF18: NA | AG18: TBD | AH18: TBD | AI18: Y | AJ18: NA | AK18: na | AL18: NA | AM18: Y | AN18: NA | AO18: NA | AP18: N | AQ18: N | AR18: NA | AS18: N | AT18: NA | AU18: NA | AV18: NA | AW18: NA | AX18: NA | AY18: NA | AZ18: NA | BB18: NA | BC18: NA | BL18: NA | BN18: =CD1 -> THOMAS, LISA | BO18: Y | BP18: NA | BQ18: NA | BR18: GARAGE | BS18: TBD | BT18: Y | BV18: X591641 | BW18: NA | BY18: ext | CA18: GARAGE | CB18: NA | CC18: TBD | CD18: TBD | CE18: Y | CF18: Y
B19: =$AK$1 -> Craig Ringo | C19: =$W$1 -> HICKS, JASON | D19: Replacement | F19: ='[1]jobinfo(2)'!$C$58 -> Back Foyer | G19: Hallway- DN | H19: Stairs Up | I19: CLOSET | J19: Stairs UP | K19: Kitchen | L19: STAIRS DN | M19: NA | N19: Bath @ Rear Foyer | O19: Linen Closet HALL | P19: Pantry/HALL | Q19: Guest Closet | R19: BATH | S19: PBR | T19: Y | U19: Y | V19: Y | W19: Y | AA19: Y | AB19: Y | AC19: Y | AD19: Y | AE19: Y | AF19: Y | AG19: Y | AH19: Y | AI19: Y | AJ19: Y | AK19: y | AL19: Y | AM19: Y | AN19: Y | AO19: Y | AP19: Y | AQ19: Y | AR19: Y | AS19: Y | AT19: Y | AU19: Y | AV19: Y | AW19: Y | AX19: Y | AY19: Y | AZ19: Y | BB19: Y | BC19: Y | BL19: Y | BN19: =CE1 -> Ragland | BO19: Y | BP19: Y | BQ19: Y | BR19: y | BS19: Y | BT19: Y | BU19: TBD | BV19: Kitchen | BW19: Y | BY19: PBR CLOSET | CA19: Y | CB19: Y | CC19: Y | CD19: TBD | CE19: Y | CF19: Y
B20: =$AO$1 -> Dejarnette Mattie | C20: =$X$1 -> Akala, Ayo SMOKE FIRE | D20: CPS / CLN / CON/ CGN | F20: ='[1]jobinfo(2)'!$C$59 -> Stairs Up | G20: LR CLOSET2 DN | H20: Up Hallway | I20: LAUNDRY | J20: Hallway- up | K20: BATH DN | L20: REC ROOM | M20: NA | N20: Dining Room | O20: Bedroom 2 TRAVEL AREA | P20: STAIRS UP | Q20: Bedroom 3 | R20: LAUNDRY | S20: PBR CLST | T20: Y | U20: Y | V20: Y | W20: Y | AA20: NA | AB20: NA | AC20: Y | AD20: NA | AE20: Y | AF20: Y | AG20: Y | AH20: Y | AI20: Y | AJ20: Y | AK20: y | AL20: Y | AM20: Y | AN20: Y | AO20: Y | AP20: Y | AQ20: Y | AR20: TBD | AS20: Y | AT20: Y | AU20: Y | AV20: Y | AW20: Y | AX20: Y | AY20: NA | AZ20: NA | BB20: Y | BC20: Y | BL20: Y | BN20: =CF1 -> Webb, Terika | BO20: Y | BP20: Y | BQ20: Y | BR20: y | BS20: Y | BT20: Y | BU20: TBD | BV20: Pantry | BW20: Y | BY20: STAIRS UP TRAVEL | CA20: Y | CB20: Y | CC20: Y | CD20: TBD | CE20: Y | CF20: Y
B21: =$L$1 -> FERGUSON, ROBERT & MRS | C21: =$Y$1 -> Akala, Ayo VND | D21: Year Built | F21: GRANGE 800-422-0550 | G21: TBD | H21: claims@claims.allstate.com | I21: TBD | J21: 0 | K21: 0 | M21: PRE 1978 | N21: TBD | O21: 0 | P21: TBD | Q21: 0 | R21: TBD | S21: (800) 354-2172 | T21: PRE 1980 | U21: PRE 1978 | V21: TBD | W21: PRE 1978 | AA21: PRE 1978 | AB21: PRE 1978 | AC21: POST 1978 | AD21: PRE 1978 | AE21: POST 1978 | AF21: TBD | AG21: TBD | AH21: PRE 1978 | AI21: POST 1978 | AJ21: PRE 1978 | AK21: 2016 | AL21: PRE 1978 | AM21: PRE 1978 | AN21: POST 1978 | AO21: PRE 1978 | AP21: POST 1978 | AQ21: POST 1978 | AR21: PRE 1978 | AS21: POST 1978 | AT21: PRE 1978 | AU21: POST 1978 | AV21: POST 1978 | AW21: 1920 | AX21: PRE 1978 | AY21: 1920 | AZ21: POST 1978 | BB21: 1956 | BC21: POST 1978 | BL21: POST 1978 | BN21: =CG1 -> Red Ink CLE LLC Amir | BO21: POST 1978 | BP21: TBD | BQ21: TBD | BR21: POST 1978 | BS21: post 1980 | BT21: PRE 1978 | BU21: 216.654.1548 | BW21: pre 1980 | CA21: POST 1978 | CB21: POST 1978 | CC21: PRE 1980 | CD21: TBD | CE21: PRE 1978 | CF21: 1991
B22: =$AI$1 -> Goshen, Aaron & Shania | C22: =$Z$1 -> Akala, Ayo TREE | D22: Contract Date | G22: PA 18002 | H22: Fax: (866) 447-4293 | I22: TBD | J22: 0 | K22: 469.997.6270 | N22: TBD | O22: Hartford, CT 06183 | P22: TBD | Q22: TBD | R22: TBD | T22: 45165 | U22: TBD | V22: 45371 | W22: 45483 | AA22: 45511 | AB22: 45511 | AC22: 45405 | AD22: 45525 | AE22: =AE12 -> 45568 | AF22: 45330 | AH22: 45545 | AI22: 45564 | AJ22: 45618 | AK22: 44858 | AL22: =AL12 -> 45628 | AM22: 45693 | AN22: 45727 | AO22: 45737 | AP22: Wednesday, March 26, 2025 | AQ22: 45742 | AR22: Sunday, April 6, 2025 | AS22: 45751 | AT22: 45822 | AU22: 45721 | AV22: 45727 | AW22: 45836 | AX22: 45826 | AY22: 45836 | AZ22: 45896 | BB22: =BB12+1 -> 45987 | BL22: 45727 | BN22: =CH1 -> 0 | BO22: 45571 | BP22: 45330 | BQ22: 45330 | BR22: 45620 | BS22: 44316 | BT22: 45353 | BU22: TBD | BV22: bjstrong@alacritysolutions.com | BW22: 45332 | BY22: Bloomington, IL 61710 | CA22: 45571 | CB22: 45569 | CC22: 45165 | CD22: 45189 | CE22: 45569 | CF22: 45511
B23: =$P$1 -> Harvey, CORA | C23: =$AA$1 -> Cousette, JOHN Vandalism | D23: Loss of use/ ALE | E23: JOB INFO | F23: 3525 West 47th Str | G23: 255 DOVECOTE TRACE | H23: 4514 Wellington Avenue | I23: 6389 South Canterbury Road | J23: 771 Edgewood Rd, | K23: 331 ROYAL OAK DR | L23: 23542 Hillcroft Drive | N23: 956 Roanoke Road, | O23: 1201 SPRINGWOOD DR NW | P23: 5125 Greenhurst Extension | Q23: 357 E 270TH ST | R23: 2079 Miami Road | S23: 1439 West 98th Str | T23: Y | U23: NA | V23: Y | W23: TBD | AA23: Y | AB23: Y | AC23: Y | AD23: Y | AE23: TBD | AF23: Y | AG23: NA | AH23: Y | AI23: Y | AJ23: NA | AK23: y | AL23: TBD | AM23: Y | AN23: Y | AO23: TBD | AP23: TBD | AQ23: TBD | AR23: TBD | AS23: Y | AT23: Y | AU23: Y | AV23: Y | AW23: TBD | AX23: Y | AY23: TBD | AZ23: TBD | BB23: Y | BC23: NA | BL23: Y | BO23: NA | BP23: Y | BQ23: Y | BR23: y | BS23: sample cost 3 | BT23: Y | BU23: 36875 PEPPER DR | BV23: 5992 HIDDEN HOLM LN | BW23: Y | BY23: 750 East 256th | CA23: NA | CB23: Y | CC23: Y | CD23: TBD | CE23: NA | CF23: NA
B24: =$AX$1 -> Hatten, Nedra | C24: =$AB$1 -> Cousette, JOHN ROOF | D24: Breathing issue | E24: =D22 -> Contract Date | F24: Cleveland, OH | G24: MACEDONIA, OH 44056 | H24: Parma, OH, 44134 | I24: Parma,Ohio 44129 | J24: Richmond Heights, OH 44143 | K24: RICHMOND HGTS.,OH 44143 | L24: Warrensville Heights, OH, 44128 | N24: Cleveland Heights, OH | O24: CONYERS, GA 30012 | P24: Maple Heights, OH | Q24: EUCLID OH 44132-1603 | R24: Euclid, OH, | S24: Cleveland, OH | T24: Y | U24: TBD | V24: Y | W24: TBD | AA24: TBD | AB24: TBD | AC24: Y | AD24: Y | AE24: Y | AF24: Y | AG24: TBD | AH24: TBD | AI24: Y | AJ24: TBD | AK24: TBD | AL24: TBD | AM24: TBD | AN24: TBD | AO24: TBD | AP24: TBD | AQ24: TBD | AR24: TBD | AS24: TBD | AT24: TBD | AU24: TBD | AV24: TBD | AW24: TBD | AX24: TBD | AY24: TBD | AZ24: TBD | BB24: TBD | BC24: TBD | BL24: TBD | BO24: TBD | BP24: Y | BQ24: Y | BR24: TBD | BS24: doctor letter | BT24: TBD | BU24: Cleveland, OH 44139 | BV24: AUSTELL, GA 30168 | BW24: tbd | BY24: Euclid, OH | CA24: TBD | CB24: Y | CC24: Y | CD24: TBD | CE24: Y | CF24: NA
B25: =$W$1 -> HICKS, JASON | C25: =$AC$1 -> JONES, BREANNA | D25: HMR | E25: A1 | F25: curtisbradley10@gmail.com | G25: eakoswatta@aol.com | H25: blw8958@gmail.com | I25: lbjr77@gmail.com | J25: drama_kenn2002@yahoo.com | K25: nickwynn24@gmail.com | L25: F@gmail.com | N25: dr.tiffanyrw@counselingsecure.com | O25: ngeelectric@gmail.com | P25: harvcora@icloud.com | Q25: nikkolenrob@aol.com | R25: leeth123@roadrunner.com | S25: AnthonyLANEY26@GMAIL.COM | T25: Y | U25: TBD | V25: Y | W25: TBD | AA25: Y | AB25: Y | AC25: TBD | AD25: Y | AE25: TBD | AF25: Y | AH25: TBD | AI25: TBD | AJ25: TBD | AK25: TBD | AL25: TBD | AM25: TBD | AN25: TBD | AO25: TBD | AP25: TBD | AQ25: TBD | AR25: TBD | AS25: TBD | AT25: TBD | AU25: TBD | AV25: TBD | AW25: TBD | AX25: TBD | AY25: TBD | AZ25: TBD | BB25: TBD | BC25: TBD | BL25: TBD | BO25: TBD | BP25: Y | BQ25: Y | BR25: TBD | BS25: lab test | BT25: TBD | BU25: CARWASH1946@YAHOO.COM | BV25: ml_aps@yahoo.com | BW25: Y | BY25: estrictfranklin@gmail.com | CA25: TBD | CB25: TBD | CC25: Y | CD25: TBD | CE25: TBD | CF25: TBD
B26: =$AY$1 -> HOWARD, MATTHEW | C26: =$AD$1 -> Collins, Darlene | D26: Insurance Co. Name | E26: =D157 -> 0 | F26: (216) 334-6445 | G26: (216) 219-1054 | H26: (216) 512-4318 | I26: 216) 224-1548 | J26: (216) 894-1563 | K26: 216.712.0152 | L26: (216) 785-1363 | M26: NATIONAL FIRE & MARINE | N26: 2163168265 | O26: 678-646-7704 | P26: (216) 407-1810 | Q26: (440) 431-7350 | R26: 216) 255-2231 | S26: (216) 299-6104 | T26: State Farm | U26: TBD | V26: STATEFARM | W26: STATE FARM INS | X26: STATE FARM | Y26: STATE FARM | Z26: STATE FARM | AA26: STATE FARM | AB26: STATE FARM | AC26: Trisura Insurance Company. | AD26: STATE FARM | AE26: ALLSTATE | AF26: Westfield Insurance | AG26: Statefarm | AH26: State Farm | AI26: STATE FARM | AJ26: State Farm | AK26: QBE INS | AL26: GEICO/HOMESITE | AM26: Allstate Insurance Company | AN26: Allstate Insurance Company | AO26: Allstate Insurance Company | AP26: STATE FARM | AQ26: FARMERS | AR26: Spinnaker Insurance Company | AS26: Allstate Vehicle and Property Insurance Co | AT26: AAA Insurance | AU26: Allstate Insurance Company | AV26: Esurance | AW26: ALLSTATE INS CO. | AX26: LIBERTY MUTUAL | AY26: SAFECO # | AZ26: ASSURANT INS | BB26: ALLSTATE INS CO. | BC26: AMERICAN FAMILY | BL26: Esurance | BO26: Allstate | BP26: STATEFARM | BQ26: STATEFARM | BR26: GRANGE | BS26: STANDARD GUARANTY INS. CO. | BT26: Alstate 0662951359 | BU26: (216) 402-0049 | BV26: 956.371.3974 | BW26: Universal Ins | BX26: STATE FARM | BY26: 216-407-6481 | BZ26: Allstate Vehicle and Property Insurance Co | CA26: Homesite | CB26: Geigo I | CC26: TBD | CD26: STATE FARM | CE26: PROGRESSIVE | CF26: STATE FARM | CG26: Erie
B27: =$AN$1 -> Hurt, Chaunte | C27: =$AE$1 -> NEWMAN, NICOLE | D27: Claim # | E27: w | F27: TBD | G27: TBD | H27: TBD | I27: tbd | J27: vnssmrshll@yahoo.com | K27: #REF! | L27: MRS. | M27: BH01737488 | N27: #0579206154LoaN | O27: na | P27: TBD | Q27: TBD | R27: tbd | S27: TBD | T27: 3556W964G | U27: CLM | V27: CLM 11- 65W674M | W27: 3570V537Z | Y27: CLM3570X095J | Z27: 3573K614T | AA27: 3572C952H | AB27: 3571Z117Q | AC27: TIC-00005092 | AD27: 3572Q140L | AE27: #0771511680 | AF27: #002534872 | AG27: 11-63G7-91F | AH27: 3572H977V | AI27: 3574M271X | AJ27: 3577Q641P | AK27: 873368N | AL27: # 01-008-402478 | AM27: #0782519052 | AN27: #0785946666 | AO27: #0787407485 | AP27: 3582G431B | AQ27: 7008788987-1 | AR27: 24PROH621255022 | AS27: 0790205199 | AT27: #017095711 | AU27: #0786294926 | AV27: #250254318 | AW27: 0807044169 | AX27: #059633981 | AY27: 059597581-01 | AZ27: 00201936986 | BB27: 0814056289 | BC27: TBD | BL27: 250254318 | BO27: #0772562245 | BP27: 1163C742W | BQ27: 1163C746F | BR27: ZHM003759154 | BS27: 00201358720 | BT27: Alstate 0662951359 | BU27: TBD | BV27: TBD | BW27: GA240100643 | BX27: 3582G711L | BY27: TBD | BZ27: 0786750778 | CA27: 1007995316 | CC27: TBD | CD27: 35 | CE27: 01-007-956327 | CF27: 3573H030H | CG27: A00006100647
B28: =$BC$1 -> HUTCHINSON | C28: =$AF$1 -> Peggy Henderson | D28: policy # | E28: =FINAL_INVOICES_STATEMENT -> DA Ph. Ext. # | F28: TBD | G28: TBD | H28: TBD | I28: TBD | J28: 0 | K28: #REF! | M28: 42PFP26378901 | N28: (678) 789-2192 | O28: na | P28: TBD | Q28: TBD | R28: TBD | S28: TBD | T28: PL | U28: PL | V28: 11-EY-B111-9 | W28: 70 CJ 385 L3 | X28: 95GDC4816 | Y28: 95GDC4816 | Z28: 95GDC4816 | AA28: 95EMD4258 | AB28: 95EMD4258 | AC28: 83915278 | AD28: 70-C4-Y732-1 | AE28: 826 781 155 | AF28: TBD | AG28: 11EAP8759 | AH28: 70CRP2953 | AI28: 70EHX4312 | AJ28: 70-CA-H811-3 | AK28: PHP4140181 | AL28: 38748576 | AM28: 880 0025757 | AN28: Policy 992755402 | AO28: 126 061 389 | AP28: PL | AQ28: PL# | AR28: DOH-10908612-01 | AS28: 826763419 | AT28: OHH000190052 | AU28: 980 610 253 | AV28: : 10610052 | AW28: 880 022 226 | AX28: H3V28806334771 | AY28: OK7558571 | AZ28: 2MR07293165041 | BB28: PL# 026-164-325 | BC28: # 41105-87553 | BL28: PL# | BO28: 885015525 | BP28: TBD | BQ28: TBD | BR28: TBD | BS28: MIP-RCH-00755-99 | BT28: TBD | BU28: TBD | BV28: TBD | BW28: 1701-1601-0661 | BX28: 95J8Y8775 | BY28: TBD | BZ28: 000880016618 | CA28: 39209494 | CB28: REN 1945339 | CC28: TBD | CD28: TBD | CE28: 38353012 | CF28: 95-J8-M309-7 | CG28: Q61 0295794
B29: =$AS$1 -> Johnson, Paul & Tamra | C29: =$AG$1 -> Romero Beverly | D29: Email INS. co. | E29: A154 | F29: TBD | G29: TBD | H29: TBD | I29: TBD | J29: na | K29: na | M29: BSCHEUER@PROCTORLP.COM | N29: TBD | O29: na | P29: TBD | Q29: TBD | R29: TBD | S29: TBD | T29: statefarmfireclaims@statefarm.com | U29: TBD | V29: STATEFARM | W29: TBD | Y29: statefarmfireclaims@statefarm.com | AA29: statefarmfireclaims@statefarm.com | AB29: statefarmfireclaims@statefarm.com | AD29: statefarmfireclaims@statefarm.com | AE29: CLAIMS@CLAIMS.ALLSTATE.COM | AF29: TBD | AG29: statefarmfireclaims@statefarm.com | AH29: statefarmfireclaims@statefarm.com | AJ29: statefarmfireclaims@statefarm.com | AK29: CLAIMMAIL@US.QBE.COM | AL29: Jameka.Hines@afics.com | AM29: claims@claims.allstate.com | AN29: claims@claims.allstate.com | AO29: claims@claims.allstate.com | AP29: statefarmfireclaims@statefarm.com | AQ29: myclaim@farmersinsurance.com | AR29: info+emld300ef05ab65@claims.hippo.com | AS29: claims@claims.allstate.com | AT29: STAPLES.OLIVIA @ace.aaa.com | AU29: claims@claims.allstate.com | AV29: carla.robledo@ngic.com | AW29: claims@claims.allstate.com | AX29: IMAGING@LIBERTYMUTUAL.COM | AZ29: MYCLAIMINFO@ASSURANT.COM | BB29: claims@claims.allstate.com | BL29: TBD | BO29: claims@claims.allstate.com | BP29: statefarmfireclaims@statefarm.com | BQ29: statefarmfireclaims@statefarm.com | BR29: BenczeR@Grangeinsurance.com | BS29: myclaiminfo@assurant.com | BU29: TBD | BV29: TBD | BW29: claimpathuniversalproperty.com | BX29: statefarmfireclaims@statefarm.com | BY29: TBD | BZ29: claims@claims.allstate.com | CC29: TBD | CD29: TBD | CE29: CLIMDOCUMENTS@AFICS.COM | CF29: statefarmfireclaims@statefarm.com
B30: =$AC$1 -> JONES, BREANNA | C30: =$AH$1 -> TAYLOR DAVIDSON, WARREN | D30: DESK Adjuster DA | F30: TBD | G30: POST 1978 | H30: TBD | I30: PRE 1980 | J30: POST 1978 | K30: POST 1978 | L30: AFTER 1980 | M30: SCHEUER, BRANDON | N30: TBD | O30: POST 1980 | P30: PRE 1980 | Q30: BEFORE 1980 | R30: PRE 1980 | S30: PRE 1978 | T30: DA | U30: TBD | V30: TBD | W30: TBD | Y30: RAMOS, ROSELYN | Z30: TARA HARRINGTON | AA30: RAMOS, ROSELYN | AB30: FOWLER, CHARITY | AC30: Owen Hanbury | AD30: RAMOS, ROSELYN | AF30: TBD | AG30: James Hudson | AH30: GIESEY, MATT 309 834 9661 | AI30: Amy Irwin | AJ30: GIESEY, MATT 309 834 9661 | AK30: Stewart Pile, Monica | AL30: Jameka.Hines | AM30: Spencer GASTON, Large Loss | AN30: Spencer GASTON, Large Loss | AO30: 0 | AR30: Brandon Timmins | AS30: KRISTEN | AT30: STAPLES, OLIVIA 207 776 6150 | AU30: LYLE KENDICKS | AV30: Carla Robledo| | AW30: Ticora Thomas | AX30: NICOLE.FITZGERALD | AY30: Goddraneika Merrill (469)242-7605 | AZ30: PERO, EMMANUEL | BB30: MEAGAN CHASAR, LRG LOSS ADJ | BL30: Carla Robledo| Homeowners Senior Inside Rep | BO30: CHARLES SCNIDIER | BP30: Tia Dortch | BQ30: SARAH KENNEDY | BR30: Rachael Bencze | BS30: Elaine Gebsbher | BU30: POST 1980 | BV30: POST 1978 | BW30: STERLING X1702 | BX30: RAMOS, ROSELYN | BY30: PRE 1980 | BZ30: Simon Moncada | CA30: WALKER, STEPHEN | CC30: TBD | CD30: TBD | CF30: RICHARD, CATHERINE
B31: =$G$1 -> KOSWATTA, ERIKA | C31: =$AI$1 -> Goshen, Aaron & Shania | D31: DA Phone | F31: grangeinsurance.com | G31: BenczeR@Grangeinsurance.com | H31: claims@claims.allstate.com | I31: tbd | J31: claims@claims.allstate.com | K31: #REF! | L31: EM | M31: (877) 491-7277. | N31: TBD | O31: consumeraffairs@travelers.com | P31: ASIA.BABLES@LIBERTYMUTUAL.COM | Q31: Nicole.Schaumleffel@libertymutual.com | R31: tbd | S31: claims@claims.allstate.com | T31: 844-458-4300 | U31: TBD | V31: TBD | W31: TBD | Y31: 844-458-4300 | AA31: 844-458-4300 | AB31: (866) 787-8678 | AC31: 844-503-7101 | AD31: 844-458-4300 | AF31: TBD | AG31: 1(866) 787 8676 Ext. 16799 | AK31: 844.723.2524 | AL31: 251-665-8527 | AM31: 888 656.8005 | AN31: (888) 656-8005 | AO31: 888 656.8005 | AQ31: HEATHER.CASOLA | AR31: Property Adjuster, Property Claims | Hippo Insurance Services | AS31: 888 656.8005 | AT31: 207 776 6150 | AU31: 888 656.8005 | AV31: (800) 378-7262 | AW31: (540) 725-6641 | AX31: 8002252467 | AY31: (469)242-7605 | AZ31: 800 358 0600 X 4030304 | BB31: 8007296400 | BL31: (800) 378-7262 | BP31: 8444584300 | BQ31: TBD | BR31: (614) 593-7718 | BS31: 1.800.358.0600 | BV31: MSI.SUPPORT@ALACRITYSOLUTIONS.COM | BW31: (800) 425-9113 | BX31: 844-458-4300 | BY31: statefarmfireclaims@statefarm.com | BZ31: (224) 559-9178 | CA31: (608) 286-8911 | CC31: TBD | CD31: TBD | CF31: 844 458 4300 | CG31: #VALUE!
A32: I | B32: =$AT$1 -> LACEY, EUNICE | C32: =$AJ$1 -> Brownlee. LAVERNE | D32: DA Ph. Ext. # | F32: 614-445-2880 | G32: (614) 593-7718 | H32: 8886568005 | I32: tbd | J32: 800-252-8294 | K32: 800-2-CLAIMS | L32: 844 458 4300 | M32: 8005216800 | N32: TBD | O32: 1.800.252.4633 | P32: 469 997 2808 | Q32: 1 (757) 854-8187 | R32: 800.531.8722 | S32: (800) 354-2172 | T32: ext | U32: TBD | V32: TBD | W32: TBD | Y32: 3097632550 | AA32: 3097632550 | AB32: 8667878678 X 5620 | AC32: FL License #: G087288 | AD32: 3097632550 | AF32: TBD | AG32: 1(866) 787 8676 Ext. 16799 | AI32: (972) 732-5783 | AK32: 770.303.2737 | AL32: Jameka.Hines@afics.com | AM32: 330 224-5157 | AN32: (330) 224-5157 | AO32: 0 | AQ32: 4044656346 | AR32: 855-999-9746 x 7476 | AS32: 8008173220 | AT32: 207 776 6150 | AU32: 9892774564 | AV32: (336) 331-6825 | AW32: (540) 725-6641 | AX32: 4692427672 | AY32: (469)242-7605 | AZ32: X4030304 | BB32: 2164908092 | BL32: (336) 331-6825 | BO32: 8472269228 | BP32: 3099941316 | BQ32: (678) 935-4670 | BR32: (614) 593-7718 | BS32: x4019804 | BV32: 844-306-0752 | BW32: (954) 958-1205 | BX32: 3097632550 | BY32: 844-458-4300 | BZ32: (224) 559-9178 | CC32: TBD | CD32: TBD | CF32: statefarmfireclaims@statefarm.com
A33: J | B33: =$S$1 -> LANEY, Anthony | C33: =$AK$1 -> Craig Ringo | D33: DA Email | F33: ='[1]jobinfo(2)'!$C$51 -> OH23H Bradley v3 | G33: OH23T KOSWATTA V2.1 | H33: OH24H WILLIAMS | I33: OH23A BATTLE @PARMA | J33: OH22 ANDERSON PETE | K33: OH22 WYNN FIRE @ROYAL OAK | L33: OH23P-FERGUSON@HILLCROFT | M33: BSCHEUER@PROCTORLP.COM | N33: OH24A RUSH WTR @Roanoke | O33: GA22 TORRES @ CONYERS | Q33: OH23A-ROBINSON@E270 | R33: LEETH | S33: OH24A Laney @ W98 | T33: statefarmfireclaims@statefarm.com | U33: TBD | V33: TBD | W33: TBD | Y33: ROSELYN.RAMOS.VAFA8T@statefarm.com | AA33: ROSELYN.RAMOS.VAFA8T@statefarm.com | AB33: statefarmfireclaims@statefarm.com | AC33: ext. 889098 | AD33: ROSELYN.RAMOS.VAFA8T@statefarm.com | AF33: MichaelRankin@westfieldgrp.com | AG33: statefarmfireclaims@statefarm.com | AH33: statefarmfireclaims@statefarm.com | AJ33: MATTHEW.GIESEY.VAF5GP@statefarm.com | AK33: CLAIMMAIL@US.QBE.COM | AL33: TBD | AM33: sgawu@allstate.com | AN33: sgawu@allstate.com | AO33: claims@claims.allstate.com | AQ33: HEATHER.CASOLA6@FARMERSINSURANCE.COM | AR33: info+eml39d20004afe2@claims.hippo.com | AS33: KDOWL@ALLSTATE.COM | AT33: STAPLES.OLIVIA @ace.aaa.com | AU33: lyle.kendrick@allstate.com | AV33: carla.robledo@ngic.com | AW33: claims@claims.allstate.com | AX33: NICOLE.FITZGERALD@LIBERTYMUTUAL.COM | AY33: Goddraneika.Merrill02@libertymutual.com | AZ33: MYCLAIMINFO@ASSURANT.COM | BB33: =BB29 -> claims@claims.allstate.com | BL33: carla.robledo@ngic.com | BO33: claims@claims.allstate.com | BP33: tia.dortch.k6r7@statefarm.com | BQ33: statefarmfireclaims@statefarm.com | BR33: BenczeR@Grangeinsurance.com | BS33: kharja.murdock@Assurant.com | BU33: 0H23A-MALIKA ALIM@WOODLAND | BV33: GA23A LOZAN0 @AUSTELL | BW33: SB0318@UNIVERSALPROPERTY.COM | BX33: ROSELYN.RAMOS.VAFA8T@statefarm.com | BY33: OH23A Franklin @256street | BZ33: claims@claims.allstate.com | CA33: STEPHEN.WALKER@AFICS.COM | CC33: TBD | CD33: statefarmfireclaims@statefarm.com | CF33: statefarmfireclaims@statefarm.com
A34: K | B34: =$T$1 -> LAWRENCE, GENEATHA | C34: =$AL$1 -> SMITH, JANET | D34: Field Adjuster Name | F34: ='[1]jobinfo(2)'!$C$68 -> BR 2 | G34: Bathroom | H34: Basement Rec Room | I34: TBD | J34: 0 | K34: HALL UP | M34: TBD | N34: REC ROOM 1 | O34: 16 | P34: TBD | Q34: HALL FLR1 | R34: TBD | S34: SIDING | T34: TBD | U34: TBD | V34: TBD | W34: TBD | Y34: RAMOS, ROSELYN | Z34: SEEK NOW HOWARD HOLCOMB | AA34: RAMOS, ROSELYN | AB34: MUHOMID | AC34: Email: tpa.support@alacritysolutions.com | AD34: SCOTT DANKO | AE34: WHITE, JUSTIENE | AF34: TBD | AH34: GIESEY, MATT 309 834 9661 | AI34: MICHAEL OZELLO | AJ34: GIESEY, MATT 309 834 9661 | AK34: Karlton Haynes | AL34: TBD | AM34: DREW STARK asst. | AN34: LYLE KENDRICK | AO34: TBD | AQ34: HEATHER.CASOLA | AR34: TBD | AT34: VINCENT, KATHERINE | AU34: Spencer GASTON, Large Loss | AW34: RIMKUS TPA | AX34: FA | AY34: MARCUS, HORACE | AZ34: KEVIN KIDD | BB34: MEAGAN CHASAR, LRG LOSS ADJ | BC34: FA | BL34: TBD | BP34: TBD | BQ34: TBD | BR34: TBD | BS34: Jason Jones | BU34: TBD | BW34: STERLING X1702 | BX34: RONALD MANCE | BY34: TBD | BZ34: Demrovsky, Andrew appraiser | CA34: SCOTT JACOBS | CC34: TBD | CD34: TBD | CF34: RICHARD, CATHERINE
A35: L | B35: =$R$1 -> LEETH, RONNIE | C35: =$AM$1 -> Brown, Cassandra | D35: Phone # field adj | F35: ='[1]jobinfo(2)'!$C$71 -> LL Bathroom | G35: Bathroom | H35: Utility Room | I35: TBD | J35: 0 | K35: Bedroom # 2 | M35: TBD | N35: Utility room | O35: 19 | P35: TBD | Q35: BSMNT CLOSET | R35: TBD | T35: TBD | U35: TBD | V35: TBD | W35: TBD | Y35: 844-458-4300 | Z35: 8553137311 | AA35: 844-458-4300 | AB35: 8667878678 X 4013 | AD35: 3307228703 | AE35: 4632141136 | AF35: TBD | AI35: 3097632416 | AK35: 800-647-3626 ext 3148 | AL35: TBD | AM35: 5138238034 | AN35: 9892774564 | AO35: TBD | AR35: TBD | AT35: 3306184299 | AU35: 330 224-5157 | AW35: 4106271546 | AX35: FA | AY35: 9363065323 | AZ35: 3304412955 | BB35: 2164908092 | BC35: FA | BL35: TBD | BP35: TBD | BQ35: TBD | BR35: TBD | BS35: 219.614.1819 | BU35: TBD | BW35: (954) 958-1205 | BX35: 4125237897 | BY35: TBD | BZ35: 3307068014 | CA35: 3303893040 | CC35: TBD | CD35: TBD | CF35: 844 458 4300
A36: M | B36: =$AZ$1 -> MONTGOMERY, JAVIONNA | C36: =$AN$1 -> Hurt, Chaunte | D36: Field adj email | F36: ='[1]jobinfo(2)'!$C$75 -> Basement Rec Room | G36: Master BR Closet | H36: TBD | I36: TBD | J36: 0 | K36: PRIMARY Bedroom | M36: TBD | N36: TBD | O36: - | P36: TBD | Q36: HALL BONUS ROOM | R36: TBD | T36: TBD | U36: TBD | V36: TBD | W36: TBD | Y36: ROSELYN.RAMOS.VAFA8T@statefarm.com | AA36: ROSELYN.RAMOS.VAFA8T@statefarm.com | AB36: statefarmfireclaims@statefarm.com | AC36: Alacrity Solutions | AD36: SDANKO@INSRESCON.COM | AE36: JWHK7@ALLSTATE.COM | AF36: TBD | AI36: MICHAEL.OZELLO.VAFCRL@STATEFARM.COM | AK36: khaynes@alacritysolutions.com | AL36: TBD | AM36: ASTCP@ALLSTATE.COM | AN36: lyle.kendrick@allstate.com | AO36: TBD | AR36: HIPPO INS CO. | AT36: KATHERINE@KGVINCENT.COM | AU36: sgawu@allstate.com | AW36: FA EM ? | AX36: PH | AY36: Preston.Cone@libertymutual.com | AZ36: KIDD.STANDARD.ADJUSTING@GMAIL.COM | BB36: MCHEM@ALLSTATE.COM | BC36: PH | BL36: TBD | BP36: TBD | BQ36: TBD | BR36: TBD | BS36: JKLIQUIDATION@GMAIL.COM | BU36: TBD | BW36: SB0318@UNIVERSALPROPERTY.COM | BX36: RMANCE@INSRESCON.COM | BY36: TBD | BZ36: andyd@sikegroupllc.com | CA36: SCOTT@AFICS.COM | CC36: TBD | CD36: TBD | CF36: statefarmfireclaims@statefarm.com
A37: N | B37: =$AE$1 -> NEWMAN, NICOLE | C37: =$AO$1 -> Dejarnette Mattie | D37: adj contents | F37: HM 5265029 00 | G37: HM 4186290 06 02 | H37: #000826481282 | I37: PL | J37: 992 832 919 | K37: #REF! | L37: 70B9K5636 | M37: 42PFP263789-01 /PFI 10625393 | N37: 42PFP263789-01 /PFI 10625393 | O37: 606732655-633-1 | P37: OK6372979 | Q37: H3DT8174525670 | R37: 27853880 | S37: PL # 000826686789 | T37: TBD | U37: TBD | V37: TBD | W37: TBD | Y37: Kevin Salmon, SPVR | Z37: Kevin Salmon, SPVR | AA37: Kevin Salmon, SPVR | AB37: Kevin Salmon, SPVR | AC37: Owen Hanbury | AD37: ANTONIO | AE37: FABIOLA, CHRISTENE | AF37: TBD | AH37: GIESEY, MATT 309 834 9661 | AJ37: GIESEY, MATT 309 834 9661 | AK37: mgr: Patrick Atwell ext 2218 | AL37: TBD | AM37: BRANDY CPS | AN37: KEISHA | AO37: Kianha Taylor | AR37: Info@claims.hippo.com | AT37: SPV Tanya Sayer 207-791-8544 | AU37: TENETIA MOORE | AX37: TBD | AY37: NICK | BB37: Chad Hages | BC37: TBD | BL37: TBD | BP37: TBD | BQ37: TBD | BR37: TBD | BS37: Shad Peterson | BU37: HM5097293 00 02 | BV37: PHP5336287 | BW37: TBD | BX37: Kevin Salmon, SPVR | BY37: 35GWY1289 | BZ37: insp mon 28 march 10-12am | CC37: TBD | CD37: TBD | CF37: RICHARD, CATHERINE
A38: O | B38: =$AF$1 -> Peggy Henderson | C38: =$AP$1 -> Burns2, RUBY | D38: adj CPS phone # | F38: ='[1]jobinfo(2)'!$C$62 -> Bathroom | G38: LAUNDRY CLOSET | H38: BR PRIMARY | I38: TBD | J38: BASEMENT REC | K38: STAIRS DOWN | L38: ` | N38: Up Hallway | O38: PRIMARY BATHROOM | P38: REAR/ENTRY ROOM | Q38: Closet 3 | R38: BEDROOM | S38: BATH | T38: TBD | U38: TBD | V38: TBD | W38: TBD | Y38: 3099940722 | Z38: 3099940722 | AA38: 3099940722 | AB38: 3099940722 | AC38: 844-503-7101 | AD38: 844-458-4300 | AE38: 4435657039 | AF38: TBD | AL38: TBD | AM38: 7327515219 | AN38: 4406450901 | AO38: Phone: (704) 548-2680 | AR38: 45896 | AT38: TBD | AU38: (727) 571-5062 | AX38: TBD | AY38: N/A | BB38: Phone: (425) 424-1487 | BC38: TBD | BL38: TBD | BP38: TBD | BQ38: TBD | BR38: TBD | BS38: 864.833.6360 | BU38: TBD | BV38: Hallway- up | BW38: TBD | BX38: 3099940722 | BY38: Bedroom 1 Closet | CC38: TBD | CD38: TBD | CF38: 844 458 4300
A39: P | B39: =$Q$1 -> ROBINSON, NiKKole | C39: =$AQ$1 -> CARTER, KAREN | D39: adj CPS email | F39: Michael R Carlozzi | G39: Rachael Bencze | H39: LESLIE | I39: DA | J39: Stacey Williams | K39: Orlando Reyes | L39: POLITZA,LEXI | N39: TBD | O39: Michelle Taylor , supervisor | P39: ASIA BABLES | Q39: Nicole Schaumleffel | R39: TAMI | S39: Benjamin Bybee | T39: TBD | U39: TBD | V39: TBD | W39: TBD | Y39: kevin.salmon.h9ib@statefarm.com | Z39: kevin.salmon.h9ib@statefarm.com | AA39: kevin.salmon.h9ib@statefarm.com | AB39: kevin.salmon.h9ib@statefarm.com | AC39: FL License #: G087288 | AD39: # 10135 | AE39: claims@claims.allstate.com | AF39: TBD | AL39: TBD | AM39: claims@claims.allstate.com | AN39: onsite@infraware.com | AO39: TBD | AT39: TBD | AU39: claims@claims.allstate.com | AX39: contents.claims@genpact.com | AY39: NICK@ALLCATCLAIMS.COM | BB39: claims@claims.allstate.com | BC39: TBD | BL39: TBD | BP39: TBD | BQ39: TBD | BR39: TBD | BS39: kharja.murdock@Assurant.com | BV39: Candace Brown | BW39: TBD | BX39: kevin.salmon.h9ib@statefarm.com | BY39: Jason 931-629-2250 | CC39: TBD | CD39: TBD | CF39: statefarmfireclaims@statefarm.com
A40: Q | B40: =$AG$1 -> Romero Beverly | C40: =$AR$1 -> CHERRY, LAUREN LB8997 | D40: TMP adj | F40: ='[1]jobinfo(2)'!$C$63 -> Linen Closet 2 | G40: Stairs UP | H40: CLOSET2 BR MASTER | I40: TBD | J40: STORAGE | K40: Bsmnt rec 1 | N40: Bathroom Up | O40: PRIMARY CLOSET | P40: Basement Hall/STEPS | Q40: Attic | R40: STORAGE 1 | S40: LINEN CLST | T40: TBD | U40: TBD | V40: TBD | W40: TBD | AA40: RAMOS, ROSELYN | AB40: MUHOMID | AC40: ext. 889098 | AD40: RAMOS, ROSELYN | AF40: TBD | AL40: TBD | AM40: TBD | AN40: LONGOBARDI, THOMAS | AO40: TBD | AT40: TBD | AU40: TBD | AX40: Sheree Banks | BC40: TBD | BL40: TBD | BP40: TBD | BQ40: TBD | BR40: TBD | BS40: Cory Taylor, FL Licensed Adjuster | BU40: TBD | BV40: Garage TRAVEL AREA | BW40: STERLING X1702 | BX40: RAMOS, ROSELYN | BY40: TBD | CC40: TBD | CD40: TBD | CF40: RICHARD, CATHERINE
...

Sheet ALE
A1: 1 | B1: ALE STEPS | D1: DATA INPUT FIELDS | E1: ALE INFO … APC # | F1: =ALL!#REF! -> #REF! | H1: ALE INFO … APC # | I1: =ALL!AT146 -> OH25 LACEY, E | K1: ALE INFO … APC # | L1: =ALL!AU146 -> OH25 BROOKS,@YNG | N1: ALE INFO … APC # | O1: =ALL!AV146 -> GA25 SMITH @GERTRUDE PL | P1: ALE INFO … APC # | Q1: ALE INFO … APC #
A2: =+A1+1 -> 2 | B2: Lesse info | C2: Lesse info | E2: Lesse info | F2: Lesse info | H2: Lesse info | I2: Lesse info | J2: Lesse info | K2: Lesse info | L2: Lesse info | M2: Lesse info | N2: Lesse info | O2: Lesse info | P2: Lesse info | Q2: Lesse info | R2: Lesse info | S2: Lesse info
A3: =+A2+1 -> 3 | B3: DATA INPUT | C3: IMPORTS LESSEE INFO FROM jobinfo(2) (AUTO FILL) | E3: Lesse info / NAME | F3: =ALL!#REF! -> #REF! | H3: Lesse info / NAME | I3: =ALL!AT128 -> LACEY, EUNICE | K3: Lesse info / NAME | L3: =ALL!AU128 -> BROOKS, DANIEL;JANAE POA | N3: Lesse info / NAME | O3: =ALL!AV128 -> Smith, Brian | P3: Lesse info / NAME | Q3: =ALL!AW128 -> THOMAS, ANITA
C4: INFO SHEET FOR DATA INPUT emailed to R/E CONTACT | E4: HOME ADDRESS | F4: =ALL!#REF! -> #REF! | H4: HOME ADDRESS | I4: =ALL!AT129 -> 13601 5th Ave | K4: HOME ADDRESS | L4: =ALL!AU129 -> 3427 SANDALWOOD LN | N4: HOME ADDRESS | O4: =ALL!AV129 -> 831 Gertrude Place NW, | P4: HOME ADDRESS | Q4: =ALL!AW129 -> 6600 GERTRUDE
C5: lessor info & terms manual input | E5: TENANT Property city, state, zip | F5: =ALL!#REF! -> #REF! | H5: TENANT Property city, state, zip | I5: =ALL!AT130 -> East Cleveland, OH 44112 | K5: TENANT Property city, state, zip | L5: =ALL!AU130 -> Austintown, OH 44511 | N5: Property city, state, zip | O5: =ALL!AV130 -> Atlanta, GA 30318 | P5: Property city, state, zip | Q5: =ALL!AW130 -> Cleveland, OH 44105
C6: LEASE Data APPROVED BY R/E CONTACT | E6: Customer Email | F6: =ALL!#REF! -> #REF! | H6: Customer Email | I6: =ALL!AT131 -> Emdlacey@gmail.com | K6: Customer Email | L6: =ALL!AU131 -> JANAETAB16@YAHOO.COM | N6: Customer Email | O6: =ALL!AV131 -> BRIAN.ASHTON.SMITH.211@GMAIL.COM | P6: Customer Email | Q6: Trenddamnish@yahoo.com
C7: LEASE TERMS CREATED & ENTERED (final) | E7: Cst-owner Phone# | F7: =ALL!#REF! -> #REF! | H7: Cst-owner Phone# | I7: =ALL!AT132 -> (216) 450-4913 | K7: Cst-owner Phone# | L7: =ALL!AU132 -> (330) 951-2652 | N7: Customer Phone# | O7: =ALL!AV132 -> (404) 444-1325 | P7: Customer Phone# | Q7: =ALL!AW132 -> (216) 315-2040
B9: DATA OUTPUT | C9: INFO SHEET FOR DATA INPUT (FILE COPY) | E9: RENTAL INFO | H9: RENTAL INFO | K9: RENTAL INFO | N9: RENTAL INFO | P9: RENTAL INFO | Q9: RENTAL INFO
C10: R/E ENGAGEMENT DOC CREATED | E10: bedrooms | F10: =ALL!#REF! -> #REF! | H10: bedrooms | I10: =ALL!AT148 -> 3 | K10: bedrooms | L10: =ALL!AU148 -> 3 | N10: bedrooms | O10: =ALL!AV148 -> 3 | P10: bedrooms | Q10: 3
C11: LEASECREATED | E11: months | F11: =ALL!#REF! -> #REF! | H11: months | I11: =ALL!AT149 -> 4 | K11: months | L11: =ALL!AU149 -> 4 | N11: months | O11: 6 | P11: months | Q11: 6
C12: TERM SHEET CREATED | E12: START DATE | F12: =ALL!#REF! -> #REF! | H12: START DATE | I12: =ALL!AT150 -> 45768 | K12: START DATE | L12: 45846 | N12: START DATE | O12: =ALL!AV150 -> Tuesday, March 11, 2025 | P12: START DATE | Q12: 45931
E13: END DATE | F13: =ALL!#REF! -> #REF! | H13: END DATE | I13: =ALL!AT151 -> 45888 | K13: END DATE | L13: =L12+L11*30+2 -> 45968 | N13: END DATE | O13: =ALL!AV151 -> Tuesday, March 11, 2025 | P13: END DATE | Q13: Saturday, January 31, 2026
B14: External steps SENT OUT FOR SIGNING | C14: DOCS EMAILED TO LESSOR | E14: Amount / Month | F14: =ALL!#REF! -> #REF! | H14: Amount / Month | I14: =ALL!AT152 -> 2200 | K14: Amount / Month | L14: =ALL!AU152 -> 2200 | N14: Amount / Month | O14: 3500 | P14: Amount / Month | Q14: 2200
C16: DOCS EMAILED TO TO LESSEE | E16: LESSOR INFO / NAME | F16: =ALL!#REF! -> #REF! | H16: LESSOR INFO / NAME | I16: =ALL!AT155 -> Floretta Crowell | K16: LESSOR INFO / NAME | L16: =ALL!AU155 -> BACON, MICHELLE | N16: LESSOR INFO / NAME | O16: =ALL!AV155 -> Sophia Crawford | P16: LESSOR INFO / NAME | Q16: GLOBAL REALTY INVESTOR RELATIONS, INC
E17: Leased Address | F17: =ALL!#REF! -> #REF! | H17: Leased Address | I17: =ALL!AT156 -> 19048 Watercrest Dr. | K17: Leased Address | L17: =ALL!AU156 -> 3455 MILVERTON | N17: Leased Address | O17: =ALL!AV156 -> 5507 Cascade Hills Loop SW | P17: Leased Address | Q17: 3685 E153
B18: LESSOR steps | C18: LEASE DOCS RECEIVED | E18: city zip | F18: =ALL!#REF! -> #REF! | H18: city zip | I18: =ALL!AT157 -> Mapel Heights, OH, 44137 | K18: city zip | L18: =ALL!AU157 -> SHAKER HEIGHTS, OH 44120 | N18: city zip | O18: =ALL!AV157 -> Atlanta, GA 30331 | P18: city zip | Q18: Cleveland OH 44120
C19: LEASE DOCS SIGNED BY LESSOR & RETURNED | E19: phone # | F19: =ALL!#REF! -> #REF! | H19: phone # | I19: 2164086035 | K19: phone # | L19: 3309512497 | N19: phone # | O19: =ALL!AV158 -> 404-444-7271 | P19: phone # | Q19: 216-938-2176
E20: Email lessor | F20: =ALL!#REF! -> #REF! | H20: Email lessor | I20: =ALL!AT159 -> FLOCROW48@AOL.COM | K20: Email lessor | L20: bch3oh10@gmail.com | N20: Email lessor | O20: =ALL!AV159 -> Top4118@aol.com | P20: Email lessor | Q20: grirmanagement@gmail.com
B22: LESSEE steps | C22: LEASE DOCS RECEIVED | E22: Lessor mailing Address | F22: =ALL!#REF! -> #REF! | H22: Lessor mailing Address | I22: =ALL!AT161 -> 2479 Greenvale | K22: Lessor mailing Address | L22: =ALL!AU161 -> 16100 VAN AKEN BLVD #206, | N22: Lessor mailing Address | O22: =ALL!AV161 -> 66 Crawford Rd | P22: Lessor mailing Address | Q22: 3043 Superior Avenue #301
C23: LEASE DOCS SIGNED BY LESSEE & RETURNED | E23: city zip | F23: =ALL!#REF! -> #REF! | H23: city zip | I23: =ALL!AT162 -> Cleveland, OH, 44121 | K23: city zip | L23: =ALL!AU162 -> SHAKER HEIGHTS, OH 44120 | N23: city zip | O23: =ALL!AV162 -> Pine Hill, AL 36769 | P23: city zip | Q23: Cleveland Ohio 44114
E24: LESSOR CONTACT PERSON | F24: =ALL!#REF! -> #REF! | H24: LESSOR CONTACT PERSON | I24: =ALL!AT163 -> Floretta Crowell | K24: LESSOR CONTACT PERSON | L24: =ALL!AU163 -> BACON, MICHELLE | N24: LESSOR CONTACT PERSON | O24: =ALL!AV163 -> 0 | P24: LESSOR CONTACT PERSON | Q24: Kelly Williams
A26: =+#REF!+1 -> #REF! | B26: REAL ESTATE COMPANY TASKS | C26: SIGNED LEASE APPROVED BY R/E CONTACT | E26: CLAIM INFO | F26: =ALL!#REF! -> #REF! | H26: CLAIM INFO | I26: =ALL!AT133 -> CLAIM INFO | K26: CLAIM INFO | L26: =ALL!AU133 -> CLAIM INFO | N26: CLAIM INFO | O26: =ALL!AV133 -> CLAIM INFO | P26: CLAIM INFO | Q26: =ALL!AW133 -> CLAIM INFO
A27: =+A26+1 -> #REF! | C27: DOCS SENT TO INSURANCE COMPANY | E27: Cause of Loss | F27: =ALL!#REF! -> #REF! | H27: Cause of Loss | I27: =ALL!AT134 -> BATHTUB OVERFLOW | K27: Cause of Loss | L27: =ALL!AU134 -> WATER PIPE BROKE | N27: Cause of Loss | O27: =ALL!AV134 -> KITCHEN WATER PIPE BROKE | P27: Cause of Loss | Q27: =ALL!AW134 -> Water Damage=WTR
A28: =+A27+1 -> #REF! | C28: R/E ENGAGEMENT DOC | E28: date of loss | F28: =ALL!#REF! -> #REF! | H28: date of loss | I28: =ALL!AT135 -> 45765 | K28: date of loss | L28: =ALL!AU135 -> Sunday, March 2, 2025 | N28: date of loss | O28: =ALL!AV135 -> Tuesday, March 11, 2025 | P28: date of loss | Q28: =ALL!AW135 -> Friday, September 12, 2025
A29: =+#REF!+1 -> #REF! | C29: TERM SHEET | E29: Insurance Co. Name | F29: =ALL!#REF! -> #REF! | H29: Insurance Co. Name | I29: =ALL!AT138 -> AAA Insurance | K29: Insurance Co. Name | L29: =ALL!AU138 -> Allstate Insurance Company | N29: Insurance Co. Name | O29: =ALL!AV138 -> Esurance | P29: Insurance Co. Name | Q29: ALLSTATE INS CO.
A30: =+A29+1 -> #REF! | C30: LEASE/SIGNED | E30: Claim # | F30: =ALL!#REF! -> #REF! | H30: Claim # | I30: =ALL!AT139 -> #017095711 | K30: Claim # | L30: =ALL!AU139 -> #0786294926 | N30: Claim # | O30: =ALL!AV139 -> #250254318 | P30: Claim # | Q30: #0808044169
A31: =+A30+1 -> #REF! | C31: LEAD DOCS | E31: policy # | F31: =ALL!#REF! -> #REF! | H31: policy # | I31: =ALL!AT140 -> OHH000190052 | K31: policy # | L31: =ALL!AU140 -> 980 610 253 | N31: policy # | O31: =ALL!AV140 -> : 10610052 | P31: policy # | Q31: 880 022 226
A32: =+A31+1 -> #REF! | C32: CONFIRM RECEIPT | E32: Email INS. co. | F32: =ALL!#REF! -> #REF! | H32: Email INS. co. | I32: =ALL!AT141 -> STAPLES.OLIVIA @ace.aaa.com | K32: Email INS. co. | L32: =ALL!AU141 -> claims@claims.allstate.com | N32: Email INS. co. | O32: =ALL!AV141 -> carla.robledo@ngic.com | P32: Email INS. co. | Q32: claims@claims.allstate.com
A33: =+A32+1 -> #REF! | C33: CONFIRM PAYMENT | E33: DESK Adjuster DA | F33: =ALL!#REF! -> #REF! | H33: DESK Adjuster DA | I33: =ALL!AT142 -> STAPLES, OLIVIA 207 776 6150 | K33: DESK Adjuster DA | L33: =ALL!AU142 -> LYLE KENDICKS | N33: DESK Adjuster DA | O33: =ALL!AV142 -> Carla Robledo| | P33: DESK Adjuster DA | Q33: =ALL!#REF! -> #REF!
A34: =+A33+1 -> #REF! | C34: DISBURSE FUNDS | E34: DA Phone | F34: =ALL!#REF! -> #REF! | H34: DA Phone | I34: =ALL!AT143 -> 207 776 6150 | K34: DA Phone | L34: =ALL!AU143 -> 888 656.8005 | N34: DA Phone | O34: =ALL!AV143 -> (800) 378-7262 | P34: DA Phone | Q34: TBD
A35: =+A34+1 -> #REF! | C35: FILE EXTENSION AS NEEDED (50% FEE = NEW LEASE) | E35: DA Ph. Ext. # | F35: =ALL!#REF! -> #REF! | H35: DA Ph. Ext. # | I35: =ALL!AT144 -> 207 776 6150 | K35: DA Ph. Ext. # | L35: =ALL!AU144 -> 9892774564 | N35: DA Ph. Ext. # | O35: =ALL!AV144 -> (336) 331-6825 | P35: DA Ph. Ext. # | Q35: TBD
A36: =+A35+1 -> #REF! | E36: DA Email | F36: =ALL!#REF! -> #REF! | H36: DA Email | I36: =ALL!AT145 -> STAPLES.OLIVIA @ace.aaa.com | K36: DA Email | L36: =ALL!AU145 -> lyle.kendrick@allstate.com | N36: DA Email | O36: =ALL!AV145 -> carla.robledo@ngic.com | P36: DA Email | Q36: TBD
A37: =+A36+1 -> #REF!
A38: =+#REF!+1 -> #REF! | E38: REAL ESTATE COMPANY | F38: =ALL!#REF! -> #REF! | H38: REAL ESTATE COMPANY | I38: DREAM TEAM REALTY, INC | K38: REAL ESTATE COMPANY | L38: DREAM TEAM REALTY, INC | N38: REAL ESTATE COMPANY | O38: DREAM TEAM REALTY, INC | P38: REAL ESTATE COMPANY | Q38: DREAM TEAM REALTY, INC
A39: =+A38+1 -> #REF! | E39: MAILING ADDRESS | F39: =ALL!#REF! -> #REF! | H39: MAILING ADDRESS | I39: 17419 BROADWAY AVE | K39: MAILING ADDRESS | L39: 17419 BROADWAY AVE | N39: MAILING ADDRESS | O39: 17419 BROADWAY AVE | P39: MAILING ADDRESS | Q39: 17419 BROADWAY AVE
A40: =+A39+1 -> #REF! | B40: STACKING LIST | C40: R/E ENGAGEMENT DOC | E40: city zip | F40: =ALL!#REF! -> #REF! | H40: city zip | I40: MAPLE HEIGHTS,OH 44137 | K40: city zip | L40: MAPLE HEIGHTS,OH 44137 | N40: city zip | O40: MAPLE HEIGHTS,OH 44137 | P40: city zip | Q40: MAPLE HEIGHTS,OH 44137
A41: =+A40+1 -> #REF! | C41: TERM SHEET | E41: CONTACT | F41: =ALL!#REF! -> #REF! | H41: CONTACT | I41: TREVOR ARCHER | K41: CONTACT | L41: TREVOR ARCHER | N41: CONTACT | O41: TREVOR ARCHER | P41: CONTACT | Q41: TREVOR ARCHER
A42: =+A41+1 -> #REF! | C42: LEASE/SIGNED | E42: phone # | F42: =ALL!#REF! -> #REF! | H42: phone # | I42: (914) 217-3339 | K42: phone # | L42: (914) 217-3339 | N42: phone # | O42: (914) 217-3339 | P42: phone # | Q42: (914) 217-3339
A43: =+A42+1 -> #REF! | C43: LEAD DOCS | E43: Email | F43: =ALL!#REF! -> #REF! | H43: Email | I43: INFO@2GETTREVOR.COM | K43: Email | L43: INFO@2GETTREVOR.COM | N43: Email | O43: INFO@2GETTREVOR.COM | P43: Email | Q43: INFO@2GETTREVOR.COM
