Workbook
Name a...new_customer: #REF!
Name Column.a.new.cst: #REF!
Name culpepper: #REF!
Name data: #REF!
Name Document_Stacking_List: #REF!
Name Enter_new_cst_data: #REF!
Name Jefferies: #REF!
Name LOVEJOY_INTERIOR: #REF!
Name Lovejoy_ROOF: #REF!
Name LxWxH: #REF!
Name new_customer: #REF!
Name PRICE_P: #REF!
Name Robinson: #REF!
Name Robinson: #REF!
Name sigtj: "Picture 9859"
Name SubContractor_Summary: #REF!
Name Wayside_Builders__LLC_…...OH: #REF!
Name WSB...GA.Wayside_Builders__LLC……GA: #REF!

Sheet email cvr
A1: This may seem like a lot of information; because it is a lot of information.
A2: Yet, it is the level of estimates/documentation required to substantiate the restoration process fully.
A3: It is also what separates us from many others.
A5: =+'jobinfo(2)'!C100 -> All Phase Consulting, LLC
A6: =+'jobinfo(2)'!C101 -> WWW.MYAPCLLC.COM | C6: =+'jobinfo(2)'!C102 -> Insured & GA Registered #09073201
A7: =+'jobinfo(2)'!C105 -> ECI 531 FIFTH AVE, | B7: =+'jobinfo(2)'!C103 -> 375 Rockbridge Road, Suite 172-343 | D7: =+'jobinfo(2)'!#REF! -> #REF!
A8: =+'jobinfo(2)'!C106 -> PELHAM, NY 10803 | B8: =+'jobinfo(2)'!C104 -> Lilburn, GA, 30047 | D8: =+'jobinfo(2)'!#REF! -> #REF!
A9: =+'jobinfo(2)'!C109 -> Providing Cost Estimating & Project Management Services
A10: =+'jobinfo(2)'!C110 -> Five Generations of Great Work | C10: =+'jobinfo(2)'!C111 -> Five Generations of Pride & Skills
A11: COMPANY REP. | B11: =+'jobinfo(2)'!$C$112 -> Joe Jones, PM 216.450.7228 | C11: =+'jobinfo(2)'!C113 -> wsbjoe9@gmail.com | F11: (740) 235-8196
A12: COMPANY REP. #2 | B12: =+'jobinfo(2)'!C114 -> 404-446-9060 | C12: =+'jobinfo(2)'!C115 -> info@myapcllc.com
A13: EIN # | B13: =+'jobinfo(2)'!C116 -> TIN 83-226 0563 | C13: FEDEX# | D13: =+'jobinfo(2)'!C117 -> FEDEX # 9836-2151-1
A15: Re: Initial Documents Processing
A16: =+'jobinfo(2)'!B1 -> Property-Owner Name | B16: =+'jobinfo(2)'!C1 -> Johnson, Paul & Tamra | C16: =+'jobinfo(2)'!B5 -> Cst-owner Phone# | D16: =+'jobinfo(2)'!C5 -> (216) 399-6191
A17: =+'jobinfo(2)'!B2 -> Property address: street | B17: =+'jobinfo(2)'!C2 -> 9402 Shepard Road | C17: =+'jobinfo(2)'!B6 -> Co-Owner.cst#2 | D17: =+'jobinfo(2)'!C6 -> TBD
A18: =+'jobinfo(2)'!B3 -> Property city, state, zip | B18: =+'jobinfo(2)'!C3 -> Macedonia, OH, USA | C18: =+'jobinfo(2)'!B6 -> Co-Owner.cst#2 | D18: =+'jobinfo(2)'!C10 -> TBD
A19: =+'jobinfo(2)'!B4 -> Customer Email | B19: =+'jobinfo(2)'!C4 -> tringo68@yahoo.com | C19: =+'jobinfo(2)'!B7 -> cst ph # 2 | D19: =+'jobinfo(2)'!C7 -> TBD
A20: =+signpgs!A14 -> Insurance Co. Name | B20: =+signpgs!B14 -> Allstate Insurance Company | C20: =+'jobinfo(2)'!C27 -> 0 | D20: =+'jobinfo(2)'!C28 -> 0
A22: Greetings : Please find attached the contractual documents for your review and signatures.
A23: Please sign each line indicated by your name.
A24: ALSO please INITIAL each space as indicated in Contract & MOU docs
A25: Upon your approval please print out a copy for your file.
A26: Scan and return a fully signed copy back to us. If this is a challenge for you then please advise us and we will make arrangements to get the signed documents back to us.
A27: Pages 1 -12 are what we need to get started; the remaining pages will be used later in the process.
A28: Re: Insurance Claim Check Processing, Mortgage Co.
A29: Please fill in any missing items with the info that you may have at this time. We will work with you to get all needed info as we move forward.
A30: Of course; if you have ANY questions please give us a call , text or email.
A32: Thank you for your confidence placed in us ; we shall do all within our power to be continually earn and respect that trust.
A34: The following pages 1 -12 are what we need to get started; the remaining pages will be used later in the process.
A35: 1 | B35: =+signpgs!A1 -> ** GENERAL AUTHORIZATION **
B36: gives us permission to talk with your insurance and mortgage company
A37: 2 | B37: =+signpgs!A36 -> EMERGENCY SERVICES WORK AUTHORIZATION
B38: allows us to do the emergency services/mitigation work
A40: 3 thru 6 | B40: =+aob!A5 -> Assignment of Insurance Benefits & Direct Payment Authorization:
B41: Allows us to proceed to work without payment from you !!!!!!!!!!
B42: Or you may enclose payment or provide credit card info
A43: 7 thru 8 | B43: =+signpgs!$A$97 -> CONTRACTOR & HOMEOWNER AGREEMENT
B44: rebuild contract; authorizes us to begin the resoration process on your property
A46: 9 | B46: =+signpgs!$A$188 -> Notice of Right of Recession
B47: 3 days to allow you to cancel contract
...

Sheet quicklist
C1: BASIC SUMMARY OF RESTORATION PROCESS; (Quick version). | D1: =+'jobinfo(2)'!C3 -> Macedonia, OH, USA | F1: DoneDate
A2: JOB | C2: =+'jobinfo(2)'!C1 -> Johnson, Paul & Tamra | D2: Status | E2: %
A3: 1 | B3: Introduction, Analysis & Verification | C3: Introduction, Analysis & Verification | D3: source/reffered by:
C4: Who is the Insurance Company ?!?
A5: POI | C5: Does customer Comprehend Our Role in the process?
C6: Is this an LEGITIMATE COVERED INSURANCE Claim? Or Self Pay ?
C7: IS THE DAMAGE $ MORE THAN THE DEDUCTIBLE?
C8: Do they have coverage; for AOB?
A9: 2 | B9: Contracts & Documentation | C9: Contracts & Documentation
C10: Has Customer been fully advised of Contract Contents?
C11: Has Customer had a full Consultation to Our Terms & Conditions?
A12: DOC | C12: Does Customer FULLY Agree to Our Terms & Conditions? Initials?
C13: Notary Page explained/ Fast track
A14: mou | C14: Company investment (dollars, time ,materials)into their Project?
A15: 3 | C15: Claim Reporting
A16: INS | C16: DOES THE CUSTOMER HAVE THE REQUIRED INFO?
C17: Insurer Mitigation / DMO / CPS Approval Info Sheet
A18: mit | B18: Mitigation & Demolition | C18: Mitigation & Demolition
A19: 4 | C19: Roof & EXT Mitigation TEMPORARY & EMERGENCY REPAIRS
A20: 5 | C20: Contents_ item list_; storage details; security explained?
A21: 6 | C21: HMR / Secondary Damages; Equipment & Electricity $
A22: 7 | C22: Interior Mitigation; household disruption explained? | D22: 0.5
A23: esx | B23: Estimates | C23: Estimates
A24: 8 | C24: Interior Inspection/Scope Form | D24: 0.1
C25: SKETCH/DRAWING;[1] sheet per floor
C26: PICTURES; VIA ENCIRCLE APP
C27: Create Estimates…Rebuild……...REPAIR SPECS & COST ANALYSIS
C28: Mitigation & Demolition
A29: 9 | B29: Insurance Company Meetings | C29: Insurance Company Meetings
A30: adj | C30: Prepare docs for adjuster meeting; Print & bind docs
C31: BE PRESENT WHEN ADJUSTER VISITS The PROPERTY.
A32: 10 | B32: Cashflow
A33: job | C33: General Contractor / Subcontracts
B34: Mitigation & Demolition | C34: Mitigation & Demolition
B35: Rebuild
B36: Contents
B37: Closeout | C37: Closeout

Sheet signpgs
A1: ** GENERAL AUTHORIZATION **
A2: =+'jobinfo(2)'!$C$100 -> All Phase Consulting, LLC
A3: =+'jobinfo(2)'!C$109 -> Providing Cost Estimating & Project Management Services
A4: =+'jobinfo(2)'!$C$101 -> WWW.MYAPCLLC.COM | C4: =+'jobinfo(2)'!$C$102 -> Insured & GA Registered #09073201
A5: ='jobinfo(2)'!$C$107 -> 20810 AURORA RD | B5: =+'jobinfo(2)'!$C$103 -> 375 Rockbridge Road, Suite 172-343 | D5: =+'jobinfo(2)'!$C$105 -> ECI 531 FIFTH AVE,
A6: ='jobinfo(2)'!$C$108 -> BEDFORD,OH 44146 | B6: =+'jobinfo(2)'!$C$104 -> Lilburn, GA, 30047 | D6: =+'jobinfo(2)'!$C$106 -> PELHAM, NY 10803
A7: =+'jobinfo(2)'!$C$110 -> Five Generations of Great Work | C7: =+'jobinfo(2)'!$C$111 -> Five Generations of Pride & Skills
A8: COMPANY REP. | B8: =+'jobinfo(2)'!$C$112 -> Joe Jones, PM 216.450.7228 | C8: =+'jobinfo(2)'!$C$113 -> wsbjoe9@gmail.com
A9: COMPANY REP. #2 | B9: =+'jobinfo(2)'!$C$114 -> 404-446-9060 | C9: =+'jobinfo(2)'!$C$115 -> info@myapcllc.com
A10: Claim # | B10: ='jobinfo(2)'!$C$27 -> 0 | C10: Cst-owner Phone# | D10: ='jobinfo(2)'!$C$5 -> (216) 399-6191
A11: =+'jobinfo(2)'!$B$1 -> Property-Owner Name | B11: =+'jobinfo(2)'!C$1 -> Johnson, Paul & Tamra | C11: Customer Email | D11: ='jobinfo(2)'!$C$4 -> tringo68@yahoo.com
A12: =+'jobinfo(2)'!$B$2 -> Property address: street | B12: =+'jobinfo(2)'!$C$2 -> 9402 Shepard Road | C12: Co-Owner.cst#2 | D12: =+'jobinfo(2)'!$C$6 -> TBD
A13: =+'jobinfo(2)'!$B$3 -> Property city, state, zip | B13: =+'jobinfo(2)'!$C$3 -> Macedonia, OH, USA | C13: cst ph # 2 | D13: =+'jobinfo(2)'!$C$7 -> TBD
A14: =+'jobinfo(2)'!$B$26 -> Insurance Co. Name | B14: =+'jobinfo(2)'!$C$26 -> Allstate Insurance Company | C14: =+'jobinfo(2)'!$B$28 -> policy # | D14: =+'jobinfo(2)'!$C$27 -> 0
A15: =+'jobinfo(2)'!$B$46 -> Insurance Co. Phone | B15: =+'jobinfo(2)'!$C$46 -> (800) 255-7828 | C15: =+'jobinfo(2)'!$C$29 -> 0
A16: =+'jobinfo(2)'!$B$30 -> DESK Adjuster DA | B16: =+'jobinfo(2)'!$C$30 -> 0 | C16: =+'jobinfo(2)'!$B$33 -> DA Email | D16: =+'jobinfo(2)'!$C$33 -> claims@claims.allstate.com
A17: =+'jobinfo(2)'!$B$31 -> DA Phone | B17: =+'jobinfo(2)'!$C$31 -> 888 656.8005 | C17: =+'jobinfo(2)'!$B$32 -> DA Ph. Ext. # | D17: =+'jobinfo(2)'!$C$32 -> 0
A20: Dear Insurance Company/ Mortgage Company and or To Whom It May Concern:
A21: The undersigned property owner agrees to employ | C21: =+$A$2 -> All Phase Consulting, LLC
A22: to assist in the repair of the above mentioned property that was damaged by
A23: =IF(ISBLANK('jobinfo(2)'!C11),"____________________",'jobinfo(2)'!C11) -> WATER | C23: on or about (date). | D23: =IF(ISBLANK('jobinfo(2)'!C12),"__________________________________",'jobinfo(2)'!C12) -> Friday, April 4, 2025
A24: Owners ACKNOWLEDGE as party of interest; | C24: =C21 -> All Phase Consulting, LLC
A25: and will be noted as such on all drafts, correspondence, and communications between the owner, insurer and my mortgage company. I hereby authorize all parties to discuss my account as it relates to the above noted loss and or repairs; as well as the release of draws for all repairs. This applies in full to it's employees / assigns / representatives.
A29: OWNER HEREBY SPECIFICALLY REQUESTS THAT ALL EMS & CPS PAYMENTS BE PAID TO: ; | E29: OWNER HEREBY SPECIFICALLY REQUESTS THAT EMS Mitigation & CPS Packout / Cleaning of
A30: =+$C$24 -> All Phase Consulting, LLC | C30: =+'email cvr'!A13 -> EIN # | D30: =+'email cvr'!B13 -> TIN 83-226 0563 | E30: Personal Property (ONLY) PAYMENTS ; PAYMENTS BE PAID TO REBUILD Items Excluded::
A31: ( REBUILD PAYMENT EXCLUDED AND PAID TO OWNER )
A32: X___________________________________ _____________ | C32: X_ _________________________________ _____________ | D32: =+'jobinfo(2)'!C22 -> Friday, April 4, 2025
A33: =IF(ISBLANK('jobinfo(2)'!C1),"__Property owner Signature________________________________",'jobinfo(2)'!$C$1) -> Johnson, Paul & Tamra | C33: =IF(ISBLANK('jobinfo(2)'!C6),"co-owner Signature______________________________",'jobinfo(2)'!C6) -> TBD
A35: =+$A$186 -> COMPANY REP. | B35: =+B67 -> Joe Jones, PM 216.450.7228 | D35: =+D67 -> wsbjoe9@gmail.com
A36: EMERGENCY SERVICES WORK AUTHORIZATION
A37: =+$A$2 -> All Phase Consulting, LLC
A38: =+A3 -> Providing Cost Estimating & Project Management Services | D38: =+$A$100 -> WWW.MYAPCLLC.COM
A40: =+A5 -> 20810 AURORA RD | B40: =+B5 -> 375 Rockbridge Road, Suite 172-343 | D40: =+D5 -> ECI 531 FIFTH AVE,
A41: =+A6 -> BEDFORD,OH 44146 | B41: =+B6 -> Lilburn, GA, 30047 | D41: =+D6 -> PELHAM, NY 10803
C42: =+$C$104 -> wsbjoe9@gmail.com
A43: =+A8 -> COMPANY REP. | B43: =+B35 -> Joe Jones, PM 216.450.7228 | C43: =+$D$186 -> wsbjoe9@gmail.com
A44: Claim Number: | B44: =+'jobinfo(2)'!C27 -> 0 | C44: =+B14 -> Allstate Insurance Company
A45: =+'jobinfo(2)'!B1 -> Property-Owner Name | B45: =+'jobinfo(2)'!C1 -> Johnson, Paul & Tamra | C45: =+A15 -> Insurance Co. Phone | D45: ='jobinfo(2)'!C31 -> 888 656.8005
A46: =+'jobinfo(2)'!B2 -> Property address: street | B46: =+'jobinfo(2)'!C2 -> 9402 Shepard Road
A47: =+'jobinfo(2)'!B3 -> Property city, state, zip | B47: =+'jobinfo(2)'!C3 -> Macedonia, OH, USA | C47: =+'jobinfo(2)'!B11 -> Cause of Loss | D47: =+A23 -> WATER
...

Sheet cst o&p to ins co.
A1: ='jobinfo(2)'!C27 -> 0
A2: ='jobinfo(2)'!C1 -> Johnson, Paul & Tamra
A3: ='jobinfo(2)'!C2 -> 9402 Shepard Road
A4: ='jobinfo(2)'!C3 -> Macedonia, OH, USA
A6: To whom it may concern,
A8: After discussing in depth the damages and necessary repairs per my claim with my Project Manager/Contractor of choice, I have been made aware of what needs to be done to restore my property back to the condition before the loss.
A10: My Project Manager/Contractor has educated me on what type of labor, materials, scheduling and supervision of crews will be necessary.
A12: There will also be an investment of time coordinating and managing the project that will be required due to the multiple trades and trade-specific subcontractors involved.
A14: Understanding the time, effort, and supervision necessary for the restoration of my home, I do not have the time nor the resources to coordinate or manage this project to completion.
A16: Therefore, this letter is to inform you that my Project Manager/Contractor of choice, shall be managing, coordinating and supervising the entirety of my property repairs from start to finish.
A18: I understand what “overhead and profit” is and I understand my policy’s premium includes coverage for O&P as well as material tax. Upon examination of my homeowner’s policy, I have confirmed that I have a replacement cost policy on my home and therefore overhead and profit should be included in my estimate due to the following reasons:
A19: 1. My Project Manager/Contractor of choice, is qualified, experienced and has many references.
A20: 2. Being a Project Manager/Contractor must include overhead and profit to provide their contracting services to stay in business, as they have expenses and overhead above and beyond the normal expenses of a laborer who does the work themselves.
A21: 3. As a Project Manager/Contractor coordinating the trades and overseeing the work, they have overhead costs not connected to specific line items on the estimate that must be included and factored in for all sub-contracted trades.
A22: 4. Multiple trades are involved and I feel it would be impractical/unfair to require me to coordinate these trades without my Project Manager/Contractor’s assistance, as it is not my area of expertise.
A23: 5. I would like my Project Manager/Contractor to locate, choose and hire skilled and qualified tradesman and coordinating/scheduling/supervising the work to be done
A25: Included is the actual replacement cost for the damages to my home. Please speak directly with my Project Manager/Contractor to finalize my restoration items.
A27: ='jobinfo(2)'!C100 -> All Phase Consulting, LLC
A28: ='jobinfo(2)'!C101 -> WWW.MYAPCLLC.COM
A29: ='jobinfo(2)'!C103 -> 375 Rockbridge Road, Suite 172-343
A30: ='jobinfo(2)'!C104 -> Lilburn, GA, 30047
A31: ='jobinfo(2)'!C105 -> ECI 531 FIFTH AVE,
A32: ='jobinfo(2)'!C106 -> PELHAM, NY 10803
A33: ='jobinfo(2)'!C107 -> 20810 AURORA RD
A34: ='jobinfo(2)'!C108 -> BEDFORD,OH 44146
A35: ='jobinfo(2)'!C109 -> Providing Cost Estimating & Project Management Services
A36: ='jobinfo(2)'!C110 -> Five Generations of Great Work
A37: ='jobinfo(2)'!C111 -> Five Generations of Pride & Skills
A38: ='jobinfo(2)'!C112 -> Joe Jones, PM 216.450.7228
A39: ='jobinfo(2)'!C113 -> wsbjoe9@gmail.com
A40: ='jobinfo(2)'!C114 -> 404-446-9060
... A42: ='jobinfo(2)'!C116 -> TIN 83-226 0563
A43: ='jobinfo(2)'!C118 -> 0

Sheet jobinfo(2)
A1: Customer | B1: Property-Owner Name | C1: ='[2]jobinfo(2)'!$C$1 -> Johnson, Paul & Tamra | D1: ='[2]jobinfo(2)'!$D$1 -> 0 | E1: ='[2]jobinfo(2)'!$E$1 -> 0 | F1: ='[2]jobinfo(2)'!$F$1 -> 0 | G1: ='[2]jobinfo(2)'!$G$1 -> 0 | H1: ='[2]jobinfo(2)'!$H$1 -> 0 | I1: ='[2]jobinfo(2)'!$I$1 -> 0 | J1: ='[2]jobinfo(2)'!$J$1 -> 0 | K1: Property-Owner Name | L1: SMITH, JANET
B2: Property address: street | C2: ='[2]jobinfo(2)'!$C$2 -> 9402 Shepard Road | D2: ='[2]jobinfo(2)'!$D$2 -> 0 | E2: ='[2]jobinfo(2)'!$E$2 -> 0 | F2: ='[2]jobinfo(2)'!$F$2 -> 0 | G2: ='[2]jobinfo(2)'!$G$2 -> 0 | H2: ='[2]jobinfo(2)'!$H$2 -> 0 | I2: ='[2]jobinfo(2)'!$I$2 -> 0 | J2: ='[2]jobinfo(2)'!$J$2 -> 0 | K2: Property address: street | L2: 216) 403-7739
B3: Property city, state, zip | C3: ='[2]jobinfo(2)'!$C$3 -> Macedonia, OH, USA | D3: ='[2]jobinfo(2)'!$D$3 -> 0 | E3: ='[2]jobinfo(2)'!$E$3 -> 0 | F3: ='[2]jobinfo(2)'!$F$3 -> 0 | G3: ='[2]jobinfo(2)'!$G$3 -> 0 | H3: ='[2]jobinfo(2)'!$H$3 -> 0 | I3: ='[2]jobinfo(2)'!$I$3 -> 0 | J3: ='[2]jobinfo(2)'!$J$3 -> 0 | K3: Property city, state, zip | L3: Cleveland, OH
B4: Customer Email | C4: ='[2]jobinfo(2)'!$C$4 -> tringo68@yahoo.com | D4: ='[2]jobinfo(2)'!$D$4 -> 0 | E4: ='[2]jobinfo(2)'!$E$4 -> 0 | F4: ='[2]jobinfo(2)'!$F$4 -> 0 | G4: ='[2]jobinfo(2)'!$G$4 -> 0 | H4: ='[2]jobinfo(2)'!$H$4 -> 0 | I4: ='[2]jobinfo(2)'!$I$4 -> 0 | J4: ='[2]jobinfo(2)'!$J$4 -> 0 | K4: Customer Email | L4: SMITH, JANET
B5: Cst-owner Phone# | C5: ='[2]jobinfo(2)'!$C$5 -> (216) 399-6191 | D5: ='[2]jobinfo(2)'!$D$5 -> 0 | E5: ='[2]jobinfo(2)'!$E$5 -> 0 | F5: ='[2]jobinfo(2)'!$F$5 -> 0 | G5: ='[2]jobinfo(2)'!$G$5 -> 0 | H5: ='[2]jobinfo(2)'!$H$5 -> 0 | I5: ='[2]jobinfo(2)'!$I$5 -> 0 | K5: Cst-owner Phone# | L5: (216) 403-7739
B6: Co-Owner.cst#2 | C6: ='[2]jobinfo(2)'!$C$6 -> TBD | D6: ='[2]jobinfo(2)'!$D$6 -> 0 | E6: ='[2]jobinfo(2)'!$E$6 -> 0 | F6: ='[2]jobinfo(2)'!$F$6 -> 0 | G6: ='[2]jobinfo(2)'!$G$6 -> 0 | H6: ='[2]jobinfo(2)'!$H$6 -> 0 | I6: ='[2]jobinfo(2)'!$I$6 -> 0 | J6: ='[2]jobinfo(2)'!$J$6 -> 0 | K6: Co-Owner.cst#2 | L6: TERRANCE DAVIS
B7: cst ph # 2 | C7: ='[2]jobinfo(2)'!$C$7 -> TBD | D7: ='[2]jobinfo(2)'!$D$7 -> 0 | E7: ='[2]jobinfo(2)'!$E$7 -> 0 | F7: ='[2]jobinfo(2)'!$F$7 -> 0 | G7: ='[2]jobinfo(2)'!$G$7 -> 0 | H7: ='[2]jobinfo(2)'!$H$7 -> 0 | I7: ='[2]jobinfo(2)'!$I$7 -> 0 | J7: ='[2]jobinfo(2)'!$J$7 -> 0 | K7: cst ph # 2 | L7: 2163185051
B8: Cst address # 2 | C8: ='[2]jobinfo(2)'!$C$8 -> TBD | D8: ='[2]jobinfo(2)'!$D$8 -> 0 | E8: ='[2]jobinfo(2)'!$E$8 -> 0 | F8: ='[2]jobinfo(2)'!$F$8 -> 0 | G8: ='[2]jobinfo(2)'!$G$8 -> 0 | H8: ='[2]jobinfo(2)'!$H$8 -> 0 | I8: ='[2]jobinfo(2)'!$I$8 -> 0 | J8: ='[2]jobinfo(2)'!$J$8 -> 0 | K8: Cst address # 2 | L8: TBD
B9: city, state-cst#2 | C9: ='[2]jobinfo(2)'!$C$9 -> TBD | D9: ='[2]jobinfo(2)'!$D$9 -> 0 | E9: ='[2]jobinfo(2)'!$E$9 -> 0 | F9: ='[2]jobinfo(2)'!$F$9 -> 0 | G9: ='[2]jobinfo(2)'!$G$9 -> 0 | H9: ='[2]jobinfo(2)'!$H$9 -> 0 | I9: ='[2]jobinfo(2)'!$I$9 -> 0 | J9: ='[2]jobinfo(2)'!$J$9 -> 0 | K9: city, state-cst#2 | L9: TBD
B10: email-cst #2 | C10: ='[2]jobinfo(2)'!$C$10 -> TBD | D10: ='[2]jobinfo(2)'!$D$10 -> 0 | E10: ='[2]jobinfo(2)'!$E$10 -> 0 | F10: ='[2]jobinfo(2)'!$F$10 -> 0 | G10: ='[2]jobinfo(2)'!$G$10 -> 0 | H10: ='[2]jobinfo(2)'!$H$10 -> 0 | I10: ='[2]jobinfo(2)'!$I$10 -> 0 | J10: ='[2]jobinfo(2)'!$J$10 -> 0 | K10: email-cst #2 | L10: TBD
A11: Loss Info | B11: Cause of Loss | C11: ='[2]jobinfo(2)'!$C$11 -> WATER | D11: ='[2]jobinfo(2)'!$D$11 -> 0 | E11: ='[2]jobinfo(2)'!$E$11 -> 0 | F11: ='[2]jobinfo(2)'!$F$11 -> 0 | G11: ='[2]jobinfo(2)'!$G$11 -> 0 | H11: ='[2]jobinfo(2)'!$H$11 -> 0 | I11: ='[2]jobinfo(2)'!$I$11 -> 0 | J11: ='[2]jobinfo(2)'!$J$11 -> 0 | K11: Cause of Loss | L11: WATER
B12: date of loss | C12: ='[2]jobinfo(2)'!$C$12 -> Friday, April 4, 2025 | D12: ='[2]jobinfo(2)'!$D$12 -> 0 | E12: ='[2]jobinfo(2)'!$E$12 -> 0 | F12: ='[2]jobinfo(2)'!$F$12 -> 0 | G12: ='[2]jobinfo(2)'!$G$12 -> 0 | H12: ='[2]jobinfo(2)'!$H$12 -> 0 | I12: ='[2]jobinfo(2)'!$I$12 -> 0 | J12: ='[2]jobinfo(2)'!$J$12 -> 0 | K12: date of loss | L12: TBD
B13: rebuild type 1 | C13: ='[2]jobinfo(2)'!$C$13 -> Interior Repairs LEVEL 1 | D13: ='[2]jobinfo(2)'!$D$13 -> 0 | E13: ='[2]jobinfo(2)'!$E$13 -> 0 | F13: ='[2]jobinfo(2)'!$F$13 -> 0 | G13: ='[2]jobinfo(2)'!$G$13 -> 0 | H13: ='[2]jobinfo(2)'!$H$13 -> 0 | I13: ='[2]jobinfo(2)'!$I$13 -> 0 | J13: ='[2]jobinfo(2)'!$J$13 -> 0 | K13: rebuild type 1 | L13: Interior Repairs LEVEL 1 &2
B14: rebuild type 2 | C14: ='[2]jobinfo(2)'!$C$14 -> Interior Repairs LEVEL 2 | D14: ='[2]jobinfo(2)'!$D$14 -> 0 | E14: ='[2]jobinfo(2)'!$E$14 -> 0 | F14: ='[2]jobinfo(2)'!$F$14 -> 0 | G14: ='[2]jobinfo(2)'!$G$14 -> 0 | H14: ='[2]jobinfo(2)'!$H$14 -> 0 | I14: ='[2]jobinfo(2)'!$I$14 -> 0 | J14: ='[2]jobinfo(2)'!$J$14 -> 0 | K14: rebuild type 2
B15: rebuild type 3 | C15: ='[2]jobinfo(2)'!$C$15 -> TBD | D15: ='[2]jobinfo(2)'!$D$15 -> 0 | E15: ='[2]jobinfo(2)'!$E$15 -> 0 | F15: ='[2]jobinfo(2)'!$F$15 -> 0 | G15: ='[2]jobinfo(2)'!$G$15 -> 0 | H15: ='[2]jobinfo(2)'!$H$15 -> 0 | I15: ='[2]jobinfo(2)'!$I$15 -> 0 | J15: ='[2]jobinfo(2)'!$J$15 -> 0 | K15: rebuild type 3
B16: DEMO | C16: ='[2]jobinfo(2)'!$C$16 -> Y | D16: ='[2]jobinfo(2)'!$D$16 -> 0 | E16: ='[2]jobinfo(2)'!$E$16 -> 0 | F16: ='[2]jobinfo(2)'!$F$16 -> 0 | G16: ='[2]jobinfo(2)'!$G$16 -> 0 | H16: ='[2]jobinfo(2)'!$H$16 -> 0 | I16: ='[2]jobinfo(2)'!$I$16 -> 0 | J16: ='[2]jobinfo(2)'!$J$16 -> 0 | K16: DEMO | L16: Y
B17: Mitigation | C17: ='[2]jobinfo(2)'!$C$17 -> Y | D17: ='[2]jobinfo(2)'!$D$17 -> 0 | E17: ='[2]jobinfo(2)'!$E$17 -> 0 | F17: ='[2]jobinfo(2)'!$F$17 -> 0 | G17: ='[2]jobinfo(2)'!$G$17 -> 0 | H17: ='[2]jobinfo(2)'!$H$17 -> 0 | I17: ='[2]jobinfo(2)'!$I$17 -> 0 | J17: ='[2]jobinfo(2)'!$J$17 -> 0 | K17: Mitigation | L17: Y
B18: Other Structures | C18: ='[2]jobinfo(2)'!$C$18 -> N | D18: ='[2]jobinfo(2)'!$D$18 -> 0 | E18: ='[2]jobinfo(2)'!$E$18 -> 0 | F18: ='[2]jobinfo(2)'!$F$18 -> 0 | G18: ='[2]jobinfo(2)'!$G$18 -> 0 | H18: ='[2]jobinfo(2)'!$H$18 -> 0 | I18: ='[2]jobinfo(2)'!$I$18 -> 0 | J18: ='[2]jobinfo(2)'!$J$18 -> 0 | K18: Other Structures | L18: NA
A19: CPS | B19: Replacement | C19: ='[2]jobinfo(2)'!$C$19 -> Y | D19: ='[2]jobinfo(2)'!$D$19 -> 0 | E19: ='[2]jobinfo(2)'!$E$19 -> 0 | F19: ='[2]jobinfo(2)'!$F$19 -> 0 | G19: ='[2]jobinfo(2)'!$G$19 -> 0 | H19: ='[2]jobinfo(2)'!$H$19 -> 0 | I19: ='[2]jobinfo(2)'!$I$19 -> 0 | J19: ='[2]jobinfo(2)'!$J$19 -> 0 | K19: Replacement | L19: Y
B20: CPS / CLN / CON/ CGN | C20: ='[2]jobinfo(2)'!$C$20 -> Y | D20: ='[2]jobinfo(2)'!$D$20 -> 0 | E20: ='[2]jobinfo(2)'!$E$20 -> 0 | F20: ='[2]jobinfo(2)'!$F$20 -> 0 | G20: ='[2]jobinfo(2)'!$G$20 -> 0 | H20: ='[2]jobinfo(2)'!$H$20 -> 0 | I20: ='[2]jobinfo(2)'!$I$20 -> 0 | J20: ='[2]jobinfo(2)'!$J$20 -> 0 | K20: CPS / CLN / CON/ CGN | L20: Y
B21: Year Built | C21: ='[2]jobinfo(2)'!$C$21 -> POST 1978 | D21: ='[2]jobinfo(2)'!$D$21 -> 0 | E21: ='[2]jobinfo(2)'!$E$21 -> 0 | F21: ='[2]jobinfo(2)'!$F$21 -> 0 | G21: ='[2]jobinfo(2)'!$G$21 -> 0 | H21: ='[2]jobinfo(2)'!$H$21 -> 0 | I21: ='[2]jobinfo(2)'!$I$21 -> 0 | J21: ='[2]jobinfo(2)'!$J$21 -> 0 | K21: Year Built | L21: PRE 1978
B22: Contract Date | C22: ='[2]jobinfo(2)'!$C$22 -> Friday, April 4, 2025 | D22: ='[2]jobinfo(2)'!$D$22 -> 0 | E22: ='[2]jobinfo(2)'!$E$22 -> 0 | F22: ='[2]jobinfo(2)'!$F$22 -> 0 | G22: ='[2]jobinfo(2)'!$G$22 -> 0 | H22: ='[2]jobinfo(2)'!$H$22 -> 0 | I22: ='[2]jobinfo(2)'!$I$22 -> 0 | J22: ='[2]jobinfo(2)'!$J$22 -> 0 | K22: Contract Date | L22: TBD
B23: Loss of use/ ALE | C23: ='[2]jobinfo(2)'!$C$23 -> Y | D23: ='[2]jobinfo(2)'!$D$23 -> 0 | E23: ='[2]jobinfo(2)'!$E$23 -> 0 | F23: ='[2]jobinfo(2)'!$F$23 -> 0 | G23: ='[2]jobinfo(2)'!$G$23 -> 0 | H23: ='[2]jobinfo(2)'!$H$23 -> 0 | I23: ='[2]jobinfo(2)'!$I$23 -> 0 | J23: ='[2]jobinfo(2)'!$J$23 -> 0 | K23: Loss of use/ ALE | L23: NA
B24: Breathing issue | C24: ='[2]jobinfo(2)'!$C$24 -> TBD | D24: ='[2]jobinfo(2)'!$D$24 -> 0 | E24: ='[2]jobinfo(2)'!$E$24 -> 0 | F24: ='[2]jobinfo(2)'!$F$24 -> 0 | G24: ='[2]jobinfo(2)'!$G$24 -> 0 | H24: ='[2]jobinfo(2)'!$H$24 -> 0 | I24: ='[2]jobinfo(2)'!$I$24 -> 0 | J24: ='[2]jobinfo(2)'!$J$24 -> 0 | K24: Breathing issue | L24: TBD
B25: HMR | C25: ='[2]jobinfo(2)'!$C$25 -> TBD | D25: ='[2]jobinfo(2)'!$D$25 -> 0 | E25: ='[2]jobinfo(2)'!$E$25 -> 0 | F25: ='[2]jobinfo(2)'!$F$25 -> 0 | G25: ='[2]jobinfo(2)'!$G$25 -> 0 | H25: ='[2]jobinfo(2)'!$H$25 -> 0 | I25: ='[2]jobinfo(2)'!$I$25 -> 0 | J25: ='[2]jobinfo(2)'!$J$25 -> 0 | K25: HMR | L25: TBD
B26: Insurance Co. Name | C26: ='[2]jobinfo(2)'!$C$26 -> Allstate Insurance Company | D26: ='[2]jobinfo(2)'!$D$26 -> 0 | E26: ='[2]jobinfo(2)'!$E$26 -> 0 | F26: ='[2]jobinfo(2)'!$F$26 -> 0 | G26: ='[2]jobinfo(2)'!$G$26 -> 0 | H26: ='[2]jobinfo(2)'!$H$26 -> 0 | I26: ='[2]jobinfo(2)'!$I$26 -> 0 | J26: ='[2]jobinfo(2)'!$J$26 -> 0 | K26: Insurance Co. Name | L26: TBD
A27: Insurance Co. | B27: Claim # | C27: ='[2]jobinfo(2)'!$C$27 -> 0 | D27: ='[2]jobinfo(2)'!$D$27 -> 0 | E27: ='[2]jobinfo(2)'!$E$27 -> 0 | F27: ='[2]jobinfo(2)'!$F$27 -> 0 | G27: ='[2]jobinfo(2)'!$G$27 -> 0 | H27: ='[2]jobinfo(2)'!$H$27 -> 0 | I27: ='[2]jobinfo(2)'!$I$27 -> 0 | J27: ='[2]jobinfo(2)'!$J$27 -> 0 | K27: Claim # | L27: CLM
B28: policy # | C28: ='[2]jobinfo(2)'!$C$28 -> 0 | D28: ='[2]jobinfo(2)'!$D$28 -> 0 | E28: ='[2]jobinfo(2)'!$E$28 -> 0 | F28: ='[2]jobinfo(2)'!$F$28 -> 0 | G28: ='[2]jobinfo(2)'!$G$28 -> 0 | H28: ='[2]jobinfo(2)'!$H$28 -> 0 | I28: ='[2]jobinfo(2)'!$I$28 -> 0 | J28: ='[2]jobinfo(2)'!$J$28 -> 0 | K28: policy # | L28: PL
B29: Email INS. co. | C29: ='[2]jobinfo(2)'!$C$29 -> 0 | D29: ='[2]jobinfo(2)'!$D$29 -> 0 | E29: ='[2]jobinfo(2)'!$E$29 -> 0 | F29: ='[2]jobinfo(2)'!$F$29 -> 0 | G29: ='[2]jobinfo(2)'!$G$29 -> 0 | H29: ='[2]jobinfo(2)'!$H$29 -> 0 | I29: ='[2]jobinfo(2)'!$I$29 -> 0 | J29: ='[2]jobinfo(2)'!$J$29 -> 0 | K29: Email INS. co. | L29: TBD
B30: DESK Adjuster DA | C30: ='[2]jobinfo(2)'!$C$30 -> 0 | D30: ='[2]jobinfo(2)'!$D$30 -> 0 | E30: ='[2]jobinfo(2)'!$E$30 -> 0 | F30: ='[2]jobinfo(2)'!$F$30 -> 0 | G30: ='[2]jobinfo(2)'!$G$30 -> 0 | H30: ='[2]jobinfo(2)'!$H$30 -> 0 | I30: ='[2]jobinfo(2)'!$I$30 -> 0 | J30: ='[2]jobinfo(2)'!$J$30 -> 0 | K30: DESK Adjuster DA | L30: TBD
B31: DA Phone | C31: ='[2]jobinfo(2)'!$C$31 -> 888 656.8005 | D31: ='[2]jobinfo(2)'!$D$31 -> 0 | E31: ='[2]jobinfo(2)'!$E$31 -> 0 | F31: ='[2]jobinfo(2)'!$F$31 -> 0 | G31: ='[2]jobinfo(2)'!$G$31 -> 0 | H31: ='[2]jobinfo(2)'!$H$31 -> 0 | I31: ='[2]jobinfo(2)'!$I$31 -> 0 | J31: ='[2]jobinfo(2)'!$J$31 -> 0 | K31: DA Phone | L31: TBD
B32: DA Ph. Ext. # | C32: ='[2]jobinfo(2)'!$C$32 -> 0 | D32: ='[2]jobinfo(2)'!$D$32 -> 0 | E32: ='[2]jobinfo(2)'!$E$32 -> 0 | F32: ='[2]jobinfo(2)'!$F$32 -> 0 | G32: ='[2]jobinfo(2)'!$G$32 -> 0 | H32: ='[2]jobinfo(2)'!$H$32 -> 0 | I32: ='[2]jobinfo(2)'!$I$32 -> 0 | J32: ='[2]jobinfo(2)'!$J$32 -> 0 | K32: DA Ph. Ext. # | L32: TBD
B33: DA Email | C33: ='[2]jobinfo(2)'!$C$33 -> claims@claims.allstate.com | D33: ='[2]jobinfo(2)'!$D$33 -> 0 | E33: ='[2]jobinfo(2)'!$E$33 -> 0 | F33: ='[2]jobinfo(2)'!$F$33 -> 0 | G33: ='[2]jobinfo(2)'!$G$33 -> 0 | H33: ='[2]jobinfo(2)'!$H$33 -> 0 | I33: ='[2]jobinfo(2)'!$I$33 -> 0 | J33: ='[2]jobinfo(2)'!$J$33 -> 0 | K33: DA Email | L33: TBD
B34: Field Adjuster Name | C34: ='[2]jobinfo(2)'!$C$34 -> TBD | D34: ='[2]jobinfo(2)'!$D$34 -> 0 | E34: ='[2]jobinfo(2)'!$E$34 -> 0 | F34: ='[2]jobinfo(2)'!$F$34 -> 0 | G34: ='[2]jobinfo(2)'!$G$34 -> 0 | H34: ='[2]jobinfo(2)'!$H$34 -> 0 | I34: ='[2]jobinfo(2)'!$I$34 -> 0 | J34: ='[2]jobinfo(2)'!$J$34 -> 0 | K34: Field Adjuster Name | L34: TBD
B35: Phone # field adj | C35: ='[2]jobinfo(2)'!$C$35 -> TBD | D35: ='[2]jobinfo(2)'!$D$35 -> 0 | E35: ='[2]jobinfo(2)'!$E$35 -> 0 | F35: ='[2]jobinfo(2)'!$F$35 -> 0 | G35: ='[2]jobinfo(2)'!$G$35 -> 0 | H35: ='[2]jobinfo(2)'!$H$35 -> 0 | I35: ='[2]jobinfo(2)'!$I$35 -> 0 | J35: ='[2]jobinfo(2)'!$J$35 -> 0 | K35: Phone # field adj | L35: TBD
B36: Field adj email | C36: ='[2]jobinfo(2)'!$C$36 -> TBD | D36: ='[2]jobinfo(2)'!$D$36 -> 0 | E36: ='[2]jobinfo(2)'!$E$36 -> 0 | F36: ='[2]jobinfo(2)'!$F$36 -> 0 | G36: ='[2]jobinfo(2)'!$G$36 -> 0 | H36: ='[2]jobinfo(2)'!$H$36 -> 0 | I36: ='[2]jobinfo(2)'!$I$36 -> 0 | J36: ='[2]jobinfo(2)'!$J$36 -> 0 | K36: Field adj email | L36: TBD
B37: adj contents | C37: ='[2]jobinfo(2)'!$C$37 -> TBD | D37: ='[2]jobinfo(2)'!$D$37 -> 0 | E37: ='[2]jobinfo(2)'!$E$37 -> 0 | F37: ='[2]jobinfo(2)'!$F$37 -> 0 | G37: ='[2]jobinfo(2)'!$G$37 -> 0 | H37: ='[2]jobinfo(2)'!$H$37 -> 0 | I37: ='[2]jobinfo(2)'!$I$37 -> 0 | J37: ='[2]jobinfo(2)'!$J$37 -> 0 | K37: adj contents | L37: TBD
B38: adj CPS phone # | C38: ='[2]jobinfo(2)'!$C$38 -> TBD | D38: ='[2]jobinfo(2)'!$D$38 -> 0 | E38: ='[2]jobinfo(2)'!$E$38 -> 0 | F38: ='[2]jobinfo(2)'!$F$38 -> 0 | G38: ='[2]jobinfo(2)'!$G$38 -> 0 | H38: ='[2]jobinfo(2)'!$H$38 -> 0 | I38: ='[2]jobinfo(2)'!$I$38 -> 0 | J38: ='[2]jobinfo(2)'!$J$38 -> 0 | K38: adj CPS phone # | L38: TBD
B39: adj CPS email | C39: ='[2]jobinfo(2)'!$C$39 -> TBD | D39: ='[2]jobinfo(2)'!$D$39 -> 0 | E39: ='[2]jobinfo(2)'!$E$39 -> 0 | F39: ='[2]jobinfo(2)'!$F$39 -> 0 | G39: ='[2]jobinfo(2)'!$G$39 -> 0 | H39: ='[2]jobinfo(2)'!$H$39 -> 0 | I39: ='[2]jobinfo(2)'!$I$39 -> 0 | J39: ='[2]jobinfo(2)'!$J$39 -> 0 | K39: adj CPS email | L39: TBD
B40: TMP adj | C40: ='[2]jobinfo(2)'!$C$40 -> TBD | D40: ='[2]jobinfo(2)'!$D$40 -> 0 | E40: ='[2]jobinfo(2)'!$E$40 -> 0 | F40: ='[2]jobinfo(2)'!$F$40 -> 0 | G40: ='[2]jobinfo(2)'!$G$40 -> 0 | H40: ='[2]jobinfo(2)'!$H$40 -> 0 | I40: ='[2]jobinfo(2)'!$I$40 -> 0 | J40: ='[2]jobinfo(2)'!$J$40 -> 0 | K40: TMP adj | L40: TBD
...

Sheet AOBOH
A1: =+'jobinfo(2)'!$C$100 -> All Phase Consulting, LLC
A2: =+'jobinfo(2)'!$C$103 -> 375 Rockbridge Road, Suite 172-343 | C2: Claim Number: | D2: ='jobinfo(2)'!$C$27 -> 0
A3: =+'jobinfo(2)'!$C$104 -> Lilburn, GA, 30047 | C3: =+'jobinfo(2)'!$C$110 -> Five Generations of Great Work
A4: ='jobinfo(2)'!$C$112 -> Joe Jones, PM 216.450.7228 | B4: ='jobinfo(2)'!$C$113 -> wsbjoe9@gmail.com | C4: =+'jobinfo(2)'!$C$111 -> Five Generations of Pride & Skills
A6: VIA ELECTRONIC MAIL TO (EMAIL ADDRESS) | C6: & PRIORITY MAIL WITH TRACKING
A8: ='jobinfo(2)'!B29 -> Email INS. co. | B8: ='jobinfo(2)'!C29 -> 0 | D8: ='jobinfo(2)'!B30 -> DESK Adjuster DA
A9: ='jobinfo(2)'!B26 -> Insurance Co. Name | B9: ='jobinfo(2)'!C26 -> Allstate Insurance Company | D9: ='jobinfo(2)'!C30 -> 0
A10: ='jobinfo(2)'!B48 -> Mailing address INS | B10: ='jobinfo(2)'!C48 -> TBD | C10: ='jobinfo(2)'!C33 -> claims@claims.allstate.com
A11: ='jobinfo(2)'!B49 -> Mail city, state, zip INS | B11: ='jobinfo(2)'!C49 -> TBD
A13: Re: | B13: ='jobinfo(2)'!C11 -> WATER | D13: Date of Loss:
A14: ='jobinfo(2)'!B27 -> Claim # | B14: ='jobinfo(2)'!C27 -> 0 | C14: ='jobinfo(2)'!C4 -> tringo68@yahoo.com | D14: ='jobinfo(2)'!C12 -> Friday, April 4, 2025
A15: Insured: | B15: ='jobinfo(2)'!C1 -> Johnson, Paul & Tamra | C15: ='jobinfo(2)'!C5 -> (216) 399-6191 | D15: POLICY NUMBER
A16: Property Address: | B16: ='jobinfo(2)'!C2 -> 9402 Shepard Road | C16: ='jobinfo(2)'!C3 -> Macedonia, OH, USA | D16: ='jobinfo(2)'!C28 -> 0
A18: REQUEST FOR INSURANCE INFORMATION AND NOTICE OF POST-LOSS ASSIGNMENT OF INSURANCE RIGHTS
A20: Dear Adjuster, | C20: ='jobinfo(2)'!C30 -> 0
A22: Please take notice that | C22: ='jobinfo(2)'!C100 -> All Phase Consulting, LLC
A23: was engaged to perform work at your insured's property on the date of: | D23: =D14 -> Friday, April 4, 2025
A24: to address the damage sustained in the above­ referenced loss.
A25: Our scope of work is described in the enclosed contract.
A27: Enclosed, please find an Insurance Information Release and Authorization executed by the policyholder. It includes a waiver of the policyholder's right to privacy as to the portion of the claim that relates to our scope of work and irrevocably directs you to release the following documents and information to us. Therefore, please immediately confirm in writing that you will provide the following:
A28: (1) A complete certified copy of the policy packet (including declarations, policy provisions, …........... and endorsements);
A30: (2) All information and documentation regarding this property damage claim, including status reports, letters, emails, estimates, competitive bids, and correspondence from consultants and independent adjusters engaged by the insurance company; and
A32: (3) "CC:" us on all such future correspondence for the duration of the claim.
A34: Transmit all documents by email to [address #1] | C34: ='jobinfo(2)'!C113 -> wsbjoe9@gmail.com
A36: and cc: [address #2, for redundancy]. | C36: ='jobinfo(2)'!C103 -> 375 Rockbridge Road, Suite 172-343
C37: ='jobinfo(2)'!C104 -> Lilburn, GA, 30047
A39: After the loss occurred, the insured ("Policyholder") irrevocably transferred and assigned to us all rights and policy benefits for claims for the damage we were hired to address, pursuant to the enclosed, fully-executed and enforceable post-loss Assignment of Insurance Rights and Direction to Pay ("Assignment"). Also enclosed is a copy of the Contract executed by your insured, and an irrevocable Information Release and Authorization.
A41: In pertinent part, the Assignment states:
A42: 1. Irrevocable Post-Loss Assignment of Policyholders' Rights Against Insurance Company To Contractor: By execution of this irrevocable Post-Loss Assignment of Insurance Rights and Direction of Pay ("Assignment"), the policyholder(s) identified above ("Policyholders") completely, irrevocably, and fully assign and transfer to the Contractor named above all of the Policyholders' legal and equitable rights, title, and interest under all insurance policies arising from claims for the damage Contractor was hired to address (collectively referred to as the "Assigned Rights"). The Assigned Rights include without limitation the rights to collect insurance policy benefits and proceeds, and the right but not the obligation to participate in appraisal of the loss or the portion of the loss in which Contractor is involved. The Assigned Rights include without limitation the Policyholders' rights as a first-party insured under the Policyholders' policy of insurance, the right to sue the insurance company to enforce the Assigned Rights, and to prosecute any applicable causes of action for breach of contract, breach of the implied covenant of good faith and fair dealing (insurance bad faith), fraud, and negligence. This Assignment shall be liberally construed to the fullest extent permitted by law and so that Contractor is deemed to stand in a first party position as to the policies. The Policyholders shall remain obligated with respect to all duties and liabilities under the terms of the insurance policies, including the duty to properly document all claims and cooperate with the insurer's investigation. Contractor owes none of those duties. This Assignment may only be revoked by written notice to the Contractor after the contract is terminated in writing, but is permanently irrevocable as to work performed before the contract is terminated.
A43: 2. Exclusions: Nothing in this Assignment shall be construed as an assignment of other parts of the insurance claim that are unrelated to Contractor's scope of work, such as additional living expenses, personal property, or services performed after Contractor's services are terminated. Nothing in this Assignment shall be construed as a delegation of duties.
A44: 3. No Conditions: The Policyholders agree and understand that this Assignment and each of its component parts are irrevocable. The Policyholders expressly acknowledge that it is the Policyholders' intent to assign the Policyholders' insurance policy rights and benefits under the claims to the Contractor as explained above. The Policyholders agree and understand that this irrevocable Assignment is unconditional and effective immediately upon execution of this document, and that no further action needs to be taken to make it valid, enforceable, or binding upon the Policyholders and the Policyholders' insurance company.
A45: 4. Cooperation: The Policyholders shall cooperate fully with Contractor's efforts to enforce the Assigned rights, and to collect policy benefits. Policyholders agree to execute any and all documents presented by Contractor to the Policyholders, which are reasonably required for the prosecution of Contractor's claims against the Policyholders' insurance company and/or its agents with respect to the Assigned Rights.
A46: 5. Direction to Pay: The Policyholders hereby authorize and instruct all insurance carriers who may be liable to the Policyholders for this loss in whole or in part to pay directly to Contractor the amounts due or to become due in connection with the work Contractor has been authorized to perform, and to deliver said payments directly and exclusively to Contractor within fifteen (15) calendar days of the invoice. In the event an insurer fails to name Contractor on any check for the Work, the Policyholders shall immediately notify Contractor in writing, and return the check to the insurer with a written request to the insurer to issue a replacement check payable to Contractor.
A47: 6. Security and Consideration: This Assignment is given to Contractor as security and is made in consideration for Contractor's agreement to perform services without immediate full payment from the Policyholders upon completion of services. The Policyholders acknowledge the sufficiency of this consideration.
A48: ALL PHASE CONSULTING, LLC hereby tenders the insured's assignment of the Assigned Rights, which we received as security.
A49: As assignee of the policy benefits, we step into the shoes of the insured and hold legal title to all rights for policy benefits paid pursuant to the Assigned Rights. Since this is a post-loss assignment, it is valid and enforceable. Therefore, all insurers with applicable coverage are bound by the Assignment, and we now stand in a first party position as to this portion of the claim.
A50: It is important to emphasize that this is not an assignment of the entire policy; it is merely a post-loss assignment of rights and benefits arising from a specific loss. The anti­ assignment provision in the policy only applies to pre-loss assignments of the policy.
A51: An assignment is a transfer of property or of some right or interest from one person to another that causes the property, right, or interest to vest in the other person. Ford Motor Credit Co. v. Ryan, 2010-Ohio-4601, ii 89, 189 Ohio App. 3d 560,598,939 N.E.2d 891,920
... A61: Very truly yours,
A62: .All Phase Consulting, LLC | B62: ='jobinfo(2)'!C100 -> All Phase Consulting, LLC
...

Sheet AOBGA
A1: =+'jobinfo(2)'!$C$100 -> All Phase Consulting, LLC
A2: =+'jobinfo(2)'!$C$103 -> 375 Rockbridge Road, Suite 172-343 | C2: Claim Number: | D2: ='jobinfo(2)'!$C$27 -> 0
A3: =+'jobinfo(2)'!$C$104 -> Lilburn, GA, 30047 | C3: =+'jobinfo(2)'!$C$110 -> Five Generations of Great Work
A4: ='jobinfo(2)'!$C$112 -> Joe Jones, PM 216.450.7228 | B4: ='jobinfo(2)'!$C$113 -> wsbjoe9@gmail.com | C4: =+'jobinfo(2)'!$C$111 -> Five Generations of Pride & Skills
A6: VIA ELECTRONIC MAIL TO (EMAIL ADDRESS) | C6: & PRIORITY MAIL WITH TRACKING
A8: ='jobinfo(2)'!B29 -> Email INS. co. | B8: ='jobinfo(2)'!C29 -> 0 | D8: ='jobinfo(2)'!B30 -> DESK Adjuster DA
A9: ='jobinfo(2)'!B26 -> Insurance Co. Name | B9: ='jobinfo(2)'!C26 -> Allstate Insurance Company | D9: ='jobinfo(2)'!C30 -> 0
A10: ='jobinfo(2)'!B48 -> Mailing address INS | B10: ='jobinfo(2)'!C48 -> TBD
A11: ='jobinfo(2)'!B49 -> Mail city, state, zip INS | B11: ='jobinfo(2)'!C49 -> TBD
A13: Re: | B13: ='jobinfo(2)'!C11 -> WATER | D13: Date of Loss:
A14: ='jobinfo(2)'!B27 -> Claim # | B14: ='jobinfo(2)'!C27 -> 0 | D14: ='jobinfo(2)'!C12 -> Friday, April 4, 2025
A15: Insured: | B15: ='jobinfo(2)'!C1 -> Johnson, Paul & Tamra | C15: ='jobinfo(2)'!C6 -> TBD | D15: POLICY NUMBER
A16: Property Address: | B16: ='jobinfo(2)'!C2 -> 9402 Shepard Road | C16: ='jobinfo(2)'!C3 -> Macedonia, OH, USA | D16: ='jobinfo(2)'!C28 -> 0
A18: REQUEST FOR INSURANCE INFORMATION AND NOTICE OF POST-LOSS ASSIGNMENT OF INSURANCE RIGHTS
A20: Dear Adjuster, | C20: ='jobinfo(2)'!C30 -> 0
A21: Please take notice that | C21: ='jobinfo(2)'!C100 -> All Phase Consulting, LLC
A22: was engaged to perform work at your insured's property on the date of: | D22: =D14 -> Friday, April 4, 2025
A23: to address the damage sustained in the above­ referenced loss.
A24: Our scope of work is described in the enclosed ESTIMATE & contract.
A26: Enclosed, please find an Insurance Information Release and Authorization executed by the policyholder. It includes a waiver of the policyholder's right to privacy as to the portion of the claim that relates to our scope of work and irrevocably directs you to release the following documents and information to us. Therefore, please immediately confirm in writing that you will provide the following:
A27: (1) A complete certified copy of the policy packet (including declarations, policy provisions, …........... and endorsements);
A29: (2) All information and documentation regarding this property damage claim, including status reports, letters, emails, estimates, competitive bids, and correspondence from consultants and independent adjusters engaged by the insurance company; and
A31: (3) "CC:" us on all such future correspondence for the duration of the claim.
A33: Transmit all documents by email to [address #1] | C33: ='jobinfo(2)'!C113 -> wsbjoe9@gmail.com
A35: and cc: [address #2, for redundancy]. | C35: ='jobinfo(2)'!C103 -> 375 Rockbridge Road, Suite 172-343
C36: ='jobinfo(2)'!C104 -> Lilburn, GA, 30047
A38: After the loss occurred, the insured ("Policyholder") irrevocably transferred and assigned to us all rights and policy benefits for claims for the damage we were hired to address, pursuant to the enclosed, fully-executed and enforceable post-loss Assignment of Insurance Rights and Direction to Pay ("Assignment"). Also enclosed is a copy of the Contract executed by your insured, and an irrevocable Information Release and Authorization.
A40: In pertinent part, the Assignment states:
A41: 1. Irrevocable Post-Loss Assignment of Policyholders' Rights Against Insurance Company To Contractor: By execution of this irrevocable Post-Loss Assignment of Insurance Rights and Direction of Pay ("Assignment"), the policyholder(s) identified above ("Policyholders") completely, irrevocably, and fully assign and transfer to the Contractor named above all of the Policyholders' legal and equitable rights, title, and interest under all insurance policies arising from claims for the damage Contractor was hired to address (collectively referred to as the "Assigned Rights"). The Assigned Rights include without limitation the rights to collect insurance policy benefits and proceeds, and the right but not the obligation to participate in appraisal of the loss or the portion of the loss in which Contractor is involved. The Assigned Rights include without limitation the Policyholders' rights as a first-party insured under the Policyholders' policy of insurance, the right to sue the insurance company to enforce the Assigned Rights, and to prosecute any applicable causes of action for breach of contract, breach of the implied covenant of good faith and fair dealing (insurance bad faith), fraud, and negligence. This Assignment shall be liberally construed to the fullest extent permitted by law and so that Contractor is deemed to stand in a first party position as to the policies. The Policyholders shall remain obligated with respect to all duties and liabilities under the terms of the insurance policies, including the duty to properly document all claims and cooperate with the insurer's investigation. Contractor owes none of those duties. This Assignment may only be revoked by written notice to the Contractor after the contract is terminated in writing, but is permanently irrevocable as to work performed before the contract is terminated.
A42: 2. Exclusions: Nothing in this Assignment shall be construed as an assignment of other parts of the insurance claim that are unrelated to Contractor's scope of work, such as additional living expenses, personal property, or services performed after Contractor's services are terminated. Nothing in this Assignment shall be construed as a delegation of duties.
A43: 3. No Conditions: The Policyholders agree and understand that this Assignment and each of its component parts are irrevocable. The Policyholders expressly acknowledge that it is the Policyholders' intent to assign the Policyholders' insurance policy rights and benefits under the claims to the Contractor as explained above. The Policyholders agree and understand that this irrevocable Assignment is unconditional and effective immediately upon execution of this document, and that no further action needs to be taken to make it valid, enforceable, or binding upon the Policyholders and the Policyholders' insurance company.
A44: 4. Cooperation: The Policyholders shall cooperate fully with Contractor's efforts to enforce the Assigned rights, and to collect policy benefits. Policyholders agree to execute any and all documents presented by Contractor to the Policyholders, which are reasonably required for the prosecution of Contractor's claims against the Policyholders' insurance company and/or its agents with respect to the Assigned Rights.
A45: 5. Direction to Pay: The Policyholders hereby authorize and instruct all insurance carriers who may be liable to the Policyholders for this loss in whole or in part to pay directly to Contractor the amounts due or to become due in connection with the work Contractor has been authorized to perform, and to deliver said payments directly and exclusively to Contractor within fifteen (15) calendar days of the invoice. In the event an insurer fails to name Contractor on any check for the Work, the Policyholders shall immediately notify Contractor in writing, and return the check to the insurer with a written request to the insurer to issue a replacement check payable to Contractor.
A46: 6. Security and Consideration: This Assignment is given to Contractor as security and is made in consideration for Contractor's agreement to perform services without immediate full payment from the Policyholders upon completion of services. The Policyholders acknowledge the sufficiency of this consideration.
A47: ALL PHASE CONSULTING, LLC hereby tenders the insured's assignment of the Assigned Rights, which we received as security.
A48: As assignee of the policy benefits, we step into the shoes of the insured and hold legal title to all rights for policy benefits paid pursuant to the Assigned Rights. Since this is a post-loss assignment, it is valid and enforceable. Therefore, all insurers with applicable coverage are bound by the Assignment, and we now stand in a first party position as to this portion of the claim.
A49: It is important to emphasize that this is not an assignment of the entire policy; it is merely a post-loss assignment of rights and benefits arising from a specific loss. The anti­ assignment provision in the policy only applies to pre-loss assignments of the policy.
A50: A policy may be assignable or not assignable, as provided by its terms. Subject to its terms relating to assignability, any life or accident and sickness policy issued under the terms of which the beneficiary may be changed upon the sole request of the policy owner may be assigned either by pledge or by transfer of title by an assignment executed by the policy owner alone and delivered to the insurer, whether or not the pledgee or assignee is the insurer. Any assignment shall entitle the insurer to deal with the assignee as the owner or pledgee of the policy in accordance with the terms of the assignment until the insurer has received at its home office written notice of termination of the assignment or pledge or written notice by or on behalf of some other person claiming some interest in the policy in conflict with the assignment. Ga. Code Ann., § 33-24-17.
... A56: If you have any questions, please do not hesitate to call. We thank you in advance for the documents and information listed on the first page of this letter. We look forward to working cooperatively with you for a smooth and expeditious resolution of this claim. Thank you.
A57: Very truly yours, | C57: ='jobinfo(2)'!C100 -> All Phase Consulting, LLC
...

Sheet SUB MIT
A1: ** GENERAL AUTHORIZATION ** | E1: OWNER HEREBY SPECIFICALLY REQUESTS THAT EMS Mitigation & CPS Packout / Cleaning of
A2: =+'jobinfo(2)'!$C$100 -> All Phase Consulting, LLC | E2: Personal Property (ONLY) PAYMENTS ; REBUILD Items Excluded: PAYMENTS BE PAID TO:
A3: =+'jobinfo(2)'!C$109 -> Providing Cost Estimating & Project Management Services
A4: =+'jobinfo(2)'!$C$101 -> WWW.MYAPCLLC.COM | C4: =+'jobinfo(2)'!$C$102 -> Insured & GA Registered #09073201
A5: ='jobinfo(2)'!$C$107 -> 20810 AURORA RD | B5: =+'jobinfo(2)'!$C$103 -> 375 Rockbridge Road, Suite 172-343 | D5: =+'jobinfo(2)'!$C$105 -> ECI 531 FIFTH AVE,
A6: ='jobinfo(2)'!$C$108 -> BEDFORD,OH 44146 | B6: =+'jobinfo(2)'!$C$104 -> Lilburn, GA, 30047 | D6: =+'jobinfo(2)'!$C$106 -> PELHAM, NY 10803
A7: =+'jobinfo(2)'!$C$110 -> Five Generations of Great Work | C7: =+'jobinfo(2)'!$C$111 -> Five Generations of Pride & Skills
A8: COMPANY REP. | B8: =+'jobinfo(2)'!$C$112 -> Joe Jones, PM 216.450.7228 | C8: =+'jobinfo(2)'!$C$113 -> wsbjoe9@gmail.com
A9: COMPANY REP. #2 | B9: =+'jobinfo(2)'!$C$114 -> 404-446-9060 | C9: =+'jobinfo(2)'!$C$115 -> info@myapcllc.com
A10: Claim # | B10: ='jobinfo(2)'!$C$27 -> 0 | C10: Cst-owner Phone# | D10: ='jobinfo(2)'!$C$5 -> (216) 399-6191
A11: =+'jobinfo(2)'!$B$1 -> Property-Owner Name | B11: =+'jobinfo(2)'!C$1 -> Johnson, Paul & Tamra | C11: Customer Email | D11: ='jobinfo(2)'!$C$4 -> tringo68@yahoo.com
A12: =+'jobinfo(2)'!$B$2 -> Property address: street | B12: =+'jobinfo(2)'!$C$2 -> 9402 Shepard Road | C12: Co-Owner.cst#2 | D12: =+'jobinfo(2)'!$C$6 -> TBD
A13: =+'jobinfo(2)'!$B$3 -> Property city, state, zip | B13: =+'jobinfo(2)'!$C$3 -> Macedonia, OH, USA | C13: cst ph # 2 | D13: =+'jobinfo(2)'!$C$7 -> TBD
A14: =+'jobinfo(2)'!$B$26 -> Insurance Co. Name | B14: =+'jobinfo(2)'!$C$26 -> Allstate Insurance Company | C14: =+'jobinfo(2)'!$B$28 -> policy # | D14: =+'jobinfo(2)'!$C$27 -> 0
A15: =+'jobinfo(2)'!$B$46 -> Insurance Co. Phone | B15: =+'jobinfo(2)'!$C$46 -> (800) 255-7828 | C15: =+'jobinfo(2)'!$C$29 -> 0
A16: =+'jobinfo(2)'!$B$30 -> DESK Adjuster DA | B16: =+'jobinfo(2)'!$C$30 -> 0 | C16: =+'jobinfo(2)'!$B$33 -> DA Email | D16: =+'jobinfo(2)'!$C$33 -> claims@claims.allstate.com
A17: =+'jobinfo(2)'!$B$31 -> DA Phone | B17: =+'jobinfo(2)'!$C$31 -> 888 656.8005 | C17: =+'jobinfo(2)'!$B$32 -> DA Ph. Ext. # | D17: =+'jobinfo(2)'!$C$32 -> 0
A20: Dear Insurance Company/ Mortgage Company and or To Whom It May Concern:
A21: The undersigned property owner agrees to employ | C21: =+$A$2 -> All Phase Consulting, LLC
A22: to assist in the repair of the above mentioned property that was damaged by
A23: =IF(ISBLANK('jobinfo(2)'!C11),"____________________",'jobinfo(2)'!C11) -> WATER | C23: on or about (date). | D23: =IF(ISBLANK('jobinfo(2)'!C12),"__________________________________",'jobinfo(2)'!C12) -> Friday, April 4, 2025
A24: Owners ACKNOWLEDGE as party of interest; | C24: =C21 -> All Phase Consulting, LLC
A25: and will be noted as such on all drafts, correspondence, and communications between the owner, insurer and my mortgage company. I hereby authorize all parties to discuss my account as it relates to the above noted loss and or repairs; as well as the release of draws for all repairs. This applies in full to it's employees / assigns / representatives.
A28: OWNER HEREBY SPECIFICALLY REQUESTS THAT EMS Mitigation & CPS Packout / Cleaning of | E28: EMS Mitigation & CPS Packout/Cleaning (ONLY) PAYMENTS BE PAID TO; REBUILD Items Excluded:
A29: Personal Property (ONLY) PAYMENTS ; REBUILD Items Excluded: PAYMENTS BE PAID TO:
A30: =+$C$24 -> All Phase Consulting, LLC | C30: =+'email cvr'!A13 -> EIN # | D30: =+'email cvr'!B13 -> TIN 83-226 0563
A31: X___________________________________ _____________ | C31: X_ _________________________________ _____________ | D31: =+'jobinfo(2)'!C22 -> Friday, April 4, 2025
A32: =IF(ISBLANK('jobinfo(2)'!C1),"__Property owner Signature________________________________",'jobinfo(2)'!C1) -> Johnson, Paul & Tamra | C32: =IF(ISBLANK('jobinfo(2)'!C6),"co-owner Signature______________________________",'jobinfo(2)'!C6) -> TBD
A34: =+$A$185 -> COMPANY REP. | B34: =+B66 -> Joe Jones, PM 216.450.7228 | D34: =+D66 -> wsbjoe9@gmail.com
A35: EMERGENCY SERVICES WORK AUTHORIZATION
A36: =+$A$2 -> All Phase Consulting, LLC
A37: =+A3 -> Providing Cost Estimating & Project Management Services | C37: =+$A$99 -> WWW.MYAPCLLC.COM
A39: =+A5 -> 20810 AURORA RD | B39: =+B5 -> 375 Rockbridge Road, Suite 172-343 | D39: =+D5 -> ECI 531 FIFTH AVE,
A40: =+A6 -> BEDFORD,OH 44146 | B40: =+B6 -> Lilburn, GA, 30047 | D40: =+D6 -> PELHAM, NY 10803
C41: =+$C$103 -> wsbjoe9@gmail.com
A42: =+A8 -> COMPANY REP. | B42: =+B34 -> Joe Jones, PM 216.450.7228 | C42: =+$D$185 -> wsbjoe9@gmail.com
A43: Claim Number: | B43: =+'jobinfo(2)'!C27 -> 0 | C43: =+B14 -> Allstate Insurance Company
A44: =+'jobinfo(2)'!B1 -> Property-Owner Name | B44: =+'jobinfo(2)'!C1 -> Johnson, Paul & Tamra | C44: =+A15 -> Insurance Co. Phone | D44: ='jobinfo(2)'!C31 -> 888 656.8005
A45: =+'jobinfo(2)'!B2 -> Property address: street | B45: =+'jobinfo(2)'!C2 -> 9402 Shepard Road
A46: =+'jobinfo(2)'!B3 -> Property city, state, zip | B46: =+'jobinfo(2)'!C3 -> Macedonia, OH, USA | C46: =+'jobinfo(2)'!B11 -> Cause of Loss | D46: =+A23 -> WATER
...

Sheet SUBC
A1: ** GENERAL AUTHORIZATION ** | E1: OWNER HEREBY SPECIFICALLY REQUESTS THAT EMS Mitigation & CPS Packout / Cleaning of
A2: =+'jobinfo(2)'!$C$100 -> All Phase Consulting, LLC | E2: Personal Property (ONLY) PAYMENTS ; REBUILD Items Excluded: PAYMENTS BE PAID TO:
A3: =+'jobinfo(2)'!C$109 -> Providing Cost Estimating & Project Management Services
A4: =+'jobinfo(2)'!$C$101 -> WWW.MYAPCLLC.COM | C4: =+'jobinfo(2)'!$C$102 -> Insured & GA Registered #09073201
A5: ='jobinfo(2)'!$C$107 -> 20810 AURORA RD | B5: =+'jobinfo(2)'!$C$103 -> 375 Rockbridge Road, Suite 172-343 | D5: =+'jobinfo(2)'!$C$105 -> ECI 531 FIFTH AVE,
A6: ='jobinfo(2)'!$C$108 -> BEDFORD,OH 44146 | B6: =+'jobinfo(2)'!$C$104 -> Lilburn, GA, 30047 | D6: =+'jobinfo(2)'!$C$106 -> PELHAM, NY 10803
A7: =+'jobinfo(2)'!$C$110 -> Five Generations of Great Work | C7: =+'jobinfo(2)'!$C$111 -> Five Generations of Pride & Skills
A8: COMPANY REP. | B8: =+'jobinfo(2)'!$C$112 -> Joe Jones, PM 216.450.7228 | C8: =+'jobinfo(2)'!$C$113 -> wsbjoe9@gmail.com
A9: COMPANY REP. #2 | B9: =+'jobinfo(2)'!$C$114 -> 404-446-9060 | C9: =+'jobinfo(2)'!$C$115 -> info@myapcllc.com
A10: Claim # | B10: ='jobinfo(2)'!$C$27 -> 0 | C10: Cst-owner Phone# | D10: ='jobinfo(2)'!$C$5 -> (216) 399-6191
A11: =+'jobinfo(2)'!$B$1 -> Property-Owner Name | B11: =+'jobinfo(2)'!C$1 -> Johnson, Paul & Tamra | C11: Customer Email | D11: ='jobinfo(2)'!$C$4 -> tringo68@yahoo.com
A12: =+'jobinfo(2)'!$B$2 -> Property address: street | B12: =+'jobinfo(2)'!$C$2 -> 9402 Shepard Road | C12: Co-Owner.cst#2 | D12: =+'jobinfo(2)'!$C$6 -> TBD
A13: =+'jobinfo(2)'!$B$3 -> Property city, state, zip | B13: =+'jobinfo(2)'!$C$3 -> Macedonia, OH, USA | C13: cst ph # 2 | D13: =+'jobinfo(2)'!$C$7 -> TBD
A14: =+'jobinfo(2)'!$B$26 -> Insurance Co. Name | B14: =+'jobinfo(2)'!$C$26 -> Allstate Insurance Company | C14: =+'jobinfo(2)'!$B$28 -> policy # | D14: =+'jobinfo(2)'!$C$27 -> 0
A15: =+'jobinfo(2)'!$B$46 -> Insurance Co. Phone | B15: =+'jobinfo(2)'!$C$46 -> (800) 255-7828 | C15: =+'jobinfo(2)'!$C$29 -> 0
A16: =+'jobinfo(2)'!$B$30 -> DESK Adjuster DA | B16: =+'jobinfo(2)'!$C$30 -> 0 | C16: =+'jobinfo(2)'!$B$33 -> DA Email | D16: =+'jobinfo(2)'!$C$33 -> claims@claims.allstate.com
A17: =+'jobinfo(2)'!$B$31 -> DA Phone | B17: =+'jobinfo(2)'!$C$31 -> 888 656.8005 | C17: =+'jobinfo(2)'!$B$32 -> DA Ph. Ext. # | D17: =+'jobinfo(2)'!$C$32 -> 0
A20: Dear Insurance Company/ Mortgage Company and or To Whom It May Concern:
A21: The undersigned property owner agrees to employ | C21: =+$A$2 -> All Phase Consulting, LLC
A22: to assist in the repair of the above mentioned property that was damaged by
A23: =IF(ISBLANK('jobinfo(2)'!C11),"____________________",'jobinfo(2)'!C11) -> WATER | C23: on or about (date). | D23: =IF(ISBLANK('jobinfo(2)'!C12),"__________________________________",'jobinfo(2)'!C12) -> Friday, April 4, 2025
A24: Owners ACKNOWLEDGE as party of interest; | C24: =C21 -> All Phase Consulting, LLC
A25: and will be noted as such on all drafts, correspondence, and communications between the owner, insurer and my mortgage company. I hereby authorize all parties to discuss my account as it relates to the above noted loss and or repairs; as well as the release of draws for all repairs. This applies in full to it's employees / assigns / representatives.
A28: OWNER HEREBY SPECIFICALLY REQUESTS THAT EMS Mitigation & CPS Packout / Cleaning of | E28: EMS Mitigation & CPS Packout/Cleaning (ONLY) PAYMENTS BE PAID TO; REBUILD Items Excluded:
A29: Personal Property (ONLY) PAYMENTS ; PAYMENTS BE PAID TO REBUILD Items Excluded::
A30: =+$C$24 -> All Phase Consulting, LLC | C30: =+'email cvr'!A13 -> EIN # | D30: =+'email cvr'!B13 -> TIN 83-226 0563
A31: X___________________________________ _____________ | C31: X_ _________________________________ _____________ | D31: =+'jobinfo(2)'!C22 -> Friday, April 4, 2025
A32: =IF(ISBLANK('jobinfo(2)'!C1),"__Property owner Signature________________________________",'jobinfo(2)'!C1) -> Johnson, Paul & Tamra | C32: =IF(ISBLANK('jobinfo(2)'!C6),"co-owner Signature______________________________",'jobinfo(2)'!C6) -> TBD
A34: =+$A$185 -> COMPANY REP. | B34: =+B66 -> Joe Jones, PM 216.450.7228 | D34: =+D66 -> wsbjoe9@gmail.com
A35: EMERGENCY SERVICES WORK AUTHORIZATION
A36: =+$A$2 -> All Phase Consulting, LLC
A37: =+A3 -> Providing Cost Estimating & Project Management Services | C37: =+$A$99 -> WWW.MYAPCLLC.COM
A39: =+A5 -> 20810 AURORA RD | B39: =+B5 -> 375 Rockbridge Road, Suite 172-343 | D39: =+D5 -> ECI 531 FIFTH AVE,
A40: =+A6 -> BEDFORD,OH 44146 | B40: =+B6 -> Lilburn, GA, 30047 | D40: =+D6 -> PELHAM, NY 10803
C41: =+$C$103 -> wsbjoe9@gmail.com
A42: =+A8 -> COMPANY REP. | B42: =+B34 -> Joe Jones, PM 216.450.7228 | C42: =+$D$185 -> wsbjoe9@gmail.com
A43: Claim Number: | B43: =+'jobinfo(2)'!C27 -> 0 | C43: =+B14 -> Allstate Insurance Company
A44: =+'jobinfo(2)'!B1 -> Property-Owner Name | B44: =+'jobinfo(2)'!C1 -> Johnson, Paul & Tamra | C44: =+A15 -> Insurance Co. Phone | D44: ='jobinfo(2)'!C31 -> 888 656.8005
A45: =+'jobinfo(2)'!B2 -> Property address: street | B45: =+'jobinfo(2)'!C2 -> 9402 Shepard Road
A46: =+'jobinfo(2)'!B3 -> Property city, state, zip | B46: =+'jobinfo(2)'!C3 -> Macedonia, OH, USA | C46: =+'jobinfo(2)'!B11 -> Cause of Loss | D46: =+A23 -> WATER
...

Sheet signpgs (3)
A1: ** GENERAL AUTHORIZATION ** | E1: OWNER HEREBY SPECIFICALLY REQUESTS THAT ALL Payments for the Rebuild BE PAID TO: Owner & Contractor
A2: =+'jobinfo(2)'!$C$100 -> All Phase Consulting, LLC
A3: =+'jobinfo(2)'!C$109 -> Providing Cost Estimating & Project Management Services
A4: =+'jobinfo(2)'!$C$101 -> WWW.MYAPCLLC.COM | C4: =+'jobinfo(2)'!$C$102 -> Insured & GA Registered #09073201
A5: ='jobinfo(2)'!$C$107 -> 20810 AURORA RD | B5: =+'jobinfo(2)'!$C$103 -> 375 Rockbridge Road, Suite 172-343 | D5: =+'jobinfo(2)'!$C$105 -> ECI 531 FIFTH AVE,
A6: ='jobinfo(2)'!$C$108 -> BEDFORD,OH 44146 | B6: =+'jobinfo(2)'!$C$104 -> Lilburn, GA, 30047 | D6: =+'jobinfo(2)'!$C$106 -> PELHAM, NY 10803
A7: =+'jobinfo(2)'!$C$110 -> Five Generations of Great Work | C7: =+'jobinfo(2)'!$C$111 -> Five Generations of Pride & Skills
A8: COMPANY REP. | B8: =+'jobinfo(2)'!$C$112 -> Joe Jones, PM 216.450.7228 | C8: =+'jobinfo(2)'!$C$113 -> wsbjoe9@gmail.com
A9: COMPANY REP. #2 | B9: =+'jobinfo(2)'!$C$114 -> 404-446-9060 | C9: =+'jobinfo(2)'!$C$115 -> info@myapcllc.com
A10: Claim # | B10: ='jobinfo(2)'!$C$27 -> 0 | C10: Cst-owner Phone# | D10: ='jobinfo(2)'!$C$5 -> (216) 399-6191
A11: =+'jobinfo(2)'!$B$1 -> Property-Owner Name | B11: =+'jobinfo(2)'!C$1 -> Johnson, Paul & Tamra | C11: Customer Email | D11: ='jobinfo(2)'!$C$4 -> tringo68@yahoo.com
A12: =+'jobinfo(2)'!$B$2 -> Property address: street | B12: =+'jobinfo(2)'!$C$2 -> 9402 Shepard Road | C12: Co-Owner.cst#2 | D12: =+'jobinfo(2)'!$C$6 -> TBD
A13: =+'jobinfo(2)'!$B$3 -> Property city, state, zip | B13: =+'jobinfo(2)'!$C$3 -> Macedonia, OH, USA | C13: cst ph # 2 | D13: =+'jobinfo(2)'!$C$7 -> TBD
A14: =+'jobinfo(2)'!$B$26 -> Insurance Co. Name | B14: =+'jobinfo(2)'!$C$26 -> Allstate Insurance Company | C14: =+'jobinfo(2)'!$B$28 -> policy # | D14: =+'jobinfo(2)'!$C$27 -> 0
