Workbook
Name a...new_customer: '[1]input data'!$A$1:$D$45
Name Column.a.new.cst: '[1]input data'!$A$2:$A$45
Name culpepper: #REF!
Name data: [2]QUOTE!$A$267:$R$424
Name Document_Stacking_List: #REF!
Name Enter_new_cst_data: #REF!
Name Jefferies: #REF!
Name LOVEJOY_INTERIOR: #REF!
Name Lovejoy_ROOF: #REF!
Name LxWxH: [2]QUOTE!#REF!
Name new_customer: '[1]cst list'!$B$32:$B$65
Name PRICE_P: #REF!
Name Robinson: #REF!
Name sigtj: "Picture 9859"
Name SubContractor_Summary: #REF!
Name Wayside_Builders__LLC_…...OH: '[1]co name'!$D$21
Name WSB...GA.Wayside_Builders__LLC……GA: '[1]co name'!$D$38

Sheet email cvr
A1: This may seem like a lot of information; because it is a lot of information.
A2: Yet, it is the level of estimates/documentation required to substantiate the restoration process fully.
A3: It is also what separates us from many others. | C3: =+'jobinfo(2)'!$B$27 -> Claim # | D3: =+'jobinfo(2)'!$C$27 -> 3571C126N
A6: =+'jobinfo(2)'!C100 -> All Phase Consulting, LLC
A7: =+'jobinfo(2)'!C101 -> WWW.MYAPCLLC.COM | C7: =+'jobinfo(2)'!C102 -> Insured & GA Registered #09073201
A8: =+'jobinfo(2)'!C105 -> ECI 531 FIFTH AVE, | B8: =+'jobinfo(2)'!C103 -> 375 Rockbridge Road, Suite 172-343 | D8: =+'jobinfo(2)'!C107 -> 20810 Aurora Rd
A9: =+'jobinfo(2)'!C106 -> PELHAM, NY 10803 | B9: =+'jobinfo(2)'!C104 -> Lilburn, GA, 30047 | D9: =+'jobinfo(2)'!C108 -> Bedford, OH 44146
A11: =+'jobinfo(2)'!C109 -> Providing Cost Estimating & Project Management Services
A12: =+'jobinfo(2)'!C111 -> Five Generations of Pride & Skills | C12: =+'jobinfo(2)'!C110 -> Five Generations of Great Work
A13: COMPANY REP. | B13: =+'jobinfo(2)'!C112 -> Joe Jones, PM 216.450.7228 | C13: =+'jobinfo(2)'!C113 -> wsbjoe9@gmail.com
A14: COMPANY REP. #2 | B14: =+'jobinfo(2)'!C114 -> 404-446-9060 | C14: =+'jobinfo(2)'!C115 -> info@myapcllc.com
A15: EIN # | B15: =+'jobinfo(2)'!C116 -> TIN 83-226 0563 | C15: FEDEX# | D15: 9836-2151-1
A17: Re: Initial Documents Processing; Notary pages
A18: =+'jobinfo(2)'!B1 -> Property-Owner Name | B18: =+'jobinfo(2)'!C1 -> Hendking, Anthony&Carlena | C18: =+'jobinfo(2)'!B5 -> Cst-owner Phone# | D18: =+'jobinfo(2)'!C5 -> 2166819181
A19: =+'jobinfo(2)'!B2 -> Property address: street | B19: =+'jobinfo(2)'!C2 -> 3806 Meadowbrook Blvd, | C19: =+'jobinfo(2)'!B6 -> Co-Owner.cst#2 | D19: =+'jobinfo(2)'!C6 -> MRS
A20: =+'jobinfo(2)'!B3 -> Property city, state, zip | B20: =+'jobinfo(2)'!C3 -> University Heights, OH 44117 | C20: =+'jobinfo(2)'!B6 -> Co-Owner.cst#2 | D20: =+'jobinfo(2)'!C10 -> 0
A21: =+'jobinfo(2)'!B4 -> Customer Email | B21: =+'jobinfo(2)'!C4 -> Hendkingsr@yahoo.com | C21: =+'jobinfo(2)'!B7 -> cst ph # 2 | D21: =+'jobinfo(2)'!C7 -> 0
A22: =+'jobinfo(2)'!$B$27 -> Claim # | B22: =+'jobinfo(2)'!$C$27 -> 3571C126N | C22: =+'jobinfo(2)'!B28 -> policy # | D22: =+'jobinfo(2)'!C28 -> PL#
A24: Greetings : Please find attached the contractual documents for your review and signatures.
A25: Please sign each line indicated by your name in the presence of a notary.
A26: Upon your approval please print out a copy for your file.
A27: Scan and return a fully signed copy back to us. If this is a challenge for you then please advise us and we will make arrangements to get the signed documents back to us.
A29: The notarized documents serve to inform your insurer of your selections made with us and to further verify your signature.
A31: You may also refer to the additional information provided to you under the informational Assignnment Of Benefits (AOB) & Memeorandum Of Understanding (MOU) documents.
A32: Of course; if you have ANY questions please give us a call , text or email.
A33: Thank you for your confidence placed in us ; we shall do all within our power to be continually earn and respect that trust.

Sheet docs table
A1: DOCS Table of Contents
A2: 1151 Contract Notary Pages
B4: Assignment of Insurance Benefits and Direct Payment Authorization:
A5: O | B5: NOTARY PAGE 1
B6: Chose In Action 0f Irrevocable Direction to Pay & Assignment of Insurance Benefits Direct Payment Authorization:
A7: O | B7: NOTARY PAGE 2
B9: Payment Application and Processing Order
B10: In connection with the payment processing of the construction work order with the contractor, as Recipient we comprehend that the First Payment of any and all funds received will be paid to the contractor for the mitigation work that has been completed and or is in process.
A11: O | B11: NOTARY PAGE 3
B12: JOB INFO …. Imported

Sheet notary1
A1: NOTARY PAGE
A2: Assignment of Insurance Benefits and Direct Payment Authorization:
A4: =+'jobinfo(2)'!$C$1 -> Hendking, Anthony&Carlena | C4: =+'jobinfo(2)'!$B$22 -> Contract Date | D4: =+'jobinfo(2)'!$C$22 -> 45497
A5: =+'jobinfo(2)'!$C$2 -> 3806 Meadowbrook Blvd, | C5: =+'jobinfo(2)'!$B$12 -> date of loss | D5: =+'jobinfo(2)'!$C$12 -> 45492
A6: =+'jobinfo(2)'!$C$3 -> University Heights, OH 44117 | C6: =+'jobinfo(2)'!$B$13 -> rebuild type 1 | D6: =+'jobinfo(2)'!$C$13 -> Interior Repairs LEVEL 1
A7: =+'jobinfo(2)'!$C$4 -> Hendkingsr@yahoo.com | C7: =+'jobinfo(2)'!$B$14 -> rebuild type 2 | D7: =+'jobinfo(2)'!$C$14 -> Interior Repairs LEVEL 2
A8: =+'jobinfo(2)'!$C$5 -> 2166819181 | C8: =+'jobinfo(2)'!$B$15 -> rebuild type 3 | D8: =+'jobinfo(2)'!$C$15 -> Interior Repairs BSMNT
A9: =+'jobinfo(2)'!$B$26 -> Insurance Co. Name | B9: =+'jobinfo(2)'!$C$26 -> STATE FARM | C9: =+'jobinfo(2)'!$B$16 -> DEMO | D9: =+'jobinfo(2)'!$C$16 -> Y
A10: =+'jobinfo(2)'!$B$27 -> Claim # | B10: =+'jobinfo(2)'!$C$27 -> 3571C126N | C10: =+'jobinfo(2)'!$B$17 -> Mitigation | D10: =+'jobinfo(2)'!$C$17 -> Y
A12: X______________________________ _______________________________ | D12: _____/______/2024
A13: =A4 -> Hendking, Anthony&Carlena
A15: X______________________________ _______________________________ | D15: =D12 -> _____/______/2024
A16: ='jobinfo(2)'!C6 -> MRS
A18: Sworn to before me & subscribed in my presence on this ____ day of_________, 2024
A19: State of: ____________ County/Parish of: ______________________
A20: Notary Signature: ______________________________________________
A21: My Commission Expires: ______/_______ / 20_______ Notary Seal:
A23: Assigned to: | B23: =+'email cvr'!A6 -> All Phase Consulting, LLC
C25: =+'email cvr'!$A$15 -> EIN # | D25: =+'jobinfo(2)'!$C$116 -> TIN 83-226 0563

Sheet notary2
A1: NOTARY PAGE
A2: Chose In Action 0f Irrevocable Direction to Pay & Assignment of Insurance Benefits Direct Payment Authorization:
A4: =+'jobinfo(2)'!$C$1 -> Hendking, Anthony&Carlena | C4: =+'jobinfo(2)'!$B$22 -> Contract Date | D4: =+'jobinfo(2)'!$C$22 -> 45497
A5: =+'jobinfo(2)'!$C$2 -> 3806 Meadowbrook Blvd, | C5: =+'jobinfo(2)'!$B$12 -> date of loss | D5: =+'jobinfo(2)'!$C$12 -> 45492
A6: =+'jobinfo(2)'!$C$3 -> University Heights, OH 44117 | C6: =+'jobinfo(2)'!$B$13 -> rebuild type 1 | D6: =+'jobinfo(2)'!$C$13 -> Interior Repairs LEVEL 1
A7: =+'jobinfo(2)'!$C$4 -> Hendkingsr@yahoo.com | C7: =+'jobinfo(2)'!$B$14 -> rebuild type 2 | D7: =+'jobinfo(2)'!$C$14 -> Interior Repairs LEVEL 2
A8: =+'jobinfo(2)'!$C$5 -> 2166819181 | C8: =+'jobinfo(2)'!$B$15 -> rebuild type 3 | D8: =+'jobinfo(2)'!$C$15 -> Interior Repairs BSMNT
A9: =+'jobinfo(2)'!$B$26 -> Insurance Co. Name | B9: =+'jobinfo(2)'!$C$26 -> STATE FARM | C9: =+'jobinfo(2)'!$B$16 -> DEMO | D9: =+'jobinfo(2)'!$C$16 -> Y
A10: =+'jobinfo(2)'!$B$27 -> Claim # | B10: =+'jobinfo(2)'!$C$27 -> 3571C126N | C10: =+'jobinfo(2)'!$B$17 -> Mitigation | D10: =+'jobinfo(2)'!$C$17 -> Y
A12: X______________________________ _______________________________ | D12: _____/______/2022
A13: =A4 -> Hendking, Anthony&Carlena
A15: X______________________________ _______________________________ | D15: =D12 -> _____/______/2022
A16: ='jobinfo(2)'!C6 -> MRS
A18: Sworn to before me & subscribed in my presence on this ____ day of_________, 2022
A19: State of: ____________ County/Parish of: ______________________
A20: Notary Signature: ______________________________________________
A21: My Commission Expires: ______/_______ / 20_______ Notary Seal:
A23: Assigned to: | B23: =+'email cvr'!A6 -> All Phase Consulting, LLC
C25: =+'email cvr'!$A$15 -> EIN # | D25: =+'jobinfo(2)'!$C$116 -> TIN 83-226 0563

Sheet notary3
A1: NOTARY PAGE
A3: Payment Application and Processing Order
A5: =+'jobinfo(2)'!$C$1 -> Hendking, Anthony&Carlena | C5: =+'jobinfo(2)'!$B$22 -> Contract Date | D5: =+'jobinfo(2)'!$C$22 -> 45497
A6: =+'jobinfo(2)'!$C$2 -> 3806 Meadowbrook Blvd, | C6: =+'jobinfo(2)'!$B$12 -> date of loss | D6: =+'jobinfo(2)'!$C$12 -> 45492
A7: =+'jobinfo(2)'!$C$3 -> University Heights, OH 44117 | C7: =+'jobinfo(2)'!$B$13 -> rebuild type 1 | D7: =+'jobinfo(2)'!$C$13 -> Interior Repairs LEVEL 1
A8: =+'jobinfo(2)'!$C$4 -> Hendkingsr@yahoo.com | C8: =+'jobinfo(2)'!$B$14 -> rebuild type 2 | D8: =+'jobinfo(2)'!$C$14 -> Interior Repairs LEVEL 2
A9: =+'jobinfo(2)'!$C$5 -> 2166819181 | C9: =+'jobinfo(2)'!$B$15 -> rebuild type 3 | D9: =+'jobinfo(2)'!$C$15 -> Interior Repairs BSMNT
A10: =+'jobinfo(2)'!$B$26 -> Insurance Co. Name | B10: =+'jobinfo(2)'!$C$26 -> STATE FARM | C10: =+'jobinfo(2)'!$B$16 -> DEMO | D10: =+'jobinfo(2)'!$C$16 -> Y
A11: =+'jobinfo(2)'!$B$27 -> Claim # | B11: =+'jobinfo(2)'!$C$27 -> 3571C126N | C11: =+'jobinfo(2)'!$B$17 -> Mitigation | D11: =+'jobinfo(2)'!$C$17 -> Y
A13: X______________________________ _______________________________ | D13: _____/______/2022
A14: =A5 -> Hendking, Anthony&Carlena
A16: X______________________________ _______________________________ | D16: =D13 -> _____/______/2022
A17: ='jobinfo(2)'!C6 -> MRS
A19: Sworn to before me & subscribed in my presence on this ____ day of_________, 2024
A20: State of: ____________ County/Parish of: ______________________
A21: Notary Signature: ______________________________________________
A22: My Commission Expires: ______/_______ / 20_______ Notary Seal:
A24: Assigned to: | B24: =+'email cvr'!A6 -> All Phase Consulting, LLC
C26: =+'email cvr'!$A$15 -> EIN # | D26: =+'jobinfo(2)'!C116 -> TIN 83-226 0563

Sheet email cvr (2)
A1: Key Items to the Process;
A2: CONTRACTOR & HOMEOWNER AGREEMENT
A3: 15. The Owner shall promptly notify the contractor of any funds received and promptly remit to the Contractor;
A4: without delay. The Contractor also agrees to notify the Owner of any funds received on their behalf.
A5: The Owner shall promptly notify and provide the Contractor with a copy of any paperwork received.
A6: The Contractor agrees to wait for payments as disbursed from the insurance and or the escrow company.
A7: The Contractor further agrees to not demand payments from the Owner unless otherwise agreed.
A9: 16. The Owner and the contractor agree that the contractor shall '“discuss the amount of damage to the consumer’s home, the appropriate replacement, and reasonable cost of replacement with the insurance company.”; as needed. The Contractor agrees to release the owner from any obligation to complete work not covered by the insurance company.
A10: The Owner may choose to pay the contractor for work not covered by insurance proceeds.
A12: Assignment of Insurance Benefits & Direct Payment Authorization:
A13: Essentially the Restoration Company is extending credit to the customer.
A14: I do comprehend there will be a large amount of time, research, money, resources, equipment, supplies, hours spent working (pictures, documentation, inspections, setup) on my estimate to properly present to my insurer.
... A17: Proof of loss supporting documents and scheduling.
A18: Cost analysis/repair specifications/Estimating services | C18: Jobsite visits
A19: Money/Job costs … | B19: Resources/Materials | C19: Miscellaneous services rendered
A20: Damages Control | B20: Labor & Professional Expertise | C20: Time & Staff Resources
A21: Testing services | B21: Document preparation services | C21: Damages report & discovery
A22: Jobsite Protection | B22: Mitigation Services | C22: Inspection services
A24: Payment Application and Processing Order
A25: In connection with the transaction of the construction work order with All Phase Consulting LLC, as Recipient we comprehend that the First Payment of any and all funds received will be paid to All Phase Consulting, LLC for the mitigation work. As a condition to, and as consideration for, Recipient being furnished with the Mitigation work, evaluation and materia ls, Recipient hereby agrees to treat all First Payments for the purpose of Mitigation payments at any time by the Insurance Company to, or otherwise obtained by, Recipient and /or any person or entity controlling, controlled by, or under common control with, Recipient, or any principal independent contractor, agent, representative, advisor of Recipient of, or person or entity affiliated with Recipient construction work order.
A27: It is stated that this submittal does not represent a final invoice of any type.
A28: Owner and or the Contractor also specifically reserves the right to submit for review and payment any additional/supplemental invoices as may be deemed necessary to restore the property to the pre-loss condition or better.
A30: Payments: Issuance, payment and acceptance of payment are without prejudice to any rights of the Owner or the Contractor under the terms of this agreement.

Sheet pay
A1: Chose In Action per & AOBs and , Irrevocable Direction to Pay
A2: A chose in action is a form of property and can be assigned,
A3: Under the law, an assignment is a transfer of rights or property.
A4: Similarly, a direction to pay is a document that directs an insurer to make payment to a
A5: separate entity and or to make payment in a specific manner.
A6: OWNER HEREBY SPECIFICALLY REQUESTS THAT ALL PAYMENTS BE PAID TO CONTRACTOR:
A8: Insurer may make payment per it's legal obligation to include all parties of interest to include policyholders, mortgagor and contractor/assignee. Contractor/ Assignee has no objection to this manner of disbursement and reserves all other rights contained herein. However, per the customer's direction the Contractor shall always be named as a payee of the funds.
A9: Essentially, the AOB allows the assignee to bring a claim for any unpaid claim related benefits.
A11: A restoration company is entitled to full and complete payment for services rendered.
A12: Assignment of Benefits is one way to provide payment.
A14: This assignment essentially allows the restoration service company to perform its work on credit or with no immediate payment by the homeowner, leaving the homeowner with the comforting satisfaction that the restoration company will collect its fee for services from the homeowners insurance company directly. Or customer may exercise any one of the folllowing actions:
A15: a) Provide a check for payment of services
... A28: NOTARY PAGE attached

Sheet 1st pay
A1: Payment Application and Processing Order
A2: In connection with the payment processing of the construction work order with HEREIN NAMED CONTRACTOR, as Recipient we comprehend that the First Payment of any and all funds received will be paid to THE HEREIN NAMED CONTRACTOR, for the mitigation work that has been completed AND OR MITIGATION WORK IN PROCESS..
A4: As a condition to, and as consideration for, Recipient being furnished with the Mitigation work, evaluation and materials, Recipient hereby agrees to treat all First Payments for the purpose of Mitigation payments at any time by the Insurance Company to, or otherwise obtained by, Recipient and /or any person or entity controlling, controlled by, or under common control with, Recipient, or any principal independent contractor, agent, representative, advisor of Recipient of, or person or entity affiliated with Recipient construction work order.
A5: Essentially the Restoration Company is extending credit to the customer.
A6: Assignment of Insurance Benefits & Direct Payment Authorization:
A7: Key Items to the Process; CONTRACTOR & HOMEOWNER AGREEMENT
A8: I do comprehend there will be a large amount of time, research, money, resources, equipment, supplies, hours spent working (pictures, documentation, inspections, setup) on my estimate to properly present to my insurer.
A9: The company is very willing to take an educated/calculated risk of having the insurer pay for the restoration.
A10: The company is very willing to invest our following items towards the restoration work on your property;
A11: Proof of loss supporting documents Job scheduling. | C11: Jobsite Protection Mitigation Services
A12: Money/Job costs … Resources/Materials | C12: Inspection services Jobsite visits
A13: Labor & Professional Expertise Damages Control | C13: Time & Staff Resources
A14: Document preparation services Testing services | C14: Damages report & discovery
A15: Cost analysis/repair specifications/Estimating services | C15: Miscellaneous services rendered
A17: CONTRACTOR & HOMEOWNER AGREEMENT
A18: 15. The Owner shall promptly notify the contractor of any funds received and promptly remit to the Contractor;
A19: without delay. The Contractor also agrees to notify the Owner of any funds received on their behalf.
A20: The Owner shall promptly notify and provide the Contractor with a copy of any paperwork received.
A21: The Contractor agrees to wait for payments as disbursed from the insurance and or the escrow company.
A22: The Contractor further agrees to not demand payments from the Owner unless otherwise agreed.
A24: 16. The Owner and the contractor agree that the contractor shall '“discuss the amount of damage to the consumer’s home, the appropriate replacement, and reasonable cost of replacement with the insurance company.”; as needed. The Contractor agrees to release the owner from any obligation to complete work not covered by the insurance company.
A25: The Owner may choose to pay the contractor for work not covered by insurance proceeds.
A26: Payments: Issuance, payment and acceptance of payment are without prejudice to any rights of the Owner or the Contractor under the terms of this agreement.
A27: Owner and or the Contractor also specifically reserves the right to submit for review and payment any additional/supplemental invoices as may be deemed necessary to restore the property to the pre-loss condition or better.
A28: It is stated that this submittal does not represent a final invoice of any type.

Sheet jobinfo(2)
A1: Customer | B1: Property-Owner Name | C1: Hendking, Anthony&Carlena | D1: Enter info here | H1: ADD SOS LINK
B2: Property address: street | C2: 3806 Meadowbrook Blvd, | D2: New Customer Info required | H2: LINK TO VIDEOS
B3: Property city, state, zip | C3: University Heights, OH 44117 | H3: BEFORE AND AFTER P[CS
B4: Customer Email | C4: Hendkingsr@yahoo.com | H4: CLE ATL NY NC NY
B5: Cst-owner Phone# | C5: 2166819181
B6: Co-Owner.cst#2 | C6: MRS
B7: cst ph # 2 | H7: RFG WIP…CURRENT JOBS
B8: Cst address # 2 | H8: SIGNAGE
B9: city, state-cst#2
B10: email-cst #2
A11: Loss Info | B11: Cause of Loss | C11: FIRE | D11: Wind = Roof | E11: Water Damage=WTR | F11: Fire Smoke | G11: Wind=Tree | H11: Hurricane =HURR
B12: date of loss | C12: 45492 | D12: rebuild type
B13: rebuild type 1 | C13: Interior Repairs LEVEL 1 | D13: roofing shingles replacement | F13: fencing
B14: rebuild type 2 | C14: Interior Repairs LEVEL 2 | D14: interior repairs | F14: shed
B15: rebuild type 3 | C15: Interior Repairs BSMNT | D15: exterior repairs | F15: porch patio
B16: DEMO | C16: Y
B17: Mitigation | C17: Y
B18: Other Structures | C18: NA
A19: CPS | B19: Replacement | C19: Y
B20: CPS / CLN / CON/ CGN | C20: Y
B21: Year Built | C21: POST 1978
B22: Contract Date | C22: 45497 | D22: TBD | E22: pre 1980 | F22: post 1980
B23: Loss of use/ ALE | C23: Y | D23: sample cost 3
B24: Breathing issue | C24: Y | D24: doctor letter
B25: HMR | C25: TBD | D25: lab test
B26: Insurance Co. Name | C26: STATE FARM | D26: Insurance Company Supplied Info | E26: Per declaration pages
A27: Insurance Co. | B27: Claim # | C27: 3571C126N | E27: Assigned by Insurer
B28: policy # | C28: PL# | E28: Per declaration pages
B29: Email INS. co. | C29: statefarmfireclaims@statefarm.com | E29: Per declaration pages
B30: DESK Adjuster DA | C30: KENNETH SAMS | E30: Assigned by Insurer
B31: DA Phone | C31: 844-458-4300 | E31: customer service rep
B32: DA Ph. Ext. # | C32: 309 763 2612 | E32: Hazel
B33: DA Email | C33: statefarmfireclaims@statefarm.com | E33: 43789
B34: Field Adjuster Name | C34: SCOTT DANKO | E34: 5pm
B35: Phone # field adj | C35: 3307228703
B36: Field adj email | C36: sdanko@insrescon.com
B37: adj contents | C37: Kevin Salmon, SPVR | E37: Assigned by Insurer
B38: adj CPS phone # | C38: 844-458-4300
B39: adj CPS email | C39: 972 362 3661
B40: TMP adj | E40: Assigned by Insurer
...
