Workbook
Name a...new_customer: '[1]input data'!$A$1:$D$45
Name basicroompichow2: #REF!
Name box_names: +'[2]CPS Quick'!$E$2:$S$2
Name Column.a.new.cst: '[1]input data'!$A$2:$A$45
Name culpepper: #REF!
Name culpepper: #REF!
Name data: [3]QUOTE!$A$267:$R$424
Name Document_Stacking_List: '[4]sign pgs'!#REF!
Name Document_Stacking_List: '[4]sign pgs'!#REF!
Name Enter_new_cst_data: #REF!
Name Enter_new_cst_data: #REF!
Name Jefferies: #REF!
Name Jefferies: #REF!
Name LOVEJOY_INTERIOR: #REF!
Name LOVEJOY_INTERIOR: #REF!
Name Lovejoy_ROOF: #REF!
Name Lovejoy_ROOF: #REF!
Name LxWxH: [3]QUOTE!#REF!
Name LxWxH: [3]QUOTE!#REF!
Name new_customer: '[1]cst list'!$B$32:$B$65
Name PRICE_P: #REF!
Name PRICE_P: #REF!
Name Robinson: #REF!
Name Robinson: #REF!
Name sigtj: "Picture 9859"
Name SubContractor_Summary: #REF!
Name SubContractor_Summary: #REF!
Name Wayside_Builders__LLC_…...OH: '[1]co name'!$D$21
Name WSB...GA.Wayside_Builders__LLC……GA: '[1]co name'!$D$38

Sheet RFG spply
A1: Roofing / Exterior Supplies / Materials / Equipment | D1: =+'jobinfo(2)'!C4 -> stephanie@trisproductions.com
A2: =+'jobinfo(2)'!C1 -> BENJAMIN, SANDRA L. | C2: =+'jobinfo(2)'!C2 -> 1441 Thomas Road, | D2: =+'jobinfo(2)'!C3 -> Decatur, GA
A3: =+'jobinfo(2)'!C5 -> 678) 361-6713
A5: EagleView | B5: [__] | C5: Quick squares ________ | D5: Full report ________
B6: [__] | C6: gutters / siding / windows
A7: Tarps
B8: [__] | C8: 9 X 19______ 11 x 23 __ ___ 20 x 25_______ /_____
B9: [__] | C9: Buttons/ nails | D9: screws
B10: [__] | C10: Bracing 1 x 4 x 8
A11: Temp Repairs Materials | B11: [__] | C11: Sheathing - CDX - 5/8" | D11: # __________
B12: [__] | C12: Temp covering; felt, ice guard
B13: [__] | C13: Pipe collars / repair "donuts"
A14: Ladders | B14: [__] | C14: Ladder 22-30-40 | D14: Extension ladder
B15: [__] | C15: Folding type 17 / 21
B16: [__] | C16: Hook ladder/ goat
B17: [__] | C17: Step ladder
A18: Safety gear | B18: [__] | C18: Work boots, "Cougar Paws"
B19: [__] | C19: Rope & tie offs 25 / 50 / 100 lf
B20: [__] | C20: Harness
A21: Tools | B21: [__] | C21: CHALK | D21: FLASHLIGHT
B22: [__] | C22: HAMMER, toolbelt | D22: magnetic
B23: [__] | C23: Cordless drill, bits screws
B24: [__] | C24: Lopper, tree trimmer tool
B25: [__] | C25: Saws; bow handsaw / Chainsaw
B26: [__] | C26: gutter scooper | D26: torch
B27: [__] | C27: Generator | D27: Safety Cones
B28: [__] | C28: Extension Cords | D28: Caution tape
B29: [__] | C29: Power washer & water hoses | D29: FENCING
A30: SPECIAL SITE CIRCUMSTANCES COVERED; DUMPSTER LOCATION, ELEC.

Sheet RFG SCOPE
A1: EXTERIOR ROOF Systems Checklist | E1: PICTURES NEED OF THE FOLLOWING ITEMS……..SHOW EXISITNG AND OR NEW…….
A2: =+'jobinfo(2)'!C1 -> BENJAMIN, SANDRA L. | C2: =+'jobinfo(2)'!C2 -> 1441 Thomas Road, | E2: =+'jobinfo(2)'!C3 -> Decatur, GA
C3: EAGLEVIEW/ DRAWING | E3: ORDERED__________ | G3: PICTURES
A4: Roof shingles | C4: 3 tab -25 yr. shingles OR 30 yr. | E4: TYPE_______________ | H4: {__}
C5: 10%_______15%______ | G5: WASTE % | H5: {__}
C6: Additional layer Roof shingles | G6: Yes | H6: NO
C7: Gable cornice return - 3 tab | G7: Yes | H7: NO
C8: High roof (2 stories or more) | G8: Yes | H8: NO
C9: Steep roof - 7/12 0r higher | E9: SLOPE =______________ | G9: Yes | H9: NO
A10: Flashing - Metals | C10: Drip edge | G10: Yes | H10: NO
C11: Chimney flashing - avge (3x3) | F11: ________ | G11: quantity | H11: {__}
C12: Flashing - pipe jack PVC____ :Lead_________ | G12: quantity | H12: {__}
C13: Exhaust cap - through roof | F13: ________ | G13: quantity | H13: {__}
C14: Valley metal SHOW | E14: EGV | G14: Yes | H14: NO
C15: Ice & water shield | G15: Yes | H15: NO
C16: Flashing, 14" wide | E16: EGV | G16: Yes | H16: NO
C17: Step flashing SHOW | E17: EGV | G17: Yes | H17: NO
C18: Roof window SKYLITE step flashing kit | F18: ________ | G18: Yes | H18: NO
A19: Vent System | C19: Continuous ridge vent - aluminum | G19: Yes | H19: NO
C20: Continuous ridge vent - shingle-over style | G20: Yes | H20: NO
C21: Roof vent - turbine type | F21: ________ | G21: quantity | H21: {__}
C22: Roof vent - turtle type - Metal | F22: ________ | G22: quantity | H22: {__}
C23: Roof mount power attic vent - Detach & reset | F23: ________ | G23: quantity | H23: {__}
A24: Gutters | C24: Gutter guard/screen - Detach & reset | F24: replace | G24: Yes | H24: NO
C25: Gutter / downspout - aluminum - 6" | F25: ________ | G25: Yes | H25: NO
C26: Gutter / downspout - Detach & reset | F26: replace | G26: Yes | H26: NO
C27: Clean gutter/downspout | E27: Storm debris | F27: ________ | G27: Yes | H27: NO
A28: MISC. damaged ? | C28: Digital satellite system - | E28: TV antenna | F28: ________ | G28: quantity | H28: {__}
C29: Clothes dryer vent cover | F29: ________ | G29: Yes | H29: NO
C30: Comb & straighten a/c condenser unit fins | F30: ________ | G30: Yes | H30: NO
C31: Window screen, 10 - 16 sf | F31: ________ | G31: Yes | H31: NO
A32: Clear , detailed & properly labeled emailed {ONLY !!!!} Pictures are a critical part of the full process for payment!!

Sheet EXT MIT
A1: ROOF Mitigation PICTURES
A2: JOBSITE Verification Pics | C2: [A]Take a picture of the property address; upon arrival & last picture.
C3: [B] Take picture of the front & sides, & rear of property.
A4: ROOF Pictures | C4: [C] PICTURE OF Every damaged area/slope
C5: [D] Include damage details notes as described below
A6: North/Front Slope | C6: Identify & Label Roof Damage - A] TYPE & B] Quantity | E6: PHOTO
A7: W = 6 + | C7: " O " Circle = Hail damage | E7: [ ____]
A8: O = 8 + | C8: " W " = Wind damage | E8: [ ____]
A9: SAMPLE | C9: Creased Shingles; line showing stress test results, debris underneath
A10: Direction = (use compass APP); N___S___E ___W __ | C10: " Tree " tree damage | E10: [ ____]
A14: Pics of Label & Temporary Repairs
A15: Temp Repairs & Materials = BILLABLE ITEMS | C15: [__] | D15: Safety Cones & Caution Tape | E15: [ ____]
C16: [__] | D16: SAFETY FENCING & POSTS (4) | E16: [ ____]
C17: [__] | D17: TARPS 9 X 19_____ 11 x 23 ___ 20 x 25_______ /_____ | E17: [ ____]
C18: [__] | D18: Bracing 1 x 2 x 8 | E18: [ ____]
C19: [__] | D19: Sheathing - CDX - 5/8" = sf | E19: [ ____] | G19: Look for exposed wood/roof decking & Roof Penetrations
C20: LABEL "TEMP REPAIR" | E20: [ ____]
C21: [__] | D21: Temp covering; felt, ice guard | E21: [ ____]
C22: [__] | D22: Generator | E22: [ ____]
C23: [__] | D23: Generator POWER CABLE | E23: [ ____]
C24: [__] | D24: Harness, Rope & tie offs/anchors 25/50/100 lf | E24: [ ____]
D25: ROOF ANCHORS fastened in place
C26: [__] | D26: DUMPSTER BAG | E26: [ ____]
A27: [ E ] EXTERIOR / other storm / fire damage; garage, siding , fascia, gutters , fencing, shed, ……………...windows, A/C unit [see EXT PICS OTHER ]

Sheet mnt EXT
A1: Maintenance Items- Exterior/Roof non claim related issues
A2: Failure to address these items could result in claim denial !!
A3: Some typical Examples to be inspected are as follows:
A4: First impresssion of Property | B4: {__} | C4: Curb Appeal | D4: Landscaping
B5: {__} | C5: Overall condition of Property | D5: Housekeeping
B6: {__} | C6: IS THERE THE IMAGE THAT They NEED the Money??
A8: Roofing | B8: {__} | C8: Caulk Failure | D8: Column2
B9: {__} | C9: Pipe collars
B10: {__} | C10: Loose chimney bricks
B11: {__} | C11: Flashing
B12: {__} | C12: Clogged gutter/downspout
B13: {__} | C13: Loose gutters, gutter boards,
B14: {__} | C14: Trees contacting roof / house siding
A16: Misc Items to be inspected | B16: {__} | C16: Peeling Paint
B17: {__} | C17: Trip Hazards/Sidewalks
B18: {__} | C18: Loose/Missing Railings
B19: {__} | C19: Excess debris/contents on site
B20: {__} | C20: Loose Fixtures/lights/Awnings/Siding
B21: {__} | C21: Cracked walls/loose fencing
B22: {__} | C22: Broken Windows
B23: {__} | C23: Hazard Materials on site
B24: {__} | C24: Electrical overloads
A25: Code upgrades to be considered | B25: {__} | C25: "Deck" | D25: 3/8" existing
B26: {__} | C26: Drip edge
B27: {__} | C27: Ventilation
A29: We may work with you to correct these items,with your approval;Costs,if any,to be determined.

Sheet pics
B1: Index of Required Pictures | C1: =+'jobinfo(2)'!C2 -> 1441 Thomas Road,
B2: =+'jobinfo(2)'!C1 -> BENJAMIN, SANDRA L. | C2: Taken IN ENCIRCLE | D2: reviewed & ok By | E2: Emailed to insurer
B3: Each picture set requires a site verification set of pictures as follows:
B4: [A] Take a picture of the property address;
B5: [ 1 ]upon arrival [ 2 ] last picture before leaving job. | C5: Part of each project
B6: [B] At opposite corners of the house, take one picture of the front & side,
B7: then take a picture of the back and the other side. This should give full view. ….
A9: 1 | B9: ORIGINAL SITE VISIT
B10: Documents the initial damages BEFORE any work is done.
B11: Provides the primary basis for the restoration work scope.
B12: a] Roof & EXT …....................b] Interior …..... …....................
A13: 2 | B13: ROOF & EXTERIOR MITIGATION
A14: 3 | B14: INTERIOR MITIGATION & DEMO
B15: DEMOLITION DMO
B16: SECONDARY DAMAGES HAZARDOUS MATERIALS REMEDIATION/HMR
A17: 4 | B17: MITIGATION EQUIPMENT
B18: Provides the supporting documentation of equipment billed.
A19: 5 | B19: DRY LOGS DOCS & TRIP MONITORING
B20: Required info to support our professional drying techniques & our drying/mitigation invoices…............
A21: 6 | B21: CONTENTS; PACKOUT a] Storage Only
B22: Gives detailed support for contents pack out & related charges.
B23: IF resetting is done , provide picture after unpacking.
A24: 7 | B24: Cleaning INHOUSE & Sent to outside vendor
A25: 8 | B25: CONTENTS, REPLACEMENT ITEMS CPS / CON
B26: Required documentation to get customer paid for damaged items.
A27: 9 | B27: REBUILD CLOSEOUT
B28: Allows support to finalize the job and receive payment,
B29: Shows our quality of work & attracts new customers.
B30: a] Roof & EXT …....................b] Interior …..... …....................
A31: 10 | B31: SECONDARY DAMAGES HAZARDOUS MATERIALS REMEDIATION/HMR
A32: 11 | B32: Exterior contents
B33: General Info & Tips:
B34: You cannot take too many photos of the damages;/Water damage which may be especially hard to photograph.
B35: Some lighted cameras flash-out the stains. Taking non-lighted photos sometimes works much better.
A37: How to take pictures
A38: FIRST !!!! Put on your safety shoes, goggles, gloves, hard hat and mask., take photos of everything in the the interior on the property. Pictures of the personal property inventory handled by other subcontractor. Photos of the damages to your home, business, and especially the water damage which may be hard to photograph or video-graph. Some lighted cameras flash-out the stains. So, taking non-lighted photos and video sometimes works much better when trying to get photo evidence of water stained ceilings and walls.
A39: [A] Take a picture of the property address;
B40: [ 1 ]upon arrival
B41: [ 2 ] last picture before leaving job.
A42: [ B ] At opposite corners of the house, take one picture of the front and side,
...

Sheet quicklist
A1: BASIC SUMMARY OF RESTORATION PROCESS; (Quick version). | D1: =+'jobinfo(2)'!C2 -> 1441 Thomas Road, | F1: DoneDate
A2: JOB | C2: =+'jobinfo(2)'!C1 -> BENJAMIN, SANDRA L. | D2: Status | E2: %
A3: 1 | B3: Introduction, Analysis & Verification | C3: Introduction, Analysis & Verification | D3: source/reffered by:
A4: POI | C4: Who is the Insurance Company ?!?
C5: Does customer Comprehend Our Role in the process?
C6: Is this an LEGITIMATE COVERED INSURANCE Claim? Or Self Pay ?
C7: IS THE DAMAGE $ MORE THAN THE DEDUCTIBLE?
C8: Do they have coverage; for AOB? Proof of Insurance, POI | G8: EMAIL
A9: 2 | B9: Contracts & Documentation | C9: Contracts & Documentation | G9: ENC
A10: DOC | C10: Has Customer been fully advised of Contract Contents?
C11: Has Customer had a full Consultation to Our Terms & Conditions?
C12: Does Customer FULLY Agree to Our Terms & Conditions? Initials? | G12: 0NLINE
C13: Notary Page explained/ Fast track
A14: mou | C14: Company investment (dollars, time ,materials)into their Project?
A15: 3 | C15: Claim Reporting
A16: INS | C16: DOES THE CUSTOMER HAVE THE REQUIRED INFO?
C17: Insurer Mitigation / DMO / CPS Approval Info Sheet
A18: mit | B18: Mitigation & Demolition | C18: Mitigation & Demolition
A19: 4 | C19: Roof & EXT Mitigation TEMPORARY & EMERGENCY REPAIRS | G19: 2
A20: 5 | C20: Contents_ item list_; storage details; security explained?
A21: 6 | C21: HMR / Secondary Damages; Equipment & Electricity $
A22: 7 | C22: Interior Mitigation; household disruption explained?
A23: esx | B23: Estimates | C23: Estimates
A24: 8 | C24: Interior Inspection/Scope Form
C25: SKETCH/DRAWING;[1] sheet per floor
C26: PICTURES; In Encircle APP
C27: Create Estimates… Rebuild…… …...... CPS
C28: Mitigation & Demolition
A29: 9 | B29: Insurance Company Meetings | C29: Insurance Company Meetings ( be present for adjuster visit)
A30: adj | C30: Prepare docs for adjuster meeting; Print & bind docs
A31: 10 | B31: Cashflow
A32: job | C32: General Contractor / Subcontracts
B33: Mitigation & Demolition | C33: Mitigation & Demolition
B34: Rebuild | C34: REBUILD
B35: Contents | C35: CONTENTS CPS
B36: Closeout | C36: Closeout

Sheet chklst
A1: Documents Checklist for CONTRACT PACKAGE | C1: 0
A2: CUSTOMER # | B2: =+'jobinfo(2)'!B11 -> Cause of Loss | C2: =+'jobinfo(2)'!C11 -> WIND HAIL | F2: =+'jobinfo(2)'!B26 -> Insurance Co. Name | G2: =+'jobinfo(2)'!C26 -> STATE FARM
A3: =+'jobinfo(2)'!C1 -> BENJAMIN, SANDRA L. | B3: =+'jobinfo(2)'!B12 -> date of loss | C3: =+'jobinfo(2)'!C12 -> 45300 | F3: =+'jobinfo(2)'!B27 -> Claim # | G3: =+'jobinfo(2)'!C27 -> CL 11-
A4: =+'jobinfo(2)'!C2 -> 1441 Thomas Road, | B4: =+'jobinfo(2)'!B13 -> rebuild type 1 | C4: =+'jobinfo(2)'!C13 -> ROOF SHINGLES | F4: =+'jobinfo(2)'!B28 -> policy # | G4: =+'jobinfo(2)'!C28 -> TBD PL#
A5: =+'jobinfo(2)'!C3 -> Decatur, GA | B5: =+'jobinfo(2)'!B14 -> rebuild type 2 | C5: =+'jobinfo(2)'!C14 -> interior repairs | F5: =+'jobinfo(2)'!B29 -> Email INS. co. | G5: =+'jobinfo(2)'!C29 -> STATEFARMFIRECLAIMS@STATEFARM.COM
A6: =+'jobinfo(2)'!C4 -> stephanie@trisproductions.com | B6: =+'jobinfo(2)'!B15 -> rebuild type 3 | C6: =+'jobinfo(2)'!C15 -> exterior repairs | F6: =+'jobinfo(2)'!B30 -> DESK Adjuster DA | G6: =+'jobinfo(2)'!C30 -> DA
A7: =+'jobinfo(2)'!C5 -> 678) 361-6713 | B7: =+'jobinfo(2)'!B16 -> DEMO | C7: =+'jobinfo(2)'!C16 -> Y | F7: =+'jobinfo(2)'!B31 -> DA Phone | G7: =+'jobinfo(2)'!C31 -> DA PH
A9: CONTRACT PACKAGE; | B9: PGS | C9: CST Sign | D9: I | E9: Scan | F9: Upload | G9: DONE | H9: Report#
A10: Copy of Policy full pages [ ] for AOB | B10: 3 | C10: N/A | D10: I | E10: [ ] | F10: [ ] | G10: [ ]
A11: Declaration page [ ] for AOB | B11: 20 | D11: I | E11: [ ] | F11: [ ] | G11: [ ]
A12: {1} MEMORANDUM OF UNDERSTANDING | B12: 25 | C12: FORWARD | D12: I | E12: [ ] | F12: [ ] | G12: [ ] | H12: # 50
A13: MOU. REVIEWED / SENT | C13: [ ] | D13: I | E13: [ ] | F13: [ ] | G13: [ ]
A14: {2} AUTHORIZATION, General | B14: 1 | C14: [ ] | D14: I | E14: [ ] | F14: [ ] | G14: [ ]
A15: {3} TMP Authorization | B15: 1 | C15: [ ] | D15: I | E15: [ ] | F15: [ ] | G15: [ ]
A16: {5} CONTRACT w/ initials { } & RECISSION | B16: 3 | C16: [ ] | D16: I | E16: [ ] | F16: [ ] | G16: [ ]
A17: {6} AOB---- Notary Pages | B17: 6 | C17: [ ] | D17: I | E17: [ ] | F17: [ ] | G17: [ ] | H17: # 51
D18: I
A19: {7} Brief Narrative of Claim.'REPORTING SUMMARY | C19: UPDATE | D19: I | E19: [ ] | F19: [ ] | G19: [ ] | H19: #25
A20: {__} INDEX = LISTING of Job Work Areas.
A21: {8} MOLD DISCLAIMER | C21: [ ] | D21: I | E21: [ ] | F21: [ ] | G21: [ ]
A22: {9} Mortgage Co, Info | C22: [ ] | D22: I | E22: [ ] | F22: [ ] | G22: [ ]
D23: I
A24: {10} EagleView, Full report & EV# _______ | B24: [ ] | C24: Xactimate________ | D24: I | E24: N/A | F24: [ ] | G24: [ ] | H24: EGV
A25: OTHER_____siding_____WDW___ | B25: [ ] | C25: gutters | D25: I | F25: [ ] | G25: [ ]
A27: {12} SKETCH / DRAWING;[1] sheet per floor | B27: [ ] | C27: SKETCH & SCOPE | D27: I | E27: [ ] | F27: [ ] | G27: [ ]
A28: {13} Interior SCOPE/SHEET; [1] sheet per room | B28: [ ] | D28: I | E28: [ ] | F28: [ ] | G28: [ ]
A30: {14} ROOM Pictures/ SEE app guideline | B30: [ ] | C30: PICTURES | D30: I | E30: N/A | F30: [ ] | G30: [ ] | H30: ENC
A31: Pictures are a critical part of full process for payment! | D31: I | E31: Scan | F31: Upload | G31: DONE
A33: {15} Mitigation -Exterior SCOPE & MIT | B33: [ ] | C33: EXTERIOR MITIGATION | D33: I | E33: [ ] | F33: =+F30 -> [ ] | G33: [ ] | H33: #65
A34: SUPPLIES | B34: [ ] | E34: [ ] | F34: [ ] | G34: [ ]
A35: EQUIPTMENT | B35: [ ] | E35: [ ] | F35: [ ] | G35: [ ]
A37: {16} Mitigation -Interior SCOPE & MIT | B37: [ ] | C37: INTERIOR MITIGATION | D37: I | E37: [ ] | F37: [ ] | G37: [ ] | H37: #80
A38: SUPPLIES | B38: [ ] | E38: [ ] | F38: [ ] | G38: [ ]
A39: EQUIPTMENT | B39: [ ] | E39: [ ] | F39: [ ] | G39: [ ]
A41: {17} DEMO SCOPE | B41: [ ] | C41: DMO | D41: I | E41: [ ] | F41: [ ] | G41: [ ]
A43: {18} Contents SCOPE = QUICKVIEW | B43: [ ] | C43: CPS CLN CON | D43: I | E43: [ ] | F43: [ ] | G43: [ ] | H43: #90
A44: SUPPLIES | B44: [ ] | E44: [ ] | F44: [ ] | G44: [ ]
A45: EQUIPTMENT | B45: [ ] | E45: [ ] | F45: [ ] | G45: [ ]
A47: Team leader: | C47: 0

Sheet jobinfo(2)
A1: Customer | B1: Property-Owner Name | C1: BENJAMIN, SANDRA L. | D1: Enter info here
B2: Property address: street | C2: ='[5]jobinfo(2)'!$C$2 -> 1441 Thomas Road, | D2: New Customer Info required
B3: Property city, state, zip | C3: ='[5]jobinfo(2)'!$C$3 -> Decatur, GA
B4: Customer Email | C4: ='[5]jobinfo(2)'!$C$4 -> stephanie@trisproductions.com
B5: Cst-owner Phone# | C5: ='[5]jobinfo(2)'!$C$5 -> 678) 361-6713
B6: Co-Owner.cst#2 | C6: ='[5]jobinfo(2)'!$C$6 -> TBD
B7: cst ph # 2 | C7: ='[5]jobinfo(2)'!$C$7 -> TBD
B8: Cst address # 2 | C8: ='[5]jobinfo(2)'!$C$8 -> TBD | E8: Cause of Loss
B9: city, state-cst#2 | C9: ='[5]jobinfo(2)'!$C$9 -> TBD | E9: Wind roof
B10: email-cst #2 | C10: ='[5]jobinfo(2)'!$C$10 -> TBD | E10: Roofing = RFG
A11: Loss Info | B11: Cause of Loss | C11: ='[5]jobinfo(2)'!$C$11 -> WIND HAIL | D11: Wind = Roof | E11: Fire
B12: date of loss | C12: ='[5]jobinfo(2)'!$C$12 -> 45300 | D12: rebuild type | E12: Wind=Wind
B13: rebuild type 1 | C13: ='[5]jobinfo(2)'!$C$13 -> ROOF SHINGLES | D13: roofing shingles replacement | E13: Water Damage=WTR
B14: rebuild type 2 | C14: ='[5]jobinfo(2)'!$C$14 -> interior repairs | D14: interior repairs | E14: Hurricane =HURR
B15: rebuild type 3 | C15: ='[5]jobinfo(2)'!$C$15 -> exterior repairs | D15: exterior repairs | E15: TREE | F15: Wind=Tree
B16: DEMO | C16: ='[5]jobinfo(2)'!$C$16 -> Y | E16: FIRE
B17: Mitigation | C17: ='[5]jobinfo(2)'!$C$17 -> Y
B18: Other Structures | C18: ='[5]jobinfo(2)'!$C$18 -> TBD | E18: rebuild type 1
A19: CPS | B19: Replacement | C19: ='[5]jobinfo(2)'!$C$19 -> Y | E19: exterior repairs
B20: CPS / CLN / CON/ CGN | C20: ='[5]jobinfo(2)'!$C$20 -> Y | E20: interior repairs
B21: Year Built | C21: ='[5]jobinfo(2)'!$C$21 -> TBD | E21: TBD
B22: Contract Date | C22: 45301 | D22: TBD | E22: roofing shingles replacement
B23: Loss of use/ ALE | C23: ='[5]jobinfo(2)'!$C$23 -> Y | D23: sample cost 3 | E23: fencing
B24: Breathing issue | C24: ='[5]jobinfo(2)'!$C$24 -> Y | D24: doctor letter | E24: shed
B25: HMR | C25: ='[5]jobinfo(2)'!$C$25 -> Y | D25: lab test
B26: Insurance Co. Name | C26: ='[5]jobinfo(2)'!$C$26 -> STATE FARM | E26: Insurance Co. Name
A27: Insurance Co. | B27: Claim # | C27: ='[5]jobinfo(2)'!$C$27 -> CL 11-
B28: policy # | C28: ='[5]jobinfo(2)'!$C$28 -> TBD PL#
B29: Email INS. co. | C29: ='[5]jobinfo(2)'!$C$29 -> STATEFARMFIRECLAIMS@STATEFARM.COM
B30: DESK Adjuster DA | C30: ='[5]jobinfo(2)'!$C$30 -> DA
B31: DA Phone | C31: ='[5]jobinfo(2)'!$C$31 -> DA PH
B32: DA Ph. Ext. # | C32: ='[5]jobinfo(2)'!$C$32 -> DA EXT
B33: DA Email | C33: ='[5]jobinfo(2)'!$C$33 -> TBD
B34: Field Adjuster Name | C34: ='[5]jobinfo(2)'!$C$34 -> TBD
B35: Phone # field adj | C35: ='[5]jobinfo(2)'!$C$35 -> TBD
B36: Field adj email | C36: ='[5]jobinfo(2)'!$C$36 -> TBD
B37: adj contents | C37: ='[5]jobinfo(2)'!$C$37 -> TBD
B38: adj CPS phone # | C38: ='[5]jobinfo(2)'!$C$38 -> TBD
B39: adj CPS email | C39: ='[5]jobinfo(2)'!$C$39 -> TBD
B40: TMP adj | C40: ='[5]jobinfo(2)'!$C$40 -> TBD
...

Sheet brief
A1: Brief Narrative of Claim details | C1: =+'jobinfo(2)'!C2 -> 1441 Thomas Road,
A2: =+'jobinfo(2)'!C1 -> BENJAMIN, SANDRA L. | B2: =+'jobinfo(2)'!C5 -> 678) 361-6713 | C2: =+'jobinfo(2)'!C3 -> Decatur, GA
A3: =+'jobinfo(2)'!B27 -> Claim # | B3: =+'jobinfo(2)'!C27 -> CL 11- | C3: =+'jobinfo(2)'!C26 -> STATE FARM
A4: =+'jobinfo(2)'!B12 -> date of loss | B4: =+'jobinfo(2)'!C12 -> 45300 | C4: =+'jobinfo(2)'!B11 -> Cause of Loss | D4: =+'jobinfo(2)'!C11 -> WIND HAIL
A5: Property damage | B5: =+'jobinfo(2)'!C13 -> ROOF SHINGLES | C5: =+'jobinfo(2)'!C14 -> interior repairs | D5: =+'jobinfo(2)'!C15 -> exterior repairs
A6: Description of each location where damage observed; ___________________________________________ | C6: Type of property damage
A10: __________________________________________ | C10: __________________________________________
A11: INS CO.Contact person | B11: Phone extension Number | C11: DAY / DATE | D11: TIME | E11: OK
A12: ________________________ | B12: ______________________ | C12: __________________________________________ | D12: AM ___ PM_____ ; _____
A13: Mitigation emergency Services; TARP/TMP WTR HMR DMO | C13: YES _____ | D13: NO_____
A14: Demolition DMO Remove Wet DRY / PLA; materials | C14: YES _____ | D14: NO_____
A15: Contents | B15: CPS/CLN/CON; list all PACKOUT ROOMS | C15: YES _____ | D15: NO_____
A16: CON | B16: Replacement Items; personal property | C16: YES _____ | D16: NO_____
A17: Rebuild | B17: _________________________________________________ | C17: YES _____ | D17: NO_____
A18: Roof & EXT> | B18: _________________________________________________ | C18: YES _____ | D18: NO_____
A19: Other Structures | B19: _________________________________________________ | C19: YES _____ | D19: NO_____
A20: ALE | B20: Additional living Expenses | C20: YES _____ | D20: NO_____
A21: Advance Payment Request/ Materials Draw Request | C21: YES _____ | D21: NO_____
A22: Any Insurer contact about this particular claim . | C22: YES _____ | D22: NO_____
A23: Claim History | B23: _________________________________________________ | D23: YES _____ / NO_____
A27: Claim Reporting | B27: The notice of loss should include the following information:
B28: =+'jobinfo(2)'!C1 -> BENJAMIN, SANDRA L.
A29: Policyholder INFO | B29: =+'jobinfo(2)'!C2 -> 1441 Thomas Road, | D29: =+B2 -> 678) 361-6713
A30: WHO ?? | B30: =+'jobinfo(2)'!C3 -> Decatur, GA
A31: PROVIDE A COPY OF YOUR INSURANCE POLICY & Declarations Page
A32: Insurance Co. Name | B32: =+'jobinfo(2)'!C26 -> STATE FARM | C32: policy # | D32: =+B3 -> CL 11-
A33: Declarations Page dated_________________ | C33: Verify deductable $___________________
A34: Notice of loss should include the policy number & EFFECTIVE DATES
A35: FROM | B35: _____/_____/______ | C35: TO | D35: _____/_____/______
A37: CALL INSURANCE COMPANY TO FILE CLAIM & REQUEST INSPECTION OF PROPERTY.
A38: CLAIMS DEPARTMENT | B38: =+'jobinfo(2)'!C46 -> TBD | C38: =+'jobinfo(2)'!C31 -> DA PH
A40: WHAT ?? | B40: TYPE OF LOSS (PROBLEM)
B41: Causes of the property damage. ________________________ | D41: =+'jobinfo(2)'!C36 -> TBD
B42: ________________________________________
A43: WHEN ?? | B43: DATE OF LOSS ( AS CLOSE AS YOU KNOW)__________________
B44: Date damage first occurred _____/____/2021 | D44: =+'jobinfo(2)'!C37 -> TBD
A46: WHERE ?? | B46: DAMAGES | D46: Also see room index
B47: Type of property damage. | D47: Room/Area
A48: Room/Area | B48: ___________________________ | C48: ___________ | D48: __________________
A49: ___________ | B49: ___________________________ | C49: ___________ | D49: __________________
...

Sheet forms
A1: =+'jobinfo(2)'!$C$1 -> BENJAMIN, SANDRA L. | C1: =+N1 -> JOB FORMS | D1: =+'jobinfo(2)'!C1 -> BENJAMIN, SANDRA L. | F1: #155 | G1: =+'jobinfo(2)'!$C$1 -> BENJAMIN, SANDRA L. | H1: NEW CUSTOMER # | I1: =+N1 -> JOB FORMS | L1: =+'jobinfo(2)'!$C$1 -> BENJAMIN, SANDRA L. | N1: JOB FORMS
A2: 1 | B2: =+M2 -> CONTRACT PACKAGE; | C2: =+N2 -> CONTRACT PACKAGE; | D2: as needed per job | F2: FORMS | H2: =+'jobinfo(2)'!B1 -> Property-Owner Name | I2: =+'jobinfo(2)'!C1 -> BENJAMIN, SANDRA L. | L2: 1 | M2: CONTRACT PACKAGE; | N2: =+M2 -> CONTRACT PACKAGE;
B3: =+M3 -> BASIC SUMMARY OF RESTORATION PROCESS; (Quick version). | D3: ADJUST PRINT AREA | H3: =+'jobinfo(2)'!B2 -> Property address: street | I3: =+'jobinfo(2)'!C2 -> 1441 Thomas Road, | M3: BASIC SUMMARY OF RESTORATION PROCESS; (Quick version).
B4: =+M4 -> Signed contract verification , MOU sent | H4: =+'jobinfo(2)'!B3 -> Property city, state, zip | I4: =+'jobinfo(2)'!C3 -> Decatur, GA | M4: Signed contract verification , MOU sent
B5: =+M5 -> Copy of Policy (full pages) Declaration page for AOB | H5: =+'jobinfo(2)'!B4 -> Customer Email | I5: =+'jobinfo(2)'!C4 -> stephanie@trisproductions.com | M5: Copy of Policy (full pages) Declaration page for AOB
A6: =1+A2 -> 2 | B6: =+M6 -> Claim Brief & .'REPORTING SUMMARY | C6: =+N6 -> Claim Brief & .'REPORTING SUMMARY | D6: =+B7 -> INDEX = LISTING of Job Work Areas. | H6: =+'jobinfo(2)'!B5 -> Cst-owner Phone# | I6: =+'jobinfo(2)'!C5 -> 678) 361-6713 | L6: =1+L2 -> 2 | M6: Claim Brief & .'REPORTING SUMMARY | N6: =+M6 -> Claim Brief & .'REPORTING SUMMARY
B7: =+M7 -> INDEX = LISTING of Job Work Areas. | D7: ADJUST PRINT AREA | F7: =+I2 -> BENJAMIN, SANDRA L. | H7: =+'jobinfo(2)'!B11 -> Cause of Loss | I7: =+'jobinfo(2)'!C11 -> WIND HAIL | M7: INDEX = LISTING of Job Work Areas.
A8: =1+A6 -> 3 | B8: =+M8 -> Exterior Mitigation & Scope | C8: =+B8 -> Exterior Mitigation & Scope | H8: =+'jobinfo(2)'!B12 -> date of loss | I8: =+'jobinfo(2)'!C12 -> 45300 | L8: =1+L6 -> 3 | M8: Exterior Mitigation & Scope | N8: =+M8 -> Exterior Mitigation & Scope
B9: =+M9 -> a.) Supplies & Equipment b.) Mitigation c.) Scope | H9: =+'jobinfo(2)'!B13 -> rebuild type 1 | I9: =+'jobinfo(2)'!C13 -> ROOF SHINGLES | M9: a.) Supplies & Equipment b.) Mitigation c.) Scope
A10: =1+A8 -> 4 | B10: =+M10 -> SKETCHES / FLOOR PLAN / Interior SCOPE | C10: =+B10 -> SKETCHES / FLOOR PLAN / Interior SCOPE | D10: ADJUST PRINT AREA | H10: =+'jobinfo(2)'!B14 -> rebuild type 2 | I10: =+'jobinfo(2)'!C14 -> interior repairs | L10: =1+L8 -> 4 | M10: SKETCHES / FLOOR PLAN / Interior SCOPE | N10: =+M10 -> SKETCHES / FLOOR PLAN / Interior SCOPE
B11: =+M11 -> Interior SCOPE/SHEETS | D11: =+B10 -> SKETCHES / FLOOR PLAN / Interior SCOPE | H11: =+'jobinfo(2)'!B15 -> rebuild type 3 | I11: =+'jobinfo(2)'!C15 -> exterior repairs | M11: Interior SCOPE/SHEETS
G12: FORMS | H12: =+'jobinfo(2)'!B16 -> DEMO | I12: =+'jobinfo(2)'!C16 -> Y | M12: per room/area; as needed per job/ Kitchen&Bath=SCOPE Of Work
A13: =1+A10 -> 5 | B13: =+M13 -> Interior SCOPE/SHEETS | C13: =+N13 -> Interior SCOPE/SHEETS | D13: ADJUST PRINT AREA | H13: =+'jobinfo(2)'!B17 -> Mitigation | I13: =+'jobinfo(2)'!C17 -> Y | L13: =1+L10 -> 5 | M13: Interior SCOPE/SHEETS | N13: =+M13 -> Interior SCOPE/SHEETS
B14: =+M14 -> per room/area; as needed per job | D14: =+B13 -> Interior SCOPE/SHEETS | H14: =+'jobinfo(2)'!B18 -> Other Structures | I14: =+'jobinfo(2)'!C18 -> TBD | M14: per room/area; as needed per job
B15: =+#REF! -> #REF! | M15: =+B15 -> #REF!
A16: =1+A13 -> 6 | B16: =+M16 -> INTERIOR Mitigation a) Equipment b) Supplies c) Scope of Mitigation | C16: =+N16 -> INTERIOR Mitigation a) Equipment b) Supplies c) Scope of Mitigation | D16: ADJUST PRINT AREA | H16: =+'jobinfo(2)'!B19 -> Replacement | I16: =+'jobinfo(2)'!C19 -> Y | L16: =1+L13 -> 6 | M16: INTERIOR Mitigation a) Equipment b) Supplies c) Scope of Mitigation | N16: =+M16 -> INTERIOR Mitigation a) Equipment b) Supplies c) Scope of Mitigation
B17: =+M17 -> a) Equipment b) Supplies c) Mitigation Scope | D17: b)Mitigation c)Scope d)Readings | F17: 1 | G17: 1 | H17: =+'jobinfo(2)'!B20 -> CPS / CLN / CON/ CGN | I17: =+'jobinfo(2)'!C20 -> Y | M17: a) Equipment b) Supplies c) Mitigation Scope
D18: DH Dry Chambers zip poles Elc | F18: 5 | G18: 5 | H18: =+'jobinfo(2)'!B26 -> Insurance Co. Name | I18: =+'jobinfo(2)'!C26 -> STATE FARM
A19: =1+A16 -> 7 | B19: =+M19 -> INTERIOR Mitigation READINGS !!!! a.) MC b.) RH c.) F TEMP | C19: =+B19 -> INTERIOR Mitigation READINGS !!!! a.) MC b.) RH c.) F TEMP | D19: ADJUST PRINT AREA | F19: 5 | G19: 5 | H19: =+'jobinfo(2)'!B27 -> Claim # | I19: =+'jobinfo(2)'!C27 -> CL 11- | L19: =1+L16 -> 7 | M19: INTERIOR Mitigation READINGS !!!! a.) MC b.) RH c.) F TEMP | N19: =+M19 -> INTERIOR Mitigation READINGS !!!! a.) MC b.) RH c.) F TEMP
B20: =+M20 -> a.) MC b.) RH c.) F TEMP | C20: =+B20 -> a.) MC b.) RH c.) F TEMP | D20: =+B21 -> Contents SCOPE = QUICKVIEW | F20: I | H20: =+'jobinfo(2)'!B28 -> policy # | I20: =+'jobinfo(2)'!C28 -> TBD PL# | M20: a.) MC b.) RH c.) F TEMP
A21: =1+A19 -> 8 | B21: =+M21 -> Contents SCOPE = QUICKVIEW | C21: =+B21 -> Contents SCOPE = QUICKVIEW | F21: I | H21: =+'jobinfo(2)'!B29 -> Email INS. co. | I21: =+'jobinfo(2)'!C29 -> STATEFARMFIRECLAIMS@STATEFARM.COM | L21: =1+L19 -> 8 | M21: Contents SCOPE = QUICKVIEW | N21: =+M21 -> Contents SCOPE = QUICKVIEW
B22: HMR Hazrdous Materials | F22: I | H22: =+'jobinfo(2)'!B30 -> DESK Adjuster DA | I22: =+'jobinfo(2)'!C30 -> DA | M22: =+B22 -> HMR Hazrdous Materials
B23: Exterior Maintenance INT Maintenance | M23: =+B23 -> Exterior Maintenance INT Maintenance
