Workbook
Name a...new_customer: #REF!
Name a...new_customer: #REF!
Name a...new_customer: #REF!
Name Advance_Payment_Request: 'notary pgs'!#REF!
Name Advance_Payment_Request: release!#REF!
Name Advance_Payment_Request: current!#REF!
Name Assignment_of_Benefits_and_Direct_Payment_Authorization: 'notary pgs'!#REF!
Name Assignment_of_Benefits_and_Direct_Payment_Authorization: release!#REF!
Name Assignment_of_Benefits_and_Direct_Payment_Authorization: current!#REF!
Name causeoflosslist: #REF!
Name CO.REP._email: [1]current!$F$14
Name Column.a.new.cst: 'jobinfo(2)'!$B$1:$B$43
Name Column.a.new.cst: 'jobinfo(2)'!$B$1:$B$43
Name Column.a.new.cst: current!#REF!
Name column.c.new.cst: #REF!
Name column.c.new.cst: #REF!
Name column.c.new.cst: #REF!
Name company.rep.1: [1]current!$F$13
Name cst.Barnes: #REF!
Name cst.Barnes: #REF!
Name cst.Barnes: #REF!
Name cst.Bethlehem_Temple_of_Praise: #REF!
Name cst.Bradford_Rivers: #REF!
Name cst.Hamilton__Nakeysha: #REF!
Name cst.Motley__Gloria: #REF!
Name cst.Motley__Gloria: #REF!
Name cst.Motley__Gloria: #REF!
Name cst.nori9rock_gmail.com: #REF!
Name cst.Nunn: #REF!
Name cst.Nunn: #REF!
Name cst.Nunn: #REF!
Name cst.Stewart__Antwain: #REF!
Name cst.Stewart__Antwain: #REF!
Name cst.Stewart__Antwain: #REF!
Name culpepper: #REF!
Name culpepper: #REF!
Name culpepper: #REF!
Name data: [2]QUOTE!$A$267:$R$424
Name DATA2: [3]estimate!$A$117:$R$440
Name Emergency: [4]estimate!#REF!
Name Emergency: [4]estimate!#REF!
Name Emergency: [4]estimate!#REF!
Name EMERGENCY_Repairs: [4]estimate!#REF!
Name EMERGENCY_Repairs: [4]estimate!#REF!
Name EMERGENCY_Repairs: [4]estimate!#REF!
Name Homeowner_______________________________________________Phone_________________________: [5]estimate!$D$10
Name Insurance_Claim___Check_Processing: 'notary pgs'!#REF!
Name Insurance_Claim___Check_Processing: release!#REF!
Name Insurance_Claim___Check_Processing: current!$A$292:$D$336
Name Jefferies: #REF!
Name Jefferies: #REF!
Name Jefferies: #REF!
Name LOVEJOY_INTERIOR: #REF!
Name LOVEJOY_INTERIOR: #REF!
Name LOVEJOY_INTERIOR: #REF!
Name Lovejoy_ROOF: #REF!
Name Lovejoy_ROOF: #REF!
Name Lovejoy_ROOF: #REF!
Name LxWxH: [2]QUOTE!#REF!
Name LxWxH: [2]QUOTE!#REF!

Sheet notary pgs
A1: GLOBAL SETTLEMENT AGREEMENT & MUTUAL RELEASE OF ALL CLAIMS BY ALL PARTIES
A4: Governing Law
A5: This RELEASE is to be construed under the laws of the State of | D5: =+'jobinfo(2)'!C3 -> 0
A6: The prevailing party in any action to enforce this RELEASE shall be entitled to attorneys’ fees, interest, costs and expenses of litigation (both at trial and upon appeal).
A7: Severability
A8: If any provision of this RELEASE is declared unenforceable for any reason, the remaining provisions of this RELEASE shall be unaffected thereby and shall remain in full force and effect.
A10: Attachments as fully associated and as fully part of the foregoing document:
A12: Witness Attestation; "Contractor" " of "The Parties" | D12: "Party #1"
A13: Accceptance of Full Agreement & Full Authority to execute This Agreement | D13: "Party #1"
A14: Accceptance of Full Agreement & Full Authority to execute This Agreement | D14: "Party #2"
A15: Witness Attestation; "Owner" " of "The Parties" | D15: "Party #2"
A16: Accceptance of Full Agreement & Full Authority to execute This Agreement | D16: "Party #3"
A17: Witness Attestation; "PARTY #3" " of "The Parties" | D17: "Party #3"
A19: Witness Attestation; "Contractor" " of "The Parties" | D19: "Party #1"
A20: We, the undersigned "Contractor" as one of "The Parties" and the undersigned witnesses, respectively, whose names are signed to the attached or foregoing instrument declare:
A21: (1) that the "Contractor " as one of "The Parties" executed this "Agreement" .
A22: (2) that, in the presence of both witnesses, the "Contractor " as one of "The Parties" signed this document
A23: (3) that the "Contractor" as one of "The Parties" executed this "Agreement" as a free and voluntary act for the purposes expressed in it;
A24: (4) that each of the witnesses, in the presence of the "Contractor " as one of "The Parties" and of each other, signed this "Agreement" as a witness;
A25: (5) that the "Contractor " as one of "The Parties" was of sound mind when the "Agreement" was ….. .. executed;
A26: (6) that to the best knowledge of each of the witnesses the "Contractor " as one of "The Parties" was, …. at the time the will was executed, at least eighteen (18) years of age .
A27: Witness Signature # 1 of 2_ X_____________________________________ Date ____/_____/_____
A28: Printed Legal Name ____________________________________________
A29: Witness Signature # 2 of 2_ X_____________________________________ Date ____/_____/_____
A30: Printed Legal Name ____________________________________________
A31: =+A19 -> Witness Attestation; "Contractor" " of "The Parties" | D31: =+D19 -> "Party #1"
A32: Accceptance of Full Agreement & Full Authority to execute This Agreement | D32: "Party #1"
A33: " The Parties" represent and warrant that the representative signing this agreement:
A34: • has read this agreement and is knowingly and voluntarily executing this agreement
A35: in good faith for the reasons set forth herein;
A36: • is at least eighteen (18) years of age and has never been declared incompetent by
A37: any court or agency of the government; and
A38: • has been fully advised as to its legal effect.
A39: * fully understands that by signing this pages agrees to to the foregoing above pages
A40: " The Parties" declare that they have read and understand the foregoing
A41: RELEASE and have full legal capacity to execute this RELEASE.
A42: SIGNED WITNESSED AND SEALED this _____ day of ____________, 20_____.
A43: X ________________________________________________
A44: =+'jobinfo(2)'!C96 -> 0
B45: as one of "The Parties" executed this "Agreement"
...

Sheet release
A1: GLOBAL SETTLEMENT AGREEMENT & MUTUAL RELEASE OF ALL CLAIMS BY ALL PARTIES
D2: page #
A3: "The Parties" | D3: 2
A4: ACKNOWLEDGEMENT OF CONSIDERATION | D4: 3
A5: "The Parties" Responsible for Fees | D5: 4
A6: No Assignment Clause | D6: 4
A7: Non Disclosure Clause | D7: 5
A8: A general release intended to release all claims | D8: 5
A9: Voluntary and Non inducement Clause of Agreement | D9: 5
A10: "The Project " Work performed | D10: 6
A11: Covenant not to cause or to institute any lawsuit. | D11: 7
A12: Withdrawal of Any Existing Lawsuits / Litigation | D12: 7
A13: Waiver of Liens | D13: 7
A14: Complete and FINAL RELEASE. | D14: 7
A15: Governing Law | D15: 7
A16: Severability
A19: Attachments as fully associated and as fully part of the foregoing document:
A20: Witness Attestation; "Contractor" " of "The Parties" | D20: "Party #1"
A21: Acceptance of Full Agreement & Full Authority to execute This Agreement | D21: "Party #1"
A22: Acceptance of Full Agreement & Full Authority to execute This Agreement | D22: "Party #2"
A23: Witness Attestation; "Owner" " of "The Parties" | D23: "Party #2"
A24: Acceptance of Full Agreement & Full Authority to execute This Agreement | D24: "Party #3"
A25: Witness Attestation; "PARTY #3" " of "The Parties" | D25: "Party #3"
A26: Witness Attestation; "Contractor" " of "The Parties" | D26: "Party #1"
A29: X | B29: the referring/connecting party | D29: Party #3
A31: GLOBAL SETTLEMENT AGREEMENT & MUTUAL RELEASE OF ALL CLAIMS BY ALL PARTIES
A32: "The Parties"
A33: THIS GLOBAL SETTLEMENT AGREEMENT & MUTUAL RELEASE OF ALL CLAIMS BY ALL PARTIES (“Agreement”) is dated, entered into and made fully effective
A34: 44510 | B34: (irrespective of the date actually signed by "THE PARTIES").
A35: =+'jobinfo(2)'!C100 -> 0 | C35: =+'jobinfo(2)'!C112 -> 0
A36: Project Manager, | B36: personally and corporately. | D36: , Party #1/Contractor
A37: =+'jobinfo(2)'!C1 -> 0 | B37: =+'jobinfo(2)'!C6 -> 0 | D37: , Party #2/Owner{s}
A38: =+A29 -> X | B38: the referring/connecting party | D38: Party #3
A39: ( "The Parties" as herein collectively referred to.) Have been in settlement discussions regarding the herein stated matter ( "Contract" or "PROJECT").
A41: As per our conversation, we ( "The Parties") have reached an "Agreement" in compromise of this "Contract & or PROJECT"; as a resolution to bring this matter to closure. In no way do ( "The Parties"") imply or convey that the execution of the release of all claims is required for settlement of this matter; as other settlement options and means are available for resolution.
A43: Execution of this Agreement or any act or failure to act on the part of all "THE PARTIES" by contract or at law as all such rights and defenses are hereby specifically reserved.
A45: Whereas the herein stated parties with full purpose and intent desire to sever and forever cancel and extinguish any and all contractual relationships by mutual execution of this document.
A47: COMES NOW, | B47: =+A35 -> 0 | C47: in its individual capacity and as assignee.
A48: =+C35 -> 0 | C48: , personally and corporately.
A49: =+A29 -> X | B49: the referring/connecting party
...

Sheet atty rel
A1: =+'jobinfo(2)'!C95 -> 0
A2: =+'jobinfo(2)'!C96 -> 0 | C2: =+'jobinfo(2)'!C97 -> 0
A3: =+'jobinfo(2)'!C100 -> 0 | B3: =+'jobinfo(2)'!C98 -> 0 | D3: =+'jobinfo(2)'!C102 -> 0
A4: =+'jobinfo(2)'!C101 -> 0 | B4: =+'jobinfo(2)'!C99 -> 0 | D4: =+'jobinfo(2)'!C103 -> 0
A5: =+'jobinfo(2)'!C104 -> 0
A6: =+'jobinfo(2)'!C105 -> 0 | C6: =+'jobinfo(2)'!C106 -> 0
A7: COMPANY REP. | B7: =+'jobinfo(2)'!C107 -> 0 | C7: =+'jobinfo(2)'!C108 -> 0
A8: COMPANY REP. #2 | B8: =+'jobinfo(2)'!C109 -> 0 | C8: =+'jobinfo(2)'!C110 -> 0
A9: =+'jobinfo(2)'!B1 -> Property-Owner Name | B9: =+'jobinfo(2)'!C1 -> 0 | C9: =+'jobinfo(2)'!B11 -> Cause of Loss | D9: =+'jobinfo(2)'!C11 -> 0
A10: =+'jobinfo(2)'!B2 -> Property address: street | B10: =+'jobinfo(2)'!C2 -> 0 | C10: =+'jobinfo(2)'!B12 -> date of loss | D10: =+'jobinfo(2)'!C12 -> 0
A11: =+'jobinfo(2)'!B3 -> Property city, state, zip | B11: =+'jobinfo(2)'!C3 -> 0 | C11: =+'jobinfo(2)'!B13 -> rebuild type 1 | D11: =+'jobinfo(2)'!C13 -> 0
A12: =+'jobinfo(2)'!B4 -> Customer Email | B12: =+'jobinfo(2)'!C4 -> 0 | C12: =+'jobinfo(2)'!B14 -> rebuild type 2 | D12: =+'jobinfo(2)'!C14 -> 0
A13: =+'jobinfo(2)'!B5 -> Cst-owner Phone# | B13: =+'jobinfo(2)'!C5 -> 0 | C13: =+'jobinfo(2)'!B15 -> rebuild type 3 | D13: =+'jobinfo(2)'!C15 -> 0
A14: Insurance Co. Name & Policy # | B14: =+'jobinfo(2)'!C26 -> 0 | C14: =+'jobinfo(2)'!C27 -> 0 | D14: =+'jobinfo(2)'!C16 -> 0
A15: To Whom It May Concern:
A16: Please be advised that we are under the impression that you either desire to cancel or modify the terms of our original legally binding contract
A17: dated on or about | B17: =+'jobinfo(2)'!C22 -> 0
A18: It is our stern and fast position that we choose only to work with people whom we can maintain a cordial , professional relationship.
A19: Your actions suggest and have caused the nature of the relationship to deteriorate greatly, some of your remarks could occur as personal threats and or harassment. Also possible liebel and or slander. We do have concerns for our safety in dealing with you. No one from our firm will meet with in person any longer; unless it is a highly public place where we feel safe.
A20: We have invested more time into this file that than our standard time frame and we will not proceed any further without a clear , well defined understanding with you.
A21: Including raising the insurance company's offer from $2,144 to 8,914; an increase of $6,770. That was round one only!!!!!!
A22: Then raising the insurance company's offer from $8,914 to $17,814; an increase of $9,000. That was based on our efforts and expertise!!!!!!
A23: If you desire to end this business relationship you may prepare your own release proposal , use our standard mutual release form or possibly have your attorney prepare a mutual release document.
A24: Per the contract terms please advise us " in writing" of your position on this matter.
A26: =+current!#REF! -> #REF! | B26: =+current!#REF! -> #REF! | D26: =+current!#REF! -> #REF!
E30: 2000
A31: =+current!#REF! -> #REF! | E31: 6625.18
A32: =+current!#REF! -> #REF! | E32: 6800
A33: =+current!#REF! -> #REF! | E33: 9000
A34: =+current!#REF! -> #REF! | E34: =SUM(E30:E33) -> 24425.18
A35: =+current!#REF! -> #REF!
A36: =+current!#REF! -> #REF!
D40: Gross | E40: 17913.76
D41: 0.2 | E41: =-E40*D41 -> -3582.752
E42: =+E40+E41 -> 14331.008
D43: MTGE | E43: -6500
E44: =+E42+E43 -> 7831.008
D45: roof | E45: =-250*25 -> -6250
D46: Paint | E46: =+E44+E45 -> 1581.008
D47: Deductible | E47: -1000
...

Sheet current
A1: ** GENERAL AUTHORIZATION **
A2: _____CONTRACTOR & HOMEOWNER AGREEMENT_____
A3: AFFIDAVIT AND CERTIFICATION OF INTENT TO REPAIR
A4: Mortgage Company Insurance Claim Check Processing,
A5: Enclosed is an Assignment of Insurance Benefits and Direct Payment Authorization Thus, all monies due to named herein contractor are to be released without delay; solely and directly to contractor.
A6: Original Documents | B6: GENERAL AUTHORIZATION | C6: Policyholder {___} CONTRACTOR {___} | E6: page # | F6: Cover Letter
B7: EMERGENCY SERVICES WORK AUTHORIZATION
B8: Assignment Of Benefits AOB | C8: Policyholder {___} CONTRACTOR {___}
B9: CONTRACTOR & HOMEOWNER AGREEMENT_____
B10: $$ Amount | C10: Policyholder {___} CONTRACTOR {___} | E10: 1
B11: Notice of Right of Recession | E11: =1+E10 -> 2 | F11: EMERGENCY SERVICES WORK AUTHORIZATION
B12: AFFIDAVIT AND CERTIFICATION OF INTENT TO REPAIR | D12: Policyholder {___}
B13: NOTARY | C13: Policyholder {___} | D13: na
A14: Contractor Documents | B14: CONDITIONAL WAIVER OF LIEN | D14: CONTRACTOR {___}
B15: NOTARY PAGE | D15: CONTRACTOR {___}
A16: Enclosed is an Assignment of Insurance Benefits and Direct Payment Authorization Thus, all monies due to named herein contractor are to be released without delay; solely and directly to contractor. | E16: =1+#REF! -> #REF!
A18: FRAUD STATEMENT
A19: Any person who knowingly and with intent to defraud any insurance company or other person files an application for insurance or statement of claim containing any materially false information, or conceals for the purpose of misleading, information concerning any fact material thereto commits a fraudulent insurance act, which is a crime and subjects such person to criminal and civil penalties.
A20: This may include submitting or causing to be submitted on your behalf documents which claim to be for the purpose of obtaining funds not used for the specific purpose of paying the contractor whom provides his services in relation to such documentation.
A22: 14. Owner agrees to use all funds received from insurance proceeds as originally reported and declares all the information concerning their damages and or loss are true to the best of their knowledge. Owner agrees to indemnify and hold harmless the contractor. in relation to this item specifically.
A23: 15. Owner shall promptly notify contractor of any funds received and promptly remit to Contractor;
A24: without delay. Contractor also agrees to notify Owner of any funds received on their behalf.
A25: Owner shall promptly notify and provide contractor with a copy of any paperwork received.
A26: Contractor agrees to wait for payments as disbursed from the insurance and or escrow company.
A27: Contractor further agrees to not demand payments from Owner unless otherwise agreed.
A28: X______________________________ X ___________________________________ | D28: ____/_____/2018
A29: =+$A$62 -> #REF! | C29: Signature of Co- Owner Date
A30: Contract Addendum / Memorandum of UNDERSTANDING
A31: Dear Property-owner:
A32: Please note that we have compiled a listing of issues that may cause unneccessary delays or claim failure or our withdrawal from the claim process.
A33: We ask that you please review the list and initial each and every item. If you feel that any item is not workable for you , then it may be best that we not move forward. .
A34: We are more than willing to discuss in detail any of these or any others and get a mutual understanding
A35: Deductible | D35: ___________INITIAL
A36: * HOMEOWNER MAY USE THE Referral program FUNDS TO PAY FOR THE INSURANCE DEDUCTIBLE.
A37: * HOMEOWNER MAY perform as subcontractor for some of the work; paint / clean/ inventory contents
A38: Roof upgrade & Other work upgrades
A39: HOMEOWNER MAY USE Referrals FUNDS TO PAY FOR UPGRADED 30 YEAR ROOF. | D39: ___________INITIAL
A40: Fear | B40: Fear &Intimidation from insurer | D40: ___________INITIAL
B41: Integrity, concern that we are doing something illegal.
A42: Greed | B42: Overly Concern about our profits. | D42: ___________INITIAL
...

Sheet letter close
A1: =+'jobinfo(2)'!C95 -> 0
A2: =+'jobinfo(2)'!C96 -> 0 | C2: =+'jobinfo(2)'!C97 -> 0
A3: =+'jobinfo(2)'!C100 -> 0 | B3: =+'jobinfo(2)'!C98 -> 0 | D3: =+'jobinfo(2)'!C102 -> 0
A4: =+'jobinfo(2)'!C101 -> 0 | B4: =+'jobinfo(2)'!C99 -> 0 | D4: =+'jobinfo(2)'!C103 -> 0
A5: =+'jobinfo(2)'!C104 -> 0
A6: =+'jobinfo(2)'!C105 -> 0 | C6: =+'jobinfo(2)'!C106 -> 0
A7: COMPANY REP. | B7: =+'jobinfo(2)'!C107 -> 0 | C7: =+'jobinfo(2)'!C108 -> 0
A8: COMPANY REP. #2 | B8: =+'jobinfo(2)'!C109 -> 0 | C8: =+'jobinfo(2)'!C110 -> 0
A9: =+'jobinfo(2)'!B1 -> Property-Owner Name | B9: =+'jobinfo(2)'!C1 -> 0 | C9: =+'jobinfo(2)'!B11 -> Cause of Loss | D9: =+'jobinfo(2)'!C11 -> 0
A10: =+'jobinfo(2)'!B2 -> Property address: street | B10: =+'jobinfo(2)'!C2 -> 0 | C10: =+'jobinfo(2)'!B12 -> date of loss | D10: =+'jobinfo(2)'!C12 -> 0
A11: =+'jobinfo(2)'!B3 -> Property city, state, zip | B11: =+'jobinfo(2)'!C3 -> 0 | C11: =+'jobinfo(2)'!B13 -> rebuild type 1 | D11: =+'jobinfo(2)'!C13 -> 0
A12: =+'jobinfo(2)'!B4 -> Customer Email | B12: =+'jobinfo(2)'!C4 -> 0 | C12: =+'jobinfo(2)'!B14 -> rebuild type 2 | D12: =+'jobinfo(2)'!C14 -> 0
A13: =+'jobinfo(2)'!B5 -> Cst-owner Phone# | B13: =+'jobinfo(2)'!C5 -> 0 | C13: =+'jobinfo(2)'!B15 -> rebuild type 3 | D13: =+'jobinfo(2)'!C15 -> 0
A14: Insurance Co. Name & Policy # | B14: =+'jobinfo(2)'!C26 -> 0 | C14: =+'jobinfo(2)'!C27 -> 0 | D14: =+'jobinfo(2)'!C16 -> 0
A15: To Whom It May Concern:
A16: Please be advised that we are under the impression that you either desire to cancel or modify the terms of our original legally binding contract
A17: dated on or about | B17: =+'jobinfo(2)'!C22 -> 0
A18: It is our stern and fast position that we choose only to work with people whom we can maintain a cordial , professional relationship. | E18: It is our stern and fast position that we choose only to work with people whom we can maintain a cordial , professional relationship.
A19: Your actions suggest and have caused the nature of the relationship to deteriorate greatly, some of your remarks could occur as personal threats and or harassment. Also possible liebel and or slander. We do have concerns for our safety in dealing with you. No one from our firm will meet with in person any longer; unless it is a highly public place where we feel safe. | E19: Your actions suggest and have caused the nature of the relationship to deteriorate greatly, some of your remarks could occur as personal threats and or harassment. Also possible liebel and or slander. We do have concerns for our safety in dealing with you. No one from our firm will meet with in person any longer; unless it is a highly public place where we feel safe.
A20: We have invested more time into this file that than our standard time frame and we will not proceed any further without a clear , well defined understanding with you. | E20: We have invested more time into this file that than our standard time frame and we will not proceed any further without a clear , well defined understanding with you.
A21: Including raising the insurance company's offer from $2,144 to 8,914; an increase of $6,770. That was round one only!!!!!! | E21: Including raising the insurance company's offer from $2,144 to 8,914; an increase of $6,770. That was round one only!!!!!!
A22: Then raising the insurance company's offer from $8,914 to $17,814; an increase of $9,000. That was based on our efforts and expertise!!!!!! | E22: Then raising the insurance company's offer from $8,914 to 17 8,914; an increase of $9,000. That was based on our efforts and expertise!!!!!!
A23: If you desire to end this business relationship you may prepare your own release proposal , use our standard mutual release form or possibly have your attorney prepare a mutual release document.
A24: Per the contract terms please advise us " in writing" of your position on this matter.
A26: =+current!#REF! -> #REF! | B26: =+current!#REF! -> #REF! | D26: =+current!#REF! -> #REF!
E30: 2000
A31: =+current!#REF! -> #REF! | E31: 6625.18
A32: =+current!#REF! -> #REF! | E32: 6800
A33: =+current!#REF! -> #REF! | E33: 9000
A34: =+current!#REF! -> #REF! | E34: =SUM(E30:E33) -> 24425.18
A35: =+current!#REF! -> #REF!
A36: =+current!#REF! -> #REF!
D40: Gross | E40: 17913.76
D41: 0.2 | E41: =-E40*D41 -> -3582.752
E42: =+E40+E41 -> 14331.008
D43: MTGE | E43: -6500
E44: =+E42+E43 -> 7831.008
D45: roof | E45: =-250*25 -> -6250
D46: Paint | E46: =+E44+E45 -> 1581.008
D47: Deductible | E47: -1000
...

Sheet jobinfo(2)
A1: Customer | B1: Property-Owner Name
B2: Property address: street
B3: Property city, state, zip
B4: Customer Email
B5: Cst-owner Phone#
B6: Co-Owner.cst#2
B7: cst ph # 2
B8: Cst address # 2
B9: city, state-cst#2
B10: email-cst #2
A11: Loss Info | B11: Cause of Loss
B12: date of loss
B13: rebuild type 1
B14: rebuild type 2
B15: rebuild type 3
B16: DEMO
B17: Mitigation
B18: Other Structures
A19: CPS | B19: Replacement
B20: CPS / CLN / CON/ CGN
B21: Year Built
B22: Contract Date
B23: Loss of use/ ALE
B24: Breathing issue
B25: HMR
B26: Insurance Co. Name
A27: Insurance Co. | B27: Claim #
B28: policy #
B29: Email INS. co.
B30: DESK Adjuster DA
B31: DA Phone
B32: DA Ph. Ext. #
B33: DA Email
B34: Field Adjuster Name
B35: Phone # field adj
B36: Field adj email
B37: adj contents
B38: adj CPS phone #
B39: adj CPS email
... B52: ROOM ID
...
