Workbook
Name a...new_customer: #REF!
Name a...new_customer: #REF!
Name a...new_customer: #REF!
Name basicroompichow2: #REF!
Name box_names: +#REF!
Name Column.a.new.cst: #REF!
Name culpepper: #REF!
Name data: #REF!
Name Document_Stacking_List: #REF!
Name Enter_new_cst_data: #REF!
Name Jefferies: #REF!
Name LOVEJOY_INTERIOR: #REF!
Name Lovejoy_ROOF: #REF!
Name LxWxH: #REF!
Name new_customer: #REF!
Name PRICE_P: #REF!
Name Robinson: #REF!
Name sigtj: "Picture 9859"
Name SubContractor_Summary: #REF!
Name Wayside_Builders__LLC_…...OH: #REF!
Name WSB...GA.Wayside_Builders__LLC……GA: #REF!

Sheet quick chklst
A1: BASIC SUMMARY OF RESTORATION PROCESS; (Quick version). | D1: =+'jobinfo(2)'!C2 -> 6600 GERTRUDE
A2: JOB | C2: =+'jobinfo(2)'!C51 -> OH25THOMAS@GERTRUDE | D2: =+'jobinfo(2)'!C3 -> Cleveland, OH 44105
A3: 1 | B3: Introduction, Analysis & Verification | C3: Introduction, Analysis & Verification /source/referred by: | D3: Status Notes / %
C4: Who is the Insurance Company ?!? | D4: ='jobinfo(2)'!C26 -> ALLSTATE INS CO. | G4: 100
A5: POI | C5: Does customer Comprehend Our Role in the process? | D5: Y
C6: Is this a COVERED INSURANCE Claim? Or Self Pay ? | D6: Y
C7: IS THE DAMAGE $ MORE THAN THE DEDUCTIBLE? | D7: Y
C8: Do they have coverage; for AOB? = POLICY & DEC PAGE | D8: Y | G8: 200
A9: 2 | B9: Contracts & Documentation | C9: Contracts & Documentation | D9: Y
C10: Has Customer been fully advised of Contract Contents? | D10: Y
C11: Has Customer had a full Consultation to Our Terms & Conditions? | D11: Y | G11: 500
A12: DOC | C12: Does Customer FULLY Agree to Terms &Conditions? Signed / Initials? | D12: Y
C13: Notary Page explained/ Fast track | D13: Y
A14: mou | C14: Company investment (dollars, time ,materials)into their Project? | D14: Y
C15: Mutual trust , cooperation & confidence | D15: Y
A16: 3 | C16: CLAIM REPORTING;DOES THE CUSTOMER HAVE REQUIRED INFO? | D16: Y
A17: INS | C17: Insurer Mitigation / DMO / CPS Approval Info Sheet | D17: Y | G17: 100
A18: PICS | C18: Create ENCIRCLE project (Pictures critical part of PAYMENTprocess! | D18: Y
A19: mit | B19: Mitigation & Demolition | C19: Mitigation & Demolition (ROOM LABELS POSTED)
A20: 4 | C20: Roof & EXT Mitigation TEMPORARY & EMERGENCY REPAIRS | D20: Y | G20: 1000
A21: 5 | C21: Contents_ item list_; storage details; security explained? | D21: Y | G21: 2000
A22: 6 | C22: Interior Mitigation; household disruption explained? | D22: NA | G22: 2000
C23: HMR / Secondary Damages; Equipment & Electricity $ | D23: NA
A24: esx | B24: Estimates | C24: Estimates (Inspection/Scope Form)
C25: SKETCH/DRAWING;[1] sheet per floor
A26: 7 | C26: Interior & EXTERIOR REBUILD | G26: 200
C27: EXTERIOR MITIGATION | D27: Y
C28: INTERIOR Mitigation & Demolition | D28: NA
A29: 8 | B29: Insurance Company Meetings | C29: Insurance Company Meetings
A30: adj | C30: Docs for adjuster meeting; Print & bind docs BE PRESENT WHEN ADJUSTER VISITS The PROPERTY. | G30: 500
A31: 9 | B31: Cashflow General Contractor / Subcontracts | C31: Cashflow General Contractor / Subcontracts
A32: job | C32: Contents
A33: 10 | B33: Mitigation & Demolition | C33: & EXterior Mitigation & Demolition
B34: Interior Mitigation & Demolition | C34: Closeout Interior Mitigation & Demolition
C35: Rebuild
G36: =SUM(G1:G35) -> 6600
C37: BASIC SUMMARY OF RESTORATION PROCESS; (Quick version). | D37: =+'jobinfo(2)'!$C$2 -> 6600 GERTRUDE
A38: JOB | C38: =+'jobinfo(2)'!C51 -> OH25THOMAS@GERTRUDE | D38: =+'jobinfo(2)'!$C$3 -> Cleveland, OH 44105
A39: 1 | B39: Introduction, Analysis & Verification | C39: Introduction, Analysis & Verification /source/referred by: | D39: ='jobinfo(2)'!$C$27 -> CLM
C40: Who is the Insurance Company ?!? | D40: ='jobinfo(2)'!$C$26 -> ALLSTATE INS CO.
...

Sheet OFS INITIAL CKLST
B1: OFFICE QUICKLIST | D1: ='jobinfo(2)'!C1 -> THOMAS, ANITA
A2: INITIAL DOCS IN ( to start claim)
A3: 1 | B3: VERIFY / ASSESS DAMAGE; Full Consultation to Our Terms/Conditions? MOU Our Role in process? | C3: REQUEST IN & OUT | E3: 201
A4: 2 | B4: POLICY & DEC PAGE = ACV or Replacement Do they have coverage; | C4: REQUEST IN | D4: ='jobinfo(2)'!C2 -> 6600 GERTRUDE | E4: =E3+1 -> 202
A5: 3 | B5: Does customer Comprehend AOB? DEDUCTABLE PAYMENT? PAID____ | C5: REQUEST IN | E5: =E4+1 -> 203
A6: 4 | B6: Create ENCIRCLE project; CONTRACT SIGNED / Notary Page explained = Fast track ….AOB? | C6: REQUEST SENT & IN | E6: =E5+1 -> 204
A7: 5 | B7: JOBSITE VERIFICATION PICS & ROOMS VIDEO …..& SHORT ROOM LIST... (upon initial visit) | C7: CREATE | D7: ='jobinfo(2)'!B5 -> Cst-owner Phone# | E7: =E6+1 -> 205
A8: INITIAL DOCS OUT TO CUSTOMER ( to start claim) | D8: ='jobinfo(2)'!C5 -> (216) 315-2040 | E8: =E7+1 -> 206
A9: 6 | B9: CLAIM REPORTING Info Sheet;Insurer Approval [Mitigation/DMO/CPS] DOCUMENT CONTACT | C9: REQUEST SENT & IN | E9: =E8+1 -> 207
A10: 7 | B10: MOU SENT OUT TO CUSTOMER | C10: REQUEST SENT & IN | D10: ='jobinfo(2)'!C4 -> A@EM | E10: =E9+1 -> 208
A11: INITIAL REPORTS/DOCS GENERATED ( to start claim) | E11: =E10+1 -> 209
A12: 8 | B12: Order REPORT ..; Eagleview Roof / …. Siding / ….. PLUMBERS / …. FIRE / …..POLICE | C12: CREATE | E12: =E11+1 -> 210
B13: LEAD HMR TESTING
A14: 9 | B14: ENCIRCLE FLOOR PLAN …................... CREATED @ JOBSITE | C14: CREATE | E14: =E12+1 -> 211
A15: 10 | B15: Create ENCIRCLE Project; ROOM LISTS….. SHARE 2 TEAM Option ( V2 then Merge) | C15: CREATE | E15: =E14+1 -> 212
B16: SELECT JOB TYPE per STOCK ROOM LISTS; = WTR / FIRE or RFG & WTR | C16: CREATE | D16: ='jobinfo(2)'!C26 -> ALLSTATE INS CO. | E16: =E15+1 -> 213
B17: Determine / Input job Room names per jobsite visit ROOM ORDER SET-UP | C17: CREATE | E17: =E16+1 -> 214
B18: GENERATE ROOM LABELS & CPS BOX LABELS ; EMAIL OUT | C18: CREATE | E18: =E17+1 -> 215
B19: 100 ROOMS Overview / 360 = Scope Form | C19: CREATE | E19: =E18+1 -> 216
B20: 400 SOURCE OF LOSS 500 CPS DAY 1 / 2 / 3 / 4 | C20: CREATE | E20: =E19+1 -> 217
B21: 800 MIT W.I.P. & EQPT Mitigation LABELS (Demolition) | C21: CREATE | E21: =E20+1 -> 218
B22: READINGS DAY 1 / 2 / 3 / 4 … 6000 MC & 7000 RHT+GPP | C22: CREATE | E22: =E21+1 -> 219
A23: 12 | B23: IMPORT & EDIT The ENCIRCLE FLOOR PLAN (PRINT AS NEEDED) | C23: IN | E23: =E22+1 -> 220
A24: 13 | B24: (UPDATE AS NEEDED) CREATE ROOM Names LISTS in ENCIRCLE & EXCEL | E24: =E23+1 -> 221
A25: 14 | B25: RUN EXCEL MACRO & VERIFY TEMPLATES | C25: CREATE | D25: ='jobinfo(2)'!C27 -> CLM | E25: =E24+1 -> 222
A26: AUTOMATE THE FOLLOWING | E26: =E25+1 -> 223
A27: GENERATE LABELS = ROOMS / CPS BOXES / MITIGATION EQUIPTMENT PLACEMENT; …. | C27: EMAIL OUT | E27: =E26+1 -> 224
A28: 16 | B28: RUN EXCEL MACRO 4 MITIGATION WORK & EQUIPMENT | C28: CREATE | E28: =E27+1 -> 225
A29: 17 | B29: CREATE & SEND; ROOMS SCOPE FORM (FUTURE = 360 CAMERA) | C29: EMAIL OUT
A30: 19 | B30: Mitigation LABELS (Demolition) | C30: EMAIL OUT
A31: 20 | B31: Enter Room Sizes (from Encircle Floor Plan) & Damage Percentages %: @ jobinfo2 | C31: CREATE
A32: 21 | B32: Calculate MIT Equipment (MIT Eqpmnt ALL) & Deliver To Jobsite/Set Up Equipment | C32: EMAIL OUT
B33: CREATE & SEND; MIT EQUIPMENT SETUP WORK & EQUIPMENT FORM | C33: EMAIL OUT
A34: 22 | B34: Calculate/Estimate CPS Supplies | C34: EMAIL OUT
A35: 23 | B35: Order & Deliver to Jobsite…..... Packout Supplies = boxes / tape / shrink wrap | C35: EMAIL OUT
A36: 24 | B36: GET Inspection/Scope Form [ ENCIRCLE or Genius Scan] sent from app | C36: REQUEST IN
A37: 25 | B37: CREATE XACTIMATE PROJECT; (Copy & Paste DATA from Encircle)
B38: Estimates
A40: 26
A41: 27
...

Sheet jobinfo(2)
A1: Customer | B1: Property-Owner Name | C1: THOMAS, ANITA | M1: Enter info here | Q1: ADD SOS LINK
B2: Property address: street | C2: 6600 GERTRUDE | M2: New Customer Info required | N2: NEEDS TO SELF POPULATE | Q2: LINK TO VIDEOS
B3: Property city, state, zip | C3: Cleveland, OH 44105 | Q3: BEFORE AND AFTER P[CS
B4: Customer Email | C4: A@EM | Q4: CLE ATL NY NC NY
B5: Cst-owner Phone# | C5: (216) 315-2040
B6: Co-Owner.cst#2
B7: cst ph # 2 | Q7: RFG WIP…CURRENT JOBS
B8: Cst address # 2 | Q8: SIGNAGE
B9: city, state-cst#2
B10: email-cst #2
A11: Loss Info | B11: Cause of Loss | C11: Water Damage=WTR | M11: Wind = Roof | N11: Water Damage=WTR | O11: Fire Smoke | P11: Wind=Tree | Q11: Hurricane =HURR
B12: date of loss | C12: Friday, September 12, 2025 | M12: rebuild type
B13: rebuild type 1 | C13: interior repairs LVL1 | M13: roofing shingles replacement | O13: fencing
B14: rebuild type 2 | C14: interior repairs LVL2 | M14: interior repairs | O14: shed
B15: rebuild type 3 | C15: interior repairs LVL13 | M15: exterior repairs | O15: porch patio
B16: DEMO | C16: Y | M16: Y
B17: Mitigation | C17: Y | M17: Y
B18: Other Structures | C18: NA | M18: Y
A19: CPS | B19: Replacement | C19: Y | M19: Y
B20: CPS / CLN / CON/ CGN | C20: Y | M20: Y
B21: Year Built | C21: 1920 | M21: TBD
B22: Contract Date | C22: 45836 | M22: TBD | N22: pre 1980 | O22: post 1980
B23: Loss of use/ ALE | C23: TBD | M23: sample cost 3
B24: Breathing issue | C24: TBD | M24: doctor letter
B25: HMR | C25: TBD | M25: lab test
B26: Insurance Co. Name | C26: ALLSTATE INS CO. | M26: Insurance Company Supplied Info | N26: Per declaration pages | P26: 34-H-6822C9-2
A27: Insurance Co. | B27: Claim # | C27: CLM | N27: Assigned by Insurer
B28: policy # | C28: 880 022 226 | N28: Per declaration pages | O28: OFP DWF 7266580
B29: Email INS. co. | N29: Per declaration pages
B30: DESK Adjuster DA | N30: Assigned by Insurer
B31: DA Phone | N31: customer service rep
B32: DA Ph. Ext. # | N32: Hazel
B33: DA Email | N33: 43789
B34: Field Adjuster Name | N34: 5pm
B35: Phone # field adj
B36: Field adj email
B37: adj contents | N37: Assigned by Insurer
B38: adj CPS phone #
B39: adj CPS email
B40: TMP adj | N40: Assigned by Insurer
...

Sheet ROOMS#
A1: ='jobinfo(2)'!C51 -> OH25THOMAS@GERTRUDE | B1: ='jobinfo(2)'!C3 -> Cleveland, OH 44105 | C1: SOURCE of LOSS | D1: CPS | E1: PPR | F1: DMO DEMO | G1: MIT WTR | H1: MC ... READ INGS | L1: RH &T & GPP DRY CHAMBERS [DC] .READ INGS | P1: LISTS | R1: INPUT = ROOM NAMES | T1: LOS / TRAVEL | U1: OUTPUT = | W1: ROOM NAME ADD TO ENCIRCLE ROOM LISTS | Y1: LOS / TRAVEL | Z1: OUTPUT = ENC ROOM NAME | AD1: LOS / TRAVEL | AE1: OUTPUT = ENC ROOM NAME | AI1: LOS / TRAVEL | AJ1: OUTPUT = ENC ROOM NAME | AK1: OUTPUT = ENC ROOM NAME | AO1: LOS / TRAVEL | AP1: ? | AT1: LOS / TRAVEL | AU1: … MITIGATION EQUIPMENT & W.I.P . ... | AY1: LOS / TRAVEL | AZ1: ... DAY1 MC READINGS .. | BE1: LOS / TRAVEL | BF1: ... DAY2 MC READINGS .. | BJ1: LOS / TRAVEL | BK1: ... DAY3 MC READINGS .. | BO1: LOS / TRAVEL | BP1: ... DAY4 MC READINGS | BT1: LOS / TRAVEL | BU1: RH &T & GPP DRY CHAMBERS [DC] .READ INGS | CB1: DEFAULT TMP1 1 | CD1: WTR METER | CE1: ADD CPS OVERVIEW = MULTIPLE ROOMS / WITH LABELS | CH1: … DAY # 0 … MC READINGS STABILIZATION | CP1: ROOM LABELS
A2: ='jobinfo(2)'!C2 -> 6600 GERTRUDE | H2: DAY1 | I2: DAY2 | J2: DAY3 | K2: DAY4 | L2: DAY1 | M2: DAY2 | N2: DAY3 | O2: DAY4 | P2: = … JOB/ROOMS OVERVIEW PICS .. | U2: =P2 -> = … JOB/ROOMS OVERVIEW PICS .. | Z2: ….. SOURCE of LOSS PICS ….. | AE2: ….. C.P.S. …... | AK2: NON SALVAGEABLE ITEMS | AN2: =E1 -> PPR | AP2: ,,,,,, DMO = DEMOLITION ….... | AU2: =G1 -> MIT WTR | AZ2: .. DAY 1 … | BF2: ….. DAY 2 ….. | BK2: ….. DAY 3 ….. | BP2: ….. DAY 4 ….. | BU2: ….. DAY 1 ….. | CB2: KITCHEN CABINETS SIZES | CE2: BATHROOM VANITY SIZE & FIXTURES | CH2: =CH1 -> … DAY # 0 … MC READINGS STABILIZATION | CL2: LOS / TRAVEL | CP2: ROOM LABELS
A3: =R3 -> JOB/ROOMS OVERVIEW PICS | B3: =B4-1 -> 100 | C3: =C4-1 -> 200 | D3: 300 | E3: =E4-1 -> 400 | F3: 500 | G3: =G4-1 -> 800 | H3: =H4-1 -> 6100.1 | I3: =I4-1 -> 6200.2 | J3: =J4-1 -> 6300.3 | K3: =K4-1 -> 6400.4 | P3: =P4-1 -> 100 | Q3: …. | R3: JOB/ROOMS OVERVIEW PICS | S3: , | T3: ======= | U3: =P3 -> 100 | V3: =Q3 -> …. | W3: =U2 -> = … JOB/ROOMS OVERVIEW PICS .. | Y3: ====== | Z3: =C3 -> 200 | AA3: =V3 -> …. | AB3: =Z2 -> ….. SOURCE of LOSS PICS ….. | AC3: ==================== | AD3: ====== | AE3: =D3 -> 300 | AF3: =AA3 -> …. | AG3: =AE2 -> ….. C.P.S. …... | AH3: ============== | AI3: ====== | AK3: =E3 -> 400 | AL3: =AF3 -> …. | AM3: =AK2 -> NON SALVAGEABLE ITEMS | AN3: ============================== | AP3: =F3 -> 500 | AQ3: …. | AR3: =AP2 -> ,,,,,, DMO = DEMOLITION ….... | AS3: ============================== | AT3: ============================== | AU3: =G3 -> 800 | AV3: . | AW3: MITIGATION EQUIPMENT & W.I.P. ================ MIT & WIP === | AY3: ============================== | AZ3: =AZ4-0.1 -> 6101 | BA3: . | BB3: =AZ1 -> ... DAY1 MC READINGS .. | BC3: ========= | BD3: =============== | BE3: ===== | BF3: =BF4-0.2 -> 6201 | BG3: . | BH3: =BF1 -> ... DAY2 MC READINGS .. | BI3: =============== | BJ3: ====== | BK3: =BK4-0.3 -> 6301 | BL3: . | BM3: =BK2 -> ….. DAY 3 ….. | BN3: ===================== | BO3: ====== | BP3: =BP4-0.4 -> 6401 | BQ3: . | BR3: =BP2 -> ….. DAY 4 ….. | BS3: =============== | BT3: =BP2 -> ….. DAY 4 ….. | BU3: =BU5-0.1 -> 7099.9 | BV3: STABILIZATION READINGS | BW3: ---------------- | CB3: 0 | CC3: ….. | CD3: DEFAULT LIST EXISTS (AS BELOW); CLICK DROPDOWN MENU; ADD JOB TYPES AS NEEDED | CH3: 70000 | CI3: ….. | CJ3: ======= DAY # 0 ….. MC READINGS STABILIZATION =============== | CP3: =R4 -> Living Room | CQ3: =T4 -> ….........
A4: =R4 -> Living Room | B4: =P4 -> 101 | C4: 201 | D4: 301 | E4: 401 | F4: 501 | G4: 801 | H4: 6101.1 | I4: 6201.2 | J4: 6301.3 | K4: 6401.4 | P4: 101 | Q4: …. | R4: Living Room | S4: , | T4: …......... | U4: =P4 -> 101 | V4: =Q4 -> …. | W4: =R4 -> Living Room | X4: =$U$2 -> = … JOB/ROOMS OVERVIEW PICS .. | Y4: =$T$4 -> …......... | Z4: =C4 -> 201 | AA4: =V4 -> …. | AB4: =W4 -> Living Room | AC4: =$Z$2 -> ….. SOURCE of LOSS PICS ….. | AD4: =$T$4 -> …......... | AE4: =D4 -> 301 | AF4: =AA4 -> …. | AG4: =AB4 -> Living Room | AH4: =$AE$2 -> ….. C.P.S. …... | AI4: =$T$4 -> …......... | AK4: =E4 -> 401 | AL4: =AF4 -> …. | AM4: =AG4 -> Living Room | AN4: =$AK$2 -> NON SALVAGEABLE ITEMS | AO4: =$T$4 -> …......... | AP4: =F4 -> 501 | AQ4: …. | AR4: =AM4 -> Living Room | AS4: =AR3 -> ,,,,,, DMO = DEMOLITION ….... | AT4: =T4 -> …......... | AU4: =G4 -> 801 | AV4: . | AW4: =AM4 -> Living Room | AX4: =AU1 -> … MITIGATION EQUIPMENT & W.I.P . ... | AY4: =$T$4 -> …......... | AZ4: =H4 -> 6101.1 | BA4: . | BB4: =AW4 -> Living Room | BC4: =AZ1 -> ... DAY1 MC READINGS .. | BE4: =$T$4 -> …......... | BF4: =I4 -> 6201.2 | BG4: . | BH4: =BB4 -> Living Room | BI4: =BF1 -> ... DAY2 MC READINGS .. | BJ4: =$T$4 -> …......... | BK4: =J4 -> 6301.3 | BL4: . | BM4: =BH4 -> Living Room | BN4: =BK1 -> ... DAY3 MC READINGS .. | BO4: =$T$4 -> …......... | BP4: =K4 -> 6401.4 | BQ4: . | BR4: =BM4 -> Living Room | BS4: =BP1 -> ... DAY4 MC READINGS | BT4: =$T$4 -> …......... | BU4: 7100 | BV4: RH &T & GPP DRY CHAMBERS [DC] .READ INGS =========== | BW4: =BU2 -> ….. DAY 1 ….. | CB4: 0.0001 | CC4: ….. | CD4: JOBSITE VERIFICATION | CH4: 70101 | CI4: . | CJ4: =R4 -> Living Room | CK4: , | CL4: =T4 -> …......... | CM4: , | CN4: =CH1 -> … DAY # 0 … MC READINGS STABILIZATION | CP4: =R5 -> GUEST CLOSET | CQ4: =T5 -> …..........
A5: =R5 -> GUEST CLOSET | B5: =P5 -> 102 | C5: =C4+1 -> 202 | D5: =D4+1 -> 302 | E5: =E4+1 -> 402 | F5: =F4+1 -> 502 | G5: 802 | H5: =H4+1 -> 6102.1 | I5: =I4+1 -> 6202.2 | J5: =J4+1 -> 6302.3 | K5: =K4+1 -> 6402.4 | L5: STABILIZATION READINGS | P5: 102 | Q5: …. | R5: GUEST CLOSET | S5: , | T5: ….......... | U5: =P5 -> 102 | V5: =Q5 -> …. | W5: =R5 -> GUEST CLOSET | X5: =$U$2 -> = … JOB/ROOMS OVERVIEW PICS .. | Y5: =$T$5 -> ….......... | Z5: =C5 -> 202 | AA5: =V5 -> …. | AB5: =W5 -> GUEST CLOSET | AC5: =$Z$2 -> ….. SOURCE of LOSS PICS ….. | AD5: =$T$5 -> ….......... | AE5: =D5 -> 302 | AF5: =AA5 -> …. | AG5: =AB5 -> GUEST CLOSET | AH5: =$AE$2 -> ….. C.P.S. …... | AI5: =$T$5 -> ….......... | AK5: =E5 -> 402 | AL5: =AF5 -> …. | AM5: =AG5 -> GUEST CLOSET | AN5: =$AK$2 -> NON SALVAGEABLE ITEMS | AO5: =$T$5 -> ….......... | AP5: =F5 -> 502 | AQ5: …. | AR5: =AM5 -> GUEST CLOSET | AS5: =AS4 -> ,,,,,, DMO = DEMOLITION ….... | AT5: =T5 -> ….......... | AU5: =G5 -> 802 | AV5: . | AW5: =AM5 -> GUEST CLOSET | AX5: =AX4 -> … MITIGATION EQUIPMENT & W.I.P . ... | AY5: =$T$5 -> ….......... | AZ5: =H5 -> 6102.1 | BA5: . | BB5: =AW5 -> GUEST CLOSET | BC5: =BC4 -> ... DAY1 MC READINGS .. | BE5: =$T$5 -> ….......... | BF5: =I5 -> 6202.2 | BG5: . | BH5: =BB5 -> GUEST CLOSET | BI5: =BI4 -> ... DAY2 MC READINGS .. | BJ5: =$T$5 -> ….......... | BK5: =J5 -> 6302.3 | BL5: . | BM5: =BH5 -> GUEST CLOSET | BN5: =BN4 -> ... DAY3 MC READINGS .. | BO5: =$T$5 -> ….......... | BP5: =K5 -> 6402.4 | BQ5: . | BR5: =BM5 -> GUEST CLOSET | BS5: =BS4 -> ... DAY4 MC READINGS | BT5: =$T$5 -> ….......... | BU5: 7100 | BV5: EXTERIOR & UNAFFECTED AREA | BW5: =BU2 -> ….. DAY 1 ….. | CB5: 0.0002 | CC5: . | CD5: MECHANICALS = WATER METER READING & PLUMBING REPORT/INVOICE | CF5: , | CG5: ====== | CH5: =CH4+1 -> 70102 | CI5: . | CJ5: =R5 -> GUEST CLOSET | CK5: , | CL5: N/A | CM5: , | CN5: =CN4 -> … DAY # 0 … MC READINGS STABILIZATION | CP5: =R6 -> Dining Room | CQ5: =T6 -> ….........
A6: =R6 -> Dining Room | B6: =P6 -> 103 | C6: =C5+1 -> 203 | D6: =D5+1 -> 303 | E6: =E5+1 -> 403 | F6: =F5+1 -> 503 | G6: 803 | H6: =H5+1 -> 6103.1 | I6: =I5+1 -> 6203.2 | J6: =J5+1 -> 6303.3 | K6: =K5+1 -> 6403.4 | L6: =L8-0.1 -> 7100 | M6: =M8-0.1 -> 7200.1 | P6: 103 | Q6: …. | R6: Dining Room | S6: , | T6: …......... | U6: =P6 -> 103 | V6: =Q6 -> …. | W6: =R6 -> Dining Room | X6: =$U$2 -> = … JOB/ROOMS OVERVIEW PICS .. | Y6: =$T$6 -> …......... | Z6: =C6 -> 203 | AA6: =V6 -> …. | AB6: =W6 -> Dining Room | AC6: =$Z$2 -> ….. SOURCE of LOSS PICS ….. | AD6: =$T$6 -> …......... | AE6: =D6 -> 303 | AF6: =AA6 -> …. | AG6: =AB6 -> Dining Room | AH6: =$AE$2 -> ….. C.P.S. …... | AI6: =$T$6 -> …......... | AK6: =E6 -> 403 | AL6: =AF6 -> …. | AM6: =AG6 -> Dining Room | AN6: =$AK$2 -> NON SALVAGEABLE ITEMS | AO6: =$T$6 -> …......... | AP6: =F6 -> 503 | AQ6: …. | AR6: =AM6 -> Dining Room | AS6: =AS5 -> ,,,,,, DMO = DEMOLITION ….... | AT6: =T6 -> …......... | AU6: =G6 -> 803 | AV6: . | AW6: =AM6 -> Dining Room | AX6: =AX5 -> … MITIGATION EQUIPMENT & W.I.P . ... | AY6: =$T$6 -> …......... | AZ6: =H6 -> 6103.1 | BA6: . | BB6: =AW6 -> Dining Room | BC6: =BC5 -> ... DAY1 MC READINGS .. | BE6: =$T$6 -> …......... | BF6: =I6 -> 6203.2 | BG6: . | BH6: =BB6 -> Dining Room | BI6: =BI5 -> ... DAY2 MC READINGS .. | BJ6: =$T$6 -> …......... | BK6: =J6 -> 6303.3 | BL6: . | BM6: =BH6 -> Dining Room | BN6: =BN5 -> ... DAY3 MC READINGS .. | BO6: =$T$6 -> …......... | BP6: =K6 -> 6403.4 | BQ6: . | BR6: =BM6 -> Dining Room | BS6: =BS5 -> ... DAY4 MC READINGS | BT6: =$T$6 -> …......... | BU6: =BU5+1 -> 7101 | BV6: DRY CHAMBER # 1 | BW6: =BW5 -> ….. DAY 1 ….. | BX6: RH &T & GPP | CB6: 0.0003 | CC6: . | CD6: MECHANICALS = ELECTRICAL HAZARDS | CF6: , | CG6: ====== | CH6: =CH5+1 -> 70103 | CI6: . | CJ6: =R6 -> Dining Room | CK6: , | CL6: =T6 -> …......... | CM6: , | CN6: =CN5 -> … DAY # 0 … MC READINGS STABILIZATION | CP6: =R7 -> DEN | CQ6: =T7 -> ….........
A7: =R7 -> DEN | B7: =P7 -> 104 | C7: =C6+1 -> 204 | D7: =D6+1 -> 304 | E7: =E6+1 -> 404 | F7: =F6+1 -> 504 | G7: 804 | H7: =H6+1 -> 6104.1 | I7: =I6+1 -> 6204.2 | J7: =J6+1 -> 6304.3 | K7: =K6+1 -> 6404.4 | L7: EXTERIOR & UNAFFECTED AREA | P7: 104 | Q7: …. | R7: DEN | S7: , | T7: …......... | U7: =P7 -> 104 | V7: =Q7 -> …. | W7: =R7 -> DEN | X7: =$U$2 -> = … JOB/ROOMS OVERVIEW PICS .. | Y7: =$T$7 -> …......... | Z7: =C7 -> 204 | AA7: =V7 -> …. | AB7: =W7 -> DEN | AC7: =$Z$2 -> ….. SOURCE of LOSS PICS ….. | AD7: =$T$7 -> …......... | AE7: =D7 -> 304 | AF7: =AA7 -> …. | AG7: =AB7 -> DEN | AH7: =$AE$2 -> ….. C.P.S. …... | AI7: =$T$7 -> …......... | AK7: =E7 -> 404 | AL7: =AF7 -> …. | AM7: =AG7 -> DEN | AN7: =$AK$2 -> NON SALVAGEABLE ITEMS | AO7: =$T$7 -> …......... | AP7: =F7 -> 504 | AQ7: …. | AR7: =AM7 -> DEN | AS7: =AS6 -> ,,,,,, DMO = DEMOLITION ….... | AT7: =T7 -> …......... | AU7: =G7 -> 804 | AV7: . | AW7: =AM7 -> DEN | AX7: =AX6 -> … MITIGATION EQUIPMENT & W.I.P . ... | AY7: =$T$7 -> …......... | AZ7: =H7 -> 6104.1 | BA7: . | BB7: =AW7 -> DEN | BC7: =BC6 -> ... DAY1 MC READINGS .. | BE7: =$T$7 -> …......... | BF7: =I7 -> 6204.2 | BG7: . | BH7: =BB7 -> DEN | BI7: =BI6 -> ... DAY2 MC READINGS .. | BJ7: =$T$7 -> …......... | BK7: =J7 -> 6304.3 | BL7: . | BM7: =BH7 -> DEN | BN7: =BN6 -> ... DAY3 MC READINGS .. | BO7: =$T$7 -> …......... | BP7: =K7 -> 6404.4 | BQ7: . | BR7: =BM7 -> DEN | BS7: =BS6 -> ... DAY4 MC READINGS | BT7: =$T$7 -> …......... | BU7: =BU6+1 -> 7102 | BV7: DRY CHAMBER # 2 | BW7: =BW6 -> ….. DAY 1 ….. | BX7: RH &T & GPP | CB7: 0.0004 | CC7: . | CD7: EXT DAMAGE IF APPLICABLE | CE7: ROOF TARPS …............................. | CF7: , | CG7: ====== | CH7: =CH6+1 -> 70104 | CI7: . | CJ7: =R7 -> DEN | CK7: , | CL7: =T7 -> …......... | CM7: , | CN7: =CN6 -> … DAY # 0 … MC READINGS STABILIZATION | CP7: =R8 -> Kitchen | CQ7: =T8 -> ….........
A8: =R8 -> Kitchen | B8: =P8 -> 105 | C8: =C7+1 -> 205 | D8: =D7+1 -> 305 | E8: =E7+1 -> 405 | F8: =F7+1 -> 505 | G8: 805 | H8: =H7+1 -> 6105.1 | I8: =I7+1 -> 6205.2 | J8: =J7+1 -> 6305.3 | K8: =K7+1 -> 6405.4 | L8: 7100.1 | M8: 7200.2 | N8: 7300.3 | O8: 7400.4 | P8: 105 | Q8: …. | R8: Kitchen | S8: , | T8: …......... | U8: =P8 -> 105 | V8: =Q8 -> …. | W8: =R8 -> Kitchen | X8: =$U$2 -> = … JOB/ROOMS OVERVIEW PICS .. | Y8: =$T$8 -> …......... | Z8: =C8 -> 205 | AA8: =V8 -> …. | AB8: =W8 -> Kitchen | AC8: =$Z$2 -> ….. SOURCE of LOSS PICS ….. | AD8: =$T$8 -> …......... | AE8: =D8 -> 305 | AF8: =AA8 -> …. | AG8: =AB8 -> Kitchen | AH8: =$AE$2 -> ….. C.P.S. …... | AI8: =$T$8 -> …......... | AK8: =E8 -> 405 | AL8: =AF8 -> …. | AM8: =AG8 -> Kitchen | AN8: =$AK$2 -> NON SALVAGEABLE ITEMS | AO8: =$T$8 -> …......... | AP8: =F8 -> 505 | AQ8: …. | AR8: =AM8 -> Kitchen | AS8: =AS7 -> ,,,,,, DMO = DEMOLITION ….... | AT8: =T8 -> …......... | AU8: =G8 -> 805 | AV8: . | AW8: =AM8 -> Kitchen | AX8: =AX7 -> … MITIGATION EQUIPMENT & W.I.P . ... | AY8: =$T$8 -> …......... | AZ8: =H8 -> 6105.1 | BA8: . | BB8: =AW8 -> Kitchen | BC8: =BC7 -> ... DAY1 MC READINGS .. | BE8: =$T$8 -> …......... | BF8: =I8 -> 6205.2 | BG8: . | BH8: =BB8 -> Kitchen | BI8: =BI7 -> ... DAY2 MC READINGS .. | BJ8: =$T$8 -> …......... | BK8: =J8 -> 6305.3 | BL8: . | BM8: =BH8 -> Kitchen | BN8: =BN7 -> ... DAY3 MC READINGS .. | BO8: =$T$8 -> …......... | BP8: =K8 -> 6405.4 | BQ8: . | BR8: =BM8 -> Kitchen | BS8: =BS7 -> ... DAY4 MC READINGS | BT8: =$T$8 -> …......... | BU8: =BU7+1 -> 7103 | BV8: DRY CHAMBER # 3 | BW8: =BW7 -> ….. DAY 1 ….. | BX8: RH &T & GPP | CB8: 1997 | CC8: . | CD8: LEAD & HMR TESTING | CE8: LAB RESULTS | CF8: , | CG8: ====== | CH8: =CH7+1 -> 70105 | CI8: . | CJ8: =R8 -> Kitchen | CK8: , | CL8: =T8 -> …......... | CM8: , | CN8: =CN7 -> … DAY # 0 … MC READINGS STABILIZATION | CP8: =R9 -> STAIRS UP | CQ8: =T9 -> LOS / TRAVEL
A9: =R9 -> STAIRS UP | B9: =P9 -> 106 | C9: =C8+1 -> 206 | D9: =D8+1 -> 306 | E9: =E8+1 -> 406 | F9: =F8+1 -> 506 | G9: 806 | H9: =H8+1 -> 6106.1 | I9: =I8+1 -> 6206.2 | J9: =J8+1 -> 6306.3 | K9: =K8+1 -> 6406.4 | L9: DRY CHAMBER 1 | P9: 106 | Q9: …. | R9: STAIRS UP | S9: , | T9: LOS / TRAVEL | U9: =P9 -> 106 | V9: =Q9 -> …. | W9: =R9 -> STAIRS UP | X9: =$U$2 -> = … JOB/ROOMS OVERVIEW PICS .. | Y9: =$T$9 -> LOS / TRAVEL | Z9: =C9 -> 206 | AA9: =V9 -> …. | AB9: =W9 -> STAIRS UP | AC9: =$Z$2 -> ….. SOURCE of LOSS PICS ….. | AD9: =$T$9 -> LOS / TRAVEL | AE9: =D9 -> 306 | AF9: =AA9 -> …. | AG9: =AB9 -> STAIRS UP | AH9: =$AE$2 -> ….. C.P.S. …... | AI9: =$T$9 -> LOS / TRAVEL | AK9: =E9 -> 406 | AL9: =AF9 -> …. | AM9: =AG9 -> STAIRS UP | AN9: =$AK$2 -> NON SALVAGEABLE ITEMS | AO9: =$T$9 -> LOS / TRAVEL | AP9: =F9 -> 506 | AQ9: …. | AR9: =AM9 -> STAIRS UP | AS9: =AS8 -> ,,,,,, DMO = DEMOLITION ….... | AT9: =T9 -> LOS / TRAVEL | AU9: =G9 -> 806 | AV9: . | AW9: =AM9 -> STAIRS UP | AX9: =AX8 -> … MITIGATION EQUIPMENT & W.I.P . ... | AY9: =$T$9 -> LOS / TRAVEL | AZ9: =H9 -> 6106.1 | BA9: . | BB9: =AW9 -> STAIRS UP | BC9: =BC8 -> ... DAY1 MC READINGS .. | BE9: =$T$9 -> LOS / TRAVEL | BF9: =I9 -> 6206.2 | BG9: . | BH9: =BB9 -> STAIRS UP | BI9: =BI8 -> ... DAY2 MC READINGS .. | BJ9: =$T$9 -> LOS / TRAVEL | BK9: =J9 -> 6306.3 | BL9: . | BM9: =BH9 -> STAIRS UP | BN9: =BN8 -> ... DAY3 MC READINGS .. | BO9: =$T$9 -> LOS / TRAVEL | BP9: =K9 -> 6406.4 | BQ9: . | BR9: =BM9 -> STAIRS UP | BS9: =BS8 -> ... DAY4 MC READINGS | BT9: =$T$9 -> LOS / TRAVEL | BU9: =BU8+1 -> 7104 | BV9: DRY CHAMBER # 4 | BW9: =BW8 -> ….. DAY 1 ….. | BX9: RH &T & GPP | CB9: 1998 | CC9: . | CD9: KITCHEN CABINETS SIZES | CE9: U & L =LF/ CT = SF; APPLIANCES | CF9: , | CG9: ====== | CH9: =CH8+1 -> 70106 | CI9: . | CJ9: =R9 -> STAIRS UP | CK9: , | CL9: =T9 -> LOS / TRAVEL | CM9: , | CN9: =CN8 -> … DAY # 0 … MC READINGS STABILIZATION | CP9: =R10 -> HALL UP | CQ9: =T10 -> ….........
A10: =R10 -> HALL UP | B10: =P10 -> 107 | C10: =C9+1 -> 207 | D10: =D9+1 -> 307 | E10: =E9+1 -> 407 | F10: =F9+1 -> 507 | G10: 807 | H10: =H9+1 -> 6107.1 | I10: =I9+1 -> 6207.2 | J10: =J9+1 -> 6307.3 | K10: =K9+1 -> 6407.4 | L10: =L8+1 -> 7101.1 | M10: =M8+1 -> 7201.2 | N10: =N8+1 -> 7301.3 | O10: =O8+1 -> 7401.4 | P10: 107 | Q10: …. | R10: HALL UP | S10: , | T10: …......... | U10: =P10 -> 107 | V10: =Q10 -> …. | W10: =R10 -> HALL UP | X10: =$U$2 -> = … JOB/ROOMS OVERVIEW PICS .. | Y10: =$T$10 -> …......... | Z10: =C10 -> 207 | AA10: =V10 -> …. | AB10: =W10 -> HALL UP | AC10: =$Z$2 -> ….. SOURCE of LOSS PICS ….. | AD10: =$T$10 -> …......... | AE10: =D10 -> 307 | AF10: =AA10 -> …. | AG10: =AB10 -> HALL UP | AH10: =$AE$2 -> ….. C.P.S. …... | AI10: =$T$10 -> …......... | AK10: =E10 -> 407 | AL10: =AF10 -> …. | AM10: =AG10 -> HALL UP | AN10: =$AK$2 -> NON SALVAGEABLE ITEMS | AO10: =$T$10 -> …......... | AP10: =F10 -> 507 | AQ10: …. | AR10: =AM10 -> HALL UP | AS10: =AS9 -> ,,,,,, DMO = DEMOLITION ….... | AT10: =T10 -> …......... | AU10: =G10 -> 807 | AV10: . | AW10: =AM10 -> HALL UP | AX10: =AX9 -> … MITIGATION EQUIPMENT & W.I.P . ... | AY10: =$T$10 -> …......... | AZ10: =H10 -> 6107.1 | BA10: . | BB10: =AW10 -> HALL UP | BC10: =BC9 -> ... DAY1 MC READINGS .. | BE10: =$T$10 -> …......... | BF10: =I10 -> 6207.2 | BG10: . | BH10: =BB10 -> HALL UP | BI10: =BI9 -> ... DAY2 MC READINGS .. | BJ10: =$T$10 -> …......... | BK10: =J10 -> 6307.3 | BL10: . | BM10: =BH10 -> HALL UP | BN10: =BN9 -> ... DAY3 MC READINGS .. | BO10: =$T$10 -> …......... | BP10: =K10 -> 6407.4 | BQ10: . | BR10: =BM10 -> HALL UP | BS10: =BS9 -> ... DAY4 MC READINGS | BT10: =$T$10 -> …......... | BU10: =BU11-0.2 -> 7200 | BV10: =BV4 -> RH &T & GPP DRY CHAMBERS [DC] .READ INGS =========== | BW10: ….. DAY 2 ….. | CB10: 1999 | CC10: . | CD10: BATHROOM FIXTURES | CE10: CAB SIZE & FIXTURES & TYPE | CF10: , | CG10: ====== | CH10: =CH9+1 -> 70107 | CI10: . | CJ10: =R10 -> HALL UP | CK10: , | CL10: =T10 -> …......... | CM10: , | CN10: =CN9 -> … DAY # 0 … MC READINGS STABILIZATION | CP10: =R11 -> LINEN CLOSET | CQ10: =T11 -> ….........
A11: =R11 -> LINEN CLOSET | B11: =P11 -> 108 | C11: =C10+1 -> 208 | D11: =D10+1 -> 308 | E11: =E10+1 -> 408 | F11: =F10+1 -> 508 | G11: 808 | H11: =H10+1 -> 6108.1 | I11: =I10+1 -> 6208.2 | J11: =J10+1 -> 6308.3 | K11: =K10+1 -> 6408.4 | L11: DRY CHAMBER 2 | P11: 108 | Q11: …. | R11: LINEN CLOSET | S11: , | T11: …......... | U11: =P11 -> 108 | V11: =Q11 -> …. | W11: =R11 -> LINEN CLOSET | X11: =$U$2 -> = … JOB/ROOMS OVERVIEW PICS .. | Y11: =$T$11 -> …......... | Z11: =C11 -> 208 | AA11: =V11 -> …. | AB11: =W11 -> LINEN CLOSET | AC11: =$Z$2 -> ….. SOURCE of LOSS PICS ….. | AD11: =$T$11 -> …......... | AE11: =D11 -> 308 | AF11: =AA11 -> …. | AG11: =AB11 -> LINEN CLOSET | AH11: =$AE$2 -> ….. C.P.S. …... | AI11: =$T$11 -> …......... | AK11: =E11 -> 408 | AL11: =AF11 -> …. | AM11: =AG11 -> LINEN CLOSET | AN11: =$AK$2 -> NON SALVAGEABLE ITEMS | AO11: =$T$11 -> …......... | AP11: =F11 -> 508 | AQ11: …. | AR11: =AM11 -> LINEN CLOSET | AS11: =AS10 -> ,,,,,, DMO = DEMOLITION ….... | AT11: =T11 -> …......... | AU11: =G11 -> 808 | AV11: . | AW11: =AM11 -> LINEN CLOSET | AX11: =AX10 -> … MITIGATION EQUIPMENT & W.I.P . ... | AY11: =$T$11 -> …......... | AZ11: =H11 -> 6108.1 | BA11: . | BB11: =AW11 -> LINEN CLOSET | BC11: =BC10 -> ... DAY1 MC READINGS .. | BE11: =$T$11 -> …......... | BF11: =I11 -> 6208.2 | BG11: . | BH11: =BB11 -> LINEN CLOSET | BI11: =BI10 -> ... DAY2 MC READINGS .. | BJ11: =$T$11 -> …......... | BK11: =J11 -> 6308.3 | BL11: . | BM11: =BH11 -> LINEN CLOSET | BN11: =BN10 -> ... DAY3 MC READINGS .. | BO11: =$T$11 -> …......... | BP11: =K11 -> 6408.4 | BQ11: . | BR11: =BM11 -> LINEN CLOSET | BS11: =BS10 -> ... DAY4 MC READINGS | BT11: =$T$11 -> …......... | BU11: 7200.2 | BV11: EXTERIOR & UNAFFECTED AREA | BW11: =BW10 -> ….. DAY 2 ….. | CB11: 3222 | CC11: . | CD11: CPS DAY2 WIP | CE11: OVERVIEW WIP BOXES PACKOUT PICS | CF11: , | CG11: ====== | CH11: =CH10+1 -> 70108 | CI11: . | CJ11: =R11 -> LINEN CLOSET | CK11: , | CL11: =T11 -> …......... | CM11: , | CN11: =CN10 -> … DAY # 0 … MC READINGS STABILIZATION | CP11: =R12 -> BATH UP | CQ11: =T12 -> ….........
A12: =R12 -> BATH UP | B12: =P12 -> 109 | C12: =C11+1 -> 209 | D12: =D11+1 -> 309 | E12: =E11+1 -> 409 | F12: =F11+1 -> 509 | G12: 809 | H12: =H11+1 -> 6109.1 | I12: =I11+1 -> 6209.2 | J12: =J11+1 -> 6309.3 | K12: =K11+1 -> 6409.4 | L12: =L10+1 -> 7102.1 | M12: =M10+1 -> 7202.2 | N12: =N10+1 -> 7302.3 | O12: =O10+1 -> 7402.4 | P12: 109 | Q12: …. | R12: BATH UP | S12: , | T12: …......... | U12: =P12 -> 109 | V12: =Q12 -> …. | W12: =R12 -> BATH UP | X12: =$U$2 -> = … JOB/ROOMS OVERVIEW PICS .. | Y12: =$T$12 -> …......... | Z12: =C12 -> 209 | AA12: =V12 -> …. | AB12: =W12 -> BATH UP | AC12: =$Z$2 -> ….. SOURCE of LOSS PICS ….. | AD12: =$T$12 -> …......... | AE12: =D12 -> 309 | AF12: =AA12 -> …. | AG12: =AB12 -> BATH UP | AH12: =$AE$2 -> ….. C.P.S. …... | AI12: =$T$12 -> …......... | AK12: =E12 -> 409 | AL12: =AF12 -> …. | AM12: =AG12 -> BATH UP | AN12: =$AK$2 -> NON SALVAGEABLE ITEMS | AO12: =$T$12 -> …......... | AP12: =F12 -> 509 | AQ12: …. | AR12: =AM12 -> BATH UP | AS12: =AS11 -> ,,,,,, DMO = DEMOLITION ….... | AT12: =T12 -> …......... | AU12: =G12 -> 809 | AV12: . | AW12: =AM12 -> BATH UP | AX12: =AX11 -> … MITIGATION EQUIPMENT & W.I.P . ... | AY12: =$T$12 -> …......... | AZ12: =H12 -> 6109.1 | BA12: . | BB12: =AW12 -> BATH UP | BC12: =BC11 -> ... DAY1 MC READINGS .. | BE12: =$T$12 -> …......... | BF12: =I12 -> 6209.2 | BG12: . | BH12: =BB12 -> BATH UP | BI12: =BI11 -> ... DAY2 MC READINGS .. | BJ12: =$T$12 -> …......... | BK12: =J12 -> 6309.3 | BL12: . | BM12: =BH12 -> BATH UP | BN12: =BN11 -> ... DAY3 MC READINGS .. | BO12: =$T$12 -> …......... | BP12: =K12 -> 6409.4 | BQ12: . | BR12: =BM12 -> BATH UP | BS12: =BS11 -> ... DAY4 MC READINGS | BT12: =$T$12 -> …......... | BU12: =BU11+1 -> 7201.2 | BV12: DRY CHAMBER # 1 | BW12: =BW11 -> ….. DAY 2 ….. | BX12: RH &T & GPP | CB12: 3322 | CC12: . | CD12: CPS3 DAY3 STORAGE | CE12: OVERVIEW STORAGE MOVE OUT PICS | CF12: , | CG12: ====== | CH12: =CH11+1 -> 70109 | CI12: . | CJ12: =R12 -> BATH UP | CK12: , | CL12: =T12 -> …......... | CM12: , | CN12: =CN11 -> … DAY # 0 … MC READINGS STABILIZATION | CP12: =R13 -> Bedroom 1 | CQ12: =T13 -> ….........
A13: =R13 -> Bedroom 1 | B13: =P13 -> 110 | C13: =C12+1 -> 210 | D13: =D12+1 -> 310 | E13: =E12+1 -> 410 | F13: =F12+1 -> 510 | G13: 810 | H13: =H12+1 -> 6110.1 | I13: =I12+1 -> 6210.2 | J13: =J12+1 -> 6310.3 | K13: =K12+1 -> 6410.4 | L13: DRY CHAMBER 3 | P13: 110 | Q13: …. | R13: Bedroom 1 | S13: , | T13: …......... | U13: =P13 -> 110 | V13: =Q13 -> …. | W13: =R13 -> Bedroom 1 | X13: =$U$2 -> = … JOB/ROOMS OVERVIEW PICS .. | Y13: =$T$13 -> …......... | Z13: =C13 -> 210 | AA13: =V13 -> …. | AB13: =W13 -> Bedroom 1 | AC13: =$Z$2 -> ….. SOURCE of LOSS PICS ….. | AD13: =$T$13 -> …......... | AE13: =D13 -> 310 | AF13: =AA13 -> …. | AG13: =AB13 -> Bedroom 1 | AH13: =$AE$2 -> ….. C.P.S. …... | AI13: =$T$13 -> …......... | AK13: =E13 -> 410 | AL13: =AF13 -> …. | AM13: =AG13 -> Bedroom 1 | AN13: =$AK$2 -> NON SALVAGEABLE ITEMS | AO13: =$T$13 -> …......... | AP13: =F13 -> 510 | AQ13: …. | AR13: =AM13 -> Bedroom 1 | AS13: =AS12 -> ,,,,,, DMO = DEMOLITION ….... | AT13: =T13 -> …......... | AU13: =G13 -> 810 | AV13: . | AW13: =AM13 -> Bedroom 1 | AX13: =AX12 -> … MITIGATION EQUIPMENT & W.I.P . ... | AY13: =$T$13 -> …......... | AZ13: =H13 -> 6110.1 | BA13: . | BB13: =AW13 -> Bedroom 1 | BC13: =BC12 -> ... DAY1 MC READINGS .. | BE13: =$T$13 -> …......... | BF13: =I13 -> 6210.2 | BG13: . | BH13: =BB13 -> Bedroom 1 | BI13: =BI12 -> ... DAY2 MC READINGS .. | BJ13: =$T$13 -> …......... | BK13: =J13 -> 6310.3 | BL13: . | BM13: =BH13 -> Bedroom 1 | BN13: =BN12 -> ... DAY3 MC READINGS .. | BO13: =$T$13 -> …......... | BP13: =K13 -> 6410.4 | BQ13: . | BR13: =BM13 -> Bedroom 1 | BS13: =BS12 -> ... DAY4 MC READINGS | BT13: =$T$13 -> …......... | BU13: =BU12+1 -> 7202.2 | BV13: DRY CHAMBER # 2 | BW13: =BW12 -> ….. DAY 2 ….. | BX13: RH &T & GPP | CB13: 3444 | CC13: . | CD13: CPS4 DAY4 PACKBACK | CE13: OVERVIEW PACK-BACK / RESET PICS | CF13: , | CG13: ====== | CH13: =CH12+1 -> 70110 | CI13: . | CJ13: =R13 -> Bedroom 1 | CK13: , | CL13: =T13 -> …......... | CM13: , | CN13: =CN12 -> … DAY # 0 … MC READINGS STABILIZATION | CP13: =R14 -> BR1 Closet | CQ13: =T14 -> LOS / TRAVEL
A14: =R14 -> BR1 Closet | B14: =P14 -> 111 | C14: =C13+1 -> 211 | D14: =D13+1 -> 311 | E14: =E13+1 -> 411 | F14: =F13+1 -> 511 | G14: 811 | H14: =H13+1 -> 6111.1 | I14: =I13+1 -> 6211.2 | J14: =J13+1 -> 6311.3 | K14: =K13+1 -> 6411.4 | L14: =L12+1 -> 7103.1 | M14: =M12+1 -> 7203.2 | N14: =N12+1 -> 7303.3 | O14: =O12+1 -> 7403.4 | P14: 111 | Q14: …. | R14: BR1 Closet | S14: , | T14: LOS / TRAVEL | U14: =P14 -> 111 | V14: =Q14 -> …. | W14: =R14 -> BR1 Closet | X14: =$U$2 -> = … JOB/ROOMS OVERVIEW PICS .. | Y14: =$T$14 -> LOS / TRAVEL | Z14: =C14 -> 211 | AA14: =V14 -> …. | AB14: =W14 -> BR1 Closet | AC14: =$Z$2 -> ….. SOURCE of LOSS PICS ….. | AD14: =$T$14 -> LOS / TRAVEL | AE14: =D14 -> 311 | AF14: =AA14 -> …. | AG14: =AB14 -> BR1 Closet | AH14: =$AE$2 -> ….. C.P.S. …... | AI14: =$T$14 -> LOS / TRAVEL | AK14: =E14 -> 411 | AL14: =AF14 -> …. | AM14: =AG14 -> BR1 Closet | AN14: =$AK$2 -> NON SALVAGEABLE ITEMS | AO14: =$T$14 -> LOS / TRAVEL | AP14: =F14 -> 511 | AQ14: …. | AR14: =AM14 -> BR1 Closet | AS14: =AS13 -> ,,,,,, DMO = DEMOLITION ….... | AT14: =T14 -> LOS / TRAVEL | AU14: =G14 -> 811 | AV14: . | AW14: =AM14 -> BR1 Closet | AX14: =AX13 -> … MITIGATION EQUIPMENT & W.I.P . ... | AY14: =$T$14 -> LOS / TRAVEL | AZ14: =H14 -> 6111.1 | BA14: . | BB14: =AW14 -> BR1 Closet | BC14: =BC13 -> ... DAY1 MC READINGS .. | BE14: =$T$14 -> LOS / TRAVEL | BF14: =I14 -> 6211.2 | BG14: . | BH14: =BB14 -> BR1 Closet | BI14: =BI13 -> ... DAY2 MC READINGS .. | BJ14: =$T$14 -> LOS / TRAVEL | BK14: =J14 -> 6311.3 | BL14: . | BM14: =BH14 -> BR1 Closet | BN14: =BN13 -> ... DAY3 MC READINGS .. | BO14: =$T$14 -> LOS / TRAVEL | BP14: =K14 -> 6411.4 | BQ14: . | BR14: =BM14 -> BR1 Closet | BS14: =BS13 -> ... DAY4 MC READINGS | BT14: =$T$14 -> LOS / TRAVEL | BU14: =BU13+1 -> 7203.2 | BV14: DRY CHAMBER # 3 | BW14: =BW12 -> ….. DAY 2 ….. | BX14: RH &T & GPP | CB14: 4111.1 | CC14: . | CD14: REPLACEMENT 1 CON OVERVIEW DAY PICS, | CF14: , | CG14: ====== | CH14: =CH13+1 -> 70111 | CI14: . | CJ14: =R14 -> BR1 Closet | CK14: , | CL14: =T14 -> LOS / TRAVEL | CM14: , | CN14: =CN13 -> … DAY # 0 … MC READINGS STABILIZATION | CP14: =R15 -> Bedroom 2 | CQ14: =T15 -> ….........
A15: =R15 -> Bedroom 2 | B15: =P15 -> 112 | C15: =C14+1 -> 212 | D15: =D14+1 -> 312 | E15: =E14+1 -> 412 | F15: =F14+1 -> 512 | G15: 812 | H15: =H14+1 -> 6112.1 | I15: =I14+1 -> 6212.2 | J15: =J14+1 -> 6312.3 | K15: =K14+1 -> 6412.4 | L15: DRY CHAMBER 4 | P15: 112 | Q15: …. | R15: Bedroom 2 | S15: , | T15: …......... | U15: =P15 -> 112 | V15: =Q15 -> …. | W15: =R15 -> Bedroom 2 | X15: =$U$2 -> = … JOB/ROOMS OVERVIEW PICS .. | Y15: =$T$15 -> …......... | Z15: =C15 -> 212 | AA15: =V15 -> …. | AB15: =W15 -> Bedroom 2 | AC15: =$Z$2 -> ….. SOURCE of LOSS PICS ….. | AD15: =$T$15 -> …......... | AE15: =D15 -> 312 | AF15: =AA15 -> …. | AG15: =AB15 -> Bedroom 2 | AH15: =$AE$2 -> ….. C.P.S. …... | AI15: =$T$15 -> …......... | AK15: =E15 -> 412 | AL15: =AF15 -> …. | AM15: =AG15 -> Bedroom 2 | AN15: =$AK$2 -> NON SALVAGEABLE ITEMS | AO15: =$T$15 -> …......... | AP15: =F15 -> 512 | AQ15: …. | AR15: =AM15 -> Bedroom 2 | AS15: =AS14 -> ,,,,,, DMO = DEMOLITION ….... | AT15: =T15 -> …......... | AU15: =G15 -> 812 | AV15: . | AW15: =AM15 -> Bedroom 2 | AX15: =AX14 -> … MITIGATION EQUIPMENT & W.I.P . ... | AY15: =$T$15 -> …......... | AZ15: =H15 -> 6112.1 | BA15: . | BB15: =AW15 -> Bedroom 2 | BC15: =BC14 -> ... DAY1 MC READINGS .. | BE15: =$T$15 -> …......... | BF15: =I15 -> 6212.2 | BG15: . | BH15: =BB15 -> Bedroom 2 | BI15: =BI14 -> ... DAY2 MC READINGS .. | BJ15: =$T$15 -> …......... | BK15: =J15 -> 6312.3 | BL15: . | BM15: =BH15 -> Bedroom 2 | BN15: =BN14 -> ... DAY3 MC READINGS .. | BO15: =$T$15 -> …......... | BP15: =K15 -> 6412.4 | BQ15: . | BR15: =BM15 -> Bedroom 2 | BS15: =BS14 -> ... DAY4 MC READINGS | BT15: =$T$15 -> …......... | BU15: =BU14+1 -> 7204.2 | BV15: DRY CHAMBER # 4 | BW15: =BW13 -> ….. DAY 2 ….. | BX15: RH &T & GPP | CB15: 4222.2 | CC15: . | CD15: REPLACEMENT 2 CON WIP, | CF15: , | CH15: =CH14+1 -> 70112 | CI15: . | CJ15: =R15 -> Bedroom 2 | CK15: , | CL15: =T15 -> …......... | CM15: , | CN15: =CN14 -> … DAY # 0 … MC READINGS STABILIZATION | CP15: =R16 -> BR2 Closet, | CQ15: =T16 -> LOS / TRAVEL
A16: =R16 -> BR2 Closet, | B16: =P16 -> 113 | C16: =C15+1 -> 213 | D16: =D15+1 -> 313 | E16: =E15+1 -> 413 | F16: =F15+1 -> 513 | G16: 813 | H16: =H15+1 -> 6113.1 | I16: =I15+1 -> 6213.2 | J16: =J15+1 -> 6313.3 | K16: =K15+1 -> 6413.4 | L16: =L14+1 -> 7104.1 | M16: =M14+1 -> 7204.2 | N16: =N14+1 -> 7304.3 | O16: =O14+1 -> 7404.4 | P16: 113 | Q16: …. | R16: BR2 Closet, | S16: , | T16: LOS / TRAVEL | U16: =P16 -> 113 | V16: =Q16 -> …. | W16: =R16 -> BR2 Closet, | X16: =$U$2 -> = … JOB/ROOMS OVERVIEW PICS .. | Y16: =$T$16 -> LOS / TRAVEL | Z16: =C16 -> 213 | AA16: =V16 -> …. | AB16: =W16 -> BR2 Closet, | AC16: =$Z$2 -> ….. SOURCE of LOSS PICS ….. | AD16: =$T$16 -> LOS / TRAVEL | AE16: =D16 -> 313 | AF16: =AA16 -> …. | AG16: =AB16 -> BR2 Closet, | AH16: =$AE$2 -> ….. C.P.S. …... | AI16: =$T$16 -> LOS / TRAVEL | AK16: =E16 -> 413 | AL16: =AF16 -> …. | AM16: =AG16 -> BR2 Closet, | AN16: =$AK$2 -> NON SALVAGEABLE ITEMS | AO16: =$T$16 -> LOS / TRAVEL | AP16: =F16 -> 513 | AQ16: …. | AR16: =AM16 -> BR2 Closet, | AS16: =AS15 -> ,,,,,, DMO = DEMOLITION ….... | AT16: =T16 -> LOS / TRAVEL | AU16: =G16 -> 813 | AV16: . | AW16: =AM16 -> BR2 Closet, | AX16: =AX15 -> … MITIGATION EQUIPMENT & W.I.P . ... | AY16: =$T$16 -> LOS / TRAVEL | AZ16: =H16 -> 6113.1 | BA16: . | BB16: =AW16 -> BR2 Closet, | BC16: =BC15 -> ... DAY1 MC READINGS .. | BE16: =$T$16 -> LOS / TRAVEL | BF16: =I16 -> 6213.2 | BG16: . | BH16: =BB16 -> BR2 Closet, | BI16: =BI15 -> ... DAY2 MC READINGS .. | BJ16: =$T$16 -> LOS / TRAVEL | BK16: =J16 -> 6313.3 | BL16: . | BM16: =BH16 -> BR2 Closet, | BN16: =BN15 -> ... DAY3 MC READINGS .. | BO16: =$T$16 -> LOS / TRAVEL | BP16: =K16 -> 6413.4 | BQ16: . | BR16: =BM16 -> BR2 Closet, | BS16: =BS15 -> ... DAY4 MC READINGS | BT16: =$T$16 -> LOS / TRAVEL | BU16: =BU15+1 -> 7205.2 | BV16: DRY CHAMBER # 5 | BW16: =BW14 -> ….. DAY 2 ….. | BX16: RH &T & GPP | CB16: 4333.3 | CC16: . | CD16: REPLACEMENT 3 CON STORAGE | CF16: , | CH16: =CH15+1 -> 70113 | CI16: . | CJ16: =R16 -> BR2 Closet, | CK16: , | CL16: =T16 -> LOS / TRAVEL | CM16: , | CN16: =CN15 -> … DAY # 0 … MC READINGS STABILIZATION | CP16: =R17 -> 0 | CQ16: =T17 -> ….........
A17: =R17 -> 0 | B17: =P17 -> 114 | C17: =C16+1 -> 214 | D17: =D16+1 -> 314 | E17: =E16+1 -> 414 | F17: =F16+1 -> 514 | G17: 814 | H17: =H16+1 -> 6114.1 | I17: =I16+1 -> 6214.2 | J17: =J16+1 -> 6314.3 | K17: =K16+1 -> 6414.4 | L17: DRY CHAMBER 5 | P17: 114 | Q17: …. | S17: , | T17: …......... | U17: =P17 -> 114 | V17: =Q17 -> …. | W17: =R17 -> 0 | X17: =$U$2 -> = … JOB/ROOMS OVERVIEW PICS .. | Y17: =$T$17 -> …......... | Z17: =C17 -> 214 | AA17: =V17 -> …. | AB17: =W17 -> 0 | AC17: =$Z$2 -> ….. SOURCE of LOSS PICS ….. | AD17: =$T$17 -> …......... | AE17: =D17 -> 314 | AF17: =AA17 -> …. | AG17: =AB17 -> 0 | AH17: =$AE$2 -> ….. C.P.S. …... | AI17: =$T$17 -> …......... | AK17: =E17 -> 414 | AL17: =AF17 -> …. | AM17: =AG17 -> 0 | AN17: =$AK$2 -> NON SALVAGEABLE ITEMS | AO17: =$T$17 -> …......... | AP17: =F17 -> 514 | AQ17: …. | AR17: =AM17 -> 0 | AS17: =AS16 -> ,,,,,, DMO = DEMOLITION ….... | AT17: =T17 -> …......... | AU17: =G17 -> 814 | AV17: . | AW17: =AM17 -> 0 | AX17: =AX16 -> … MITIGATION EQUIPMENT & W.I.P . ... | AY17: =$T$17 -> …......... | AZ17: =H17 -> 6114.1 | BA17: . | BB17: =AW17 -> 0 | BC17: =BC16 -> ... DAY1 MC READINGS .. | BE17: =$T$17 -> …......... | BF17: =I17 -> 6214.2 | BG17: . | BH17: =BB17 -> 0 | BI17: =BI16 -> ... DAY2 MC READINGS .. | BJ17: =$T$17 -> …......... | BK17: =J17 -> 6314.3 | BL17: . | BM17: =BH17 -> 0 | BN17: =BN16 -> ... DAY3 MC READINGS .. | BO17: =$T$17 -> …......... | BP17: =K17 -> 6414.4 | BQ17: . | BR17: =BM17 -> 0 | BS17: =BS16 -> ... DAY4 MC READINGS | BT17: =$T$17 -> …......... | BU17: 7300 | BV17: =BV4 -> RH &T & GPP DRY CHAMBERS [DC] .READ INGS =========== | BW17: ….. DAY 3 ….. | CB17: 4444.4 | CC17: . | CD17: REPLACEMENT 4 CON DISPOSAL, | CF17: , | CH17: =CH16+1 -> 70114 | CI17: . | CJ17: =R17 -> 0 | CK17: , | CL17: =T17 -> …......... | CM17: , | CN17: =CN16 -> … DAY # 0 … MC READINGS STABILIZATION | CP17: =R18 -> 0 | CQ17: =T18 -> ….........
A18: =R18 -> 0 | B18: =P18 -> 115 | C18: =C17+1 -> 215 | D18: =D17+1 -> 315 | E18: =E17+1 -> 415 | F18: =F17+1 -> 515 | G18: 815 | H18: =H17+1 -> 6115.1 | I18: =I17+1 -> 6215.2 | J18: =J17+1 -> 6315.3 | K18: =K17+1 -> 6415.4 | L18: =L16+1 -> 7105.1 | M18: =M16+1 -> 7205.2 | N18: =N16+1 -> 7305.3 | O18: =O16+1 -> 7405.4 | P18: 115 | Q18: …. | S18: , | T18: …......... | U18: =P18 -> 115 | V18: =Q18 -> …. | W18: =R18 -> 0 | X18: =$U$2 -> = … JOB/ROOMS OVERVIEW PICS .. | Y18: =$T$18 -> …......... | Z18: =C18 -> 215 | AA18: =V18 -> …. | AB18: =W18 -> 0 | AC18: =$Z$2 -> ….. SOURCE of LOSS PICS ….. | AD18: =$T$18 -> …......... | AE18: =D18 -> 315 | AF18: =AA18 -> …. | AG18: =AB18 -> 0 | AH18: =$AE$2 -> ….. C.P.S. …... | AI18: =$T$18 -> …......... | AK18: =E18 -> 415 | AL18: =AF18 -> …. | AM18: =AG18 -> 0 | AN18: =$AK$2 -> NON SALVAGEABLE ITEMS | AO18: =$T$18 -> …......... | AP18: =F18 -> 515 | AQ18: …. | AR18: =AM18 -> 0 | AS18: =AS17 -> ,,,,,, DMO = DEMOLITION ….... | AT18: =T18 -> …......... | AU18: =G18 -> 815 | AV18: . | AW18: =AM18 -> 0 | AX18: =AX17 -> … MITIGATION EQUIPMENT & W.I.P . ... | AY18: =$T$18 -> …......... | AZ18: =H18 -> 6115.1 | BA18: . | BB18: =AW18 -> 0 | BC18: =BC17 -> ... DAY1 MC READINGS .. | BE18: =$T$18 -> …......... | BF18: =I18 -> 6215.2 | BG18: . | BH18: =BB18 -> 0 | BI18: =BI17 -> ... DAY2 MC READINGS .. | BJ18: =$T$18 -> …......... | BK18: =J18 -> 6315.3 | BL18: . | BM18: =BH18 -> 0 | BN18: =BN17 -> ... DAY3 MC READINGS .. | BO18: =$T$18 -> …......... | BP18: =K18 -> 6415.4 | BQ18: . | BR18: =BM18 -> 0 | BS18: =BS17 -> ... DAY4 MC READINGS | BT18: =$T$18 -> …......... | BU18: =BU17 -> 7300 | BV18: EXTERIOR & UNAFFECTED AREA | BW18: =BW17 -> ….. DAY 3 ….. | CB18: 9998 | CC18: . | CD18: REBUILD OVERVIEW WORK IN PROGRESS.......WIP, | CF18: , | CG18: ====== | CH18: =CH17+1 -> 70115 | CI18: . | CJ18: =R19 -> 0 | CK18: , | CL18: =T18 -> …......... | CM18: , | CN18: =CN17 -> … DAY # 0 … MC READINGS STABILIZATION | CP18: =R19 -> 0 | CQ18: =T19 -> ….........
A19: =R19 -> 0 | B19: =P19 -> 116 | C19: =C18+1 -> 216 | D19: =D18+1 -> 316 | E19: =E18+1 -> 416 | F19: =F18+1 -> 516 | G19: 816 | H19: =H18+1 -> 6116.1 | I19: =I18+1 -> 6216.2 | J19: =J18+1 -> 6316.3 | K19: =K18+1 -> 6416.4 | P19: 116 | Q19: …. | S19: , | T19: …......... | U19: =P19 -> 116 | V19: =Q19 -> …. | W19: =R19 -> 0 | X19: =$U$2 -> = … JOB/ROOMS OVERVIEW PICS .. | Y19: =$T$19 -> …......... | Z19: =C19 -> 216 | AA19: =V19 -> …. | AB19: =W19 -> 0 | AC19: =$Z$2 -> ….. SOURCE of LOSS PICS ….. | AD19: =$T$19 -> …......... | AE19: =D19 -> 316 | AF19: =AA19 -> …. | AG19: =AB19 -> 0 | AH19: =$AE$2 -> ….. C.P.S. …... | AI19: =$T$19 -> …......... | AK19: =E19 -> 416 | AL19: =AF19 -> …. | AM19: =AG19 -> 0 | AN19: =$AK$2 -> NON SALVAGEABLE ITEMS | AO19: =$T$19 -> …......... | AP19: =F19 -> 516 | AQ19: …. | AR19: =AM19 -> 0 | AS19: =AS18 -> ,,,,,, DMO = DEMOLITION ….... | AT19: =T19 -> …......... | AU19: =G19 -> 816 | AV19: . | AW19: =AM19 -> 0 | AX19: =AX18 -> … MITIGATION EQUIPMENT & W.I.P . ... | AY19: =$T$19 -> …......... | AZ19: =H19 -> 6116.1 | BA19: . | BB19: =AW19 -> 0 | BC19: =BC18 -> ... DAY1 MC READINGS .. | BE19: =$T$19 -> …......... | BF19: =I19 -> 6216.2 | BG19: . | BH19: =BB19 -> 0 | BI19: =BI18 -> ... DAY2 MC READINGS .. | BJ19: =$T$19 -> …......... | BK19: =J19 -> 6316.3 | BL19: . | BM19: =BH19 -> 0 | BN19: =BN18 -> ... DAY3 MC READINGS .. | BO19: =$T$19 -> …......... | BP19: =K19 -> 6416.4 | BQ19: . | BR19: =BM19 -> 0 | BS19: =BS18 -> ... DAY4 MC READINGS | BT19: =$T$19 -> …......... | BU19: =BU18+1 -> 7301 | BV19: DRY CHAMBER # 1 | BW19: =BW18 -> ….. DAY 3 ….. | BX19: RH &T & GPP | CB19: 9999 | CC19: . | CD19: REBUILD INTERIOR COMPLETED WORK, | CF19: , | CH19: =CH18+1 -> 70116 | CJ19: =R20 -> 0 | CK19: , | CL19: =T19 -> …......... | CM19: , | CN19: =CN18 -> … DAY # 0 … MC READINGS STABILIZATION | CP19: =R20 -> 0 | CQ19: =T20 -> ….........
A20: =R20 -> 0 | B20: =P20 -> 117 | C20: =C19+1 -> 217 | D20: =D19+1 -> 317 | E20: =E19+1 -> 417 | F20: =F19+1 -> 517 | G20: 817 | H20: =H19+1 -> 6117.1 | I20: =I19+1 -> 6217.2 | J20: =J19+1 -> 6317.3 | K20: =K19+1 -> 6417.4 | P20: 117 | Q20: …. | S20: , | T20: …......... | U20: =P20 -> 117 | V20: =Q20 -> …. | W20: =R20 -> 0 | X20: =$U$2 -> = … JOB/ROOMS OVERVIEW PICS .. | Y20: =$T$20 -> …......... | Z20: =C20 -> 217 | AA20: =V20 -> …. | AB20: =W20 -> 0 | AC20: =$Z$2 -> ….. SOURCE of LOSS PICS ….. | AD20: =$T$20 -> …......... | AE20: =D20 -> 317 | AF20: =AA20 -> …. | AG20: =AB20 -> 0 | AH20: =$AE$2 -> ….. C.P.S. …... | AI20: =$T$20 -> …......... | AK20: =E20 -> 417 | AL20: =AF20 -> …. | AM20: =AG20 -> 0 | AN20: =$AK$2 -> NON SALVAGEABLE ITEMS | AO20: =$T$20 -> …......... | AP20: =F20 -> 517 | AQ20: …. | AR20: =AM20 -> 0 | AS20: =AS19 -> ,,,,,, DMO = DEMOLITION ….... | AT20: =T20 -> …......... | AU20: =G20 -> 817 | AV20: . | AW20: =AM20 -> 0 | AX20: =AX19 -> … MITIGATION EQUIPMENT & W.I.P . ... | AY20: =$T$20 -> …......... | AZ20: =H20 -> 6117.1 | BA20: . | BB20: =AW20 -> 0 | BC20: =BC19 -> ... DAY1 MC READINGS .. | BE20: =$T$20 -> …......... | BF20: =I20 -> 6217.2 | BG20: . | BH20: =BB20 -> 0 | BI20: =BI19 -> ... DAY2 MC READINGS .. | BJ20: =$T$20 -> …......... | BK20: =J20 -> 6317.3 | BL20: . | BM20: =BH20 -> 0 | BN20: =BN19 -> ... DAY3 MC READINGS .. | BO20: =$T$20 -> …......... | BP20: =K20 -> 6417.4 | BQ20: . | BR20: =BM20 -> 0 | BS20: =BS19 -> ... DAY4 MC READINGS | BT20: =$T$20 -> …......... | BU20: =BU19+1 -> 7302 | BV20: DRY CHAMBER # 2 | BW20: =BW19 -> ….. DAY 3 ….. | BX20: RH &T & GPP | CF20: , | CH20: =CH19+1 -> 70117 | CI20: ---------------- | CJ20: =R21 -> 0 | CK20: , | CL20: =T20 -> …......... | CM20: , | CN20: =CN19 -> … DAY # 0 … MC READINGS STABILIZATION | CP20: =R21 -> 0 | CQ20: =T21 -> ….........
A21: =R21 -> 0 | B21: =P21 -> 118 | C21: =C20+1 -> 218 | D21: =D20+1 -> 318 | E21: =E20+1 -> 418 | F21: =F20+1 -> 518 | G21: 818 | H21: =H20+1 -> 6118.1 | I21: =I20+1 -> 6218.2 | J21: =J20+1 -> 6318.3 | K21: =K20+1 -> 6418.4 | P21: 118 | Q21: …. | S21: , | T21: …......... | U21: =P21 -> 118 | V21: =Q21 -> …. | W21: =R21 -> 0 | X21: =$U$2 -> = … JOB/ROOMS OVERVIEW PICS .. | Y21: =$T$21 -> …......... | Z21: =C21 -> 218 | AA21: =V21 -> …. | AB21: =W21 -> 0 | AC21: =$Z$2 -> ….. SOURCE of LOSS PICS ….. | AD21: =$T$21 -> …......... | AE21: =D21 -> 318 | AF21: =AA21 -> …. | AG21: =AB21 -> 0 | AH21: =$AE$2 -> ….. C.P.S. …... | AI21: =$T$21 -> …......... | AK21: =E21 -> 418 | AL21: =AF21 -> …. | AM21: =AG21 -> 0 | AN21: =$AK$2 -> NON SALVAGEABLE ITEMS | AO21: =$T$21 -> …......... | AP21: =F21 -> 518 | AQ21: …. | AR21: =AM21 -> 0 | AS21: =AS20 -> ,,,,,, DMO = DEMOLITION ….... | AT21: =T21 -> …......... | AU21: =G21 -> 818 | AV21: . | AW21: =AM21 -> 0 | AX21: =AX20 -> … MITIGATION EQUIPMENT & W.I.P . ... | AY21: =$T$21 -> …......... | AZ21: =H21 -> 6118.1 | BA21: . | BB21: =AW21 -> 0 | BC21: =BC20 -> ... DAY1 MC READINGS .. | BE21: =$T$21 -> …......... | BF21: =I21 -> 6218.2 | BG21: . | BH21: =BB21 -> 0 | BI21: =BI20 -> ... DAY2 MC READINGS .. | BJ21: =$T$21 -> …......... | BK21: =J21 -> 6318.3 | BL21: . | BM21: =BH21 -> 0 | BN21: =BN20 -> ... DAY3 MC READINGS .. | BO21: =$T$21 -> …......... | BP21: =K21 -> 6418.4 | BQ21: . | BR21: =BM21 -> 0 | BS21: =BS20 -> ... DAY4 MC READINGS | BT21: =$T$21 -> …......... | BU21: =BU20+1 -> 7303 | BV21: DRY CHAMBER # 3 | BW21: =BW19 -> ….. DAY 3 ….. | BX21: RH &T & GPP | CF21: , | CH21: =CH20+1 -> 70118 | CI21: ….. DAY 1 ….. | CJ21: =R22 -> 0 | CK21: , | CL21: =T21 -> …......... | CM21: , | CN21: =CN20 -> … DAY # 0 … MC READINGS STABILIZATION | CP21: =R22 -> 0 | CQ21: =T22 -> ….........
A22: =R22 -> 0 | B22: =P22 -> 119 | C22: =C21+1 -> 219 | D22: =D21+1 -> 319 | E22: =E21+1 -> 419 | F22: =F21+1 -> 519 | G22: 819 | H22: =H21+1 -> 6119.1 | I22: =I21+1 -> 6219.2 | J22: =J21+1 -> 6319.3 | K22: =K21+1 -> 6419.4 | P22: 119 | Q22: …. | S22: , | T22: …......... | U22: =P22 -> 119 | V22: =Q22 -> …. | W22: =R22 -> 0 | X22: =$U$2 -> = … JOB/ROOMS OVERVIEW PICS .. | Y22: =$T$22 -> …......... | Z22: =C22 -> 219 | AA22: =V22 -> …. | AB22: =W22 -> 0 | AC22: =$Z$2 -> ….. SOURCE of LOSS PICS ….. | AD22: =$T$22 -> …......... | AE22: =D22 -> 319 | AF22: =AA22 -> …. | AG22: =AB22 -> 0 | AH22: =$AE$2 -> ….. C.P.S. …... | AI22: =$T$22 -> …......... | AK22: =E22 -> 419 | AL22: =AF22 -> …. | AM22: =AG22 -> 0 | AN22: =$AK$2 -> NON SALVAGEABLE ITEMS | AO22: =$T$22 -> …......... | AP22: =F22 -> 519 | AQ22: …. | AR22: =AM22 -> 0 | AS22: =AS21 -> ,,,,,, DMO = DEMOLITION ….... | AT22: =T22 -> …......... | AU22: =G22 -> 819 | AV22: . | AW22: =AM22 -> 0 | AX22: =AX21 -> … MITIGATION EQUIPMENT & W.I.P . ... | AY22: =$T$22 -> …......... | AZ22: =H22 -> 6119.1 | BA22: . | BB22: =AW22 -> 0 | BC22: =BC21 -> ... DAY1 MC READINGS .. | BE22: =$T$22 -> …......... | BF22: =I22 -> 6219.2 | BG22: . | BH22: =BB22 -> 0 | BI22: =BI21 -> ... DAY2 MC READINGS .. | BJ22: =$T$22 -> …......... | BK22: =J22 -> 6319.3 | BL22: . | BM22: =BH22 -> 0 | BN22: =BN21 -> ... DAY3 MC READINGS .. | BO22: =$T$22 -> …......... | BP22: =K22 -> 6419.4 | BQ22: . | BR22: =BM22 -> 0 | BS22: =BS21 -> ... DAY4 MC READINGS | BT22: =$T$22 -> …......... | BU22: =BU21+1 -> 7304 | BV22: DRY CHAMBER # 4 | BW22: =BW20 -> ….. DAY 3 ….. | BX22: RH &T & GPP | CF22: , | CH22: =CH21+1 -> 70119 | CI22: ….. DAY 1 ….. | CJ22: =R23 -> 0 | CK22: , | CL22: =T22 -> …......... | CM22: , | CN22: =CN21 -> … DAY # 0 … MC READINGS STABILIZATION | CP22: =R23 -> 0 | CQ22: =T23 -> ….........
A23: =R23 -> 0 | B23: =P23 -> 120 | C23: =C22+1 -> 220 | D23: =D22+1 -> 320 | E23: =E22+1 -> 420 | F23: =F22+1 -> 520 | G23: 820 | H23: =H22+1 -> 6120.1 | I23: =I22+1 -> 6220.2 | J23: =J22+1 -> 6320.3 | K23: =K22+1 -> 6420.4 | P23: 120 | Q23: …. | S23: , | T23: …......... | U23: =P23 -> 120 | V23: =Q23 -> …. | W23: =R23 -> 0 | X23: =$U$2 -> = … JOB/ROOMS OVERVIEW PICS .. | Y23: =$T$23 -> …......... | Z23: =C23 -> 220 | AA23: =V23 -> …. | AB23: =W23 -> 0 | AC23: =$Z$2 -> ….. SOURCE of LOSS PICS ….. | AD23: =$T$23 -> …......... | AE23: =D23 -> 320 | AF23: =AA23 -> …. | AG23: =AB23 -> 0 | AH23: =$AE$2 -> ….. C.P.S. …... | AI23: =$T$23 -> …......... | AK23: =E23 -> 420 | AL23: =AF23 -> …. | AM23: =AG23 -> 0 | AN23: =$AK$2 -> NON SALVAGEABLE ITEMS | AO23: =$T$23 -> …......... | AP23: =F23 -> 520 | AQ23: …. | AR23: =AM23 -> 0 | AS23: =AS22 -> ,,,,,, DMO = DEMOLITION ….... | AT23: =T23 -> …......... | AU23: =G23 -> 820 | AV23: . | AW23: =AM23 -> 0 | AX23: =AX22 -> … MITIGATION EQUIPMENT & W.I.P . ... | AY23: =$T$23 -> …......... | AZ23: =H23 -> 6120.1 | BA23: . | BB23: =AW23 -> 0 | BC23: =BC22 -> ... DAY1 MC READINGS .. | BE23: =$T$23 -> …......... | BF23: =I23 -> 6220.2 | BG23: . | BH23: =BB23 -> 0 | BI23: =BI22 -> ... DAY2 MC READINGS .. | BJ23: =$T$23 -> …......... | BK23: =J23 -> 6320.3 | BL23: . | BM23: =BH23 -> 0 | BN23: =BN22 -> ... DAY3 MC READINGS .. | BO23: =$T$23 -> …......... | BP23: =K23 -> 6420.4 | BQ23: . | BR23: =BM23 -> 0 | BS23: =BS22 -> ... DAY4 MC READINGS | BT23: =$T$23 -> …......... | BU23: 7400 | BV23: =BV17 -> RH &T & GPP DRY CHAMBERS [DC] .READ INGS =========== | BW23: ….. DAY 4 ….. | CF23: , | CH23: =CH22+1 -> 70120 | CI23: ….. DAY 1 ….. | CJ23: =R24 -> 0 | CK23: , | CL23: =T23 -> …......... | CM23: , | CN23: =CN22 -> … DAY # 0 … MC READINGS STABILIZATION | CP23: =R24 -> 0 | CQ23: =T24 -> ….........
A24: =R24 -> 0 | B24: =P24 -> 121 | C24: =C23+1 -> 221 | D24: =D23+1 -> 321 | E24: =E23+1 -> 421 | F24: =F23+1 -> 521 | G24: 821 | H24: =H23+1 -> 6121.1 | I24: =I23+1 -> 6221.2 | J24: =J23+1 -> 6321.3 | K24: =K23+1 -> 6421.4 | P24: 121 | Q24: …. | S24: , | T24: …......... | U24: =P24 -> 121 | V24: =Q24 -> …. | W24: =R24 -> 0 | X24: =$U$2 -> = … JOB/ROOMS OVERVIEW PICS .. | Y24: =$T$24 -> …......... | Z24: =C24 -> 221 | AA24: =V24 -> …. | AB24: =W24 -> 0 | AC24: =$Z$2 -> ….. SOURCE of LOSS PICS ….. | AD24: =$T$24 -> …......... | AE24: =D24 -> 321 | AF24: =AA24 -> …. | AG24: =AB24 -> 0 | AH24: =$AE$2 -> ….. C.P.S. …... | AI24: =$T$24 -> …......... | AK24: =E24 -> 421 | AL24: =AF24 -> …. | AM24: =AG24 -> 0 | AN24: =$AK$2 -> NON SALVAGEABLE ITEMS | AO24: =$T$24 -> …......... | AP24: =F24 -> 521 | AQ24: …. | AR24: =AM24 -> 0 | AS24: =AS23 -> ,,,,,, DMO = DEMOLITION ….... | AT24: =T24 -> …......... | AU24: =G24 -> 821 | AV24: . | AW24: =AM24 -> 0 | AX24: =AX23 -> … MITIGATION EQUIPMENT & W.I.P . ... | AY24: =$T$24 -> …......... | AZ24: =H24 -> 6121.1 | BA24: . | BB24: =AW24 -> 0 | BC24: =BC23 -> ... DAY1 MC READINGS .. | BE24: =$T$24 -> …......... | BF24: =I24 -> 6221.2 | BG24: . | BH24: =BB24 -> 0 | BI24: =BI23 -> ... DAY2 MC READINGS .. | BJ24: =$T$24 -> …......... | BK24: =J24 -> 6321.3 | BL24: . | BM24: =BH24 -> 0 | BN24: =BN23 -> ... DAY3 MC READINGS .. | BO24: =$T$24 -> …......... | BP24: =K24 -> 6421.4 | BQ24: . | BR24: =BM24 -> 0 | BS24: =BS23 -> ... DAY4 MC READINGS | BT24: =$T$24 -> …......... | BU24: 7400 | BV24: EXTERIOR & UNAFFECTED AREA | BW24: ….. DAY 4 ….. | CF24: , | CH24: =CH23+1 -> 70121 | CI24: ….. DAY 1 ….. | CJ24: =R25 -> 0 | CK24: , | CL24: =T24 -> …......... | CM24: , | CN24: =CN23 -> … DAY # 0 … MC READINGS STABILIZATION | CP24: =R25 -> 0 | CQ24: =T25 -> ….........
A25: =R25 -> 0 | B25: =P25 -> 122 | C25: =C24+1 -> 222 | D25: =D24+1 -> 322 | E25: =E24+1 -> 422 | F25: =F24+1 -> 522 | G25: 822 | H25: =H24+1 -> 6122.1 | I25: =I24+1 -> 6222.2 | J25: =J24+1 -> 6322.3 | K25: =K24+1 -> 6422.4 | P25: 122 | Q25: …. | S25: , | T25: …......... | U25: =P25 -> 122 | V25: =Q25 -> …. | W25: =R25 -> 0 | X25: =$U$2 -> = … JOB/ROOMS OVERVIEW PICS .. | Y25: =$T$25 -> …......... | Z25: =C25 -> 222 | AA25: =V25 -> …. | AB25: =W25 -> 0 | AC25: =$Z$2 -> ….. SOURCE of LOSS PICS ….. | AD25: =$T$25 -> …......... | AE25: =D25 -> 322 | AF25: =AA25 -> …. | AG25: =AB25 -> 0 | AH25: =$AE$2 -> ….. C.P.S. …... | AI25: =$T$25 -> …......... | AK25: =E25 -> 422 | AL25: =AF25 -> …. | AM25: =AG25 -> 0 | AN25: =$AK$2 -> NON SALVAGEABLE ITEMS | AO25: =$T$25 -> …......... | AP25: =F25 -> 522 | AQ25: …. | AR25: =AM25 -> 0 | AS25: =AS24 -> ,,,,,, DMO = DEMOLITION ….... | AT25: =T25 -> …......... | AU25: =G25 -> 822 | AV25: . | AW25: =AM25 -> 0 | AX25: =AX24 -> … MITIGATION EQUIPMENT & W.I.P . ... | AY25: =$T$25 -> …......... | AZ25: =H25 -> 6122.1 | BA25: . | BB25: =AW25 -> 0 | BC25: =BC24 -> ... DAY1 MC READINGS .. | BE25: =$T$25 -> …......... | BF25: =I25 -> 6222.2 | BG25: . | BH25: =BB25 -> 0 | BI25: =BI24 -> ... DAY2 MC READINGS .. | BJ25: =$T$25 -> …......... | BK25: =J25 -> 6322.3 | BL25: . | BM25: =BH25 -> 0 | BN25: =BN24 -> ... DAY3 MC READINGS .. | BO25: =$T$25 -> …......... | BP25: =K25 -> 6422.4 | BQ25: . | BR25: =BM25 -> 0 | BS25: =BS24 -> ... DAY4 MC READINGS | BT25: =$T$25 -> …......... | BU25: =BU24+1 -> 7401 | BV25: DRY CHAMBER # 1 | BW25: =BW24 -> ….. DAY 4 ….. | BX25: RH &T & GPP | CF25: , | CH25: =CH24+1 -> 70122 | CI25: ….. DAY 1 ….. | CJ25: =R26 -> 0 | CK25: , | CL25: =T25 -> …......... | CM25: , | CN25: =CN24 -> … DAY # 0 … MC READINGS STABILIZATION | CP25: =R26 -> 0 | CQ25: =T26 -> ….........
A26: =R26 -> 0 | B26: =P26 -> 123 | C26: =C25+1 -> 223 | D26: =D25+1 -> 323 | E26: =E25+1 -> 423 | F26: =F25+1 -> 523 | G26: 823 | H26: =H25+1 -> 6123.1 | I26: =I25+1 -> 6223.2 | J26: =J25+1 -> 6323.3 | K26: =K25+1 -> 6423.4 | P26: 123 | Q26: …. | S26: , | T26: …......... | U26: =P26 -> 123 | V26: =Q26 -> …. | W26: =R26 -> 0 | X26: =$U$2 -> = … JOB/ROOMS OVERVIEW PICS .. | Y26: =$T$26 -> …......... | Z26: =C26 -> 223 | AA26: =V26 -> …. | AB26: =W26 -> 0 | AC26: =$Z$2 -> ….. SOURCE of LOSS PICS ….. | AD26: =$T$26 -> …......... | AE26: =D26 -> 323 | AF26: =AA26 -> …. | AG26: =AB26 -> 0 | AH26: =$AE$2 -> ….. C.P.S. …... | AI26: =$T$26 -> …......... | AK26: =E26 -> 423 | AL26: =AF26 -> …. | AM26: =AG26 -> 0 | AN26: =$AK$2 -> NON SALVAGEABLE ITEMS | AO26: =$T$26 -> …......... | AP26: =F26 -> 523 | AQ26: …. | AR26: =AM26 -> 0 | AS26: =AS25 -> ,,,,,, DMO = DEMOLITION ….... | AT26: =T26 -> …......... | AU26: =G26 -> 823 | AV26: . | AW26: =AM26 -> 0 | AX26: =AX25 -> … MITIGATION EQUIPMENT & W.I.P . ... | AY26: =$T$26 -> …......... | AZ26: =H26 -> 6123.1 | BA26: . | BB26: =AW26 -> 0 | BC26: =BC25 -> ... DAY1 MC READINGS .. | BE26: =$T$26 -> …......... | BF26: =I26 -> 6223.2 | BG26: . | BH26: =BB26 -> 0 | BI26: =BI25 -> ... DAY2 MC READINGS .. | BJ26: =$T$26 -> …......... | BK26: =J26 -> 6323.3 | BL26: . | BM26: =BH26 -> 0 | BN26: =BN25 -> ... DAY3 MC READINGS .. | BO26: =$T$26 -> …......... | BP26: =K26 -> 6423.4 | BQ26: . | BR26: =BM26 -> 0 | BS26: =BS25 -> ... DAY4 MC READINGS | BT26: =$T$26 -> …......... | BU26: =BU25+1 -> 7402 | BV26: DRY CHAMBER # 2 | BW26: =BW25 -> ….. DAY 4 ….. | BX26: RH &T & GPP | CF26: , | CH26: =CH25+1 -> 70123 | CI26: ….. DAY 1 ….. | CJ26: =R27 -> 0 | CK26: , | CL26: =T26 -> …......... | CM26: , | CN26: =CN25 -> … DAY # 0 … MC READINGS STABILIZATION | CP26: =R27 -> 0 | CQ26: =T27 -> ….........
