Workbook
Name a...new_customer: #REF!
Name a...new_customer: #REF!
Name a...new_customer: #REF!
Name basicroompichow2: #REF!
Name box_names: +#REF!
Name Column.a.new.cst: #REF!
Name culpepper: #REF!
Name data: #REF!
Name Document_Stacking_List: #REF!
Name Enter_new_cst_data: #REF!
Name Jefferies: #REF!
Name LOVEJOY_INTERIOR: #REF!
Name Lovejoy_ROOF: #REF!
Name LxWxH: #REF!
Name new_customer: #REF!
Name PRICE_P: #REF!
Name Robinson: #REF!
Name sigtj: "Picture 9859"
Name SubContractor_Summary: #REF!
Name Wayside_Builders__LLC_…...OH: #REF!
Name WSB...GA.Wayside_Builders__LLC……GA: #REF!

Sheet docs
A1: DOCS Table of Contents
B2: 01 Info Page Only
A3: O | B3: JOB INFO
A4: O | B4: =+'quick chklst'!A1 -> BASIC SUMMARY OF RESTORATION PROCESS; (Quick version).
A6: O | B6: =+#REF! -> #REF!
A7: O | B7: =ENC!#REF! -> #REF!
A8: O | B8: =ENC!A1 -> ENCIRCLE
A9: O | B9: =+#REF! -> #REF!
A10: O | B10: =+#REF! -> #REF!
A11: O | B11: =+'how2'!A115 -> Note on creating the New Custmer Contract & Docs
A12: O | B12: JOB INFO (2) …......... for exporting

Sheet quick chklst
A1: BASIC SUMMARY OF RESTORATION PROCESS; (Quick version). | D1: =+'jobinfo(2)'!C2 -> 3922 E 189 STR
A2: JOB | C2: =+'jobinfo(2)'!C51 -> OH25 BROWNLEE @E189 | D2: =+'jobinfo(2)'!C3 -> CLEVELAND, OH 44128
A3: 1 | B3: Introduction, Analysis & Verification | C3: Introduction, Analysis & Verification /source/referred by: | D3: Status Notes / %
C4: Who is the Insurance Company ?!? | D4: ='jobinfo(2)'!C26 -> ALLSTATE INS CO. | G4: 100
A5: POI | C5: Does customer Comprehend Our Role in the process? | D5: Y
C6: Is this a COVERED INSURANCE Claim? Or Self Pay ? | D6: Y
C7: IS THE DAMAGE $ MORE THAN THE DEDUCTIBLE? | D7: Y
C8: Do they have coverage; for AOB? = POLICY & DEC PAGE | D8: Y | G8: 200
A9: 2 | B9: Contracts & Documentation | C9: Contracts & Documentation | D9: Y
C10: Has Customer been fully advised of Contract Contents? | D10: Y
C11: Has Customer had a full Consultation to Our Terms & Conditions? | D11: Y | G11: 500
A12: DOC | C12: Does Customer FULLY Agree to Terms &Conditions? Signed / Initials? | D12: Y
C13: Notary Page explained/ Fast track | D13: Y
A14: mou | C14: Company investment (dollars, time ,materials)into their Project? | D14: Y
C15: Mutual trust , cooperation & confidence | D15: Y
A16: 3 | C16: CLAIM REPORTING;DOES THE CUSTOMER HAVE REQUIRED INFO? | D16: Y
A17: INS | C17: Insurer Mitigation / DMO / CPS Approval Info Sheet | D17: Y | G17: 100
A18: PICS | C18: Create ENCIRCLE project (Pictures critical part of PAYMENTprocess! | D18: Y
A19: mit | B19: Mitigation & Demolition | C19: Mitigation & Demolition (ROOM LABELS POSTED)
A20: 4 | C20: Roof & EXT Mitigation TEMPORARY & EMERGENCY REPAIRS | D20: Y | G20: 1000
A21: 5 | C21: Contents_ item list_; storage details; security explained? | D21: Y | G21: 2000
A22: 6 | C22: Interior Mitigation; household disruption explained? | D22: NA | G22: 2000
C23: HMR / Secondary Damages; Equipment & Electricity $ | D23: NA
A24: esx | B24: Estimates | C24: Estimates (Inspection/Scope Form)
C25: SKETCH/DRAWING;[1] sheet per floor
A26: 7 | C26: Interior & EXTERIOR REBUILD | G26: 200
C27: EXTERIOR MITIGATION | D27: Y
C28: INTERIOR Mitigation & Demolition | D28: NA
A29: 8 | B29: Insurance Company Meetings | C29: Insurance Company Meetings
A30: adj | C30: Docs for adjuster meeting; Print & bind docs BE PRESENT WHEN ADJUSTER VISITS The PROPERTY. | G30: 500
A31: 9 | B31: Cashflow General Contractor / Subcontracts | C31: Cashflow General Contractor / Subcontracts
A32: job | C32: Contents
A33: 10 | B33: Mitigation & Demolition | C33: & EXterior Mitigation & Demolition
B34: Interior Mitigation & Demolition | C34: Closeout Interior Mitigation & Demolition
C35: Rebuild
G36: =SUM(G1:G35) -> 6600
C37: BASIC SUMMARY OF RESTORATION PROCESS; (Quick version). | D37: =+'jobinfo(2)'!$C$2 -> 3922 E 189 STR
A38: JOB | C38: =+'jobinfo(2)'!C51 -> OH25 BROWNLEE @E189 | D38: =+'jobinfo(2)'!$C$3 -> CLEVELAND, OH 44128
A39: 1 | B39: Introduction, Analysis & Verification | C39: Introduction, Analysis & Verification /source/referred by: | D39: ='jobinfo(2)'!$C$27 -> CLM
C40: Who is the Insurance Company ?!? | D40: ='jobinfo(2)'!$C$26 -> ALLSTATE INS CO.
...

Sheet OFS INITIAL CKLST
B1: OFFICE QUICKLIST | D1: ='jobinfo(2)'!C1 -> BROWNLEE, KEN
A2: INITIAL DOCS IN ( to start claim)
A3: 1 | B3: VERIFY / ASSESS DAMAGE; Full Consultation to Our Terms/Conditions? MOU Our Role in process? | C3: REQUEST IN & OUT | E3: 201
A4: 2 | B4: POLICY & DEC PAGE = ACV or Replacement Do they have coverage; | C4: REQUEST IN | D4: ='jobinfo(2)'!C2 -> 3922 E 189 STR | E4: =E3+1 -> 202
A5: 3 | B5: Does customer Comprehend AOB? DEDUCTABLE PAYMENT? PAID____ | C5: REQUEST IN | E5: =E4+1 -> 203
A6: 4 | B6: Create ENCIRCLE project; CONTRACT SIGNED / Notary Page explained = Fast track ….AOB? | C6: REQUEST SENT & IN | E6: =E5+1 -> 204
A7: 5 | B7: JOBSITE VERIFICATION PICS & ROOMS VIDEO …..& SHORT ROOM LIST... (upon initial visit) | C7: CREATE | D7: ='jobinfo(2)'!B5 -> Cst-owner Phone# | E7: =E6+1 -> 205
A8: INITIAL DOCS OUT TO CUSTOMER ( to start claim) | D8: ='jobinfo(2)'!C5 -> 2163241337 | E8: =E7+1 -> 206
A9: 6 | B9: CLAIM REPORTING Info Sheet;Insurer Approval [Mitigation/DMO/CPS] DOCUMENT CONTACT | C9: REQUEST SENT & IN | E9: =E8+1 -> 207
A10: 7 | B10: MOU SENT OUT TO CUSTOMER | C10: REQUEST SENT & IN | D10: ='jobinfo(2)'!C4 -> KHAIAKEN@SBCGLOBAL.NET | E10: =E9+1 -> 208
A11: INITIAL REPORTS/DOCS GENERATED ( to start claim) | E11: =E10+1 -> 209
A12: 8 | B12: Order REPORT ..; Eagleview Roof / …. Siding / ….. PLUMBERS / …. FIRE / …..POLICE | C12: CREATE | E12: =E11+1 -> 210
B13: LEAD HMR TESTING
A14: 9 | B14: ENCIRCLE FLOOR PLAN …................... CREATED @ JOBSITE | C14: CREATE | E14: =E12+1 -> 211
A15: 10 | B15: Create ENCIRCLE Project; ROOM LISTS….. SHARE 2 TEAM Option ( V2 then Merge) | C15: CREATE | E15: =E14+1 -> 212
B16: SELECT JOB TYPE per STOCK ROOM LISTS; = WTR / FIRE or RFG & WTR | C16: CREATE | D16: ='jobinfo(2)'!C26 -> ALLSTATE INS CO. | E16: =E15+1 -> 213
B17: Determine / Input job Room names per jobsite visit ROOM ORDER SET-UP | C17: CREATE | E17: =E16+1 -> 214
B18: GENERATE ROOM LABELS & CPS BOX LABELS ; EMAIL OUT | C18: CREATE | E18: =E17+1 -> 215
B19: 100 ROOMS Overview / 360 = Scope Form | C19: CREATE | E19: =E18+1 -> 216
B20: 400 SOURCE OF LOSS 500 CPS DAY 1 / 2 / 3 / 4 | C20: CREATE | E20: =E19+1 -> 217
B21: 800 MIT W.I.P. & EQPT Mitigation LABELS (Demolition) | C21: CREATE | E21: =E20+1 -> 218
B22: READINGS DAY 1 / 2 / 3 / 4 … 6000 MC & 7000 RHT+GPP | C22: CREATE | E22: =E21+1 -> 219
A23: 12 | B23: IMPORT & EDIT The ENCIRCLE FLOOR PLAN (PRINT AS NEEDED) | C23: IN | E23: =E22+1 -> 220
A24: 13 | B24: (UPDATE AS NEEDED) CREATE ROOM Names LISTS in ENCIRCLE & EXCEL | E24: =E23+1 -> 221
A25: 14 | B25: RUN EXCEL MACRO & VERIFY TEMPLATES | C25: CREATE | D25: ='jobinfo(2)'!C27 -> CLM | E25: =E24+1 -> 222
A26: AUTOMATE THE FOLLOWING | E26: =E25+1 -> 223
A27: GENERATE LABELS = ROOMS / CPS BOXES / MITIGATION EQUIPTMENT PLACEMENT; …. | C27: EMAIL OUT | E27: =E26+1 -> 224
A28: 16 | B28: RUN EXCEL MACRO 4 MITIGATION WORK & EQUIPMENT | C28: CREATE | E28: =E27+1 -> 225
A29: 17 | B29: CREATE & SEND; ROOMS SCOPE FORM (FUTURE = 360 CAMERA) | C29: EMAIL OUT
A30: 19 | B30: Mitigation LABELS (Demolition) | C30: EMAIL OUT
A31: 20 | B31: Enter Room Sizes (from Encircle Floor Plan) & Damage Percentages %: @ jobinfo2 | C31: CREATE
A32: 21 | B32: Calculate MIT Equipment (MIT Eqpmnt ALL) & Deliver To Jobsite/Set Up Equipment | C32: EMAIL OUT
B33: CREATE & SEND; MIT EQUIPMENT SETUP WORK & EQUIPMENT FORM | C33: EMAIL OUT
A34: 22 | B34: Calculate/Estimate CPS Supplies | C34: EMAIL OUT
A35: 23 | B35: Order & Deliver to Jobsite…..... Packout Supplies = boxes / tape / shrink wrap | C35: EMAIL OUT
A36: 24 | B36: GET Inspection/Scope Form [ ENCIRCLE or Genius Scan] sent from app | C36: REQUEST IN
A37: 25 | B37: CREATE XACTIMATE PROJECT; (Copy & Paste DATA from Encircle)
B38: Estimates
A40: 26
A41: 27
...

Sheet jobinfo(2)
A1: Customer | B1: Property-Owner Name | C1: BROWNLEE, KEN | O1: Enter info here | S1: ADD SOS LINK
B2: Property address: street | C2: 3922 E 189 STR | O2: New Customer Info required | P2: NEEDS TO SELF POPULATE | S2: LINK TO VIDEOS
B3: Property city, state, zip | C3: CLEVELAND, OH 44128 | S3: BEFORE AND AFTER P[CS
B4: Customer Email | C4: KHAIAKEN@SBCGLOBAL.NET | S4: CLE ATL NY NC NY
B5: Cst-owner Phone# | C5: 2163241337
B6: Co-Owner.cst#2 | C6: NA
B7: cst ph # 2 | C7: NA | S7: RFG WIP…CURRENT JOBS
B8: Cst address # 2 | C8: NA | S8: SIGNAGE
B9: city, state-cst#2 | C9: NA
B10: email-cst #2 | C10: NA
A11: Loss Info | B11: Cause of Loss | C11: WATER | O11: Wind = Roof | P11: Water Damage=WTR | Q11: Fire Smoke | R11: Wind=Tree | S11: Hurricane =HURR
B12: date of loss | C12: 45986 | O12: rebuild type
B13: rebuild type 1 | C13: interior repairs LVL1 | O13: roofing shingles replacement | Q13: fencing
B14: rebuild type 2 | C14: interior repairs LVL2 | O14: interior repairs | Q14: shed
B15: rebuild type 3 | O15: exterior repairs | Q15: porch patio
B16: DEMO | C16: Y | O16: Y
B17: Mitigation | C17: Y | O17: Y
B18: Other Structures | C18: NA | O18: Y
A19: CPS | B19: Replacement | C19: Y | O19: Y
B20: CPS / CLN / CON/ CGN | C20: Y | O20: Y
B21: Year Built | C21: 1956 | O21: TBD
B22: Contract Date | C22: =C12+1 -> 45987 | O22: TBD | P22: pre 1980 | Q22: post 1980
B23: Loss of use/ ALE | C23: Y | O23: sample cost 3
B24: Breathing issue | C24: TBD | O24: doctor letter
B25: HMR | C25: TBD | O25: lab test
B26: Insurance Co. Name | C26: ALLSTATE INS CO. | O26: Insurance Company Supplied Info | P26: Per declaration pages | R26: 34-H-6822C9-2
A27: Insurance Co. | B27: Claim # | C27: CLM | P27: Assigned by Insurer
B28: policy # | C28: PL3\ | P28: Per declaration pages | Q28: OFP DWF 7266580
B29: Email INS. co. | C29: claims@claims.allstate.com | P29: Per declaration pages
B30: DESK Adjuster DA | P30: Assigned by Insurer
B31: DA Phone | P31: customer service rep
B32: DA Ph. Ext. # | P32: Hazel
B33: DA Email | P33: 43789
B34: Field Adjuster Name | P34: 5pm
B35: Phone # field adj
B36: Field adj email
B37: adj contents | P37: Assigned by Insurer
B38: adj CPS phone #
B39: adj CPS email
B40: TMP adj | P40: Assigned by Insurer
...

Sheet ROOMS#
A1: LISTS | C1: INPUT = ROOM NAMES | E1: LOS / TRAVEL | G1: OUTPUT = | I1: ROOM NAME ADD TO ENCIRCLE ROOM LISTS | K1: LOS / TRAVEL | M1: OUTPUT = ENC ROOM NAME | Q1: LOS / TRAVEL | S1: OUTPUT = ENC ROOM NAME | W1: LOS / TRAVEL | Y1: OUTPUT = ENC ROOM NAME | AC1: LOS / TRAVEL | AE1: ,,,,,, DMO = DEMOLITION ….... | AI1: LOS / TRAVEL | AK1: … WTR MITIGATION EQUIPMENT & W.I.P . ... | AO1: LOS / TRAVEL | AQ1: … HMR MITIGATION EQUIPMENT & W.I.P . ... | AU1: LOS / TRAVEL | AW1: … DAY # 0 … MC READINGS STABILIZATION | BD1: ... DAY1 MC READINGS .. | BI1: LOS / TRAVEL | BK1: ... DAY2 MC READINGS .. | BO1: LOS / TRAVEL | BQ1: ... DAY3 MC READINGS .. | BU1: LOS / TRAVEL | BW1: ... DAY4 MC READINGS | CA1: LOS / TRAVEL | CC1: RH &T & GPP DRY CHAMBERS [DC] .READ INGS | CJ1: DEFAULT TMP1 1 | CL1: WTR METER | CM1: ADD CPS OVERVIEW = MULTIPLE ROOMS / WITH LABELS | CX1: ROOM LABELS
A2: = … JOB/ROOMS OVERVIEW PICS .. | G2: =A2 -> = … JOB/ROOMS OVERVIEW PICS .. | M2: ….. SOURCE of LOSS PICS ….. | S2: ….. C.P.S. …... | Y2: NON SALVAGEABLE ITEMS | AB2: ='ROOMS-out'!I1 -> 0 | AE2: ,,,,,, DMO = DEMOLITION ….... | AK2: ='ROOMS-out'!K1 -> 0 | AQ2: ='ROOMS-out'!Q1 -> 0 | AW2: =AW1 -> … DAY # 0 … MC READINGS STABILIZATION | BD2: .. DAY 1 … | BK2: ….. DAY 2 ….. | BQ2: ….. DAY 3 ….. | BW2: ….. DAY 4 ….. | CC2: ….. DAY 1 ….. | CJ2: KITCHEN CABINETS SIZES | CM2: BATHROOM VANITY SIZE & FIXTURES | CX2: ROOM LABELS
A3: =A4-1 -> 100 | B3: …. | C3: =A2 -> = … JOB/ROOMS OVERVIEW PICS .. | D3: , | E3: ======= | G3: =A3 -> 100 | H3: =B3 -> …. | I3: =G2 -> = … JOB/ROOMS OVERVIEW PICS .. | K3: ====== | M3: 200 | N3: =H3 -> …. | O3: =M2 -> ….. SOURCE of LOSS PICS ….. | P3: ==================== | Q3: ====== | S3: 300 | T3: =N3 -> …. | U3: =S2 -> ….. C.P.S. …... | V3: ============== | W3: ====== | Y3: 400 | Z3: =T3 -> …. | AA3: =Y2 -> NON SALVAGEABLE ITEMS | AB3: ============================== | AE3: 500 | AF3: …. | AG3: =AE2 -> ,,,,,, DMO = DEMOLITION ….... | AH3: ============================== | AI3: ============================== | AK3: 600 | AL3: . | AM3: MITIGATION EQUIPMENT & W.I.P. ================ MIT & WIP === | AO3: ============================== | AQ3: 700 | AR3: . | AS3: =AQ1 -> … HMR MITIGATION EQUIPMENT & W.I.P . ... | AU3: ============================== | AW3: 8000 | AX3: ….. | AY3: ======= DAY # 0 ….. MC READINGS STABILIZATION =============== | BD3: 8100 | BE3: . | BF3: =BD1 -> ... DAY1 MC READINGS .. | BG3: ========= | BH3: =============== | BI3: ===== | BK3: =BD3+100 -> 8200 | BL3: . | BM3: =BK1 -> ... DAY2 MC READINGS .. | BN3: =============== | BO3: ====== | BQ3: =BK3+100 -> 8300 | BR3: . | BS3: =BQ2 -> ….. DAY 3 ….. | BT3: ===================== | BU3: ====== | BW3: =BQ3+100 -> 8400 | BX3: . | BY3: =BW2 -> ….. DAY 4 ….. | BZ3: =============== | CA3: =$E$3 -> ======= | CC3: =CC5-0.1 -> 9099.9 | CD3: =CC1 -> RH &T & GPP DRY CHAMBERS [DC] .READ INGS | CF3: ---------------- | CJ3: 0 | CK3: ….. | CL3: DEFAULT LIST EXISTS (AS BELOW); CLICK DROPDOWN MENU; ADD JOB TYPES AS NEEDED | CX3: =C3 -> = … JOB/ROOMS OVERVIEW PICS .. | CY3: =========
A4: 101 | B4: …. | C4: ='jobinfo(2)'!C53 -> Living Room, | D4: , | E4: …......... | G4: =A4 -> 101 | H4: =B4 -> …. | I4: =C4 -> Living Room, | J4: =$G$2 -> = … JOB/ROOMS OVERVIEW PICS .. | K4: =$E$4 -> …......... | M4: =M3+1 -> 201 | N4: =H4 -> …. | O4: =I4 -> Living Room, | P4: =$M$2 -> ….. SOURCE of LOSS PICS ….. | Q4: =$E$4 -> …......... | S4: =S3+1 -> 301 | T4: =N4 -> …. | U4: =O4 -> Living Room, | V4: =$S$2 -> ….. C.P.S. …... | W4: =$E$4 -> …......... | Y4: =Y3+1 -> 401 | Z4: =T4 -> …. | AA4: =U4 -> Living Room, | AB4: =$Y$2 -> NON SALVAGEABLE ITEMS | AC4: =$E$4 -> …......... | AE4: =AE3+1 -> 501 | AF4: …. | AG4: =AA4 -> Living Room, | AH4: =AG3 -> ,,,,,, DMO = DEMOLITION ….... | AI4: =E4 -> …......... | AK4: =AK3+1 -> 601 | AL4: . | AM4: =AA4 -> Living Room, | AN4: =AK1 -> … WTR MITIGATION EQUIPMENT & W.I.P . ... | AO4: =$E$4 -> …......... | AQ4: =AQ3+1 -> 701 | AR4: . | AS4: =AG4 -> Living Room, | AT4: =AQ1 -> … HMR MITIGATION EQUIPMENT & W.I.P . ... | AU4: =$E$4 -> …......... | AW4: =AW3+1 -> 8001 | AX4: . | AY4: =C4 -> Living Room, | AZ4: =AW1 -> … DAY # 0 … MC READINGS STABILIZATION | BD4: 8101.1 | BE4: . | BF4: =AM4 -> Living Room, | BG4: =BD1 -> ... DAY1 MC READINGS .. | BI4: =$E$4 -> …......... | BK4: =BK3+1.2 -> 8201.2 | BL4: . | BM4: =BF4 -> Living Room, | BN4: =BK1 -> ... DAY2 MC READINGS .. | BO4: =$E$4 -> …......... | BQ4: =BQ3+1.3 -> 8301.3 | BR4: . | BS4: =BM4 -> Living Room, | BT4: =BQ1 -> ... DAY3 MC READINGS .. | BU4: =$E$4 -> …......... | BW4: =BW3+1.4 -> 8401.4 | BX4: . | BY4: =BS4 -> Living Room, | BZ4: =BW1 -> ... DAY4 MC READINGS | CA4: =$E$4 -> …......... | CC4: 9100 | CD4: RH &T & GPP DRY CHAMBERS [DC] .READ INGS =========== | CE4: =CC2 -> ….. DAY 1 ….. | CJ4: 0.0001 | CK4: ….. | CL4: JOBSITE VERIFICATION | CX4: =C4 -> Living Room, | CY4: =E4 -> ….........
A5: 102 | B5: …. | C5: ='jobinfo(2)'!C54 -> HALLWAY | D5: , | E5: ….......... | G5: =A5 -> 102 | H5: =B5 -> …. | I5: =C5 -> HALLWAY | J5: =$G$2 -> = … JOB/ROOMS OVERVIEW PICS .. | K5: =$E$5 -> ….......... | M5: =M4+1 -> 202 | N5: =H5 -> …. | O5: =I5 -> HALLWAY | P5: =$M$2 -> ….. SOURCE of LOSS PICS ….. | Q5: =$E$5 -> ….......... | S5: =S4+1 -> 302 | T5: =N5 -> …. | U5: =O5 -> HALLWAY | V5: =$S$2 -> ….. C.P.S. …... | W5: =$E$5 -> ….......... | Y5: =Y4+1 -> 402 | Z5: =T5 -> …. | AA5: =U5 -> HALLWAY | AB5: =$Y$2 -> NON SALVAGEABLE ITEMS | AC5: =$E$5 -> ….......... | AE5: =AE4+1 -> 502 | AF5: …. | AG5: =AA5 -> HALLWAY | AH5: =AH4 -> ,,,,,, DMO = DEMOLITION ….... | AI5: =E5 -> ….......... | AK5: =AK4+1 -> 602 | AL5: . | AM5: =AA5 -> HALLWAY | AN5: =AN4 -> … WTR MITIGATION EQUIPMENT & W.I.P . ... | AO5: =$E$5 -> ….......... | AQ5: =AQ4+1 -> 702 | AR5: . | AS5: =AG5 -> HALLWAY | AT5: =AT4 -> … HMR MITIGATION EQUIPMENT & W.I.P . ... | AU5: =$E$5 -> ….......... | AW5: =AW4+1 -> 8002 | AX5: . | AY5: =C5 -> HALLWAY | AZ5: =AZ4 -> … DAY # 0 … MC READINGS STABILIZATION | BD5: =BD4+1 -> 8102.1 | BE5: . | BF5: =AM5 -> HALLWAY | BG5: =BG4 -> ... DAY1 MC READINGS .. | BI5: =$E$5 -> ….......... | BK5: =BK4+1 -> 8202.2 | BL5: . | BM5: =BF5 -> HALLWAY | BN5: =BN4 -> ... DAY2 MC READINGS .. | BO5: =$E$5 -> ….......... | BQ5: =BQ4+1 -> 8302.3 | BR5: . | BS5: =BM5 -> HALLWAY | BT5: =BT4 -> ... DAY3 MC READINGS .. | BU5: =$E$5 -> ….......... | BW5: =BW4+1 -> 8402.4 | BX5: . | BY5: =BS5 -> HALLWAY | BZ5: =BZ4 -> ... DAY4 MC READINGS | CA5: =$E$5 -> ….......... | CC5: =CC4 -> 9100 | CD5: EXTERIOR & UNAFFECTED AREA | CE5: =CC2 -> ….. DAY 1 ….. | CF5: RH &T & GPP | CJ5: 0.0002 | CK5: . | CL5: MECHANICALS = WATER METER READING & PLUMBING REPORT/INVOICE | CN5: , | CO5: ====== | CX5: =C5 -> HALLWAY | CY5: =E5 -> …..........
A6: 103 | B6: …. | C6: ='jobinfo(2)'!C55 -> Kitchen, | D6: , | E6: …......... | G6: =A6 -> 103 | H6: =B6 -> …. | I6: =C6 -> Kitchen, | J6: =$G$2 -> = … JOB/ROOMS OVERVIEW PICS .. | K6: =$E$6 -> …......... | M6: =M5+1 -> 203 | N6: =H6 -> …. | O6: =I6 -> Kitchen, | P6: =$M$2 -> ….. SOURCE of LOSS PICS ….. | Q6: =$E$6 -> …......... | S6: =S5+1 -> 303 | T6: =N6 -> …. | U6: =O6 -> Kitchen, | V6: =$S$2 -> ….. C.P.S. …... | W6: =$E$6 -> …......... | Y6: =Y5+1 -> 403 | Z6: =T6 -> …. | AA6: =U6 -> Kitchen, | AB6: =$Y$2 -> NON SALVAGEABLE ITEMS | AC6: =$E$6 -> …......... | AE6: =AE5+1 -> 503 | AF6: …. | AG6: =AA6 -> Kitchen, | AH6: =AH5 -> ,,,,,, DMO = DEMOLITION ….... | AI6: =E6 -> …......... | AK6: =AK5+1 -> 603 | AL6: . | AM6: =AA6 -> Kitchen, | AN6: =AN5 -> … WTR MITIGATION EQUIPMENT & W.I.P . ... | AO6: =$E$6 -> …......... | AQ6: =AQ5+1 -> 703 | AR6: . | AS6: =AG6 -> Kitchen, | AT6: =AT5 -> … HMR MITIGATION EQUIPMENT & W.I.P . ... | AU6: =$E$6 -> …......... | AW6: =AW5+1 -> 8003 | AX6: . | AY6: =C6 -> Kitchen, | AZ6: =AZ5 -> … DAY # 0 … MC READINGS STABILIZATION | BD6: =BD5+1 -> 8103.1 | BE6: . | BF6: =AM6 -> Kitchen, | BG6: =BG5 -> ... DAY1 MC READINGS .. | BI6: =$E$6 -> …......... | BK6: =BK5+1 -> 8203.2 | BL6: . | BM6: =BF6 -> Kitchen, | BN6: =BN5 -> ... DAY2 MC READINGS .. | BO6: =$E$6 -> …......... | BQ6: =BQ5+1 -> 8303.3 | BR6: . | BS6: =BM6 -> Kitchen, | BT6: =BT5 -> ... DAY3 MC READINGS .. | BU6: =$E$6 -> …......... | BW6: =BW5+1 -> 8403.4 | BX6: . | BY6: =BS6 -> Kitchen, | BZ6: =BZ5 -> ... DAY4 MC READINGS | CA6: =$E$6 -> …......... | CC6: =CC5+1.1 -> 9101.1 | CD6: DRY CHAMBER # 1 | CE6: =CE5 -> ….. DAY 1 ….. | CF6: RH &T & GPP | CJ6: 0.0003 | CK6: . | CL6: MECHANICALS = ELECTRICAL HAZARDS | CN6: , | CO6: ====== | CX6: =C6 -> Kitchen, | CY6: =E6 -> ….........
A7: 104 | B7: …. | C7: ='jobinfo(2)'!C56 -> DEN | D7: , | E7: …......... | G7: =A7 -> 104 | H7: =B7 -> …. | I7: =C7 -> DEN | J7: =$G$2 -> = … JOB/ROOMS OVERVIEW PICS .. | K7: =$E$7 -> …......... | M7: =M6+1 -> 204 | N7: =H7 -> …. | O7: =I7 -> DEN | P7: =$M$2 -> ….. SOURCE of LOSS PICS ….. | Q7: =$E$7 -> …......... | S7: =S6+1 -> 304 | T7: =N7 -> …. | U7: =O7 -> DEN | V7: =$S$2 -> ….. C.P.S. …... | W7: =$E$7 -> …......... | Y7: =Y6+1 -> 404 | Z7: =T7 -> …. | AA7: =U7 -> DEN | AB7: =$Y$2 -> NON SALVAGEABLE ITEMS | AC7: =$E$7 -> …......... | AE7: =AE6+1 -> 504 | AF7: …. | AG7: =AA7 -> DEN | AH7: =AH6 -> ,,,,,, DMO = DEMOLITION ….... | AI7: =E7 -> …......... | AK7: =AK6+1 -> 604 | AL7: . | AM7: =AA7 -> DEN | AN7: =AN6 -> … WTR MITIGATION EQUIPMENT & W.I.P . ... | AO7: =$E$7 -> …......... | AQ7: =AQ6+1 -> 704 | AR7: . | AS7: =AG7 -> DEN | AT7: =AT6 -> … HMR MITIGATION EQUIPMENT & W.I.P . ... | AU7: =$E$7 -> …......... | AW7: =AW6+1 -> 8004 | AX7: . | AY7: =C7 -> DEN | AZ7: =AZ6 -> … DAY # 0 … MC READINGS STABILIZATION | BD7: =BD6+1 -> 8104.1 | BE7: . | BF7: =AM7 -> DEN | BG7: =BG6 -> ... DAY1 MC READINGS .. | BI7: =$E$7 -> …......... | BK7: =BK6+1 -> 8204.2 | BL7: . | BM7: =BF7 -> DEN | BN7: =BN6 -> ... DAY2 MC READINGS .. | BO7: =$E$7 -> …......... | BQ7: =BQ6+1 -> 8304.3 | BR7: . | BS7: =BM7 -> DEN | BT7: =BT6 -> ... DAY3 MC READINGS .. | BU7: =$E$7 -> …......... | BW7: =BW6+1 -> 8404.4 | BX7: . | BY7: =BS7 -> DEN | BZ7: =BZ6 -> ... DAY4 MC READINGS | CA7: =$E$7 -> …......... | CC7: =CC6+1 -> 9102.1 | CD7: DRY CHAMBER # 2 | CE7: =CE6 -> ….. DAY 1 ….. | CF7: RH &T & GPP | CJ7: 0.0004 | CK7: . | CL7: EXT DAMAGE IF APPLICABLE | CM7: ROOF TARPS …............................. | CN7: , | CO7: ====== | CX7: =C7 -> DEN | CY7: =E7 -> ….........
A8: 105 | B8: …. | C8: ='jobinfo(2)'!C57 -> STAIRS UP | D8: , | E8: …......... | G8: =A8 -> 105 | H8: =B8 -> …. | I8: =C8 -> STAIRS UP | J8: =$G$2 -> = … JOB/ROOMS OVERVIEW PICS .. | K8: =$E$8 -> …......... | M8: =M7+1 -> 205 | N8: =H8 -> …. | O8: =I8 -> STAIRS UP | P8: =$M$2 -> ….. SOURCE of LOSS PICS ….. | Q8: =$E$8 -> …......... | S8: =S7+1 -> 305 | T8: =N8 -> …. | U8: =O8 -> STAIRS UP | V8: =$S$2 -> ….. C.P.S. …... | W8: =$E$8 -> …......... | Y8: =Y7+1 -> 405 | Z8: =T8 -> …. | AA8: =U8 -> STAIRS UP | AB8: =$Y$2 -> NON SALVAGEABLE ITEMS | AC8: =$E$8 -> …......... | AE8: =AE7+1 -> 505 | AF8: …. | AG8: =AA8 -> STAIRS UP | AH8: =AH7 -> ,,,,,, DMO = DEMOLITION ….... | AI8: =E8 -> …......... | AK8: =AK7+1 -> 605 | AL8: . | AM8: =AA8 -> STAIRS UP | AN8: =AN7 -> … WTR MITIGATION EQUIPMENT & W.I.P . ... | AO8: =$E$8 -> …......... | AQ8: =AQ7+1 -> 705 | AR8: . | AS8: =AG8 -> STAIRS UP | AT8: =AT7 -> … HMR MITIGATION EQUIPMENT & W.I.P . ... | AU8: =$E$8 -> …......... | AW8: =AW7+1 -> 8005 | AX8: . | AY8: =C8 -> STAIRS UP | AZ8: =AZ7 -> … DAY # 0 … MC READINGS STABILIZATION | BD8: =BD7+1 -> 8105.1 | BE8: . | BF8: =AM8 -> STAIRS UP | BG8: =BG7 -> ... DAY1 MC READINGS .. | BI8: =$E$8 -> …......... | BK8: =BK7+1 -> 8205.2 | BL8: . | BM8: =BF8 -> STAIRS UP | BN8: =BN7 -> ... DAY2 MC READINGS .. | BO8: =$E$8 -> …......... | BQ8: =BQ7+1 -> 8305.3 | BR8: . | BS8: =BM8 -> STAIRS UP | BT8: =BT7 -> ... DAY3 MC READINGS .. | BU8: =$E$8 -> …......... | BW8: =BW7+1 -> 8405.4 | BX8: . | BY8: =BS8 -> STAIRS UP | BZ8: =BZ7 -> ... DAY4 MC READINGS | CA8: =$E$8 -> …......... | CC8: =CC7+1 -> 9103.1 | CD8: DRY CHAMBER # 3 | CE8: =CE7 -> ….. DAY 1 ….. | CF8: RH &T & GPP | CJ8: 1997 | CK8: . | CL8: LEAD & HMR TESTING | CM8: LAB RESULTS | CN8: , | CO8: ====== | CX8: =C8 -> STAIRS UP | CY8: =E8 -> ….........
A9: 106 | B9: …. | C9: ='jobinfo(2)'!C58 -> HALL UP | D9: , | E9: LOS / TRAVEL | G9: =A9 -> 106 | H9: =B9 -> …. | I9: =C9 -> HALL UP | J9: =$G$2 -> = … JOB/ROOMS OVERVIEW PICS .. | K9: =$E$9 -> LOS / TRAVEL | M9: =M8+1 -> 206 | N9: =H9 -> …. | O9: =I9 -> HALL UP | P9: =$M$2 -> ….. SOURCE of LOSS PICS ….. | Q9: =$E$9 -> LOS / TRAVEL | S9: =S8+1 -> 306 | T9: =N9 -> …. | U9: =O9 -> HALL UP | V9: =$S$2 -> ….. C.P.S. …... | W9: =$E$9 -> LOS / TRAVEL | Y9: =Y8+1 -> 406 | Z9: =T9 -> …. | AA9: =U9 -> HALL UP | AB9: =$Y$2 -> NON SALVAGEABLE ITEMS | AC9: =$E$9 -> LOS / TRAVEL | AE9: =AE8+1 -> 506 | AF9: …. | AG9: =AA9 -> HALL UP | AH9: =AH8 -> ,,,,,, DMO = DEMOLITION ….... | AI9: =E9 -> LOS / TRAVEL | AK9: =AK8+1 -> 606 | AL9: . | AM9: =AA9 -> HALL UP | AN9: =AN8 -> … WTR MITIGATION EQUIPMENT & W.I.P . ... | AO9: =$E$9 -> LOS / TRAVEL | AQ9: =AQ8+1 -> 706 | AR9: . | AS9: =AG9 -> HALL UP | AT9: =AT8 -> … HMR MITIGATION EQUIPMENT & W.I.P . ... | AU9: =$E$9 -> LOS / TRAVEL | AW9: =AW8+1 -> 8006 | AX9: . | AY9: =C9 -> HALL UP | AZ9: =AZ8 -> … DAY # 0 … MC READINGS STABILIZATION | BD9: =BD8+1 -> 8106.1 | BE9: . | BF9: =AM9 -> HALL UP | BG9: =BG8 -> ... DAY1 MC READINGS .. | BI9: =$E$9 -> LOS / TRAVEL | BK9: =BK8+1 -> 8206.2 | BL9: . | BM9: =BF9 -> HALL UP | BN9: =BN8 -> ... DAY2 MC READINGS .. | BO9: =$E$9 -> LOS / TRAVEL | BQ9: =BQ8+1 -> 8306.3 | BR9: . | BS9: =BM9 -> HALL UP | BT9: =BT8 -> ... DAY3 MC READINGS .. | BU9: =$E$9 -> LOS / TRAVEL | BW9: =BW8+1 -> 8406.4 | BX9: . | BY9: =BS9 -> HALL UP | BZ9: =BZ8 -> ... DAY4 MC READINGS | CA9: =$E$9 -> LOS / TRAVEL | CC9: =CC8+1 -> 9104.1 | CD9: DRY CHAMBER # 4 | CE9: =CE8 -> ….. DAY 1 ….. | CF9: RH &T & GPP | CJ9: 1998 | CK9: . | CL9: KITCHEN CABINETS SIZES | CM9: U & L =LF/ CT = SF; APPLIANCES | CN9: , | CO9: ====== | CX9: =C9 -> HALL UP | CY9: =E9 -> LOS / TRAVEL
A10: 107 | B10: …. | C10: ='jobinfo(2)'!C59 -> PBR UP | D10: , | E10: …......... | G10: =A10 -> 107 | H10: =B10 -> …. | I10: =C10 -> PBR UP | J10: =$G$2 -> = … JOB/ROOMS OVERVIEW PICS .. | K10: =$E$10 -> …......... | M10: =M9+1 -> 207 | N10: =H10 -> …. | O10: =I10 -> PBR UP | P10: =$M$2 -> ….. SOURCE of LOSS PICS ….. | Q10: =$E$10 -> …......... | S10: =S9+1 -> 307 | T10: =N10 -> …. | U10: =O10 -> PBR UP | V10: =$S$2 -> ….. C.P.S. …... | W10: =$E$10 -> …......... | Y10: =Y9+1 -> 407 | Z10: =T10 -> …. | AA10: =U10 -> PBR UP | AB10: =$Y$2 -> NON SALVAGEABLE ITEMS | AC10: =$E$10 -> …......... | AE10: =AE9+1 -> 507 | AF10: …. | AG10: =AA10 -> PBR UP | AH10: =AH9 -> ,,,,,, DMO = DEMOLITION ….... | AI10: =E10 -> …......... | AK10: =AK9+1 -> 607 | AL10: . | AM10: =AA10 -> PBR UP | AN10: =AN9 -> … WTR MITIGATION EQUIPMENT & W.I.P . ... | AO10: =$E$10 -> …......... | AQ10: =AQ9+1 -> 707 | AR10: . | AS10: =AG10 -> PBR UP | AT10: =AT9 -> … HMR MITIGATION EQUIPMENT & W.I.P . ... | AU10: =$E$10 -> …......... | AW10: =AW9+1 -> 8007 | AX10: . | AY10: =C10 -> PBR UP | AZ10: =AZ9 -> … DAY # 0 … MC READINGS STABILIZATION | BD10: =BD9+1 -> 8107.1 | BE10: . | BF10: =AM10 -> PBR UP | BG10: =BG9 -> ... DAY1 MC READINGS .. | BI10: =$E$10 -> …......... | BK10: =BK9+1 -> 8207.2 | BL10: . | BM10: =BF10 -> PBR UP | BN10: =BN9 -> ... DAY2 MC READINGS .. | BO10: =$E$10 -> …......... | BQ10: =BQ9+1 -> 8307.3 | BR10: . | BS10: =BM10 -> PBR UP | BT10: =BT9 -> ... DAY3 MC READINGS .. | BU10: =$E$10 -> …......... | BW10: =BW9+1 -> 8407.4 | BX10: . | BY10: =BS10 -> PBR UP | BZ10: =BZ9 -> ... DAY4 MC READINGS | CA10: =$E$10 -> …......... | CC10: =CC5+100.2 -> 9200.2 | CD10: =CD4 -> RH &T & GPP DRY CHAMBERS [DC] .READ INGS =========== | CE10: ….. DAY 2 ….. | CF10: RH &T & GPP | CJ10: 1999 | CK10: . | CL10: BATHROOM FIXTURES | CM10: CAB SIZE & FIXTURES & TYPE | CN10: , | CO10: ====== | CX10: =C10 -> PBR UP | CY10: =E10 -> ….........
A11: 108 | B11: …. | C11: ='jobinfo(2)'!C60 -> BATH UP | D11: , | E11: …......... | G11: =A11 -> 108 | H11: =B11 -> …. | I11: =C11 -> BATH UP | J11: =$G$2 -> = … JOB/ROOMS OVERVIEW PICS .. | K11: =$E$11 -> …......... | M11: =M10+1 -> 208 | N11: =H11 -> …. | O11: =I11 -> BATH UP | P11: =$M$2 -> ….. SOURCE of LOSS PICS ….. | Q11: =$E$11 -> …......... | S11: =S10+1 -> 308 | T11: =N11 -> …. | U11: =O11 -> BATH UP | V11: =$S$2 -> ….. C.P.S. …... | W11: =$E$11 -> …......... | Y11: =Y10+1 -> 408 | Z11: =T11 -> …. | AA11: =U11 -> BATH UP | AB11: =$Y$2 -> NON SALVAGEABLE ITEMS | AC11: =$E$11 -> …......... | AE11: =AE10+1 -> 508 | AF11: …. | AG11: =AA11 -> BATH UP | AH11: =AH10 -> ,,,,,, DMO = DEMOLITION ….... | AI11: =E11 -> …......... | AK11: =AK10+1 -> 608 | AL11: . | AM11: =AA11 -> BATH UP | AN11: =AN10 -> … WTR MITIGATION EQUIPMENT & W.I.P . ... | AO11: =$E$11 -> …......... | AQ11: =AQ10+1 -> 708 | AR11: . | AS11: =AG11 -> BATH UP | AT11: =AT10 -> … HMR MITIGATION EQUIPMENT & W.I.P . ... | AU11: =$E$11 -> …......... | AW11: =AW10+1 -> 8008 | AX11: . | AY11: =C11 -> BATH UP | AZ11: =AZ10 -> … DAY # 0 … MC READINGS STABILIZATION | BD11: =BD10+1 -> 8108.1 | BE11: . | BF11: =AM11 -> BATH UP | BG11: =BG10 -> ... DAY1 MC READINGS .. | BI11: =$E$11 -> …......... | BK11: =BK10+1 -> 8208.2 | BL11: . | BM11: =BF11 -> BATH UP | BN11: =BN10 -> ... DAY2 MC READINGS .. | BO11: =$E$11 -> …......... | BQ11: =BQ10+1 -> 8308.3 | BR11: . | BS11: =BM11 -> BATH UP | BT11: =BT10 -> ... DAY3 MC READINGS .. | BU11: =$E$11 -> …......... | BW11: =BW10+1 -> 8408.4 | BX11: . | BY11: =BS11 -> BATH UP | BZ11: =BZ10 -> ... DAY4 MC READINGS | CA11: =$E$11 -> …......... | CC11: =CC10 -> 9200.2 | CD11: EXTERIOR & UNAFFECTED AREA | CE11: =CE10 -> ….. DAY 2 ….. | CF11: RH &T & GPP | CJ11: 3222 | CK11: . | CL11: CPS DAY2 WIP | CM11: OVERVIEW WIP BOXES PACKOUT PICS | CN11: , | CO11: ====== | CX11: =C11 -> BATH UP | CY11: =E11 -> ….........
A12: 109 | B12: …. | C12: ='jobinfo(2)'!C61 -> BR-2 UP | D12: , | E12: …......... | G12: =A12 -> 109 | H12: =B12 -> …. | I12: =C12 -> BR-2 UP | J12: =$G$2 -> = … JOB/ROOMS OVERVIEW PICS .. | K12: =$E$12 -> …......... | M12: =M11+1 -> 209 | N12: =H12 -> …. | O12: =I12 -> BR-2 UP | P12: =$M$2 -> ….. SOURCE of LOSS PICS ….. | Q12: =$E$12 -> …......... | S12: =S11+1 -> 309 | T12: =N12 -> …. | U12: =O12 -> BR-2 UP | V12: =$S$2 -> ….. C.P.S. …... | W12: =$E$12 -> …......... | Y12: =Y11+1 -> 409 | Z12: =T12 -> …. | AA12: =U12 -> BR-2 UP | AB12: =$Y$2 -> NON SALVAGEABLE ITEMS | AC12: =$E$12 -> …......... | AE12: =AE11+1 -> 509 | AF12: …. | AG12: =AA12 -> BR-2 UP | AH12: =AH11 -> ,,,,,, DMO = DEMOLITION ….... | AI12: =E12 -> …......... | AK12: =AK11+1 -> 609 | AL12: . | AM12: =AA12 -> BR-2 UP | AN12: =AN11 -> … WTR MITIGATION EQUIPMENT & W.I.P . ... | AO12: =$E$12 -> …......... | AQ12: =AQ11+1 -> 709 | AR12: . | AS12: =AG12 -> BR-2 UP | AT12: =AT11 -> … HMR MITIGATION EQUIPMENT & W.I.P . ... | AU12: =$E$12 -> …......... | AW12: =AW11+1 -> 8009 | AX12: . | AY12: =C12 -> BR-2 UP | AZ12: =AZ11 -> … DAY # 0 … MC READINGS STABILIZATION | BD12: =BD11+1 -> 8109.1 | BE12: . | BF12: =AM12 -> BR-2 UP | BG12: =BG11 -> ... DAY1 MC READINGS .. | BI12: =$E$12 -> …......... | BK12: =BK11+1 -> 8209.2 | BL12: . | BM12: =BF12 -> BR-2 UP | BN12: =BN11 -> ... DAY2 MC READINGS .. | BO12: =$E$12 -> …......... | BQ12: =BQ11+1 -> 8309.3 | BR12: . | BS12: =BM12 -> BR-2 UP | BT12: =BT11 -> ... DAY3 MC READINGS .. | BU12: =$E$12 -> …......... | BW12: =BW11+1 -> 8409.4 | BX12: . | BY12: =BS12 -> BR-2 UP | BZ12: =BZ11 -> ... DAY4 MC READINGS | CA12: =$E$12 -> …......... | CC12: =CC11+1 -> 9201.2 | CD12: DRY CHAMBER # 1 | CE12: =CE11 -> ….. DAY 2 ….. | CF12: RH &T & GPP | CJ12: 3322 | CK12: . | CL12: CPS3 DAY3 STORAGE | CM12: OVERVIEW STORAGE MOVE OUT PICS | CN12: , | CO12: ====== | CX12: =C12 -> BR-2 UP | CY12: =E12 -> ….........
A13: 110 | B13: …. | C13: ='jobinfo(2)'!C62 -> GUEST CLOSET | D13: , | E13: …......... | G13: =A13 -> 110 | H13: =B13 -> …. | I13: =C13 -> GUEST CLOSET | J13: =$G$2 -> = … JOB/ROOMS OVERVIEW PICS .. | K13: =$E$13 -> …......... | M13: =M12+1 -> 210 | N13: =H13 -> …. | O13: =I13 -> GUEST CLOSET | P13: =$M$2 -> ….. SOURCE of LOSS PICS ….. | Q13: =$E$13 -> …......... | S13: =S12+1 -> 310 | T13: =N13 -> …. | U13: =O13 -> GUEST CLOSET | V13: =$S$2 -> ….. C.P.S. …... | W13: =$E$13 -> …......... | Y13: =Y12+1 -> 410 | Z13: =T13 -> …. | AA13: =U13 -> GUEST CLOSET | AB13: =$Y$2 -> NON SALVAGEABLE ITEMS | AC13: =$E$13 -> …......... | AE13: =AE12+1 -> 510 | AF13: …. | AG13: =AA13 -> GUEST CLOSET | AH13: =AH12 -> ,,,,,, DMO = DEMOLITION ….... | AI13: =E13 -> …......... | AK13: =AK12+1 -> 610 | AL13: . | AM13: =AA13 -> GUEST CLOSET | AN13: =AN12 -> … WTR MITIGATION EQUIPMENT & W.I.P . ... | AO13: =$E$13 -> …......... | AQ13: =AQ12+1 -> 710 | AR13: . | AS13: =AG13 -> GUEST CLOSET | AT13: =AT12 -> … HMR MITIGATION EQUIPMENT & W.I.P . ... | AU13: =$E$13 -> …......... | AW13: =AW12+1 -> 8010 | AX13: . | AY13: =C13 -> GUEST CLOSET | AZ13: =AZ12 -> … DAY # 0 … MC READINGS STABILIZATION | BD13: =BD12+1 -> 8110.1 | BE13: . | BF13: =AM13 -> GUEST CLOSET | BG13: =BG12 -> ... DAY1 MC READINGS .. | BI13: =$E$13 -> …......... | BK13: =BK12+1 -> 8210.2 | BL13: . | BM13: =BF13 -> GUEST CLOSET | BN13: =BN12 -> ... DAY2 MC READINGS .. | BO13: =$E$13 -> …......... | BQ13: =BQ12+1 -> 8310.3 | BR13: . | BS13: =BM13 -> GUEST CLOSET | BT13: =BT12 -> ... DAY3 MC READINGS .. | BU13: =$E$13 -> …......... | BW13: =BW12+1 -> 8410.4 | BX13: . | BY13: =BS13 -> GUEST CLOSET | BZ13: =BZ12 -> ... DAY4 MC READINGS | CA13: =$E$13 -> …......... | CC13: =CC12+1 -> 9202.2 | CD13: DRY CHAMBER # 2 | CE13: =CE12 -> ….. DAY 2 ….. | CF13: RH &T & GPP | CJ13: 3444 | CK13: . | CL13: CPS4 DAY4 PACKBACK | CM13: OVERVIEW PACK-BACK / RESET PICS | CN13: , | CO13: ====== | CX13: =C13 -> GUEST CLOSET | CY13: =E13 -> ….........
A14: 111 | B14: …. | C14: ='jobinfo(2)'!C63 -> BATH DN | D14: , | E14: LOS / TRAVEL | G14: =A14 -> 111 | H14: =B14 -> …. | I14: =C14 -> BATH DN | J14: =$G$2 -> = … JOB/ROOMS OVERVIEW PICS .. | K14: =$E$14 -> LOS / TRAVEL | M14: =M13+1 -> 211 | N14: =H14 -> …. | O14: =I14 -> BATH DN | P14: =$M$2 -> ….. SOURCE of LOSS PICS ….. | Q14: =$E$14 -> LOS / TRAVEL | S14: =S13+1 -> 311 | T14: =N14 -> …. | U14: =O14 -> BATH DN | V14: =$S$2 -> ….. C.P.S. …... | W14: =$E$14 -> LOS / TRAVEL | Y14: =Y13+1 -> 411 | Z14: =T14 -> …. | AA14: =U14 -> BATH DN | AB14: =$Y$2 -> NON SALVAGEABLE ITEMS | AC14: =$E$14 -> LOS / TRAVEL | AE14: =AE13+1 -> 511 | AF14: …. | AG14: =AA14 -> BATH DN | AH14: =AH13 -> ,,,,,, DMO = DEMOLITION ….... | AI14: =E14 -> LOS / TRAVEL | AK14: =AK13+1 -> 611 | AL14: . | AM14: =AA14 -> BATH DN | AN14: =AN13 -> … WTR MITIGATION EQUIPMENT & W.I.P . ... | AO14: =$E$14 -> LOS / TRAVEL | AQ14: =AQ13+1 -> 711 | AR14: . | AS14: =AG14 -> BATH DN | AT14: =AT13 -> … HMR MITIGATION EQUIPMENT & W.I.P . ... | AU14: =$E$14 -> LOS / TRAVEL | AW14: =AW13+1 -> 8011 | AX14: . | AY14: =C14 -> BATH DN | AZ14: =AZ13 -> … DAY # 0 … MC READINGS STABILIZATION | BD14: =BD13+1 -> 8111.1 | BE14: . | BF14: =AM14 -> BATH DN | BG14: =BG13 -> ... DAY1 MC READINGS .. | BI14: =$E$14 -> LOS / TRAVEL | BK14: =BK13+1 -> 8211.2 | BL14: . | BM14: =BF14 -> BATH DN | BN14: =BN13 -> ... DAY2 MC READINGS .. | BO14: =$E$14 -> LOS / TRAVEL | BQ14: =BQ13+1 -> 8311.3 | BR14: . | BS14: =BM14 -> BATH DN | BT14: =BT13 -> ... DAY3 MC READINGS .. | BU14: =$E$14 -> LOS / TRAVEL | BW14: =BW13+1 -> 8411.4 | BX14: . | BY14: =BS14 -> BATH DN | BZ14: =BZ13 -> ... DAY4 MC READINGS | CA14: =$E$14 -> LOS / TRAVEL | CC14: =CC13+1 -> 9203.2 | CD14: DRY CHAMBER # 3 | CE14: =CE12 -> ….. DAY 2 ….. | CF14: RH &T & GPP | CJ14: 4111.1 | CK14: . | CL14: REPLACEMENT 1 CON OVERVIEW DAY PICS, | CN14: , | CO14: ====== | CX14: =C14 -> BATH DN | CY14: =E14 -> LOS / TRAVEL
A15: 112 | B15: …. | C15: ='jobinfo(2)'!C64 -> SHOWER | D15: , | E15: …......... | G15: =A15 -> 112 | H15: =B15 -> …. | I15: =C15 -> SHOWER | J15: =$G$2 -> = … JOB/ROOMS OVERVIEW PICS .. | K15: =$E$15 -> …......... | M15: =M14+1 -> 212 | N15: =H15 -> …. | O15: =I15 -> SHOWER | P15: =$M$2 -> ….. SOURCE of LOSS PICS ….. | Q15: =$E$15 -> …......... | S15: =S14+1 -> 312 | T15: =N15 -> …. | U15: =O15 -> SHOWER | V15: =$S$2 -> ….. C.P.S. …... | W15: =$E$15 -> …......... | Y15: =Y14+1 -> 412 | Z15: =T15 -> …. | AA15: =U15 -> SHOWER | AB15: =$Y$2 -> NON SALVAGEABLE ITEMS | AC15: =$E$15 -> …......... | AE15: =AE14+1 -> 512 | AF15: …. | AG15: =AA15 -> SHOWER | AH15: =AH14 -> ,,,,,, DMO = DEMOLITION ….... | AI15: =E15 -> …......... | AK15: =AK14+1 -> 612 | AL15: . | AM15: =AA15 -> SHOWER | AN15: =AN14 -> … WTR MITIGATION EQUIPMENT & W.I.P . ... | AO15: =$E$15 -> …......... | AQ15: =AQ14+1 -> 712 | AR15: . | AS15: =AG15 -> SHOWER | AT15: =AT14 -> … HMR MITIGATION EQUIPMENT & W.I.P . ... | AU15: =$E$15 -> …......... | AW15: =AW14+1 -> 8012 | AX15: . | AY15: =C15 -> SHOWER | AZ15: =AZ14 -> … DAY # 0 … MC READINGS STABILIZATION | BD15: =BD14+1 -> 8112.1 | BE15: . | BF15: =AM15 -> SHOWER | BG15: =BG14 -> ... DAY1 MC READINGS .. | BI15: =$E$15 -> …......... | BK15: =BK14+1 -> 8212.2 | BL15: . | BM15: =BF15 -> SHOWER | BN15: =BN14 -> ... DAY2 MC READINGS .. | BO15: =$E$15 -> …......... | BQ15: =BQ14+1 -> 8312.3 | BR15: . | BS15: =BM15 -> SHOWER | BT15: =BT14 -> ... DAY3 MC READINGS .. | BU15: =$E$15 -> …......... | BW15: =BW14+1 -> 8412.4 | BX15: . | BY15: =BS15 -> SHOWER | BZ15: =BZ14 -> ... DAY4 MC READINGS | CA15: =$E$15 -> …......... | CC15: =CC14+1 -> 9204.2 | CD15: DRY CHAMBER # 4 | CE15: =CE13 -> ….. DAY 2 ….. | CF15: RH &T & GPP | CJ15: 4222.2 | CK15: . | CL15: REPLACEMENT 2 CON WIP, | CN15: , | CX15: =C15 -> SHOWER | CY15: =E15 -> ….........
A16: 113 | B16: …. | C16: ='jobinfo(2)'!C65 -> 0 | D16: , | E16: LOS / TRAVEL | G16: =A16 -> 113 | H16: =B16 -> …. | I16: =C16 -> 0 | J16: =$G$2 -> = … JOB/ROOMS OVERVIEW PICS .. | K16: =$E$16 -> LOS / TRAVEL | M16: =M15+1 -> 213 | N16: =H16 -> …. | O16: =I16 -> 0 | P16: =$M$2 -> ….. SOURCE of LOSS PICS ….. | Q16: =$E$16 -> LOS / TRAVEL | S16: =S15+1 -> 313 | T16: =N16 -> …. | U16: =O16 -> 0 | V16: =$S$2 -> ….. C.P.S. …... | W16: =$E$16 -> LOS / TRAVEL | Y16: =Y15+1 -> 413 | Z16: =T16 -> …. | AA16: =U16 -> 0 | AB16: =$Y$2 -> NON SALVAGEABLE ITEMS | AC16: =$E$16 -> LOS / TRAVEL | AE16: =AE15+1 -> 513 | AF16: …. | AG16: =AA16 -> 0 | AH16: =AH15 -> ,,,,,, DMO = DEMOLITION ….... | AI16: =E16 -> LOS / TRAVEL | AK16: =AK15+1 -> 613 | AL16: . | AM16: =AA16 -> 0 | AN16: =AN15 -> … WTR MITIGATION EQUIPMENT & W.I.P . ... | AO16: =$E$16 -> LOS / TRAVEL | AQ16: =AQ15+1 -> 713 | AR16: . | AS16: =AG16 -> 0 | AT16: =AT15 -> … HMR MITIGATION EQUIPMENT & W.I.P . ... | AU16: =$E$16 -> LOS / TRAVEL | AW16: =AW15+1 -> 8013 | AX16: . | AY16: =C16 -> 0 | AZ16: =AZ15 -> … DAY # 0 … MC READINGS STABILIZATION | BD16: =BD15+1 -> 8113.1 | BE16: . | BF16: =AM16 -> 0 | BG16: =BG15 -> ... DAY1 MC READINGS .. | BI16: =$E$16 -> LOS / TRAVEL | BK16: =BK15+1 -> 8213.2 | BL16: . | BM16: =BF16 -> 0 | BN16: =BN15 -> ... DAY2 MC READINGS .. | BO16: =$E$16 -> LOS / TRAVEL | BQ16: =BQ15+1 -> 8313.3 | BR16: . | BS16: =BM16 -> 0 | BT16: =BT15 -> ... DAY3 MC READINGS .. | BU16: =$E$16 -> LOS / TRAVEL | BW16: =BW15+1 -> 8413.4 | BX16: . | BY16: =BS16 -> 0 | BZ16: =BZ15 -> ... DAY4 MC READINGS | CA16: =$E$16 -> LOS / TRAVEL | CC16: =CC11+100.1 -> 9300.3 | CD16: =CD4 -> RH &T & GPP DRY CHAMBERS [DC] .READ INGS =========== | CE16: ….. DAY 3 ….. | CF16: RH &T & GPP | CJ16: 4333.3 | CK16: . | CL16: REPLACEMENT 3 CON STORAGE | CN16: , | CX16: =C16 -> 0 | CY16: =E16 -> LOS / TRAVEL
A17: 114 | B17: …. | C17: ='jobinfo(2)'!C66 -> 0 | D17: , | E17: …......... | G17: =A17 -> 114 | H17: =B17 -> …. | I17: =C17 -> 0 | J17: =$G$2 -> = … JOB/ROOMS OVERVIEW PICS .. | K17: =$E$17 -> …......... | M17: =M16+1 -> 214 | N17: =H17 -> …. | O17: =I17 -> 0 | P17: =$M$2 -> ….. SOURCE of LOSS PICS ….. | Q17: =$E$17 -> …......... | S17: =S16+1 -> 314 | T17: =N17 -> …. | U17: =O17 -> 0 | V17: =$S$2 -> ….. C.P.S. …... | W17: =$E$17 -> …......... | Y17: =Y16+1 -> 414 | Z17: =T17 -> …. | AA17: =U17 -> 0 | AB17: =$Y$2 -> NON SALVAGEABLE ITEMS | AC17: =$E$17 -> …......... | AE17: =AE16+1 -> 514 | AF17: …. | AG17: =AA17 -> 0 | AH17: =AH16 -> ,,,,,, DMO = DEMOLITION ….... | AI17: =E17 -> …......... | AK17: =AK16+1 -> 614 | AL17: . | AM17: =AA17 -> 0 | AN17: =AN16 -> … WTR MITIGATION EQUIPMENT & W.I.P . ... | AO17: =$E$17 -> …......... | AQ17: =AQ16+1 -> 714 | AR17: . | AS17: =AG17 -> 0 | AT17: =AT16 -> … HMR MITIGATION EQUIPMENT & W.I.P . ... | AU17: =$E$17 -> …......... | AW17: =AW16+1 -> 8014 | AX17: . | AY17: =C17 -> 0 | AZ17: =AZ16 -> … DAY # 0 … MC READINGS STABILIZATION | BD17: =BD16+1 -> 8114.1 | BE17: . | BF17: =AM17 -> 0 | BG17: =BG16 -> ... DAY1 MC READINGS .. | BI17: =$E$17 -> …......... | BK17: =BK16+1 -> 8214.2 | BL17: . | BM17: =BF17 -> 0 | BN17: =BN16 -> ... DAY2 MC READINGS .. | BO17: =$E$17 -> …......... | BQ17: =BQ16+1 -> 8314.3 | BR17: . | BS17: =BM17 -> 0 | BT17: =BT16 -> ... DAY3 MC READINGS .. | BU17: =$E$17 -> …......... | BW17: =BW16+1 -> 8414.4 | BX17: . | BY17: =BS17 -> 0 | BZ17: =BZ16 -> ... DAY4 MC READINGS | CA17: =$E$17 -> …......... | CC17: =CC16 -> 9300.3 | CD17: EXTERIOR & UNAFFECTED AREA | CE17: =CE16 -> ….. DAY 3 ….. | CF17: RH &T & GPP | CJ17: 4444.4 | CK17: . | CL17: REPLACEMENT 4 CON DISPOSAL, | CN17: , | CX17: =C17 -> 0 | CY17: =E17 -> ….........
A18: 115 | B18: …. | C18: ='jobinfo(2)'!C67 -> 0 | D18: , | E18: …......... | G18: =A18 -> 115 | H18: =B18 -> …. | I18: =C18 -> 0 | J18: =$G$2 -> = … JOB/ROOMS OVERVIEW PICS .. | K18: =$E$18 -> …......... | M18: =M17+1 -> 215 | N18: =H18 -> …. | O18: =I18 -> 0 | P18: =$M$2 -> ….. SOURCE of LOSS PICS ….. | Q18: =$E$18 -> …......... | S18: =S17+1 -> 315 | T18: =N18 -> …. | U18: =O18 -> 0 | V18: =$S$2 -> ….. C.P.S. …... | W18: =$E$18 -> …......... | Y18: =Y17+1 -> 415 | Z18: =T18 -> …. | AA18: =U18 -> 0 | AB18: =$Y$2 -> NON SALVAGEABLE ITEMS | AC18: =$E$18 -> …......... | AE18: =AE17+1 -> 515 | AF18: …. | AG18: =AA18 -> 0 | AH18: =AH17 -> ,,,,,, DMO = DEMOLITION ….... | AI18: =E18 -> …......... | AK18: =AK17+1 -> 615 | AL18: . | AM18: =AA18 -> 0 | AN18: =AN17 -> … WTR MITIGATION EQUIPMENT & W.I.P . ... | AO18: =$E$18 -> …......... | AQ18: =AQ17+1 -> 715 | AR18: . | AS18: =AG18 -> 0 | AT18: =AT17 -> … HMR MITIGATION EQUIPMENT & W.I.P . ... | AU18: =$E$18 -> …......... | AW18: =AW17+1 -> 8015 | AX18: . | AY18: =C18 -> 0 | AZ18: =AZ17 -> … DAY # 0 … MC READINGS STABILIZATION | BD18: =BD17+1 -> 8115.1 | BE18: . | BF18: =AM18 -> 0 | BG18: =BG17 -> ... DAY1 MC READINGS .. | BI18: =$E$18 -> …......... | BK18: =BK17+1 -> 8215.2 | BL18: . | BM18: =BF18 -> 0 | BN18: =BN17 -> ... DAY2 MC READINGS .. | BO18: =$E$18 -> …......... | BQ18: =BQ17+1 -> 8315.3 | BR18: . | BS18: =BM18 -> 0 | BT18: =BT17 -> ... DAY3 MC READINGS .. | BU18: =$E$18 -> …......... | BW18: =BW17+1 -> 8415.4 | BX18: . | BY18: =BS18 -> 0 | BZ18: =BZ17 -> ... DAY4 MC READINGS | CA18: =$E$18 -> …......... | CC18: =CC17+1 -> 9301.3 | CD18: DRY CHAMBER # 1 | CE18: =CE17 -> ….. DAY 3 ….. | CF18: RH &T & GPP | CJ18: 9998 | CK18: . | CL18: REBUILD OVERVIEW WORK IN PROGRESS.......WIP, | CN18: , | CO18: ====== | CX18: =C18 -> 0 | CY18: =E18 -> ….........
A19: 116 | B19: …. | C19: ='jobinfo(2)'!C68 -> 0 | D19: , | E19: …......... | G19: =A19 -> 116 | H19: =B19 -> …. | I19: =C19 -> 0 | J19: =$G$2 -> = … JOB/ROOMS OVERVIEW PICS .. | K19: =$E$19 -> …......... | M19: =M18+1 -> 216 | N19: =H19 -> …. | O19: =I19 -> 0 | P19: =$M$2 -> ….. SOURCE of LOSS PICS ….. | Q19: =$E$19 -> …......... | S19: =S18+1 -> 316 | T19: =N19 -> …. | U19: =O19 -> 0 | V19: =$S$2 -> ….. C.P.S. …... | W19: =$E$19 -> …......... | Y19: =Y18+1 -> 416 | Z19: =T19 -> …. | AA19: =U19 -> 0 | AB19: =$Y$2 -> NON SALVAGEABLE ITEMS | AC19: =$E$19 -> …......... | AE19: =AE18+1 -> 516 | AF19: …. | AG19: =AA19 -> 0 | AH19: =AH18 -> ,,,,,, DMO = DEMOLITION ….... | AI19: =E19 -> …......... | AK19: =AK18+1 -> 616 | AL19: . | AM19: =AA19 -> 0 | AN19: =AN18 -> … WTR MITIGATION EQUIPMENT & W.I.P . ... | AO19: =$E$19 -> …......... | AQ19: =AQ18+1 -> 716 | AR19: . | AS19: =AG19 -> 0 | AT19: =AT18 -> … HMR MITIGATION EQUIPMENT & W.I.P . ... | AU19: =$E$19 -> …......... | AW19: =AW18+1 -> 8016 | AX19: . | AY19: =C19 -> 0 | AZ19: =AZ18 -> … DAY # 0 … MC READINGS STABILIZATION | BD19: =BD18+1 -> 8116.1 | BE19: . | BF19: =AM19 -> 0 | BG19: =BG18 -> ... DAY1 MC READINGS .. | BI19: =$E$19 -> …......... | BK19: =BK18+1 -> 8216.2 | BL19: . | BM19: =BF19 -> 0 | BN19: =BN18 -> ... DAY2 MC READINGS .. | BO19: =$E$19 -> …......... | BQ19: =BQ18+1 -> 8316.3 | BR19: . | BS19: =BM19 -> 0 | BT19: =BT18 -> ... DAY3 MC READINGS .. | BU19: =$E$19 -> …......... | BW19: =BW18+1 -> 8416.4 | BX19: . | BY19: =BS19 -> 0 | BZ19: =BZ18 -> ... DAY4 MC READINGS | CA19: =$E$19 -> …......... | CC19: =CC18+1 -> 9302.3 | CD19: DRY CHAMBER # 2 | CE19: =CE18 -> ….. DAY 3 ….. | CF19: RH &T & GPP | CJ19: 9999 | CK19: . | CL19: REBUILD INTERIOR COMPLETED WORK, | CN19: , | CX19: =C19 -> 0 | CY19: =E19 -> ….........
A20: 117 | B20: …. | C20: ='jobinfo(2)'!C69 -> 0 | D20: , | E20: …......... | G20: =A20 -> 117 | H20: =B20 -> …. | I20: =C20 -> 0 | J20: =$G$2 -> = … JOB/ROOMS OVERVIEW PICS .. | K20: =$E$20 -> …......... | M20: =M19+1 -> 217 | N20: =H20 -> …. | O20: =I20 -> 0 | P20: =$M$2 -> ….. SOURCE of LOSS PICS ….. | Q20: =$E$20 -> …......... | S20: =S19+1 -> 317 | T20: =N20 -> …. | U20: =O20 -> 0 | V20: =$S$2 -> ….. C.P.S. …... | W20: =$E$20 -> …......... | Y20: =Y19+1 -> 417 | Z20: =T20 -> …. | AA20: =U20 -> 0 | AB20: =$Y$2 -> NON SALVAGEABLE ITEMS | AC20: =$E$20 -> …......... | AE20: =AE19+1 -> 517 | AF20: …. | AG20: =AA20 -> 0 | AH20: =AH19 -> ,,,,,, DMO = DEMOLITION ….... | AI20: =E20 -> …......... | AK20: =AK19+1 -> 617 | AL20: . | AM20: =AA20 -> 0 | AN20: =AN19 -> … WTR MITIGATION EQUIPMENT & W.I.P . ... | AO20: =$E$20 -> …......... | AQ20: =AQ19+1 -> 717 | AR20: . | AS20: =AG20 -> 0 | AT20: =AT19 -> … HMR MITIGATION EQUIPMENT & W.I.P . ... | AU20: =$E$20 -> …......... | AW20: =AW19+1 -> 8017 | AX20: . | AY20: =C20 -> 0 | AZ20: =AZ19 -> … DAY # 0 … MC READINGS STABILIZATION | BD20: =BD19+1 -> 8117.1 | BE20: . | BF20: =AM20 -> 0 | BG20: =BG19 -> ... DAY1 MC READINGS .. | BI20: =$E$20 -> …......... | BK20: =BK19+1 -> 8217.2 | BL20: . | BM20: =BF20 -> 0 | BN20: =BN19 -> ... DAY2 MC READINGS .. | BO20: =$E$20 -> …......... | BQ20: =BQ19+1 -> 8317.3 | BR20: . | BS20: =BM20 -> 0 | BT20: =BT19 -> ... DAY3 MC READINGS .. | BU20: =$E$20 -> …......... | BW20: =BW19+1 -> 8417.4 | BX20: . | BY20: =BS20 -> 0 | BZ20: =BZ19 -> ... DAY4 MC READINGS | CA20: =$E$20 -> …......... | CC20: =CC19+1 -> 9303.3 | CD20: DRY CHAMBER # 3 | CE20: =CE18 -> ….. DAY 3 ….. | CF20: RH &T & GPP | CN20: , | CX20: =C20 -> 0 | CY20: =E20 -> ….........
A21: 118 | B21: …. | C21: ='jobinfo(2)'!C70 -> 0 | D21: , | E21: …......... | G21: =A21 -> 118 | H21: =B21 -> …. | I21: =C21 -> 0 | J21: =$G$2 -> = … JOB/ROOMS OVERVIEW PICS .. | K21: =$E$21 -> …......... | M21: =M20+1 -> 218 | N21: =H21 -> …. | O21: =I21 -> 0 | P21: =$M$2 -> ….. SOURCE of LOSS PICS ….. | Q21: =$E$21 -> …......... | S21: =S20+1 -> 318 | T21: =N21 -> …. | U21: =O21 -> 0 | V21: =$S$2 -> ….. C.P.S. …... | W21: =$E$21 -> …......... | Y21: =Y20+1 -> 418 | Z21: =T21 -> …. | AA21: =U21 -> 0 | AB21: =$Y$2 -> NON SALVAGEABLE ITEMS | AC21: =$E$21 -> …......... | AE21: =AE20+1 -> 518 | AF21: …. | AG21: =AA21 -> 0 | AH21: =AH20 -> ,,,,,, DMO = DEMOLITION ….... | AI21: =E21 -> …......... | AK21: =AK20+1 -> 618 | AL21: . | AM21: =AA21 -> 0 | AN21: =AN20 -> … WTR MITIGATION EQUIPMENT & W.I.P . ... | AO21: =$E$21 -> …......... | AQ21: =AQ20+1 -> 718 | AR21: . | AS21: =AG21 -> 0 | AT21: =AT20 -> … HMR MITIGATION EQUIPMENT & W.I.P . ... | AU21: =$E$21 -> …......... | AW21: =AW20+1 -> 8018 | AX21: . | AY21: =C21 -> 0 | AZ21: =AZ20 -> … DAY # 0 … MC READINGS STABILIZATION | BD21: =BD20+1 -> 8118.1 | BE21: . | BF21: =AM21 -> 0 | BG21: =BG20 -> ... DAY1 MC READINGS .. | BI21: =$E$21 -> …......... | BK21: =BK20+1 -> 8218.2 | BL21: . | BM21: =BF21 -> 0 | BN21: =BN20 -> ... DAY2 MC READINGS .. | BO21: =$E$21 -> …......... | BQ21: =BQ20+1 -> 8318.3 | BR21: . | BS21: =BM21 -> 0 | BT21: =BT20 -> ... DAY3 MC READINGS .. | BU21: =$E$21 -> …......... | BW21: =BW20+1 -> 8418.4 | BX21: . | BY21: =BS21 -> 0 | BZ21: =BZ20 -> ... DAY4 MC READINGS | CA21: =$E$21 -> …......... | CC21: =CC20+1 -> 9304.3 | CD21: DRY CHAMBER # 4 | CE21: =CE19 -> ….. DAY 3 ….. | CF21: RH &T & GPP | CN21: , | CX21: =C21 -> 0 | CY21: =E21 -> ….........
A22: 119 | B22: …. | C22: ='jobinfo(2)'!C71 -> 0 | D22: , | E22: …......... | G22: =A22 -> 119 | H22: =B22 -> …. | I22: =C22 -> 0 | J22: =$G$2 -> = … JOB/ROOMS OVERVIEW PICS .. | K22: =$E$22 -> …......... | M22: =M21+1 -> 219 | N22: =H22 -> …. | O22: =I22 -> 0 | P22: =$M$2 -> ….. SOURCE of LOSS PICS ….. | Q22: =$E$22 -> …......... | S22: =S21+1 -> 319 | T22: =N22 -> …. | U22: =O22 -> 0 | V22: =$S$2 -> ….. C.P.S. …... | W22: =$E$22 -> …......... | Y22: =Y21+1 -> 419 | Z22: =T22 -> …. | AA22: =U22 -> 0 | AB22: =$Y$2 -> NON SALVAGEABLE ITEMS | AC22: =$E$22 -> …......... | AE22: =AE21+1 -> 519 | AF22: …. | AG22: =AA22 -> 0 | AH22: =AH21 -> ,,,,,, DMO = DEMOLITION ….... | AI22: =E22 -> …......... | AK22: =AK21+1 -> 619 | AL22: . | AM22: =AA22 -> 0 | AN22: =AN21 -> … WTR MITIGATION EQUIPMENT & W.I.P . ... | AO22: =$E$22 -> …......... | AQ22: =AQ21+1 -> 719 | AR22: . | AS22: =AG22 -> 0 | AT22: =AT21 -> … HMR MITIGATION EQUIPMENT & W.I.P . ... | AU22: =$E$22 -> …......... | AW22: =AW21+1 -> 8019 | AX22: . | AY22: =C22 -> 0 | AZ22: =AZ21 -> … DAY # 0 … MC READINGS STABILIZATION | BD22: =BD21+1 -> 8119.1 | BE22: . | BF22: =AM22 -> 0 | BG22: =BG21 -> ... DAY1 MC READINGS .. | BI22: =$E$22 -> …......... | BK22: =BK21+1 -> 8219.2 | BL22: . | BM22: =BF22 -> 0 | BN22: =BN21 -> ... DAY2 MC READINGS .. | BO22: =$E$22 -> …......... | BQ22: =BQ21+1 -> 8319.3 | BR22: . | BS22: =BM22 -> 0 | BT22: =BT21 -> ... DAY3 MC READINGS .. | BU22: =$E$22 -> …......... | BW22: =BW21+1 -> 8419.4 | BX22: . | BY22: =BS22 -> 0 | BZ22: =BZ21 -> ... DAY4 MC READINGS | CA22: =$E$22 -> …......... | CC22: =CC17+100.1 -> 9400.4 | CD22: =CD16 -> RH &T & GPP DRY CHAMBERS [DC] .READ INGS =========== | CE22: ….. DAY 4 ….. | CF22: RH &T & GPP | CN22: , | CX22: =C22 -> 0 | CY22: =E22 -> ….........
A23: 120 | B23: …. | C23: ='jobinfo(2)'!C72 -> 0 | D23: , | E23: …......... | G23: =A23 -> 120 | H23: =B23 -> …. | I23: =C23 -> 0 | J23: =$G$2 -> = … JOB/ROOMS OVERVIEW PICS .. | K23: =$E$23 -> …......... | M23: =M22+1 -> 220 | N23: =H23 -> …. | O23: =I23 -> 0 | P23: =$M$2 -> ….. SOURCE of LOSS PICS ….. | Q23: =$E$23 -> …......... | S23: =S22+1 -> 320 | T23: =N23 -> …. | U23: =O23 -> 0 | V23: =$S$2 -> ….. C.P.S. …... | W23: =$E$23 -> …......... | Y23: =Y22+1 -> 420 | Z23: =T23 -> …. | AA23: =U23 -> 0 | AB23: =$Y$2 -> NON SALVAGEABLE ITEMS | AC23: =$E$23 -> …......... | AE23: =AE22+1 -> 520 | AF23: …. | AG23: =AA23 -> 0 | AH23: =AH22 -> ,,,,,, DMO = DEMOLITION ….... | AI23: =E23 -> …......... | AK23: =AK22+1 -> 620 | AL23: . | AM23: =AA23 -> 0 | AN23: =AN22 -> … WTR MITIGATION EQUIPMENT & W.I.P . ... | AO23: =$E$23 -> …......... | AQ23: =AQ22+1 -> 720 | AR23: . | AS23: =AG23 -> 0 | AT23: =AT22 -> … HMR MITIGATION EQUIPMENT & W.I.P . ... | AU23: =$E$23 -> …......... | AW23: =AW22+1 -> 8020 | AX23: . | AY23: =C23 -> 0 | AZ23: =AZ22 -> … DAY # 0 … MC READINGS STABILIZATION | BD23: =BD22+1 -> 8120.1 | BE23: . | BF23: =AM23 -> 0 | BG23: =BG22 -> ... DAY1 MC READINGS .. | BI23: =$E$23 -> …......... | BK23: =BK22+1 -> 8220.2 | BL23: . | BM23: =BF23 -> 0 | BN23: =BN22 -> ... DAY2 MC READINGS .. | BO23: =$E$23 -> …......... | BQ23: =BQ22+1 -> 8320.3 | BR23: . | BS23: =BM23 -> 0 | BT23: =BT22 -> ... DAY3 MC READINGS .. | BU23: =$E$23 -> …......... | BW23: =BW22+1 -> 8420.4 | BX23: . | BY23: =BS23 -> 0 | BZ23: =BZ22 -> ... DAY4 MC READINGS | CA23: =$E$23 -> …......... | CC23: =CC22+1 -> 9401.4 | CD23: EXTERIOR & UNAFFECTED AREA | CE23: ….. DAY 4 ….. | CF23: RH &T & GPP | CN23: , | CX23: =C23 -> 0 | CY23: =E23 -> ….........
A24: 121 | B24: …. | C24: ='jobinfo(2)'!C73 -> 0 | D24: , | E24: …......... | G24: =A24 -> 121 | H24: =B24 -> …. | I24: =C24 -> 0 | J24: =$G$2 -> = … JOB/ROOMS OVERVIEW PICS .. | K24: =$E$24 -> …......... | M24: =M23+1 -> 221 | N24: =H24 -> …. | O24: =I24 -> 0 | P24: =$M$2 -> ….. SOURCE of LOSS PICS ….. | Q24: =$E$24 -> …......... | S24: =S23+1 -> 321 | T24: =N24 -> …. | U24: =O24 -> 0 | V24: =$S$2 -> ….. C.P.S. …... | W24: =$E$24 -> …......... | Y24: =Y23+1 -> 421 | Z24: =T24 -> …. | AA24: =U24 -> 0 | AB24: =$Y$2 -> NON SALVAGEABLE ITEMS | AC24: =$E$24 -> …......... | AE24: =AE23+1 -> 521 | AF24: …. | AG24: =AA24 -> 0 | AH24: =AH23 -> ,,,,,, DMO = DEMOLITION ….... | AI24: =E24 -> …......... | AK24: =AK23+1 -> 621 | AL24: . | AM24: =AA24 -> 0 | AN24: =AN23 -> … WTR MITIGATION EQUIPMENT & W.I.P . ... | AO24: =$E$24 -> …......... | AQ24: =AQ23+1 -> 721 | AR24: . | AS24: =AG24 -> 0 | AT24: =AT23 -> … HMR MITIGATION EQUIPMENT & W.I.P . ... | AU24: =$E$24 -> …......... | AW24: =AW23+1 -> 8021 | AX24: . | AY24: =C24 -> 0 | AZ24: =AZ23 -> … DAY # 0 … MC READINGS STABILIZATION | BD24: =BD23+1 -> 8121.1 | BE24: . | BF24: =AM24 -> 0 | BG24: =BG23 -> ... DAY1 MC READINGS .. | BI24: =$E$24 -> …......... | BK24: =BK23+1 -> 8221.2 | BL24: . | BM24: =BF24 -> 0 | BN24: =BN23 -> ... DAY2 MC READINGS .. | BO24: =$E$24 -> …......... | BQ24: =BQ23+1 -> 8321.3 | BR24: . | BS24: =BM24 -> 0 | BT24: =BT23 -> ... DAY3 MC READINGS .. | BU24: =$E$24 -> …......... | BW24: =BW23+1 -> 8421.4 | BX24: . | BY24: =BS24 -> 0 | BZ24: =BZ23 -> ... DAY4 MC READINGS | CA24: =$E$24 -> …......... | CC24: =CC23+1 -> 9402.4 | CD24: DRY CHAMBER # 1 | CE24: =CE23 -> ….. DAY 4 ….. | CF24: RH &T & GPP | CN24: , | CX24: =C24 -> 0 | CY24: =E24 -> ….........
A25: 122 | B25: …. | C25: ='jobinfo(2)'!C74 -> 0 | D25: , | E25: …......... | G25: =A25 -> 122 | H25: =B25 -> …. | I25: =C25 -> 0 | J25: =$G$2 -> = … JOB/ROOMS OVERVIEW PICS .. | K25: =$E$25 -> …......... | M25: =M24+1 -> 222 | N25: =H25 -> …. | O25: =I25 -> 0 | P25: =$M$2 -> ….. SOURCE of LOSS PICS ….. | Q25: =$E$25 -> …......... | S25: =S24+1 -> 322 | T25: =N25 -> …. | U25: =O25 -> 0 | V25: =$S$2 -> ….. C.P.S. …... | W25: =$E$25 -> …......... | Y25: =Y24+1 -> 422 | Z25: =T25 -> …. | AA25: =U25 -> 0 | AB25: =$Y$2 -> NON SALVAGEABLE ITEMS | AC25: =$E$25 -> …......... | AE25: =AE24+1 -> 522 | AF25: …. | AG25: =AA25 -> 0 | AH25: =AH24 -> ,,,,,, DMO = DEMOLITION ….... | AI25: =E25 -> …......... | AK25: =AK24+1 -> 622 | AL25: . | AM25: =AA25 -> 0 | AN25: =AN24 -> … WTR MITIGATION EQUIPMENT & W.I.P . ... | AO25: =$E$25 -> …......... | AQ25: =AQ24+1 -> 722 | AR25: . | AS25: =AG25 -> 0 | AT25: =AT24 -> … HMR MITIGATION EQUIPMENT & W.I.P . ... | AU25: =$E$25 -> …......... | AW25: =AW24+1 -> 8022 | AX25: . | AY25: =C25 -> 0 | AZ25: =AZ24 -> … DAY # 0 … MC READINGS STABILIZATION | BD25: =BD24+1 -> 8122.1 | BE25: . | BF25: =AM25 -> 0 | BG25: =BG24 -> ... DAY1 MC READINGS .. | BI25: =$E$25 -> …......... | BK25: =BK24+1 -> 8222.2 | BL25: . | BM25: =BF25 -> 0 | BN25: =BN24 -> ... DAY2 MC READINGS .. | BO25: =$E$25 -> …......... | BQ25: =BQ24+1 -> 8322.3 | BR25: . | BS25: =BM25 -> 0 | BT25: =BT24 -> ... DAY3 MC READINGS .. | BU25: =$E$25 -> …......... | BW25: =BW24+1 -> 8422.4 | BX25: . | BY25: =BS25 -> 0 | BZ25: =BZ24 -> ... DAY4 MC READINGS | CA25: =$E$25 -> …......... | CC25: =CC24+1 -> 9403.4 | CD25: DRY CHAMBER # 2 | CE25: =CE24 -> ….. DAY 4 ….. | CF25: RH &T & GPP | CN25: , | CX25: =C25 -> 0 | CY25: =E25 -> ….........
A26: 123 | B26: …. | C26: ='jobinfo(2)'!C75 -> 0 | D26: , | E26: …......... | G26: =A26 -> 123 | H26: =B26 -> …. | I26: =C26 -> 0 | J26: =$G$2 -> = … JOB/ROOMS OVERVIEW PICS .. | K26: =$E$26 -> …......... | M26: =M25+1 -> 223 | N26: =H26 -> …. | O26: =I26 -> 0 | P26: =$M$2 -> ….. SOURCE of LOSS PICS ….. | Q26: =$E$26 -> …......... | S26: =S25+1 -> 323 | T26: =N26 -> …. | U26: =O26 -> 0 | V26: =$S$2 -> ….. C.P.S. …... | W26: =$E$26 -> …......... | Y26: =Y25+1 -> 423 | Z26: =T26 -> …. | AA26: =U26 -> 0 | AB26: =$Y$2 -> NON SALVAGEABLE ITEMS | AC26: =$E$26 -> …......... | AE26: =AE25+1 -> 523 | AF26: …. | AG26: =AA26 -> 0 | AH26: =AH25 -> ,,,,,, DMO = DEMOLITION ….... | AI26: =E26 -> …......... | AK26: =AK25+1 -> 623 | AL26: . | AM26: =AA26 -> 0 | AN26: =AN25 -> … WTR MITIGATION EQUIPMENT & W.I.P . ... | AO26: =$E$26 -> …......... | AQ26: =AQ25+1 -> 723 | AR26: . | AS26: =AG26 -> 0 | AT26: =AT25 -> … HMR MITIGATION EQUIPMENT & W.I.P . ... | AU26: =$E$26 -> …......... | AW26: =AW25+1 -> 8023 | AX26: . | AY26: =C26 -> 0 | AZ26: =AZ25 -> … DAY # 0 … MC READINGS STABILIZATION | BD26: =BD25+1 -> 8123.1 | BE26: . | BF26: =AM26 -> 0 | BG26: =BG25 -> ... DAY1 MC READINGS .. | BI26: =$E$26 -> …......... | BK26: =BK25+1 -> 8223.2 | BL26: . | BM26: =BF26 -> 0 | BN26: =BN25 -> ... DAY2 MC READINGS .. | BO26: =$E$26 -> …......... | BQ26: =BQ25+1 -> 8323.3 | BR26: . | BS26: =BM26 -> 0 | BT26: =BT25 -> ... DAY3 MC READINGS .. | BU26: =$E$26 -> …......... | BW26: =BW25+1 -> 8423.4 | BX26: . | BY26: =BS26 -> 0 | BZ26: =BZ25 -> ... DAY4 MC READINGS | CA26: =$E$26 -> …......... | CC26: =CC25+1 -> 9404.4 | CD26: DRY CHAMBER # 3 | CE26: =CE24 -> ….. DAY 4 ….. | CF26: RH &T & GPP | CN26: , | CX26: =C26 -> 0 | CY26: =E26 -> ….........
A27: 124 | B27: …. | C27: ='jobinfo(2)'!C76 -> 0 | D27: , | E27: …......... | G27: =A27 -> 124 | H27: =B27 -> …. | I27: =C27 -> 0 | J27: =$G$2 -> = … JOB/ROOMS OVERVIEW PICS .. | K27: =$E$27 -> …......... | M27: =M26+1 -> 224 | N27: =H27 -> …. | O27: =I27 -> 0 | P27: =$M$2 -> ….. SOURCE of LOSS PICS ….. | Q27: =$E$27 -> …......... | S27: =S26+1 -> 324 | T27: =N27 -> …. | U27: =O27 -> 0 | V27: =$S$2 -> ….. C.P.S. …... | W27: =$E$27 -> …......... | Y27: =Y26+1 -> 424 | Z27: =T27 -> …. | AA27: =U27 -> 0 | AB27: =$Y$2 -> NON SALVAGEABLE ITEMS | AC27: =$E$27 -> …......... | AE27: =AE26+1 -> 524 | AF27: …. | AG27: =AA27 -> 0 | AH27: =AH26 -> ,,,,,, DMO = DEMOLITION ….... | AI27: =E27 -> …......... | AK27: =AK26+1 -> 624 | AL27: . | AM27: =AA27 -> 0 | AN27: =AN26 -> … WTR MITIGATION EQUIPMENT & W.I.P . ... | AO27: =$E$27 -> …......... | AQ27: =AQ26+1 -> 724 | AR27: . | AS27: =AG27 -> 0 | AT27: =AT26 -> … HMR MITIGATION EQUIPMENT & W.I.P . ... | AU27: =$E$27 -> …......... | AW27: =AW26+1 -> 8024 | AX27: . | AY27: =C27 -> 0 | AZ27: =AZ26 -> … DAY # 0 … MC READINGS STABILIZATION | BD27: =BD26+1 -> 8124.1 | BE27: . | BF27: =AM27 -> 0 | BG27: =BG26 -> ... DAY1 MC READINGS .. | BI27: =$E$27 -> …......... | BK27: =BK26+1 -> 8224.2 | BL27: . | BM27: =BF27 -> 0 | BN27: =BN26 -> ... DAY2 MC READINGS .. | BO27: =$E$27 -> …......... | BQ27: =BQ26+1 -> 8324.3 | BR27: . | BS27: =BM27 -> 0 | BT27: =BT26 -> ... DAY3 MC READINGS .. | BU27: =$E$27 -> …......... | BW27: =BW26+1 -> 8424.4 | BX27: . | BY27: =BS27 -> 0 | BZ27: =BZ26 -> ... DAY4 MC READINGS | CA27: =$E$27 -> …......... | CC27: =CC26+1 -> 9405.4 | CD27: DRY CHAMBER # 4 | CE27: =CE25 -> ….. DAY 4 ….. | CF27: RH &T & GPP | CN27: , | CX27: =C27 -> 0 | CY27: =E27 -> ….........
A28: 125 | B28: …. | C28: ='jobinfo(2)'!C77 -> 0 | D28: , | E28: …......... | G28: =A28 -> 125 | H28: =B28 -> …. | I28: =C28 -> 0 | J28: =$G$2 -> = … JOB/ROOMS OVERVIEW PICS .. | K28: =$E$28 -> …......... | M28: =M27+1 -> 225 | N28: =H28 -> …. | O28: =I28 -> 0 | P28: =$M$2 -> ….. SOURCE of LOSS PICS ….. | Q28: =$E$28 -> …......... | S28: =S27+1 -> 325 | T28: =N28 -> …. | U28: =O28 -> 0 | V28: =$S$2 -> ….. C.P.S. …... | W28: =$E$28 -> …......... | Y28: =Y27+1 -> 425 | Z28: =T28 -> …. | AA28: =U28 -> 0 | AB28: =$Y$2 -> NON SALVAGEABLE ITEMS | AC28: =$E$28 -> …......... | AE28: =AE27+1 -> 525 | AF28: …. | AG28: =AA28 -> 0 | AH28: =AH27 -> ,,,,,, DMO = DEMOLITION ….... | AI28: =E28 -> …......... | AK28: =AK27+1 -> 625 | AL28: . | AM28: =AA28 -> 0 | AN28: =AN27 -> … WTR MITIGATION EQUIPMENT & W.I.P . ... | AO28: =$E$28 -> …......... | AQ28: =AQ27+1 -> 725 | AR28: . | AS28: =AG28 -> 0 | AT28: =AT27 -> … HMR MITIGATION EQUIPMENT & W.I.P . ... | AU28: =$E$28 -> …......... | AW28: =AW27+1 -> 8025 | AX28: . | AY28: =C28 -> 0 | AZ28: =AZ27 -> … DAY # 0 … MC READINGS STABILIZATION | BD28: =BD27+1 -> 8125.1 | BE28: . | BF28: =AM28 -> 0 | BG28: =BG27 -> ... DAY1 MC READINGS .. | BI28: =$E$28 -> …......... | BK28: =BK27+1 -> 8225.2 | BL28: . | BM28: =BF28 -> 0 | BN28: =BN27 -> ... DAY2 MC READINGS .. | BO28: =$E$28 -> …......... | BQ28: =BQ27+1 -> 8325.3 | BR28: . | BS28: =BM28 -> 0 | BT28: =BT27 -> ... DAY3 MC READINGS .. | BU28: =$E$28 -> …......... | BW28: =BW27+1 -> 8425.4 | BX28: . | BY28: =BS28 -> 0 | BZ28: =BZ27 -> ... DAY4 MC READINGS | CA28: =$E$28 -> …......... | CN28: , | CX28: =C28 -> 0 | CY28: =E28 -> ….........
C30: FORMAT OF ROOM LISTS | BD30: ... MC READINGS .. | BK30: ... MC READINGS ..
C31: MUST BE 5 COLUMNS WIDE | BD31: ….. DAY 2 ….. | BK31: ….. DAY 3 …..
C32: LOGIC
C33: each work type will have leading numerical prefix
C34: Group work tpys together for easier field id of rooms ti capture picturs for
CR39: Bedroom 2 | CV39: NA
CV40: FCC CARPET/FCW
CV41: WALL/PLASTER
CV42: WALL/PLASTER

Sheet ROOMS-out
B1: ROOMS PREFIX CODE # | E1: OLD#
A2: 0.01 | B2: ='ROOMS#'!CL4 -> JOBSITE VERIFICATION
A4: 0.02 | B4: EXTERIOR DAMAGES | C4: ( IF APPLICABLE )
A6: 0.03 | B6: ='ROOMS#'!CL5 -> MECHANICALS = WATER METER READING & PLUMBING REPORT/INVOICE
A8: 0.04 | B8: ='ROOMS#'!CL6 -> MECHANICALS = ELECTRICAL HAZARDS | C8: ( IF APPLICABLE )
A10: 0.05 | B10: ='ROOMS#'!CL9 -> KITCHEN CABINETS SIZES | C10: ( IF APPLICABLE )
A12: 0.06 | B12: ='ROOMS#'!CL10 -> BATHROOM FIXTURES | C12: ( IF APPLICABLE )
A15: 100 | B15: ROOMS OVERVIEW | E15: 100
A17: 200 | B17: SOURCE of LOSS | E17: 200
A19: 300 | B19: CPS | E19: 300
A20: 3222 | B20: ='ROOMS#'!CL11 -> CPS DAY2 WIP
A21: 3322 | B21: ='ROOMS#'!CL12 -> CPS3 DAY3 STORAGE
A22: 3444 | B22: ='ROOMS#'!CL13 -> CPS4 DAY4 PACKBACK
A24: 400 | B24: PPR | E24: 400
A25: 411.1 | B25: ='ROOMS#'!CL14 -> REPLACEMENT 1 CON OVERVIEW DAY PICS,
A26: 422.2 | B26: ='ROOMS#'!CL15 -> REPLACEMENT 2 CON WIP,
